Workbook

Sheet Population Definitions
A1: Abbreviation | B1: Full Name | C1: Population type
A2: 0-4M_aus | B2: 0-4M_aus | C2: default
A3: 5-14M_aus | B3: 5-14M_aus | C3: default
A4: 15-29M_aus | B4: 15-29M_aus | C4: default
A5: 30-49M_aus | B5: 30-49M_aus | C5: default
A6: 50-64M_aus | B6: 50-64M_aus | C6: default
A7: 65+M_aus | B7: 65+M_aus | C7: default
A8: 0-4F_aus | B8: 0-4F_aus | C8: default
A9: 5-14F_aus | B9: 5-14F_aus | C9: default
A10: 15-29F_aus | B10: 15-29F_aus | C10: default
A11: 30-49F_aus | B11: 30-49F_aus | C11: default
A12: 50-64F_aus | B12: 50-64F_aus | C12: default
... A37: 65+F_fns | B37: 65+F_fns | C37: default

Sheet Demographics
A1: Total Population Size | B1: Provenance | C1: Units | D1: Uncertainty | E1: 1980 | F1: 1981 | G1: 1982 | H1: 1983 | I1: 1984 | J1: 1985 | K1: 1986 | L1: 1987 | M1: 1988 | N1: 1989 | O1: 1990 | P1: 1991 | Q1: 1992 | R1: 1993 | S1: 1994 | T1: 1995 | U1: 1996 | V1: 1997 | W1: 1998 | X1: 1999 | Y1: 2000 | Z1: 2001 | AA1: 2002 | AB1: 2003 | AC1: 2004 | AD1: 2005 | AE1: 2006 | AF1: 2007 | AG1: 2008 | AH1: 2009 | AI1: 2010 | AJ1: 2011 | AK1: 2012 | AL1: 2013 | AM1: 2014 | AN1: 2015 | AO1: 2016 | AP1: 2017 | AQ1: 2018 | AR1: 2019 | AS1: 2020 | AT1: 2021 | AU1: 2022 | AV1: 2023 | AW1: 2024 | AX1: 2025 | AY1: 2026 | AZ1: 2027 | BA1: 2028 | BB1: 2029 | BC1: 2030 | BD1: 2031 | BE1: 2032 | BF1: 2033 | BG1: 2034 | BH1: 2035 | BI1: 2036 | BJ1: 2037 | BK1: 2038 | BL1: 2039 | BM1: 2040 | BN1: 2041 | BO1: 2042 | BP1: 2043 | BQ1: 2044 | BR1: 2045 | BS1: 2046 | BT1: 2047 | BU1: 2048 | BV1: 2049 | BW1: 2050 | BX1: 2051 | BY1: 2052 | BZ1: 2053 | CA1: 2054 | CB1: 2055 | CC1: 2056 | CD1: 2057 | CE1: 2058 | CF1: 2059 | CG1: 2060 | CH1: 2061 | CI1: 2062 | CJ1: 2063 | CK1: 2064 | CL1: 2065 | CM1: 2066 | CN1: 2067 | CO1: 2068 | CP1: 2069 | CQ1: 2070 | CR1: 2071
A2: ='Population Definitions'!$B$2 -> 0-4M_aus | C2: Number | E2: 540734.46 | F2: 543109.4 | G2: 550721.62 | H2: 558266.28 | I2: 564096.7 | J2: 570466.22 | K2: 574329.34 | L2: 578330.41 | M2: 582405.91 | N2: 588817.7 | O2: 595804.87 | P2: 601601.66 | Q2: 606305.97 | R2: 609183.85 | S2: 610671.28 | T2: 609701.77 | U2: 606231.4 | V2: 605219.59 | W2: 601092.05 | X2: 596698.27 | Y2: 592192.92 | Z2: 590682.02 | AA2: 586772.07 | AB2: 585299.2 | AC2: 584713.18 | AD2: 587596.19 | AE2: 587943.37 | AF2: 606563.81 | AG2: 626851.4 | AH2: 645855.47 | AI2: 660004.92 | AJ2: 658843.13 | AK2: 675981.91 | AL2: 690684 | AM2: 699959.09 | AN2: 706836.08 | AO2: 717383.87 | AP2: 718705 | AQ2: 715073.17 | AR2: 712652.92 | AS2: 706458.96 | AT2: 697536.03 | AU2: 698848.25 | AV2: 700286.56 | AW2: 699100.88
A3: ='Population Definitions'!$B$3 -> 5-14M_aus | C3: Number | E3: 1201766.2 | F3: 1202532 | G3: 1202742 | H3: 1196337.8 | I3: 1179882.8 | J3: 1165385.2 | K3: 1146021.7 | L3: 1131694.2 | M3: 1129167.2 | N3: 1131018.9 | O3: 1135194.1 | P3: 1140497.2 | Q3: 1142860.6 | R3: 1145926.6 | S3: 1150577.4 | T3: 1159563.1 | U3: 1167765.7 | V3: 1171793 | W3: 1176812 | X3: 1184582 | Y3: 1192683.5 | Z3: 1198335.7 | AA3: 1199557 | AB3: 1198390.5 | AC3: 1196428.2 | AD3: 1191963.3 | AE3: 1184050.9 | AF3: 1175571.7 | AG3: 1168350.8 | AH3: 1165021.8 | AI3: 1164995.1 | AJ3: 1171724.2 | AK3: 1180048.5 | AL3: 1194472.2 | AM3: 1211761.3 | AN3: 1233073.9 | AO3: 1260998.3 | AP3: 1285761.6 | AQ3: 1313416.7 | AR3: 1337534.3 | AS3: 1360140.9 | AT3: 1378115.9 | AU3: 1385603.8 | AV3: 1393140.9 | AW3: 1395096.6
A4: ='Population Definitions'!$B$4 -> 15-29M_aus | C4: Number | E4: 1621065 | F4: 1635422 | G4: 1653941.1 | H4: 1660584.3 | I4: 1671148.5 | J4: 1690412.5 | K4: 1713891.3 | L4: 1731662.8 | M4: 1743209.1 | N4: 1749606.5 | O4: 1744005.6 | P4: 1719567 | Q4: 1690797.7 | R4: 1668459 | S4: 1649499.6 | T4: 1639948.7 | U4: 1635692.8 | V4: 1623717.3 | W4: 1611463.7 | X4: 1600280.2 | Y4: 1592713.5 | Z4: 1579646.7 | AA4: 1578067.1 | AB4: 1582584.1 | AC4: 1592794.7 | AD4: 1609654.1 | AE4: 1623468.9 | AF4: 1638096.8 | AG4: 1652751.7 | AH4: 1669306.6 | AI4: 1684195.5 | AJ4: 1725746.3 | AK4: 1734479.3 | AL4: 1738364.5 | AM4: 1739499.5 | AN4: 1738550.8 | AO4: 1756702.5 | AP4: 1753488.5 | AQ4: 1750062 | AR4: 1747078.6 | AS4: 1749089.8 | AT4: 1751996 | AU4: 1765457.5 | AV4: 1726319.2 | AW4: 1712254.4
A5: ='Population Definitions'!$B$5 -> 30-49M_aus | C5: Number | E5: 1318576.9 | F5: 1355379.8 | G5: 1411056.8 | H5: 1460100.5 | I5: 1503202.8 | J5: 1551980.6 | K5: 1602239.8 | L5: 1646097.6 | M5: 1695281 | N5: 1745369.3 | O5: 1792915.3 | P5: 1831613.6 | Q5: 1859987 | R5: 1901663.1 | S5: 1931241.8 | T5: 1952975.7 | U5: 1969766.4 | V5: 1965942.8 | W5: 1972169.2 | X5: 1986373.9 | Y5: 2001229.8 | Z5: 2019344.2 | AA5: 2035380.3 | AB5: 2037519.3 | AC5: 2039342.4 | AD5: 2031440.5 | AE5: 2032617.2 | AF5: 2034282.7 | AG5: 2033723.7 | AH5: 2033135.4 | AI5: 2032133.9 | AJ5: 2017246 | AK5: 2017575 | AL5: 2022313 | AM5: 2027038 | AN5: 2036473 | AO5: 2033866 | AP5: 2047628.7 | AQ5: 2059172.3 | AR5: 2068539.4 | AS5: 2084032.5 | AT5: 2066543.5 | AU5: 2065196.1 | AV5: 2046356.6 | AW5: 2034222.7
A6: ='Population Definitions'!$B$6 -> 50-64M_aus | C6: Number | E6: 646849.78 | F6: 649632.49 | G6: 655694.14 | H6: 661265.14 | I6: 667562.59 | J6: 668427.04 | K6: 668503.87 | L6: 662318.87 | M6: 658259.44 | N6: 655173.34 | O6: 654439.75 | P6: 651868.3 | Q6: 646561.95 | R6: 656913.85 | S6: 676487.19 | T6: 698999.74 | U6: 720633.09 | V6: 776378.47 | W6: 830818.57 | X6: 880763.38 | Y6: 932302.98 | Z6: 974915 | AA6: 1007600.6 | AB6: 1038421.7 | AC6: 1067592.4 | AD6: 1093494.4 | AE6: 1129159 | AF6: 1163305.6 | AG6: 1199073.6 | AH6: 1231698.5 | AI6: 1262130.3 | AJ6: 1293946 | AK6: 1311454 | AL6: 1331214 | AM6: 1349600.3 | AN6: 1359737.7 | AO6: 1358519.7 | AP6: 1368020 | AQ6: 1378680.4 | AR6: 1395425.3 | AS6: 1415092.3 | AT6: 1444303 | AU6: 1462242.6 | AV6: 1480756.1 | AW6: 1489712.4
A7: ='Population Definitions'!$B$7 -> 65+M_aus | C7: Number | E7: 322766.11 | F7: 333305.08 | G7: 346370.64 | H7: 355442.18 | I7: 366085.91 | J7: 383081.77 | K7: 405239.81 | L7: 423106.18 | M7: 437206.87 | N7: 453377.84 | O7: 466355.63 | P7: 483456.76 | Q7: 495102.86 | R7: 517787.21 | S7: 537278.49 | T7: 553084.92 | U7: 569097.84 | V7: 587203.9 | W7: 605730.67 | X7: 624929.62 | Y7: 643115.77 | Z7: 664520.07 | AA7: 681398.78 | AB7: 695365.21 | AC7: 712384.57 | AD7: 728491.17 | AE7: 742491.81 | AF7: 764003.14 | AG7: 783951.29 | AH7: 809966.08 | AI7: 840327.38 | AJ7: 857710.23 | AK7: 895588.16 | AL7: 929066 | AM7: 961822.17 | AN7: 997066.29 | AO7: 1029069.6 | AP7: 1066144.1 | AQ7: 1104418.8 | AR7: 1141708.5 | AS7: 1181517.5 | AT7: 1232353 | AU7: 1270889.3 | AV7: 1319509.2 | AW7: 1367153.5
A8: ='Population Definitions'!$B$8 -> 0-4F_aus | C8: Number | E8: 514618.56 | F8: 517814.32 | G8: 524132.48 | H8: 529757.29 | I8: 535733.04 | J8: 543338.41 | K8: 546474.35 | L8: 550444.99 | M8: 554927.5 | N8: 560435.58 | O8: 565372.25 | P8: 570625.62 | Q8: 575400.78 | R8: 577855.92 | S8: 579056.79 | T8: 578068.31 | U8: 574353.45 | V8: 572978.54 | W8: 568724.42 | X8: 565518.5 | Y8: 561808.26 | Z8: 560642.43 | AA8: 557124.16 | AB8: 555697.44 | AC8: 554436.23 | AD8: 555662.95 | AE8: 556881.82 | AF8: 573853.87 | AG8: 593164.84 | AH8: 611258.72 | AI8: 625204 | AJ8: 624011.13 | AK8: 640547.09 | AL8: 654612.23 | AM8: 664311.87 | AN8: 670952.04 | AO8: 680614.87 | AP8: 680797.91 | AQ8: 676574.04 | AR8: 672866.12 | AS8: 667049.18 | AT8: 659217.94 | AU8: 661649.33 | AV8: 663562.44 | AW8: 663837.88
A9: ='Population Definitions'!$B$9 -> 5-14F_aus | C9: Number | E9: 1151314 | F9: 1152079.3 | G9: 1151038.2 | H9: 1143629.2 | I9: 1126531 | J9: 1110724 | K9: 1089843.8 | L9: 1074818.6 | M9: 1070840.7 | N9: 1072982.9 | O9: 1077163.5 | P9: 1080839.5 | Q9: 1084308.6 | R9: 1088545.2 | S9: 1093986.1 | T9: 1103627.4 | U9: 1112155.5 | V9: 1116880.2 | W9: 1121953.4 | X9: 1128549.1 | Y9: 1134942.3 | Z9: 1139376.8 | AA9: 1139608.6 | AB9: 1137117.9 | AC9: 1134865.3 | AD9: 1131372.9 | AE9: 1124181.6 | AF9: 1116529.5 | AG9: 1109814.4 | AH9: 1106224.4 | AI9: 1105800.3 | AJ9: 1113086.9 | AK9: 1120186 | AL9: 1133621.8 | AM9: 1149064.5 | AN9: 1168722.1 | AO9: 1194620.6 | AP9: 1216632.6 | AQ9: 1240881.3 | AR9: 1263676.1 | AS9: 1285051.6 | AT9: 1301423 | AU9: 1309547.5 | AV9: 1317889.8 | AW9: 1319980.1
A10: ='Population Definitions'!$B$10 -> 15-29F_aus | C10: Number | E10: 1571071.4 | F10: 1584036.9 | G10: 1601351.2 | H10: 1606265.5 | I10: 1614646.8 | J10: 1629113.5 | K10: 1651162.5 | L10: 1673640.2 | M10: 1687982 | N10: 1695498.6 | O10: 1690914.8 | P10: 1670125.5 | Q10: 1642367 | R10: 1619753.8 | S10: 1600708.9 | T10: 1590727.3 | U10: 1588631.7 | V10: 1581753.7 | W10: 1571872 | X10: 1562650.7 | Y10: 1558501.7 | Z10: 1546119.8 | AA10: 1536454.2 | AB10: 1537835.9 | AC10: 1541364.7 | AD10: 1552803 | AE10: 1561094.9 | AF10: 1573699.6 | AG10: 1586162.2 | AH10: 1601049.5 | AI10: 1614375.5 | AJ10: 1644220.2 | AK10: 1654953.7 | AL10: 1660997.5 | AM10: 1664251.3 | AN10: 1665162.6 | AO10: 1681989 | AP10: 1675774.4 | AQ10: 1669121.6 | AR10: 1663106.7 | AS10: 1663221.7 | AT10: 1668072.8 | AU10: 1676297.4 | AV10: 1635632.5 | AW10: 1615402.7
A11: ='Population Definitions'!$B$11 -> 30-49F_aus | C11: Number | E11: 1214984.2 | F11: 1252203.6 | G11: 1305769.4 | H11: 1355526.4 | I11: 1402091.2 | J11: 1454231.6 | K11: 1504018.1 | L11: 1551265.4 | M11: 1602997.5 | N11: 1656036.2 | O11: 1708989.4 | P11: 1755990.4 | Q11: 1790482.5 | R11: 1839641.6 | S11: 1875187.8 | T11: 1902147.3 | U11: 1926720.6 | V11: 1936404.9 | W11: 1953699.7 | X11: 1976283.1 | Y11: 1996564.2 | Z11: 2020914.7 | AA11: 2036579.6 | AB11: 2040762.6 | AC11: 2041086.1 | AD11: 2030876 | AE11: 2029558.9 | AF11: 2031648.5 | AG11: 2030600.6 | AH11: 2029105.7 | AI11: 2026907.6 | AJ11: 2015329.6 | AK11: 2015967.7 | AL11: 2019758.1 | AM11: 2025192.4 | AN11: 2034298.2 | AO11: 2040515.9 | AP11: 2049057.4 | AQ11: 2055742.7 | AR11: 2058614.5 | AS11: 2067506.1 | AT11: 2052036 | AU11: 2049375.4 | AV11: 2037997.9 | AW11: 2029635.5
A12: ='Population Definitions'!$B$12 -> 50-64F_aus | C12: Number | E12: 669340.44 | F12: 672872.15 | G12: 672633.98 | H12: 672281.45 | I12: 673098.05 | J12: 670102.38 | K12: 664273.06 | L12: 656643.18 | M12: 650405.9 | N12: 645991.87 | O12: 642315.94 | P12: 638535.98 | Q12: 632553.17 | R12: 641906.92 | S12: 661502.39 | T12: 684327.9 | U12: 704900.58 | V12: 758293.57 | W12: 810310.99 | X12: 861453.55 | Y12: 914575.32 | Z12: 962163.13 | AA12: 1000597.8 | AB12: 1037547.5 | AC12: 1074010.5 | AD12: 1108249.4 | AE12: 1142144.3 | AF12: 1175438.4 | AG12: 1210660 | AH12: 1242121 | AI12: 1271692.1 | AJ12: 1304245.3 | AK12: 1324701 | AL12: 1349057.3 | AM12: 1370709.6 | AN12: 1384338.3 | AO12: 1388946.5 | AP12: 1399972.7 | AQ12: 1410456.2 | AR12: 1426214.7 | AS12: 1442748.2 | AT12: 1476019.1 | AU12: 1495059.5 | AV12: 1514282.7 | AW12: 1523540.6
A13: ='Population Definitions'!$B$13 -> 65+F_aus | C13: Number | E13: 524982.81 | F13: 541788.99 | G13: 562265.18 | H13: 579079.56 | I13: 596163.44 | J13: 618057.66 | K13: 644861.89 | L13: 665369.91 | M13: 683382.29 | N13: 701474.58 | O13: 715496.63 | P13: 733686.08 | Q13: 745385.44 | R13: 769682.2 | S13: 789706.85 | T13: 805149.78 | U13: 821577.73 | V13: 839278.19 | W13: 857271.23 | X13: 875427.39 | Y13: 893669.97 | Z13: 912601.56 | AA13: 925239.87 | AB13: 935826.05 | AC13: 949235.96 | AD13: 961080.91 | AE13: 971713.32 | AF13: 989932.38 | AG13: 1006994.5 | AH13: 1029583.6 | AI13: 1056552 | AJ13: 1070542.8 | AK13: 1103995.9 | AL13: 1132871.7 | AM13: 1161676.6 | AN13: 1192532.1 | AO13: 1219491.8 | AP13: 1254563.4 | AQ13: 1291969.8 | AR13: 1329917.6 | AS13: 1370518.9 | AT13: 1429110.4 | AU13: 1470023.2 | AV13: 1520874.1 | AW13: 1571721.8
A14: ='Population Definitions'!$B$14 -> 0-4M_oth | C14: Number | E14: 11027.418 | F14: 11308.226 | G14: 11505.991 | H14: 11721.157 | I14: 11920.031 | J14: 12079.879 | K14: 12314.808 | L14: 12683.042 | M14: 13074.7 | N14: 13483.475 | O14: 13872.84 | P14: 14305.111 | Q14: 14851.936 | R14: 14919.77 | S14: 15064.156 | T14: 15299.098 | U14: 15620.016 | V14: 15789.948 | W14: 15879.672 | X14: 15985.146 | Y14: 16099.146 | Z14: 16378.088 | AA14: 16708.882 | AB14: 17119.801 | AC14: 17450.47 | AD14: 17940.082 | AE14: 24809.851 | AF14: 26760.039 | AG14: 29220.082 | AH14: 30649.958 | AI14: 29540.079 | AJ14: 32889.868 | AK14: 34570.09 | AL14: 35580 | AM14: 34849.912 | AN14: 33739.915 | AO14: 34300.127 | AP14: 34570 | AQ14: 33219.835 | AR14: 31950.08 | AS14: 28510.036 | AT14: 22759.971 | AU14: 21509.751 | AV14: 25141.441 | AW14: 28503.119
A15: ='Population Definitions'!$B$15 -> 5-14M_oth | C15: Number | E15: 69372.788 | F15: 71139.335 | G15: 72383.462 | H15: 73737.058 | I15: 74988.158 | J15: 75993.756 | K15: 77471.674 | L15: 79788.212 | M15: 82252.108 | N15: 84823.689 | O15: 87273.159 | P15: 89992.549 | Q15: 93432.585 | R15: 93859.329 | S15: 94767.648 | T15: 96245.655 | U15: 98264.529 | V15: 99333.564 | W15: 99898.012 | X15: 100561.54 | Y15: 101278.71 | Z15: 103033.51 | AA15: 105114.52 | AB15: 107699.58 | AC15: 109779.8 | AD15: 112859.92 | AE15: 119659.66 | AF15: 127010.37 | AG15: 135949.71 | AH15: 144769.07 | AI15: 148959.89 | AJ15: 155289.78 | AK15: 162220.45 | AL15: 168139.77 | AM15: 172069.65 | AN15: 174240.12 | AO15: 170829.67 | AP15: 177099.44 | AQ15: 180380.34 | AR15: 183380.67 | AS15: 183730.11 | AT15: 175760.11 | AU15: 173720.21 | AV15: 180370.14 | AW15: 187257.39
A16: ='Population Definitions'!$B$16 -> 15-29M_oth | C16: Number | E16: 248570.99 | F16: 254900.74 | G16: 259358.6 | H16: 264208.69 | I16: 268691.53 | J16: 272294.71 | K16: 277590.26 | L16: 285890.7 | M16: 294719.13 | N16: 303933.41 | O16: 312710.16 | P16: 322454.06 | Q16: 334780.12 | R16: 336309.19 | S16: 339563.81 | T16: 344859.68 | U16: 352093.55 | V16: 355924.03 | W16: 357946.52 | X16: 360324.02 | Y16: 362893.72 | Z16: 369181.39 | AA16: 376637.89 | AB16: 385900.47 | AC16: 393354.15 | AD16: 404390.58 | AE16: 429159 | AF16: 474788.5 | AG16: 534437.9 | AH16: 595572.01 | AI16: 611659.49 | AJ16: 578590.72 | AK16: 596550.73 | AL16: 615541.5 | AM16: 629920.51 | AN16: 647149.22 | AO16: 649698.46 | AP16: 680530.53 | AQ16: 709160 | AR16: 736409.44 | AS16: 708949.18 | AT16: 628560 | AU16: 655195.51 | AV16: 759641.77 | AW16: 819366.63
A17: ='Population Definitions'!$B$17 -> 30-49M_oth | C17: Number | E17: 513995.29 | F17: 527083.94 | G17: 536301.91 | H17: 546330.94 | I17: 555600.56 | J17: 563051.21 | K17: 574001.37 | L17: 591165.01 | M17: 609420.45 | N17: 628473.75 | O17: 646622.31 | P17: 666770.75 | Q17: 692258.59 | R17: 695420.41 | S17: 702150.31 | T17: 713101.12 | U17: 728059.32 | V17: 735979.99 | W17: 740162.09 | X17: 745078.28 | Y17: 750391.91 | Z17: 763393.56 | AA17: 778812.12 | AB17: 797965.3 | AC17: 813378.01 | AD17: 836199.15 | AE17: 848779.14 | AF17: 869881.74 | AG17: 898467.92 | AH17: 928968.48 | AI17: 949598.15 | AJ17: 988540 | AK17: 1026732 | AL17: 1061868 | AM17: 1084580 | AN17: 1108778 | AO17: 1150059 | AP17: 1192829.3 | AQ17: 1231616.7 | AR17: 1268292.6 | AS17: 1299298.5 | AT17: 1323298.5 | AU17: 1352863.9 | AV17: 1427201.4 | AW17: 1492140.3
A18: ='Population Definitions'!$B$18 -> 50-64M_oth | C18: Number | E18: 377812.49 | F18: 387433.31 | G18: 394208.98 | H18: 401580.82 | I18: 408394.46 | J18: 413871.06 | K18: 421919.98 | L18: 434536.13 | M18: 447954.8 | N18: 461959.93 | O18: 475300.04 | P18: 490110.16 | Q18: 508845.01 | R18: 511169.11 | S18: 516115.92 | T18: 524165.33 | U18: 535160.36 | V18: 540982.45 | W18: 544056.5 | X18: 547670.15 | Y18: 551575.94 | Z18: 561132.8 | AA18: 572466.22 | AB18: 586544.78 | AC18: 597873.9 | AD18: 614648.59 | AE18: 624061.05 | AF18: 635379.31 | AG18: 646998.63 | AH18: 656746.93 | AI18: 667089.66 | AJ18: 676687.98 | AK18: 681519 | AL18: 687789 | AM18: 693580.66 | AN18: 699538.34 | AO18: 714887.31 | AP18: 725310 | AQ18: 735097.63 | AR18: 746680.68 | AS18: 764772.73 | AT18: 764787.98 | AU18: 770958.41 | AV18: 784795.87 | AW18: 797115.59
A19: ='Population Definitions'!$B$19 -> 65+M_oth | C19: Number | E19: 265854.32 | F19: 272624.18 | G19: 277391.99 | H19: 282579.32 | I19: 287373.85 | J19: 291227.56 | K19: 296891.32 | L19: 305768.89 | M19: 315211.17 | N19: 325066.13 | O19: 334453.13 | P19: 344874.53 | Q19: 358057.63 | R19: 359693.02 | S19: 363173.93 | T19: 368838.03 | U19: 376574.88 | V19: 380671.69 | W19: 382834.8 | X19: 385377.61 | Y19: 388125.99 | Z19: 394850.84 | AA19: 402825.8 | AB19: 412732.42 | AC19: 420704.35 | AD19: 432508.15 | AE19: 446288.88 | AF19: 462367.76 | AG19: 477748.5 | AH19: 495481.13 | AI19: 514249.62 | AJ19: 548510.77 | AK19: 574118.84 | AL19: 599510 | AM19: 622318.83 | AN19: 642412.71 | AO19: 667728.44 | AP19: 685716.9 | AQ19: 703299.23 | AR19: 722518.47 | AS19: 753688.46 | AT19: 760660 | AU19: 774748.7 | AV19: 797668.83 | AW19: 821524.47
A20: ='Population Definitions'!$B$20 -> 0-4F_oth | C20: Number | E20: 10695.371 | F20: 10967.724 | G20: 11159.534 | H20: 11368.221 | I20: 11561.107 | J20: 11716.142 | K20: 11943.996 | L20: 12301.143 | M20: 12681.007 | N20: 13077.474 | O20: 13455.115 | P20: 13874.37 | Q20: 14404.729 | R20: 14470.521 | S20: 14610.559 | T20: 14838.427 | U20: 15149.681 | V20: 15314.497 | W20: 15401.519 | X20: 15503.817 | Y20: 15614.385 | Z20: 15884.927 | AA20: 16205.761 | AB20: 16604.306 | AC20: 16925.019 | AD20: 17399.888 | AE20: 23620.075 | AF20: 25619.921 | AG20: 27720.041 | AH20: 29269.789 | AI20: 28040 | AJ20: 31169.868 | AK20: 32869.91 | AL20: 33479.774 | AM20: 32930.132 | AN20: 31929.958 | AO20: 33000.129 | AP20: 32960.086 | AQ20: 31519.959 | AR20: 30219.88 | AS20: 27189.818 | AT20: 21600.059 | AU20: 20389.667 | AV20: 23814.556 | AW20: 27054.123
A21: ='Population Definitions'!$B$21 -> 5-14F_oth | C21: Number | E21: 65512.794 | F21: 67181.047 | G21: 68355.95 | H21: 69634.23 | I21: 70815.717 | J21: 71765.362 | K21: 73161.047 | L21: 75348.69 | M21: 77675.491 | N21: 80103.986 | O21: 82417.164 | P21: 84985.244 | Q21: 88233.872 | R21: 88636.871 | S21: 89494.65 | T21: 90890.419 | U21: 92796.96 | V21: 93806.512 | W21: 94339.554 | X21: 94966.163 | Y21: 95643.427 | Z21: 97300.59 | AA21: 99265.808 | AB21: 101707.03 | AC21: 103671.51 | AD21: 106580.24 | AE21: 113019.4 | AF21: 120379.82 | AG21: 128750.58 | AH21: 137260.52 | AI21: 141609.68 | AJ21: 146660.11 | AK21: 152850 | AL21: 158419.2 | AM21: 161880.46 | AN21: 163709.89 | AO21: 161380.44 | AP21: 167130.45 | AQ21: 170020.67 | AR21: 173219.89 | AS21: 173339.45 | AT21: 165340 | AU21: 164168.54 | AV21: 170612.17 | AW21: 177312.86
A22: ='Population Definitions'!$B$22 -> 15-29F_oth | C22: Number | E22: 244077.32 | F22: 250292.64 | G22: 254669.91 | H22: 259432.32 | I22: 263834.12 | J22: 267372.16 | K22: 272571.99 | L22: 280722.37 | M22: 289391.2 | N22: 298438.9 | O22: 307056.98 | P22: 316624.73 | Q22: 328727.96 | R22: 330229.39 | S22: 333425.17 | T22: 338625.31 | U22: 345728.4 | V22: 349489.63 | W22: 351475.56 | X22: 353810.08 | Y22: 356333.32 | Z22: 362507.32 | AA22: 369829.02 | AB22: 378924.16 | AC22: 386243.09 | AD22: 397080 | AE22: 421847.97 | AF22: 456729.36 | AG22: 504527.92 | AH22: 554448.77 | AI22: 576627.48 | AJ22: 563569.76 | AK22: 585239.25 | AL22: 606950.51 | AM22: 627058.7 | AN22: 647788.4 | AO22: 656030 | AP22: 685890.55 | AQ22: 709809.43 | AR22: 725218.27 | AS22: 693380.28 | AT22: 606979.24 | AU22: 626608.55 | AV22: 723520.54 | AW22: 781503.33
A23: ='Population Definitions'!$B$23 -> 30-49F_oth | C23: Number | E23: 537597.21 | F23: 551286.88 | G23: 560928.11 | H23: 571417.66 | I23: 581112.93 | J23: 588905.71 | K23: 600358.68 | L23: 618310.45 | M23: 637404.16 | N23: 657332.35 | O23: 676314.27 | P23: 697387.9 | Q23: 724046.1 | R23: 727353.11 | S23: 734392.03 | T23: 745845.69 | U23: 761490.75 | V23: 769775.12 | W23: 774149.26 | X23: 779291.2 | Y23: 784848.82 | Z23: 798447.48 | AA23: 814574.04 | AB23: 834606.71 | AC23: 850727.15 | AD23: 874596.2 | AE23: 887517.35 | AF23: 908131.5 | AG23: 935098.78 | AH23: 964268.44 | AI23: 985798.42 | AJ23: 1020057.4 | AK23: 1054380.3 | AL23: 1089566.9 | AM23: 1120967.6 | AN23: 1154591.8 | AO23: 1197992.1 | AP23: 1247059.6 | AQ23: 1293359.3 | AR23: 1339488.5 | AS23: 1379421.9 | AT23: 1402090 | AU23: 1438358.6 | AV23: 1513684.1 | AW23: 1579986.5
A24: ='Population Definitions'!$B$24 -> 50-64F_oth | C24: Number | E24: 367152.9 | F24: 376502.28 | G24: 383086.78 | H24: 390250.63 | I24: 396872.03 | J24: 402194.12 | K24: 410015.95 | L24: 422276.14 | M24: 435316.22 | N24: 448926.21 | O24: 461889.94 | P24: 476282.21 | Q24: 494488.48 | R24: 496747 | S24: 501554.25 | T24: 509376.54 | U24: 520061.36 | V24: 525719.19 | W24: 528706.51 | X24: 532218.21 | Y24: 536013.79 | Z24: 545301.02 | AA24: 556314.68 | AB24: 569996.03 | AC24: 581005.51 | AD24: 597306.92 | AE24: 614069.66 | AF24: 631287.26 | AG24: 648459.66 | AH24: 663507.61 | AI24: 679846.93 | AJ24: 694410.68 | AK24: 704217.96 | AL24: 716551.69 | AM24: 729791.36 | AN24: 742179.66 | AO24: 761546.55 | AP24: 776058.26 | AQ24: 788403.84 | AR24: 804129.3 | AS24: 832102.85 | AT24: 819037.92 | AU24: 825459.48 | AV24: 842000.33 | AW24: 856702.36
A25: ='Population Definitions'!$B$25 -> 65+F_oth | C25: Number | E25: 286183.73 | F25: 293471.27 | G25: 298603.67 | H25: 304187.66 | I25: 309348.83 | J25: 313497.22 | K25: 319594.08 | L25: 329150.5 | M25: 339314.82 | N25: 349923.37 | O25: 360028.17 | P25: 371246.48 | Q25: 385437.67 | R25: 387198.11 | S25: 390945.21 | T25: 397042.43 | U25: 405370.9 | V25: 409780.99 | W25: 412109.51 | X25: 414846.76 | Y25: 417805.3 | Z25: 425044.39 | AA25: 433629.18 | AB25: 444293.34 | AC25: 452874.88 | AD25: 465581.29 | AE25: 478779.02 | AF25: 494928.68 | AG25: 510493.67 | AH25: 528941.01 | AI25: 548322.03 | AJ25: 581816.16 | AK25: 608722.11 | AL25: 635339.29 | AM25: 660290.36 | AN25: 683678.92 | AO25: 714658.17 | AP25: 737679.63 | AQ25: 761388.17 | AR25: 788860.37 | AS25: 828728.14 | AT25: 835629.64 | AU25: 857933.83 | AV25: 890348.93 | AW25: 922455.24
A26: ='Population Definitions'!$B$26 -> 0-4M_fns | C26: Number | E26: 27483.295 | F26: 28134.126 | G26: 28800.37 | H26: 29482.391 | I26: 30180.563 | J26: 30895.268 | K26: 31626.898 | L26: 32375.854 | M26: 33142.546 | N26: 33927.394 | O26: 34730.828 | P26: 35553.288 | Q26: 36395.225 | R26: 37257.099 | S26: 38139.384 | T26: 39042.562 | U26: 39967.128 | V26: 40913.588 | W26: 41882.462 | X26: 42874.28 | Y26: 43889.585 | Z26: 44928.933 | AA26: 45992.894 | AB26: 47082.051 | AC26: 48197 | AD26: 49338.352 | AE26: 50506.733 | AF26: 51702.781 | AG26: 52927.154 | AH26: 54180.521 | AI26: 55463.568 | AJ26: 56777 | AK26: 56794 | AL26: 56670 | AM26: 56576 | AN26: 56399 | AO26: 56462 | AP26: 56209 | AQ26: 55735 | AR26: 55483 | AS26: 55049 | AT26: 54602 | AU26: 55603 | AV26: 56883 | AW26: 58194 | AX26: 60002 | AY26: 62014 | AZ26: 62989 | BA26: 63955 | BB26: 64927 | BC26: 65887 | BD26: 66808 | BE26: 67533.161 | BF26: 68310.795 | BG26: 69195.246 | BH26: 70156.822 | BI26: 71187.072 | BJ26: 72260.788 | BK26: 73361.774 | BL26: 74506.235 | BM26: 75670.625 | BN26: 76853.425 | BO26: 78043.612 | BP26: 79231.406 | BQ26: 80422.534 | BR26: 81620.935 | BS26: 82829.485 | BT26: 84041.091 | BU26: 85263.528 | BV26: 86500.094 | BW26: 87764.268 | BX26: 89064.977 | BY26: 90389.823 | BZ26: 91733.871 | CA26: 93115.095 | CB26: 94536.228 | CC26: 95992.367 | CD26: 97485.986 | CE26: 99013.777 | CF26: 100564.61 | CG26: 102135.23 | CH26: 103732.32 | CI26: 105346.68 | CJ26: 106988.55 | CK26: 108654.48 | CL26: 110342.71 | CM26: 112052.51 | CN26: 113796.03 | CO26: 115553.31 | CP26: 117330.22 | CQ26: 119131.96 | CR26: 120953.07
A27: ='Population Definitions'!$B$27 -> 5-14M_fns | C27: Number | E27: 45488.757 | F27: 46565.976 | G27: 47668.703 | H27: 48797.545 | I27: 49953.119 | J27: 51136.057 | K27: 52347.009 | L27: 53586.638 | M27: 54855.622 | N27: 56154.656 | O27: 57484.454 | P27: 58845.742 | Q27: 60239.267 | R27: 61665.791 | S27: 63126.098 | T27: 64620.985 | U27: 66151.274 | V27: 67717.8 | W27: 69321.424 | X27: 70963.023 | Y27: 72643.497 | Z27: 74363.766 | AA27: 76124.773 | AB27: 77927.482 | AC27: 79772.881 | AD27: 81661.981 | AE27: 83595.817 | AF27: 85575.447 | AG27: 87601.958 | AH27: 89676.458 | AI27: 91800.084 | AJ27: 93974 | AK27: 96734 | AL27: 99395 | AM27: 101836 | AN27: 104106 | AO27: 105957 | AP27: 107839 | AQ27: 109854 | AR27: 111546 | AS27: 112481 | AT27: 113060 | AU27: 112825 | AV27: 112228 | AW27: 111883 | AX27: 111275 | AY27: 110892 | AZ27: 111640 | BA27: 112447 | BB27: 113506 | BC27: 114881 | BD27: 116445 | BE27: 118416 | BF27: 120341.57 | BG27: 122236.2 | BH27: 124123.55 | BI27: 126019.3 | BJ27: 127935.99 | BK27: 129880.09 | BL27: 131854.29 | BM27: 133864.2 | BN27: 135910.32 | BO27: 137992.79 | BP27: 140109.62 | BQ27: 142257.1 | BR27: 144432.97 | BS27: 146635.97 | BT27: 148865.5 | BU27: 151119.66 | BV27: 153398.2 | BW27: 155701.59 | BX27: 158032.82 | BY27: 160396.36 | BZ27: 162793.86 | CA27: 165225.82 | CB27: 167696.22 | CC27: 170209.17 | CD27: 172767.44 | CE27: 175374.04 | CF27: 178031.04 | CG27: 180738.15 | CH27: 183494.47 | CI27: 186300.49 | CJ27: 189154.88 | CK27: 192058.4 | CL27: 195011.09 | CM27: 198012.62 | CN27: 201062.58 | CO27: 204162.93 | CP27: 207311.59 | CQ27: 210507.8 | CR27: 213751.89
A28: ='Population Definitions'!$B$28 -> 15-29M_fns | C28: Number | E28: 50294.958 | F28: 51485.991 | G28: 52705.23 | H28: 53953.342 | I28: 55231.01 | J28: 56538.934 | K28: 57877.831 | L28: 59248.435 | M28: 60651.496 | N28: 62087.782 | O28: 63558.082 | P28: 65063.2 | Q28: 66603.96 | R28: 68181.207 | S28: 69795.804 | T28: 71448.637 | U28: 73140.611 | V28: 74872.652 | W28: 76645.71 | X28: 78460.755 | Y28: 80318.783 | Z28: 82220.81 | AA28: 84167.879 | AB28: 86161.057 | AC28: 88201.435 | AD28: 90290.132 | AE28: 92428.29 | AF28: 94617.083 | AG28: 96857.708 | AH28: 99151.393 | AI28: 101499.4 | AJ28: 103903 | AK28: 106816 | AL28: 109773 | AM28: 112680 | AN28: 115772 | AO28: 118837 | AP28: 121883 | AQ28: 124763 | AR28: 127468 | AS28: 130440 | AT28: 133338 | AU28: 136924 | AV28: 140434 | AW28: 143810 | AX28: 146744 | AY28: 149403 | AZ28: 152157 | BA28: 154674 | BB28: 157005 | BC28: 159081 | BD28: 160984 | BE28: 162591 | BF28: 164290.33 | BG28: 166072.32 | BH28: 167929.25 | BI28: 169856.05 | BJ28: 171849.44 | BK28: 173907.54 | BL28: 176029.14 | BM28: 178213.39 | BN28: 180460.01 | BO28: 182768.79 | BP28: 185139.52 | BQ28: 187571.85 | BR28: 190065.07 | BS28: 192618.32 | BT28: 195230.65 | BU28: 197901.14 | BV28: 200628.71 | BW28: 203412.34 | BX28: 206251.11 | BY28: 209144.43 | BZ28: 212092.17 | CA28: 215094.37 | CB28: 218151.1 | CC28: 221262.81 | CD28: 224430.32 | CE28: 227654.65 | CF28: 230937.04 | CG28: 234278.88 | CH28: 237681.42 | CI28: 241145.78 | CJ28: 244673.03 | CK28: 248264.08 | CL28: 251919.85 | CM28: 255641.2 | CN28: 259428.92 | CO28: 263283.72 | CP28: 267206.44 | CQ28: 271197.68 | CR28: 275257.93
A29: ='Population Definitions'!$B$29 -> 30-49M_fns | C29: Number | E29: 46262.28 | F29: 47357.816 | G29: 48479.296 | H29: 49627.333 | I29: 50802.557 | J29: 52005.611 | K29: 53237.155 | L29: 54497.863 | M29: 55788.425 | N29: 57109.55 | O29: 58461.96 | P29: 59846.396 | Q29: 61263.617 | R29: 62714.4 | S29: 64199.538 | T29: 65719.846 | U29: 67276.156 | V29: 68869.322 | W29: 70500.214 | X29: 72169.729 | Y29: 73878.778 | Z29: 75628.3 | AA29: 77419.252 | AB29: 79252.616 | AC29: 81129.395 | AD29: 83050.619 | AE29: 85017.339 | AF29: 87030.633 | AG29: 89091.603 | AH29: 91201.379 | AI29: 93361.117 | AJ29: 95572 | AK29: 96524 | AL29: 97789 | AM29: 99133 | AN29: 100402 | AO29: 101863 | AP29: 103312 | AQ29: 104810 | AR29: 106662 | AS29: 108455 | AT29: 110255 | AU29: 112094 | AV29: 114493 | AW29: 117182 | AX29: 120399 | AY29: 123582 | AZ29: 126928 | BA29: 130778 | BB29: 134598 | BC29: 138498 | BD29: 142180 | BE29: 145839 | BF29: 149447.52 | BG29: 153012.8 | BH29: 156541.22 | BI29: 160038.49 | BJ29: 163509.81 | BK29: 166959.98 | BL29: 170393.51 | BM29: 173814.68 | BN29: 177227.53 | BO29: 180635.96 | BP29: 184043.66 | BQ29: 187454.21 | BR29: 190871.02 | BS29: 194297.3 | BT29: 197736.11 | BU29: 201190.34 | BV29: 204662.71 | BW29: 208155.77 | BX29: 211671.9 | BY29: 215213.37 | BZ29: 218782.29 | CA29: 222380.71 | CB29: 226010.58 | CC29: 229673.8 | CD29: 233372.19 | CE29: 237107.59 | CF29: 240881.79 | CG29: 244696.6 | CH29: 248553.83 | CI29: 252455.3 | CJ29: 256402.8 | CK29: 260398.15 | CL29: 264443.12 | CM29: 268539.48 | CN29: 272688.97 | CO29: 276893.31 | CP29: 281154.19 | CQ29: 285473.3 | CR29: 289852.28
A30: ='Population Definitions'!$B$30 -> 50-64M_fns | C30: Number | E30: 19531.209 | F30: 19993.728 | G30: 20467.199 | H30: 20951.882 | I30: 21448.043 | J30: 21955.954 | K30: 22475.892 | L30: 23008.143 | M30: 23552.998 | N30: 24110.757 | O30: 24681.723 | P30: 25266.21 | Q30: 25864.539 | R30: 26477.036 | S30: 27104.038 | T30: 27745.889 | U30: 28402.938 | V30: 29075.548 | W30: 29764.085 | X30: 30468.928 | Y30: 31190.462 | Z30: 31929.083 | AA30: 32685.195 | AB30: 33459.212 | AC30: 34251.559 | AD30: 35062.669 | AE30: 35892.988 | AF30: 36742.969 | AG30: 37613.078 | AH30: 38503.793 | AI30: 39415.6 | AJ30: 40349 | AK30: 42260 | AL30: 44044 | AM30: 45944 | AN30: 47611 | AO30: 49129 | AP30: 50705 | AQ30: 52290 | AR30: 53845 | AS30: 55526 | AT30: 57503 | AU30: 59193 | AV30: 60665 | AW30: 61721 | AX30: 62499 | AY30: 63086 | AZ30: 63495 | BA30: 63752 | BB30: 64072 | BC30: 64418 | BD30: 65134 | BE30: 65828.917 | BF30: 66606.653 | BG30: 67459.951 | BH30: 68382.288 | BI30: 69367.799 | BJ30: 70411.206 | BK30: 71507.766 | BL30: 72653.215 | BM30: 73843.734 | BN30: 75075.905 | BO30: 76346.679 | BP30: 77653.345 | BQ30: 78993.504 | BR30: 80365.038 | BS30: 81766.093 | BT30: 83195.047 | BU30: 84650.496 | BV30: 86131.23 | BW30: 87636.214 | BX30: 89164.572 | BY30: 90715.568 | BZ30: 92288.598 | CA30: 93883.168 | CB30: 95498.893 | CC30: 97135.479 | CD30: 98792.721 | CE30: 100470.49 | CF30: 102168.73 | CG30: 103887.45 | CH30: 105626.72 | CI30: 107386.69 | CJ30: 109167.53 | CK30: 110969.49 | CL30: 112792.86 | CM30: 114637.96 | CN30: 116505.16 | CO30: 118394.87 | CP30: 120307.54 | CQ30: 122243.63 | CR30: 124203.65
A31: ='Population Definitions'!$B$31 -> 65+M_fns | C31: Number | E31: 5988.7512 | F31: 6130.5707 | G31: 6275.7486 | H31: 6424.3645 | I31: 6576.4997 | J31: 6732.2377 | K31: 6891.6636 | L31: 7054.865 | M31: 7221.9311 | N31: 7392.9535 | O31: 7568.0258 | P31: 7747.2441 | Q31: 7930.7064 | R31: 8118.5133 | S31: 8310.7677 | T31: 8507.5748 | U31: 8709.0425 | V31: 8915.2811 | W31: 9126.4037 | X31: 9342.5259 | Y31: 9563.766 | Z31: 9790.2454 | AA31: 10022.088 | AB31: 10259.421 | AC31: 10502.374 | AD31: 10751.08 | AE31: 11005.677 | AF31: 11266.302 | AG31: 11533.099 | AH31: 11806.214 | AI31: 12085.797 | AJ31: 12372 | AK31: 13381 | AL31: 14470 | AM31: 15454 | AN31: 16596 | AO31: 17808 | AP31: 19048 | AQ31: 20331 | AR31: 21620 | AS31: 23099 | AT31: 24600 | AU31: 26097 | AV31: 27565 | AW31: 29127 | AX31: 30761 | AY31: 32582 | AZ31: 34355 | BA31: 36088 | BB31: 37822 | BC31: 39487 | BD31: 41087 | BE31: 42708.593 | BF31: 44291.721 | BG31: 45842.723 | BH31: 47367.238 | BI31: 48870.287 | BJ31: 50356.333 | BK31: 51829.339 | BL31: 53292.824 | BM31: 54749.907 | BN31: 56203.352 | BO31: 57655.604 | BP31: 59108.83 | BQ31: 60564.945 | BR31: 62025.64 | BS31: 63492.415 | BT31: 64966.596 | BU31: 66449.357 | BV31: 67941.741 | BW31: 69444.677 | BX31: 70958.991 | BY31: 72485.424 | BZ31: 74024.642 | CA31: 75577.245 | CB31: 77143.78 | CC31: 78724.745 | CD31: 80320.601 | CE31: 81931.772 | CF31: 83558.66 | CG31: 85201.641 | CH31: 86861.075 | CI31: 88537.312 | CJ31: 90230.687 | CK31: 91941.535 | CL31: 93670.185 | CM31: 95416.968 | CN31: 97182.216 | CO31: 98966.266 | CP31: 100769.46 | CQ31: 102592.16 | CR31: 104434.71
A32: ='Population Definitions'!$B$32 -> 0-4F_fns | C32: Number | E32: 26354.959 | F32: 26979.07 | G32: 27617.961 | H32: 28271.981 | I32: 28941.489 | J32: 29626.852 | K32: 30328.445 | L32: 31046.652 | M32: 31781.867 | N32: 32534.493 | O32: 33304.941 | P32: 34093.635 | Q32: 34901.006 | R32: 35727.496 | S32: 36573.558 | T32: 37439.655 | U32: 38326.263 | V32: 39233.866 | W32: 40162.963 | X32: 41114.061 | Y32: 42087.682 | Z32: 43084.36 | AA32: 44104.64 | AB32: 45149.081 | AC32: 46218.255 | AD32: 47312.748 | AE32: 48433.161 | AF32: 49580.105 | AG32: 50754.211 | AH32: 51956.12 | AI32: 53186.492 | AJ32: 54446 | AK32: 54406 | AL32: 54051 | AM32: 53443 | AN32: 52981 | AO32: 52647 | AP32: 52118 | AQ32: 51664 | AR32: 51545 | AS32: 51291 | AT32: 51196 | AU32: 52284 | AV32: 53769 | AW32: 55318 | AX32: 57042 | AY32: 58854 | AZ32: 59777 | BA32: 60692 | BB32: 61612 | BC32: 62520 | BD32: 63392 | BE32: 64127.196 | BF32: 64903.668 | BG32: 65774.865 | BH32: 66713.873 | BI32: 67713.741 | BJ32: 68751.346 | BK32: 69811.977 | BL32: 70911.64 | BM32: 72028.372 | BN32: 73161.099 | BO32: 74299.621 | BP32: 75434.867 | BQ32: 76572.485 | BR32: 77716.383 | BS32: 78869.426 | BT32: 80024.959 | BU32: 81190.471 | BV32: 82369.167 | BW32: 83573.936 | BX32: 84813.323 | BY32: 86075.556 | BZ32: 87355.96 | CA32: 88671.676 | CB32: 90025.326 | CC32: 91412.251 | CD32: 92834.822 | CE32: 94289.897 | CF32: 95766.878 | CG32: 97262.685 | CH32: 98783.675 | CI32: 100321.1 | CJ32: 101884.7 | CK32: 103471.2 | CL32: 105078.94 | CM32: 106707.2 | CN32: 108367.58 | CO32: 110041.04 | CP32: 111733.2 | CQ32: 113449 | CR32: 115183.25
A33: ='Population Definitions'!$B$33 -> 5-14F_fns | C33: Number | E33: 43249.026 | F33: 44273.206 | G33: 45321.638 | H33: 46394.899 | I33: 47493.576 | J33: 48618.27 | K33: 49769.598 | L33: 50948.191 | M33: 52154.694 | N33: 53389.768 | O33: 54654.09 | P33: 55948.353 | Q33: 57273.264 | R33: 58629.551 | S33: 60017.956 | T33: 61439.24 | U33: 62894.182 | V33: 64383.578 | W33: 65908.244 | X33: 67469.015 | Y33: 69066.748 | Z33: 70702.316 | AA33: 72376.616 | AB33: 74090.565 | AC33: 75845.102 | AD33: 77641.188 | AE33: 79479.808 | AF33: 81361.967 | AG33: 83288.698 | AH33: 85261.056 | AI33: 87280.121 | AJ33: 89347 | AK33: 92004 | AL33: 94604 | AM33: 97062 | AN33: 99409 | AO33: 101247 | AP33: 103303 | AQ33: 104911 | AR33: 106134 | AS33: 106913 | AT33: 106984 | AU33: 106417 | AV33: 105610 | AW33: 104885 | AX33: 104171 | AY33: 103746 | AZ33: 104304 | BA33: 105334 | BB33: 106764 | BC33: 108234 | BD33: 109951 | BE33: 111958 | BF33: 113919.65 | BG33: 115848.23 | BH33: 117765.24 | BI33: 119684.95 | BJ33: 121618.91 | BK33: 123573.14 | BL33: 125550.2 | BM33: 127555.53 | BN33: 129589.81 | BO33: 131653.43 | BP33: 133744.75 | BQ33: 135860.55 | BR33: 137998.99 | BS33: 140159.17 | BT33: 142340.83 | BU33: 144542.43 | BV33: 146764.05 | BW33: 149006.37 | BX33: 151272.51 | BY33: 153566.98 | BZ33: 155891.54 | CA33: 158246.91 | CB33: 160637.06 | CC33: 163066.11 | CD33: 165536.86 | CE33: 168052.34 | CF33: 170614.66 | CG33: 173223.69 | CH33: 175878.71 | CI33: 178580.3 | CJ33: 181327.28 | CK33: 184120.49 | CL33: 186960.03 | CM33: 189845.7 | CN33: 192777.15 | CO33: 195756.33 | CP33: 198781.3 | CQ33: 201851.42 | CR33: 204967.03
A34: ='Population Definitions'!$B$34 -> 15-29F_fns | C34: Number | E34: 49178.723 | F34: 50343.323 | G34: 51535.502 | H34: 52755.913 | I34: 54005.225 | J34: 55284.121 | K34: 56593.303 | L34: 57933.488 | M34: 59305.41 | N34: 60709.82 | O34: 62147.488 | P34: 63619.201 | Q34: 65125.766 | R34: 66668.008 | S34: 68246.772 | T34: 69862.922 | U34: 71517.345 | V34: 73210.945 | W34: 74944.652 | X34: 76719.415 | Y34: 78536.206 | Z34: 80396.02 | AA34: 82299.876 | AB34: 84248.818 | AC34: 86243.912 | AD34: 88286.253 | AE34: 90376.957 | AF34: 92517.172 | AG34: 94708.069 | AH34: 96950.849 | AI34: 99246.74 | AJ34: 101597 | AK34: 104349 | AL34: 106854 | AM34: 109514 | AN34: 112025 | AO34: 114673 | AP34: 117221 | AQ34: 119817 | AR34: 122257 | AS34: 124939 | AT34: 127779 | AU34: 131085 | AV34: 134285 | AW34: 137428 | AX34: 140375 | AY34: 143108 | AZ34: 145718 | BA34: 147957 | BB34: 149801 | BC34: 151679 | BD34: 153181 | BE34: 154697 | BF34: 156314.05 | BG34: 158022.12 | BH34: 159812.89 | BI34: 161680.53 | BJ34: 163620.89 | BK34: 165631.14 | BL34: 167709.17 | BM34: 169853.23 | BN34: 172062.18 | BO34: 174335.02 | BP34: 176670.83 | BQ34: 179068.6 | BR34: 181527.06 | BS34: 184044.85 | BT34: 186620.62 | BU34: 189253.05 | BV34: 191940.76 | BW34: 194682.46 | BX34: 197476.98 | BY34: 200323.53 | BZ34: 203221.79 | CA34: 206171.6 | CB34: 209172.9 | CC34: 212226 | CD34: 215331.55 | CE34: 218490.47 | CF34: 221703.89 | CG34: 224973.06 | CH34: 228299.17 | CI34: 231683.25 | CJ34: 235126.35 | CK34: 238629.33 | CL34: 242193.1 | CM34: 245818.49 | CN34: 249506.31 | CO34: 253257.26 | CP34: 257072.2 | CQ34: 260951.73 | CR34: 264896.39
A35: ='Population Definitions'!$B$35 -> 30-49F_fns | C35: Number | E35: 48714.996 | F35: 49868.615 | G35: 51049.553 | H35: 52258.456 | I35: 53495.987 | J35: 54762.825 | K35: 56059.662 | L35: 57387.21 | M35: 58746.195 | N35: 60137.362 | O35: 61561.474 | P35: 63019.31 | Q35: 64511.669 | R35: 66039.368 | S35: 67603.245 | T35: 69204.156 | U35: 70842.978 | V35: 72520.609 | W35: 74237.968 | X35: 75995.996 | Y35: 77795.655 | Z35: 79637.933 | AA35: 81523.837 | AB35: 83454.401 | AC35: 85430.683 | AD35: 87453.765 | AE35: 89524.756 | AF35: 91644.79 | AG35: 93815.028 | AH35: 96036.66 | AI35: 98310.902 | AJ35: 100639 | AK35: 101455 | AL35: 102493 | AM35: 103586 | AN35: 104863 | AO35: 106285 | AP35: 107508 | AQ35: 108582 | AR35: 109806 | AS35: 111373 | AT35: 112917 | AU35: 114624 | AV35: 116697 | AW35: 119061 | AX35: 121813 | AY35: 124612 | AZ35: 127722 | BA35: 130815 | BB35: 133936 | BC35: 137222 | BD35: 140522 | BE35: 143752 | BF35: 146942.47 | BG35: 150100.7 | BH35: 153233.08 | BI35: 156345.32 | BJ35: 159442.57 | BK35: 162529.54 | BL35: 165610.58 | BM35: 168689.78 | BN35: 171770.95 | BO35: 174857.71 | BP35: 177953.45 | BQ35: 181061.4 | BR35: 184184.61 | BS35: 187325.92 | BT35: 190488 | BU35: 193673.33 | BV35: 196884.22 | BW35: 200122.82 | BX35: 203391.1 | BY35: 206690.92 | BZ35: 210024 | CA35: 213391.99 | CB35: 216796.44 | CC35: 220238.87 | CD35: 223720.73 | CE35: 227243.48 | CF35: 230808.55 | CG35: 234417.39 | CH35: 238071.45 | CI35: 241772.22 | CJ35: 245521.17 | CK35: 249319.77 | CL35: 253169.5 | CM35: 257071.8 | CN35: 261028.15 | CO35: 265039.97 | CP35: 269108.7 | CQ35: 273235.75 | CR35: 277422.52
A36: ='Population Definitions'!$B$36 -> 50-64F_fns | C36: Number | E36: 20457.21 | F36: 20941.657 | G36: 21437.576 | H36: 21945.239 | I36: 22464.923 | J36: 22996.915 | K36: 23541.504 | L36: 24098.99 | M36: 24669.678 | N36: 25253.88 | O36: 25851.916 | P36: 26464.115 | Q36: 27090.811 | R36: 27732.348 | S36: 28389.077 | T36: 29061.358 | U36: 29749.56 | V36: 30454.058 | W36: 31175.24 | X36: 31913.5 | Y36: 32669.243 | Z36: 33442.883 | AA36: 34234.843 | AB36: 35045.558 | AC36: 35875.471 | AD36: 36725.037 | AE36: 37594.722 | AF36: 38485.002 | AG36: 39396.364 | AH36: 40329.309 | AI36: 41284.346 | AJ36: 42262 | AK36: 44506 | AL36: 46895 | AM36: 48996 | AN36: 50953 | AO36: 52801 | AP36: 54677 | AQ36: 56624 | AR36: 58601 | AS36: 60504 | AT36: 62727 | AU36: 64667 | AV36: 66276 | AW36: 67522 | AX36: 68386 | AY36: 68840 | AZ36: 69189 | BA36: 69543 | BB36: 70069 | BC36: 70473 | BD36: 71143 | BE36: 71591.636 | BF36: 72128.484 | BG36: 72746.313 | BH36: 73438.633 | BI36: 74199.611 | BJ36: 75024.007 | BK36: 75907.112 | BL36: 76844.696 | BM36: 77832.968 | BN36: 78868.533 | BO36: 79948.358 | BP36: 81069.74 | BQ36: 82230.28 | BR36: 83427.851 | BS36: 84660.579 | BT36: 85926.813 | BU36: 87225.113 | BV36: 88554.219 | BW36: 89913.04 | BX36: 91300.634 | BY36: 92716.195 | BZ36: 94159.036 | CA36: 95628.576 | CB36: 97124.335 | CC36: 98645.92 | CD36: 100193.02 | CE36: 101765.39 | CF36: 103362.88 | CG36: 104985.36 | CH36: 106632.79 | CI36: 108305.18 | CJ36: 110002.6 | CK36: 111725.16 | CL36: 113473.01 | CM36: 115246.36 | CN36: 117045.45 | CO36: 118870.55 | CP36: 120721.99 | CQ36: 122600.1 | CR36: 124505.26
A37: ='Population Definitions'!$B$37 -> 65+F_fns | C37: Number | E37: 7189.2122 | F37: 7359.4597 | G37: 7533.739 | H37: 7712.1453 | I37: 7894.7764 | J37: 8081.7324 | K37: 8273.1158 | L37: 8469.0312 | M37: 8669.5862 | N37: 8874.8905 | O37: 9085.0566 | P37: 9300.1996 | Q37: 9520.4374 | R37: 9745.8907 | S37: 9976.6829 | T37: 10212.941 | U37: 10454.793 | V37: 10702.373 | W37: 10955.815 | X37: 11215.26 | Y37: 11480.848 | Z37: 11752.726 | AA37: 12031.042 | AB37: 12315.949 | AC37: 12607.602 | AD37: 12906.163 | AE37: 13211.793 | AF37: 13524.662 | AG37: 13844.939 | AH37: 14172.8 | AI37: 14508.426 | AJ37: 14852 | AK37: 15950 | AL37: 16958 | AM37: 18137 | AN37: 19444 | AO37: 20806 | AP37: 22255 | AQ37: 23826 | AR37: 25447 | AS37: 27053 | AT37: 28748 | AU37: 30369 | AV37: 32051 | AW37: 33828 | AX37: 35718 | AY37: 37917 | AZ37: 40054 | BA37: 42224 | BB37: 44277 | BC37: 46300 | BD37: 48261 | BE37: 50284.706 | BF37: 52249.019 | BG37: 54161.453 | BH37: 56028.794 | BI37: 57857.174 | BJ37: 59652.134 | BK37: 61418.688 | BL37: 63161.368 | BM37: 64884.277 | BN37: 66591.129 | BO37: 68285.291 | BP37: 69969.812 | BQ37: 71647.464 | BR37: 73320.763 | BS37: 74991.999 | BT37: 76663.26 | BU37: 78336.451 | BV37: 80013.317 | BW37: 81695.457 | BX37: 83384.341 | BY37: 85081.322 | BZ37: 86787.654 | CA37: 88504.495 | CB37: 90232.926 | CC37: 91973.951 | CD37: 93728.512 | CE37: 95497.493 | CF37: 97281.727 | CG37: 99082.004 | CH37: 100899.07 | CI37: 102733.65 | CJ37: 104586.42 | CK37: 106458.04 | CL37: 108349.15 | CM37: 110260.38 | CN37: 112192.34 | CO37: 114145.61 | CP37: 116120.78 | CQ37: 118118.43 | CR37: 120139.15
A39: Annual Livebirths | B39: Provenance | C39: Units | D39: Uncertainty | E39: Constant | G39: 1980 | H39: 1981 | I39: 1982 | J39: 1983 | K39: 1984 | L39: 1985 | M39: 1986 | N39: 1987 | O39: 1988 | P39: 1989 | Q39: 1990 | R39: 1991 | S39: 1992 | T39: 1993 | U39: 1994 | V39: 1995 | W39: 1996 | X39: 1997 | Y39: 1998 | Z39: 1999 | AA39: 2000 | AB39: 2001 | AC39: 2002 | AD39: 2003 | AE39: 2004 | AF39: 2005 | AG39: 2006 | AH39: 2007 | AI39: 2008 | AJ39: 2009 | AK39: 2010 | AL39: 2011 | AM39: 2012 | AN39: 2013 | AO39: 2014 | AP39: 2015 | AQ39: 2016 | AR39: 2017 | AS39: 2018 | AT39: 2019 | AU39: 2020 | AV39: 2021 | AW39: 2022 | AX39: 2023 | AY39: 2024 | AZ39: 2025 | BA39: 2026 | BB39: 2027 | BC39: 2028 | BD39: 2029 | BE39: 2030 | BF39: 2031 | BG39: 2032 | BH39: 2033 | BI39: 2034 | BJ39: 2035 | BK39: 2036 | BL39: 2037 | BM39: 2038 | BN39: 2039 | BO39: 2040 | BP39: 2041 | BQ39: 2042 | BR39: 2043 | BS39: 2044 | BT39: 2045 | BU39: 2046 | BV39: 2047 | BW39: 2048 | BX39: 2049 | BY39: 2050 | BZ39: 2051 | CA39: 2052 | CB39: 2053 | CC39: 2054 | CD39: 2055 | CE39: 2056 | CF39: 2057 | CG39: 2058 | CH39: 2059 | CI39: 2060 | CJ39: 2061 | CK39: 2062 | CL39: 2063 | CM39: 2064 | CN39: 2065 | CO39: 2066 | CP39: 2067 | CQ39: 2068 | CR39: 2069 | CS39: 2070 | CT39: 2071
A40: ='Population Definitions'!$B$2 -> 0-4M_aus | C40: Number (per year) | F40: OR | G40: 109112.79 | H40: 114243.09 | I40: 116134.04 | J40: 117426.56 | K40: 112599 | L40: 119325.92 | M40: 117380.61 | N40: 117586.11 | O40: 118357.32 | P40: 120516.74 | Q40: 127096.92 | R40: 123797.44 | S40: 127255.99 | T40: 125127.88 | U40: 123999.24 | V40: 122672.43 | W40: 121606.44 | X40: 120074.18 | Y40: 118762.17 | Z40: 117920.31 | AA40: 118626.04 | AB40: 116573.02 | AC40: 118697.28 | AD40: 119084.77 | AE40: 120319.98 | AF40: 125370.17 | AG40: 128711.32 | AH40: 139106.23 | AI40: 144011.45 | AJ40: 143482.97 | AK40: 143974.42 | AL40: 143151.13 | AM40: 147078.86 | AN40: 146876.12 | AO40: 141912.36 | AP40: 145355.53 | AQ40: 148015.42 | AR40: 147785.91 | AS40: 150562.72 | AT40: 146071.37 | AU40: 139781.35 | AV40: 146514.03 | AW40: 141640.42 | AX40: 143454.74 | AY40: 144312.73 | AZ40: 144929.67 | BA40: 145338.59 | BB40: 145559.96 | BC40: 146168.52 | BD40: 146742.37 | BE40: 147331.42 | BF40: 148131.26 | BG40: 148793.23 | BH40: 149567.15 | BI40: 150543.35 | BJ40: 151682.19 | BK40: 152971.15 | BL40: 154333.37 | BM40: 155712.82 | BN40: 157073.46 | BO40: 158335.02 | BP40: 159457.26 | BQ40: 160392.41 | BR40: 161117.2 | BS40: 161655.08 | BT40: 162009.76 | BU40: 162210.2 | BV40: 162272.74 | BW40: 162233.15 | BX40: 162110.97 | BY40: 161929.37 | BZ40: 161746.36 | CA40: 161573.09 | CB40: 161417.21 | CC40: 161299.41 | CD40: 161228.66 | CE40: 161199.57 | CF40: 161208.42 | CG40: 161263.26 | CH40: 161382.92 | CI40: 161545.7 | CJ40: 161768.6 | CK40: 162029 | CL40: 162342.81 | CM40: 162706.96 | CN40: 163125.61 | CO40: 163576.89 | CP40: 164066.34 | CQ40: 164574.86 | CR40: 165092.05 | CS40: 165612.35
A41: ='Population Definitions'!$B$3 -> 5-14M_aus | C41: Number (per year) | E41: 0 | F41: OR
...

Sheet Transfers
A1: Abbreviation | B1: Full Name | C1: From population type | D1: To population type
A2: age | B2: aging | C2: default | D2: default
B4: ='Population Definitions'!$B$2 -> 0-4M_aus | C4: ='Population Definitions'!$B$3 -> 5-14M_aus | D4: ='Population Definitions'!$B$4 -> 15-29M_aus | E4: ='Population Definitions'!$B$5 -> 30-49M_aus | F4: ='Population Definitions'!$B$6 -> 50-64M_aus | G4: ='Population Definitions'!$B$7 -> 65+M_aus | H4: ='Population Definitions'!$B$8 -> 0-4F_aus | I4: ='Population Definitions'!$B$9 -> 5-14F_aus | J4: ='Population Definitions'!$B$10 -> 15-29F_aus | K4: ='Population Definitions'!$B$11 -> 30-49F_aus | L4: ='Population Definitions'!$B$12 -> 50-64F_aus | M4: ='Population Definitions'!$B$13 -> 65+F_aus | N4: ='Population Definitions'!$B$14 -> 0-4M_oth | O4: ='Population Definitions'!$B$15 -> 5-14M_oth | P4: ='Population Definitions'!$B$16 -> 15-29M_oth | Q4: ='Population Definitions'!$B$17 -> 30-49M_oth | R4: ='Population Definitions'!$B$18 -> 50-64M_oth | S4: ='Population Definitions'!$B$19 -> 65+M_oth | T4: ='Population Definitions'!$B$20 -> 0-4F_oth | U4: ='Population Definitions'!$B$21 -> 5-14F_oth | V4: ='Population Definitions'!$B$22 -> 15-29F_oth | W4: ='Population Definitions'!$B$23 -> 30-49F_oth | X4: ='Population Definitions'!$B$24 -> 50-64F_oth | Y4: ='Population Definitions'!$B$25 -> 65+F_oth | Z4: ='Population Definitions'!$B$26 -> 0-4M_fns | AA4: ='Population Definitions'!$B$27 -> 5-14M_fns | AB4: ='Population Definitions'!$B$28 -> 15-29M_fns | AC4: ='Population Definitions'!$B$29 -> 30-49M_fns | AD4: ='Population Definitions'!$B$30 -> 50-64M_fns | AE4: ='Population Definitions'!$B$31 -> 65+M_fns | AF4: ='Population Definitions'!$B$32 -> 0-4F_fns | AG4: ='Population Definitions'!$B$33 -> 5-14F_fns | AH4: ='Population Definitions'!$B$34 -> 15-29F_fns | AI4: ='Population Definitions'!$B$35 -> 30-49F_fns | AJ4: ='Population Definitions'!$B$36 -> 50-64F_fns | AK4: ='Population Definitions'!$B$37 -> 65+F_fns
A5: ='Population Definitions'!$B$2 -> 0-4M_aus | B5: N.A. | C5: Y | D5: N | E5: N | F5: N | G5: N | H5: N | I5: N | J5: N | K5: N | L5: N | M5: N | N5: N | O5: N | P5: N | Q5: N | R5: N | S5: N | T5: N | U5: N | V5: N | W5: N | X5: N | Y5: N | Z5: N | AA5: N | AB5: N | AC5: N | AD5: N | AE5: N | AF5: N | AG5: N | AH5: N | AI5: N | AJ5: N | AK5: N
A6: ='Population Definitions'!$B$3 -> 5-14M_aus | B6: N | C6: N.A. | D6: Y | E6: N | F6: N | G6: N | H6: N | I6: N | J6: N | K6: N | L6: N | M6: N | N6: N | O6: N | P6: N | Q6: N | R6: N | S6: N | T6: N | U6: N | V6: N | W6: N | X6: N | Y6: N | Z6: N | AA6: N | AB6: N | AC6: N | AD6: N | AE6: N | AF6: N | AG6: N | AH6: N | AI6: N | AJ6: N | AK6: N
A7: ='Population Definitions'!$B$4 -> 15-29M_aus | B7: N | C7: N | D7: N.A. | E7: Y | F7: N | G7: N | H7: N | I7: N | J7: N | K7: N | L7: N | M7: N | N7: N | O7: N | P7: N | Q7: N | R7: N | S7: N | T7: N | U7: N | V7: N | W7: N | X7: N | Y7: N | Z7: N | AA7: N | AB7: N | AC7: N | AD7: N | AE7: N | AF7: N | AG7: N | AH7: N | AI7: N | AJ7: N | AK7: N
A8: ='Population Definitions'!$B$5 -> 30-49M_aus | B8: N | C8: N | D8: N | E8: N.A. | F8: Y | G8: N | H8: N | I8: N | J8: N | K8: N | L8: N | M8: N | N8: N | O8: N | P8: N | Q8: N | R8: N | S8: N | T8: N | U8: N | V8: N | W8: N | X8: N | Y8: N | Z8: N | AA8: N | AB8: N | AC8: N | AD8: N | AE8: N | AF8: N | AG8: N | AH8: N | AI8: N | AJ8: N | AK8: N
A9: ='Population Definitions'!$B$6 -> 50-64M_aus | B9: N | C9: N | D9: N | E9: N | F9: N.A. | G9: Y | H9: N | I9: N | J9: N | K9: N | L9: N | M9: N | N9: N | O9: N | P9: N | Q9: N | R9: N | S9: N | T9: N | U9: N | V9: N | W9: N | X9: N | Y9: N | Z9: N | AA9: N | AB9: N | AC9: N | AD9: N | AE9: N | AF9: N | AG9: N | AH9: N | AI9: N | AJ9: N | AK9: N
A10: ='Population Definitions'!$B$7 -> 65+M_aus | B10: N | C10: N | D10: N | E10: N | F10: N | G10: N.A. | H10: N | I10: N | J10: N | K10: N | L10: N | M10: N | N10: N | O10: N | P10: N | Q10: N | R10: N | S10: N | T10: N | U10: N | V10: N | W10: N | X10: N | Y10: N | Z10: N | AA10: N | AB10: N | AC10: N | AD10: N | AE10: N | AF10: N | AG10: N | AH10: N | AI10: N | AJ10: N | AK10: N
A11: ='Population Definitions'!$B$8 -> 0-4F_aus | B11: N | C11: N | D11: N | E11: N | F11: N | G11: N | H11: N.A. | I11: Y | J11: N | K11: N | L11: N | M11: N | N11: N | O11: N | P11: N | Q11: N | R11: N | S11: N | T11: N | U11: N | V11: N | W11: N | X11: N | Y11: N | Z11: N | AA11: N | AB11: N | AC11: N | AD11: N | AE11: N | AF11: N | AG11: N | AH11: N | AI11: N | AJ11: N | AK11: N
A12: ='Population Definitions'!$B$9 -> 5-14F_aus | B12: N | C12: N | D12: N | E12: N | F12: N | G12: N | H12: N | I12: N.A. | J12: Y | K12: N | L12: N | M12: N | N12: N | O12: N | P12: N | Q12: N | R12: N | S12: N | T12: N | U12: N | V12: N | W12: N | X12: N | Y12: N | Z12: N | AA12: N | AB12: N | AC12: N | AD12: N | AE12: N | AF12: N | AG12: N | AH12: N | AI12: N | AJ12: N | AK12: N
A13: ='Population Definitions'!$B$10 -> 15-29F_aus | B13: N | C13: N | D13: N | E13: N | F13: N | G13: N | H13: N | I13: N | J13: N.A. | K13: Y | L13: N | M13: N | N13: N | O13: N | P13: N | Q13: N | R13: N | S13: N | T13: N | U13: N | V13: N | W13: N | X13: N | Y13: N | Z13: N | AA13: N | AB13: N | AC13: N | AD13: N | AE13: N | AF13: N | AG13: N | AH13: N | AI13: N | AJ13: N | AK13: N
A14: ='Population Definitions'!$B$11 -> 30-49F_aus | B14: N | C14: N | D14: N | E14: N | F14: N | G14: N | H14: N | I14: N | J14: N | K14: N.A. | L14: Y | M14: N | N14: N | O14: N | P14: N | Q14: N | R14: N | S14: N | T14: N | U14: N | V14: N | W14: N | X14: N | Y14: N | Z14: N | AA14: N | AB14: N | AC14: N | AD14: N | AE14: N | AF14: N | AG14: N | AH14: N | AI14: N | AJ14: N | AK14: N
A15: ='Population Definitions'!$B$12 -> 50-64F_aus | B15: N | C15: N | D15: N | E15: N | F15: N | G15: N | H15: N | I15: N | J15: N | K15: N | L15: N.A. | M15: Y | N15: N | O15: N | P15: N | Q15: N | R15: N | S15: N | T15: N | U15: N | V15: N | W15: N | X15: N | Y15: N | Z15: N | AA15: N | AB15: N | AC15: N | AD15: N | AE15: N | AF15: N | AG15: N | AH15: N | AI15: N | AJ15: N | AK15: N
A16: ='Population Definitions'!$B$13 -> 65+F_aus | B16: N | C16: N | D16: N | E16: N | F16: N | G16: N | H16: N | I16: N | J16: N | K16: N | L16: N | M16: N.A. | N16: N | O16: N | P16: N | Q16: N | R16: N | S16: N | T16: N | U16: N | V16: N | W16: N | X16: N | Y16: N | Z16: N | AA16: N | AB16: N | AC16: N | AD16: N | AE16: N | AF16: N | AG16: N | AH16: N | AI16: N | AJ16: N | AK16: N
A17: ='Population Definitions'!$B$14 -> 0-4M_oth | B17: N | C17: N | D17: N | E17: N | F17: N | G17: N | H17: N | I17: N | J17: N | K17: N | L17: N | M17: N | N17: N.A. | O17: Y | P17: N | Q17: N | R17: N | S17: N | T17: N | U17: N | V17: N | W17: N | X17: N | Y17: N | Z17: N | AA17: N | AB17: N | AC17: N | AD17: N | AE17: N | AF17: N | AG17: N | AH17: N | AI17: N | AJ17: N | AK17: N
A18: ='Population Definitions'!$B$15 -> 5-14M_oth | B18: N | C18: N | D18: N | E18: N | F18: N | G18: N | H18: N | I18: N | J18: N | K18: N | L18: N | M18: N | N18: N | O18: N.A. | P18: Y | Q18: N | R18: N | S18: N | T18: N | U18: N | V18: N | W18: N | X18: N | Y18: N | Z18: N | AA18: N | AB18: N | AC18: N | AD18: N | AE18: N | AF18: N | AG18: N | AH18: N | AI18: N | AJ18: N | AK18: N
A19: ='Population Definitions'!$B$16 -> 15-29M_oth | B19: N | C19: N | D19: N | E19: N | F19: N | G19: N | H19: N | I19: N | J19: N | K19: N | L19: N | M19: N | N19: N | O19: N | P19: N.A. | Q19: Y | R19: N | S19: N | T19: N | U19: N | V19: N | W19: N | X19: N | Y19: N | Z19: N | AA19: N | AB19: N | AC19: N | AD19: N | AE19: N | AF19: N | AG19: N | AH19: N | AI19: N | AJ19: N | AK19: N
A20: ='Population Definitions'!$B$17 -> 30-49M_oth | B20: N | C20: N | D20: N | E20: N | F20: N | G20: N | H20: N | I20: N | J20: N | K20: N | L20: N | M20: N | N20: N | O20: N | P20: N | Q20: N.A. | R20: Y | S20: N | T20: N | U20: N | V20: N | W20: N | X20: N | Y20: N | Z20: N | AA20: N | AB20: N | AC20: N | AD20: N | AE20: N | AF20: N | AG20: N | AH20: N | AI20: N | AJ20: N | AK20: N
A21: ='Population Definitions'!$B$18 -> 50-64M_oth | B21: N | C21: N | D21: N | E21: N | F21: N | G21: N | H21: N | I21: N | J21: N | K21: N | L21: N | M21: N | N21: N | O21: N | P21: N | Q21: N | R21: N.A. | S21: Y | T21: N | U21: N | V21: N | W21: N | X21: N | Y21: N | Z21: N | AA21: N | AB21: N | AC21: N | AD21: N | AE21: N | AF21: N | AG21: N | AH21: N | AI21: N | AJ21: N | AK21: N
A22: ='Population Definitions'!$B$19 -> 65+M_oth | B22: N | C22: N | D22: N | E22: N | F22: N | G22: N | H22: N | I22: N | J22: N | K22: N | L22: N | M22: N | N22: N | O22: N | P22: N | Q22: N | R22: N | S22: N.A. | T22: N | U22: N | V22: N | W22: N | X22: N | Y22: N | Z22: N | AA22: N | AB22: N | AC22: N | AD22: N | AE22: N | AF22: N | AG22: N | AH22: N | AI22: N | AJ22: N | AK22: N
A23: ='Population Definitions'!$B$20 -> 0-4F_oth | B23: N | C23: N | D23: N | E23: N | F23: N | G23: N | H23: N | I23: N | J23: N | K23: N | L23: N | M23: N | N23: N | O23: N | P23: N | Q23: N | R23: N | S23: N | T23: N.A. | U23: Y | V23: N | W23: N | X23: N | Y23: N | Z23: N | AA23: N | AB23: N | AC23: N | AD23: N | AE23: N | AF23: N | AG23: N | AH23: N | AI23: N | AJ23: N | AK23: N
A24: ='Population Definitions'!$B$21 -> 5-14F_oth | B24: N | C24: N | D24: N | E24: N | F24: N | G24: N | H24: N | I24: N | J24: N | K24: N | L24: N | M24: N | N24: N | O24: N | P24: N | Q24: N | R24: N | S24: N | T24: N | U24: N.A. | V24: Y | W24: N | X24: N | Y24: N | Z24: N | AA24: N | AB24: N | AC24: N | AD24: N | AE24: N | AF24: N | AG24: N | AH24: N | AI24: N | AJ24: N | AK24: N
A25: ='Population Definitions'!$B$22 -> 15-29F_oth | B25: N | C25: N | D25: N | E25: N | F25: N | G25: N | H25: N | I25: N | J25: N | K25: N | L25: N | M25: N | N25: N | O25: N | P25: N | Q25: N | R25: N | S25: N | T25: N | U25: N | V25: N.A. | W25: Y | X25: N | Y25: N | Z25: N | AA25: N | AB25: N | AC25: N | AD25: N | AE25: N | AF25: N | AG25: N | AH25: N | AI25: N | AJ25: N | AK25: N
A26: ='Population Definitions'!$B$23 -> 30-49F_oth | B26: N | C26: N | D26: N | E26: N | F26: N | G26: N | H26: N | I26: N | J26: N | K26: N | L26: N | M26: N | N26: N | O26: N | P26: N | Q26: N | R26: N | S26: N | T26: N | U26: N | V26: N | W26: N.A. | X26: Y | Y26: N | Z26: N | AA26: N | AB26: N | AC26: N | AD26: N | AE26: N | AF26: N | AG26: N | AH26: N | AI26: N | AJ26: N | AK26: N
A27: ='Population Definitions'!$B$24 -> 50-64F_oth | B27: N | C27: N | D27: N | E27: N | F27: N | G27: N | H27: N | I27: N | J27: N | K27: N | L27: N | M27: N | N27: N | O27: N | P27: N | Q27: N | R27: N | S27: N | T27: N | U27: N | V27: N | W27: N | X27: N.A. | Y27: Y | Z27: N | AA27: N | AB27: N | AC27: N | AD27: N | AE27: N | AF27: N | AG27: N | AH27: N | AI27: N | AJ27: N | AK27: N
A28: ='Population Definitions'!$B$25 -> 65+F_oth | B28: N | C28: N | D28: N | E28: N | F28: N | G28: N | H28: N | I28: N | J28: N | K28: N | L28: N | M28: N | N28: N | O28: N | P28: N | Q28: N | R28: N | S28: N | T28: N | U28: N | V28: N | W28: N | X28: N | Y28: N.A. | Z28: N | AA28: N | AB28: N | AC28: N | AD28: N | AE28: N | AF28: N | AG28: N | AH28: N | AI28: N | AJ28: N | AK28: N
A29: ='Population Definitions'!$B$26 -> 0-4M_fns | B29: N | C29: N | D29: N | E29: N | F29: N | G29: N | H29: N | I29: N | J29: N | K29: N | L29: N | M29: N | N29: N | O29: N | P29: N | Q29: N | R29: N | S29: N | T29: N | U29: N | V29: N | W29: N | X29: N | Y29: N | Z29: N.A. | AA29: Y | AB29: N | AC29: N | AD29: N | AE29: N | AF29: N | AG29: N | AH29: N | AI29: N | AJ29: N | AK29: N
A30: ='Population Definitions'!$B$27 -> 5-14M_fns | B30: N | C30: N | D30: N | E30: N | F30: N | G30: N | H30: N | I30: N | J30: N | K30: N | L30: N | M30: N | N30: N | O30: N | P30: N | Q30: N | R30: N | S30: N | T30: N | U30: N | V30: N | W30: N | X30: N | Y30: N | Z30: N | AA30: N.A. | AB30: Y | AC30: N | AD30: N | AE30: N | AF30: N | AG30: N | AH30: N | AI30: N | AJ30: N | AK30: N
A31: ='Population Definitions'!$B$28 -> 15-29M_fns | B31: N | C31: N | D31: N | E31: N | F31: N | G31: N | H31: N | I31: N | J31: N | K31: N | L31: N | M31: N | N31: N | O31: N | P31: N | Q31: N | R31: N | S31: N | T31: N | U31: N | V31: N | W31: N | X31: N | Y31: N | Z31: N | AA31: N | AB31: N.A. | AC31: Y | AD31: N | AE31: N | AF31: N | AG31: N | AH31: N | AI31: N | AJ31: N | AK31: N
A32: ='Population Definitions'!$B$29 -> 30-49M_fns | B32: N | C32: N | D32: N | E32: N | F32: N | G32: N | H32: N | I32: N | J32: N | K32: N | L32: N | M32: N | N32: N | O32: N | P32: N | Q32: N | R32: N | S32: N | T32: N | U32: N | V32: N | W32: N | X32: N | Y32: N | Z32: N | AA32: N | AB32: N | AC32: N.A. | AD32: Y | AE32: N | AF32: N | AG32: N | AH32: N | AI32: N | AJ32: N | AK32: N
A33: ='Population Definitions'!$B$30 -> 50-64M_fns | B33: N | C33: N | D33: N | E33: N | F33: N | G33: N | H33: N | I33: N | J33: N | K33: N | L33: N | M33: N | N33: N | O33: N | P33: N | Q33: N | R33: N | S33: N | T33: N | U33: N | V33: N | W33: N | X33: N | Y33: N | Z33: N | AA33: N | AB33: N | AC33: N | AD33: N.A. | AE33: Y | AF33: N | AG33: N | AH33: N | AI33: N | AJ33: N | AK33: N
A34: ='Population Definitions'!$B$31 -> 65+M_fns | B34: N | C34: N | D34: N | E34: N | F34: N | G34: N | H34: N | I34: N | J34: N | K34: N | L34: N | M34: N | N34: N | O34: N | P34: N | Q34: N | R34: N | S34: N | T34: N | U34: N | V34: N | W34: N | X34: N | Y34: N | Z34: N | AA34: N | AB34: N | AC34: N | AD34: N | AE34: N.A. | AF34: N | AG34: N | AH34: N | AI34: N | AJ34: N | AK34: N
A35: ='Population Definitions'!$B$32 -> 0-4F_fns | B35: N | C35: N | D35: N | E35: N | F35: N | G35: N | H35: N | I35: N | J35: N | K35: N | L35: N | M35: N | N35: N | O35: N | P35: N | Q35: N | R35: N | S35: N | T35: N | U35: N | V35: N | W35: N | X35: N | Y35: N | Z35: N | AA35: N | AB35: N | AC35: N | AD35: N | AE35: N | AF35: N.A. | AG35: Y | AH35: N | AI35: N | AJ35: N | AK35: N
A36: ='Population Definitions'!$B$33 -> 5-14F_fns | B36: N | C36: N | D36: N | E36: N | F36: N | G36: N | H36: N | I36: N | J36: N | K36: N | L36: N | M36: N | N36: N | O36: N | P36: N | Q36: N | R36: N | S36: N | T36: N | U36: N | V36: N | W36: N | X36: N | Y36: N | Z36: N | AA36: N | AB36: N | AC36: N | AD36: N | AE36: N | AF36: N | AG36: N.A. | AH36: Y | AI36: N | AJ36: N | AK36: N
A37: ='Population Definitions'!$B$34 -> 15-29F_fns | B37: N | C37: N | D37: N | E37: N | F37: N | G37: N | H37: N | I37: N | J37: N | K37: N | L37: N | M37: N | N37: N | O37: N | P37: N | Q37: N | R37: N | S37: N | T37: N | U37: N | V37: N | W37: N | X37: N | Y37: N | Z37: N | AA37: N | AB37: N | AC37: N | AD37: N | AE37: N | AF37: N | AG37: N | AH37: N.A. | AI37: Y | AJ37: N | AK37: N
A38: ='Population Definitions'!$B$35 -> 30-49F_fns | B38: N | C38: N | D38: N | E38: N | F38: N | G38: N | H38: N | I38: N | J38: N | K38: N | L38: N | M38: N | N38: N | O38: N | P38: N | Q38: N | R38: N | S38: N | T38: N | U38: N | V38: N | W38: N | X38: N | Y38: N | Z38: N | AA38: N | AB38: N | AC38: N | AD38: N | AE38: N | AF38: N | AG38: N | AH38: N | AI38: N.A. | AJ38: Y | AK38: N
A39: ='Population Definitions'!$B$36 -> 50-64F_fns | B39: N | C39: N | D39: N | E39: N | F39: N | G39: N | H39: N | I39: N | J39: N | K39: N | L39: N | M39: N | N39: N | O39: N | P39: N | Q39: N | R39: N | S39: N | T39: N | U39: N | V39: N | W39: N | X39: N | Y39: N | Z39: N | AA39: N | AB39: N | AC39: N | AD39: N | AE39: N | AF39: N | AG39: N | AH39: N | AI39: N | AJ39: N.A. | AK39: Y
A40: ='Population Definitions'!$B$37 -> 65+F_fns | B40: N | C40: N | D40: N | E40: N | F40: N | G40: N | H40: N | I40: N | J40: N | K40: N | L40: N | M40: N | N40: N | O40: N | P40: N | Q40: N | R40: N | S40: N | T40: N | U40: N | V40: N | W40: N | X40: N | Y40: N | Z40: N | AA40: N | AB40: N | AC40: N | AD40: N | AE40: N | AF40: N | AG40: N | AH40: N | AI40: N | AJ40: N | AK40: N.A.
