Workbook

Sheet Population Definitions
A1: Abbreviation | B1: Full Name | C1: Population type
A2: atsi_0-14_M | B2: atsi_0-14_M | C2: default
A3: atsi_15-54_M | B3: atsi_15-54_M | C3: default
A4: atsi_65+_M | B4: atsi_65+_M | C4: default
A5: atsi_0-14_F | B5: atsi_0-14_F | C5: default
A6: atsi_15-54_F | B6: atsi_15-54_F | C6: default
A7: atsi_65+_F | B7: atsi_65+_F | C7: default
A8: ausb_0-14_M | B8: ausb_0-14_M | C8: default
A9: ausb_15-54_M | B9: ausb_15-54_M | C9: default
A10: ausb_65+_M | B10: ausb_65+_M | C10: default
A11: ausb_0-14_F | B11: ausb_0-14_F | C11: default
A12: ausb_15-54_F | B12: ausb_15-54_F | C12: default
... A25: hros_65+_F | B25: hros_65+_F | C25: default

Sheet Model Initialization
A1: Junction: Model Initialization | B1: Provenance | C1: Units | D1: Uncertainty | E1: 1980 | F1: 1981 | G1: 1982 | H1: 1983 | I1: 1984 | J1: 1985 | K1: 1986 | L1: 1987 | M1: 1988 | N1: 1989 | O1: 1990 | P1: 1991 | Q1: 1992 | R1: 1993 | S1: 1994 | T1: 1995 | U1: 1996 | V1: 1997 | W1: 1998 | X1: 1999 | Y1: 2000 | Z1: 2001 | AA1: 2002 | AB1: 2003 | AC1: 2004 | AD1: 2005 | AE1: 2006 | AF1: 2007 | AG1: 2008 | AH1: 2009 | AI1: 2010 | AJ1: 2011 | AK1: 2012 | AL1: 2013 | AM1: 2014 | AN1: 2015 | AO1: 2016 | AP1: 2017 | AQ1: 2018 | AR1: 2019 | AS1: 2020 | AT1: 2021 | AU1: 2022 | AV1: 2023 | AW1: 2024 | AX1: 2025 | AY1: 2026 | AZ1: 2027 | BA1: 2028 | BB1: 2029 | BC1: 2030 | BD1: 2031 | BE1: 2032 | BF1: 2033 | BG1: 2034 | BH1: 2035 | BI1: 2036 | BJ1: 2037 | BK1: 2038 | BL1: 2039 | BM1: 2040 | BN1: 2041 | BO1: 2042 | BP1: 2043 | BQ1: 2044 | BR1: 2045 | BS1: 2046 | BT1: 2047 | BU1: 2048 | BV1: 2049 | BW1: 2050 | BX1: 2051 | BY1: 2052 | BZ1: 2053 | CA1: 2054 | CB1: 2055 | CC1: 2056 | CD1: 2057 | CE1: 2058 | CF1: 2059 | CG1: 2060 | CH1: 2061 | CI1: 2062 | CJ1: 2063 | CK1: 2064 | CL1: 2065 | CM1: 2066 | CN1: 2067 | CO1: 2068 | CP1: 2069 | CQ1: 2070 | CR1: 2071
A2: ='Population Definitions'!$B$2 -> atsi_0-14_M | C2: Number
A3: ='Population Definitions'!$B$3 -> atsi_15-54_M | C3: Number
A4: ='Population Definitions'!$B$4 -> atsi_65+_M | C4: Number
A5: ='Population Definitions'!$B$5 -> atsi_0-14_F | C5: Number
A6: ='Population Definitions'!$B$6 -> atsi_15-54_F | C6: Number
A7: ='Population Definitions'!$B$7 -> atsi_65+_F | C7: Number
A8: ='Population Definitions'!$B$8 -> ausb_0-14_M | C8: Number
A9: ='Population Definitions'!$B$9 -> ausb_15-54_M | C9: Number
A10: ='Population Definitions'!$B$10 -> ausb_65+_M | C10: Number
A11: ='Population Definitions'!$B$11 -> ausb_0-14_F | C11: Number
A12: ='Population Definitions'!$B$12 -> ausb_15-54_F | C12: Number
A13: ='Population Definitions'!$B$13 -> ausb_65+_F | C13: Number
A14: ='Population Definitions'!$B$14 -> lros_0-14_M | C14: Number
A15: ='Population Definitions'!$B$15 -> lros_15-54_M | C15: Number
A16: ='Population Definitions'!$B$16 -> lros_65+_M | C16: Number
A17: ='Population Definitions'!$B$17 -> lros_0-14_F | C17: Number
A18: ='Population Definitions'!$B$18 -> lros_15-54_F | C18: Number
A19: ='Population Definitions'!$B$19 -> lros_65+_F | C19: Number
A20: ='Population Definitions'!$B$20 -> hros_0-14_M | C20: Number
A21: ='Population Definitions'!$B$21 -> hros_15-54_M | C21: Number
A22: ='Population Definitions'!$B$22 -> hros_65+_M | C22: Number
A23: ='Population Definitions'!$B$23 -> hros_0-14_F | C23: Number
A24: ='Population Definitions'!$B$24 -> hros_15-54_F | C24: Number
A25: ='Population Definitions'!$B$25 -> hros_65+_F | C25: Number
A27: Unadjusted initial prevalence of hepatitis B | B27: Provenance | C27: Units | D27: Uncertainty | E27: Constant | G27: 1980 | H27: 1981 | I27: 1982 | J27: 1983 | K27: 1984 | L27: 1985 | M27: 1986 | N27: 1987 | O27: 1988 | P27: 1989 | Q27: 1990 | R27: 1991 | S27: 1992 | T27: 1993 | U27: 1994 | V27: 1995 | W27: 1996 | X27: 1997 | Y27: 1998 | Z27: 1999 | AA27: 2000 | AB27: 2001 | AC27: 2002 | AD27: 2003 | AE27: 2004 | AF27: 2005 | AG27: 2006 | AH27: 2007 | AI27: 2008 | AJ27: 2009 | AK27: 2010 | AL27: 2011 | AM27: 2012 | AN27: 2013 | AO27: 2014 | AP27: 2015 | AQ27: 2016 | AR27: 2017 | AS27: 2018 | AT27: 2019 | AU27: 2020 | AV27: 2021 | AW27: 2022 | AX27: 2023 | AY27: 2024 | AZ27: 2025 | BA27: 2026 | BB27: 2027 | BC27: 2028 | BD27: 2029 | BE27: 2030 | BF27: 2031 | BG27: 2032 | BH27: 2033 | BI27: 2034 | BJ27: 2035 | BK27: 2036 | BL27: 2037 | BM27: 2038 | BN27: 2039 | BO27: 2040 | BP27: 2041 | BQ27: 2042 | BR27: 2043 | BS27: 2044 | BT27: 2045 | BU27: 2046 | BV27: 2047 | BW27: 2048 | BX27: 2049 | BY27: 2050 | BZ27: 2051 | CA27: 2052 | CB27: 2053 | CC27: 2054 | CD27: 2055 | CE27: 2056 | CF27: 2057 | CG27: 2058 | CH27: 2059 | CI27: 2060 | CJ27: 2061 | CK27: 2062 | CL27: 2063 | CM27: 2064 | CN27: 2065 | CO27: 2066 | CP27: 2067 | CQ27: 2068 | CR27: 2069 | CS27: 2070 | CT27: 2071
A28: ='Population Definitions'!$B$2 -> atsi_0-14_M | C28: N.A. | F28: OR
A29: ='Population Definitions'!$B$3 -> atsi_15-54_M | C29: N.A. | F29: OR
A30: ='Population Definitions'!$B$4 -> atsi_65+_M | C30: N.A. | F30: OR
A31: ='Population Definitions'!$B$5 -> atsi_0-14_F | C31: N.A. | F31: OR
A32: ='Population Definitions'!$B$6 -> atsi_15-54_F | C32: N.A. | F32: OR
A33: ='Population Definitions'!$B$7 -> atsi_65+_F | C33: N.A. | F33: OR
A34: ='Population Definitions'!$B$8 -> ausb_0-14_M | C34: N.A. | F34: OR
A35: ='Population Definitions'!$B$9 -> ausb_15-54_M | C35: N.A. | F35: OR
A36: ='Population Definitions'!$B$10 -> ausb_65+_M | C36: N.A. | F36: OR
A37: ='Population Definitions'!$B$11 -> ausb_0-14_F | C37: N.A. | F37: OR
A38: ='Population Definitions'!$B$12 -> ausb_15-54_F | C38: N.A. | F38: OR
A39: ='Population Definitions'!$B$13 -> ausb_65+_F | C39: N.A. | F39: OR
A40: ='Population Definitions'!$B$14 -> lros_0-14_M | C40: N.A. | F40: OR
A41: ='Population Definitions'!$B$15 -> lros_15-54_M | C41: N.A. | F41: OR
...

Sheet Populations
A1: Total Population | B1: Provenance | C1: Units | D1: Uncertainty | E1: 1980 | F1: 1981 | G1: 1982 | H1: 1983 | I1: 1984 | J1: 1985 | K1: 1986 | L1: 1987 | M1: 1988 | N1: 1989 | O1: 1990 | P1: 1991 | Q1: 1992 | R1: 1993 | S1: 1994 | T1: 1995 | U1: 1996 | V1: 1997 | W1: 1998 | X1: 1999 | Y1: 2000 | Z1: 2001 | AA1: 2002 | AB1: 2003 | AC1: 2004 | AD1: 2005 | AE1: 2006 | AF1: 2007 | AG1: 2008 | AH1: 2009 | AI1: 2010 | AJ1: 2011 | AK1: 2012 | AL1: 2013 | AM1: 2014 | AN1: 2015 | AO1: 2016 | AP1: 2017 | AQ1: 2018 | AR1: 2019 | AS1: 2020 | AT1: 2021 | AU1: 2022 | AV1: 2023 | AW1: 2024 | AX1: 2025 | AY1: 2026 | AZ1: 2027 | BA1: 2028 | BB1: 2029 | BC1: 2030 | BD1: 2031 | BE1: 2032 | BF1: 2033 | BG1: 2034 | BH1: 2035 | BI1: 2036 | BJ1: 2037 | BK1: 2038 | BL1: 2039 | BM1: 2040 | BN1: 2041 | BO1: 2042 | BP1: 2043 | BQ1: 2044 | BR1: 2045 | BS1: 2046 | BT1: 2047 | BU1: 2048 | BV1: 2049 | BW1: 2050 | BX1: 2051 | BY1: 2052 | BZ1: 2053 | CA1: 2054 | CB1: 2055 | CC1: 2056 | CD1: 2057 | CE1: 2058 | CF1: 2059 | CG1: 2060 | CH1: 2061 | CI1: 2062 | CJ1: 2063 | CK1: 2064 | CL1: 2065 | CM1: 2066 | CN1: 2067 | CO1: 2068 | CP1: 2069 | CQ1: 2070 | CR1: 2071
A2: ='Population Definitions'!$B$2 -> atsi_0-14_M | C2: Number
A3: ='Population Definitions'!$B$3 -> atsi_15-54_M | C3: Number
A4: ='Population Definitions'!$B$4 -> atsi_65+_M | C4: Number
A5: ='Population Definitions'!$B$5 -> atsi_0-14_F | C5: Number
A6: ='Population Definitions'!$B$6 -> atsi_15-54_F | C6: Number
A7: ='Population Definitions'!$B$7 -> atsi_65+_F | C7: Number
A8: ='Population Definitions'!$B$8 -> ausb_0-14_M | C8: Number
A9: ='Population Definitions'!$B$9 -> ausb_15-54_M | C9: Number
A10: ='Population Definitions'!$B$10 -> ausb_65+_M | C10: Number
A11: ='Population Definitions'!$B$11 -> ausb_0-14_F | C11: Number
A12: ='Population Definitions'!$B$12 -> ausb_15-54_F | C12: Number
A13: ='Population Definitions'!$B$13 -> ausb_65+_F | C13: Number
A14: ='Population Definitions'!$B$14 -> lros_0-14_M | C14: Number
A15: ='Population Definitions'!$B$15 -> lros_15-54_M | C15: Number
A16: ='Population Definitions'!$B$16 -> lros_65+_M | C16: Number
A17: ='Population Definitions'!$B$17 -> lros_0-14_F | C17: Number
A18: ='Population Definitions'!$B$18 -> lros_15-54_F | C18: Number
A19: ='Population Definitions'!$B$19 -> lros_65+_F | C19: Number
A20: ='Population Definitions'!$B$20 -> hros_0-14_M | C20: Number
A21: ='Population Definitions'!$B$21 -> hros_15-54_M | C21: Number
A22: ='Population Definitions'!$B$22 -> hros_65+_M | C22: Number
A23: ='Population Definitions'!$B$23 -> hros_0-14_F | C23: Number
A24: ='Population Definitions'!$B$24 -> hros_15-54_F | C24: Number
A25: ='Population Definitions'!$B$25 -> hros_65+_F | C25: Number
A27: Annual Births (by sex) | B27: Provenance | C27: Units | D27: Uncertainty | E27: Constant | G27: 1980 | H27: 1981 | I27: 1982 | J27: 1983 | K27: 1984 | L27: 1985 | M27: 1986 | N27: 1987 | O27: 1988 | P27: 1989 | Q27: 1990 | R27: 1991 | S27: 1992 | T27: 1993 | U27: 1994 | V27: 1995 | W27: 1996 | X27: 1997 | Y27: 1998 | Z27: 1999 | AA27: 2000 | AB27: 2001 | AC27: 2002 | AD27: 2003 | AE27: 2004 | AF27: 2005 | AG27: 2006 | AH27: 2007 | AI27: 2008 | AJ27: 2009 | AK27: 2010 | AL27: 2011 | AM27: 2012 | AN27: 2013 | AO27: 2014 | AP27: 2015 | AQ27: 2016 | AR27: 2017 | AS27: 2018 | AT27: 2019 | AU27: 2020 | AV27: 2021 | AW27: 2022 | AX27: 2023 | AY27: 2024 | AZ27: 2025 | BA27: 2026 | BB27: 2027 | BC27: 2028 | BD27: 2029 | BE27: 2030 | BF27: 2031 | BG27: 2032 | BH27: 2033 | BI27: 2034 | BJ27: 2035 | BK27: 2036 | BL27: 2037 | BM27: 2038 | BN27: 2039 | BO27: 2040 | BP27: 2041 | BQ27: 2042 | BR27: 2043 | BS27: 2044 | BT27: 2045 | BU27: 2046 | BV27: 2047 | BW27: 2048 | BX27: 2049 | BY27: 2050 | BZ27: 2051 | CA27: 2052 | CB27: 2053 | CC27: 2054 | CD27: 2055 | CE27: 2056 | CF27: 2057 | CG27: 2058 | CH27: 2059 | CI27: 2060 | CJ27: 2061 | CK27: 2062 | CL27: 2063 | CM27: 2064 | CN27: 2065 | CO27: 2066 | CP27: 2067 | CQ27: 2068 | CR27: 2069 | CS27: 2070 | CT27: 2071
A28: ='Population Definitions'!$B$2 -> atsi_0-14_M | C28: N.A. | F28: OR
A29: ='Population Definitions'!$B$3 -> atsi_15-54_M | C29: N.A. | F29: OR
A30: ='Population Definitions'!$B$4 -> atsi_65+_M | C30: N.A. | F30: OR
A31: ='Population Definitions'!$B$5 -> atsi_0-14_F | C31: N.A. | F31: OR
A32: ='Population Definitions'!$B$6 -> atsi_15-54_F | C32: N.A. | F32: OR
A33: ='Population Definitions'!$B$7 -> atsi_65+_F | C33: N.A. | F33: OR
A34: ='Population Definitions'!$B$8 -> ausb_0-14_M | C34: N.A. | F34: OR
A35: ='Population Definitions'!$B$9 -> ausb_15-54_M | C35: N.A. | F35: OR
A36: ='Population Definitions'!$B$10 -> ausb_65+_M | C36: N.A. | F36: OR
A37: ='Population Definitions'!$B$11 -> ausb_0-14_F | C37: N.A. | F37: OR
A38: ='Population Definitions'!$B$12 -> ausb_15-54_F | C38: N.A. | F38: OR
A39: ='Population Definitions'!$B$13 -> ausb_65+_F | C39: N.A. | F39: OR
A40: ='Population Definitions'!$B$14 -> lros_0-14_M | C40: N.A. | F40: OR
A41: ='Population Definitions'!$B$15 -> lros_15-54_M | C41: N.A. | F41: OR
...

Sheet Calibration Metrics
A1: Prevalence of HBV | B1: Provenance | C1: Units | D1: Uncertainty | E1: 1980 | F1: 1981 | G1: 1982 | H1: 1983 | I1: 1984 | J1: 1985 | K1: 1986 | L1: 1987 | M1: 1988 | N1: 1989 | O1: 1990 | P1: 1991 | Q1: 1992 | R1: 1993 | S1: 1994 | T1: 1995 | U1: 1996 | V1: 1997 | W1: 1998 | X1: 1999 | Y1: 2000 | Z1: 2001 | AA1: 2002 | AB1: 2003 | AC1: 2004 | AD1: 2005 | AE1: 2006 | AF1: 2007 | AG1: 2008 | AH1: 2009 | AI1: 2010 | AJ1: 2011 | AK1: 2012 | AL1: 2013 | AM1: 2014 | AN1: 2015 | AO1: 2016 | AP1: 2017 | AQ1: 2018 | AR1: 2019 | AS1: 2020 | AT1: 2021 | AU1: 2022 | AV1: 2023 | AW1: 2024 | AX1: 2025 | AY1: 2026 | AZ1: 2027 | BA1: 2028 | BB1: 2029 | BC1: 2030 | BD1: 2031 | BE1: 2032 | BF1: 2033 | BG1: 2034 | BH1: 2035 | BI1: 2036 | BJ1: 2037 | BK1: 2038 | BL1: 2039 | BM1: 2040 | BN1: 2041 | BO1: 2042 | BP1: 2043 | BQ1: 2044 | BR1: 2045 | BS1: 2046 | BT1: 2047 | BU1: 2048 | BV1: 2049 | BW1: 2050 | BX1: 2051 | BY1: 2052 | BZ1: 2053 | CA1: 2054 | CB1: 2055 | CC1: 2056 | CD1: 2057 | CE1: 2058 | CF1: 2059 | CG1: 2060 | CH1: 2061 | CI1: 2062 | CJ1: 2063 | CK1: 2064 | CL1: 2065 | CM1: 2066 | CN1: 2067 | CO1: 2068 | CP1: 2069 | CQ1: 2070 | CR1: 2071
A2: ='Population Definitions'!$B$2 -> atsi_0-14_M | C2: Fraction
A3: ='Population Definitions'!$B$3 -> atsi_15-54_M | C3: Fraction
A4: ='Population Definitions'!$B$4 -> atsi_65+_M | C4: Fraction
A5: ='Population Definitions'!$B$5 -> atsi_0-14_F | C5: Fraction
A6: ='Population Definitions'!$B$6 -> atsi_15-54_F | C6: Fraction
A7: ='Population Definitions'!$B$7 -> atsi_65+_F | C7: Fraction
A8: ='Population Definitions'!$B$8 -> ausb_0-14_M | C8: Fraction
A9: ='Population Definitions'!$B$9 -> ausb_15-54_M | C9: Fraction
A10: ='Population Definitions'!$B$10 -> ausb_65+_M | C10: Fraction
A11: ='Population Definitions'!$B$11 -> ausb_0-14_F | C11: Fraction
A12: ='Population Definitions'!$B$12 -> ausb_15-54_F | C12: Fraction
A13: ='Population Definitions'!$B$13 -> ausb_65+_F | C13: Fraction
A14: ='Population Definitions'!$B$14 -> lros_0-14_M | C14: Fraction
A15: ='Population Definitions'!$B$15 -> lros_15-54_M | C15: Fraction
A16: ='Population Definitions'!$B$16 -> lros_65+_M | C16: Fraction
A17: ='Population Definitions'!$B$17 -> lros_0-14_F | C17: Fraction
A18: ='Population Definitions'!$B$18 -> lros_15-54_F | C18: Fraction
A19: ='Population Definitions'!$B$19 -> lros_65+_F | C19: Fraction
A20: ='Population Definitions'!$B$20 -> hros_0-14_M | C20: Fraction
A21: ='Population Definitions'!$B$21 -> hros_15-54_M | C21: Fraction
A22: ='Population Definitions'!$B$22 -> hros_65+_M | C22: Fraction
A23: ='Population Definitions'!$B$23 -> hros_0-14_F | C23: Fraction
A24: ='Population Definitions'!$B$24 -> hros_15-54_F | C24: Fraction
A25: ='Population Definitions'!$B$25 -> hros_65+_F | C25: Fraction
A27: Diagnosed (as per def) | B27: Provenance | C27: Units | D27: Uncertainty | E27: 1980 | F27: 1981 | G27: 1982 | H27: 1983 | I27: 1984 | J27: 1985 | K27: 1986 | L27: 1987 | M27: 1988 | N27: 1989 | O27: 1990 | P27: 1991 | Q27: 1992 | R27: 1993 | S27: 1994 | T27: 1995 | U27: 1996 | V27: 1997 | W27: 1998 | X27: 1999 | Y27: 2000 | Z27: 2001 | AA27: 2002 | AB27: 2003 | AC27: 2004 | AD27: 2005 | AE27: 2006 | AF27: 2007 | AG27: 2008 | AH27: 2009 | AI27: 2010 | AJ27: 2011 | AK27: 2012 | AL27: 2013 | AM27: 2014 | AN27: 2015 | AO27: 2016 | AP27: 2017 | AQ27: 2018 | AR27: 2019 | AS27: 2020 | AT27: 2021 | AU27: 2022 | AV27: 2023 | AW27: 2024 | AX27: 2025 | AY27: 2026 | AZ27: 2027 | BA27: 2028 | BB27: 2029 | BC27: 2030 | BD27: 2031 | BE27: 2032 | BF27: 2033 | BG27: 2034 | BH27: 2035 | BI27: 2036 | BJ27: 2037 | BK27: 2038 | BL27: 2039 | BM27: 2040 | BN27: 2041 | BO27: 2042 | BP27: 2043 | BQ27: 2044 | BR27: 2045 | BS27: 2046 | BT27: 2047 | BU27: 2048 | BV27: 2049 | BW27: 2050 | BX27: 2051 | BY27: 2052 | BZ27: 2053 | CA27: 2054 | CB27: 2055 | CC27: 2056 | CD27: 2057 | CE27: 2058 | CF27: 2059 | CG27: 2060 | CH27: 2061 | CI27: 2062 | CJ27: 2063 | CK27: 2064 | CL27: 2065 | CM27: 2066 | CN27: 2067 | CO27: 2068 | CP27: 2069 | CQ27: 2070 | CR27: 2071
A28: ='Population Definitions'!$B$2 -> atsi_0-14_M | C28: Fraction
A29: ='Population Definitions'!$B$3 -> atsi_15-54_M | C29: Fraction
A30: ='Population Definitions'!$B$4 -> atsi_65+_M | C30: Fraction
A31: ='Population Definitions'!$B$5 -> atsi_0-14_F | C31: Fraction
A32: ='Population Definitions'!$B$6 -> atsi_15-54_F | C32: Fraction
A33: ='Population Definitions'!$B$7 -> atsi_65+_F | C33: Fraction
A34: ='Population Definitions'!$B$8 -> ausb_0-14_M | C34: Fraction
A35: ='Population Definitions'!$B$9 -> ausb_15-54_M | C35: Fraction
A36: ='Population Definitions'!$B$10 -> ausb_65+_M | C36: Fraction
A37: ='Population Definitions'!$B$11 -> ausb_0-14_F | C37: Fraction
A38: ='Population Definitions'!$B$12 -> ausb_15-54_F | C38: Fraction
A39: ='Population Definitions'!$B$13 -> ausb_65+_F | C39: Fraction
A40: ='Population Definitions'!$B$14 -> lros_0-14_M | C40: Fraction
A41: ='Population Definitions'!$B$15 -> lros_15-54_M | C41: Fraction
...

Sheet Immigration Model
A1: Annual Rate of Overseas Arrivals | B1: Provenance | C1: Units | D1: Uncertainty | E1: Constant | G1: 1980 | H1: 1981 | I1: 1982 | J1: 1983 | K1: 1984 | L1: 1985 | M1: 1986 | N1: 1987 | O1: 1988 | P1: 1989 | Q1: 1990 | R1: 1991 | S1: 1992 | T1: 1993 | U1: 1994 | V1: 1995 | W1: 1996 | X1: 1997 | Y1: 1998 | Z1: 1999 | AA1: 2000 | AB1: 2001 | AC1: 2002 | AD1: 2003 | AE1: 2004 | AF1: 2005 | AG1: 2006 | AH1: 2007 | AI1: 2008 | AJ1: 2009 | AK1: 2010 | AL1: 2011 | AM1: 2012 | AN1: 2013 | AO1: 2014 | AP1: 2015 | AQ1: 2016 | AR1: 2017 | AS1: 2018 | AT1: 2019 | AU1: 2020 | AV1: 2021 | AW1: 2022 | AX1: 2023 | AY1: 2024 | AZ1: 2025 | BA1: 2026 | BB1: 2027 | BC1: 2028 | BD1: 2029 | BE1: 2030 | BF1: 2031 | BG1: 2032 | BH1: 2033 | BI1: 2034 | BJ1: 2035 | BK1: 2036 | BL1: 2037 | BM1: 2038 | BN1: 2039 | BO1: 2040 | BP1: 2041 | BQ1: 2042 | BR1: 2043 | BS1: 2044 | BT1: 2045 | BU1: 2046 | BV1: 2047 | BW1: 2048 | BX1: 2049 | BY1: 2050 | BZ1: 2051 | CA1: 2052 | CB1: 2053 | CC1: 2054 | CD1: 2055 | CE1: 2056 | CF1: 2057 | CG1: 2058 | CH1: 2059 | CI1: 2060 | CJ1: 2061 | CK1: 2062 | CL1: 2063 | CM1: 2064 | CN1: 2065 | CO1: 2066 | CP1: 2067 | CQ1: 2068 | CR1: 2069 | CS1: 2070 | CT1: 2071
A2: ='Population Definitions'!$B$2 -> atsi_0-14_M | C2: N.A. | F2: OR
A3: ='Population Definitions'!$B$3 -> atsi_15-54_M | C3: N.A. | F3: OR
A4: ='Population Definitions'!$B$4 -> atsi_65+_M | C4: N.A. | F4: OR
A5: ='Population Definitions'!$B$5 -> atsi_0-14_F | C5: N.A. | F5: OR
A6: ='Population Definitions'!$B$6 -> atsi_15-54_F | C6: N.A. | F6: OR
A7: ='Population Definitions'!$B$7 -> atsi_65+_F | C7: N.A. | F7: OR
A8: ='Population Definitions'!$B$8 -> ausb_0-14_M | C8: N.A. | F8: OR
A9: ='Population Definitions'!$B$9 -> ausb_15-54_M | C9: N.A. | F9: OR
A10: ='Population Definitions'!$B$10 -> ausb_65+_M | C10: N.A. | F10: OR
A11: ='Population Definitions'!$B$11 -> ausb_0-14_F | C11: N.A. | F11: OR
A12: ='Population Definitions'!$B$12 -> ausb_15-54_F | C12: N.A. | F12: OR
A13: ='Population Definitions'!$B$13 -> ausb_65+_F | C13: N.A. | F13: OR
A14: ='Population Definitions'!$B$14 -> lros_0-14_M | C14: N.A. | F14: OR
A15: ='Population Definitions'!$B$15 -> lros_15-54_M | C15: N.A. | F15: OR
A16: ='Population Definitions'!$B$16 -> lros_65+_M | C16: N.A. | F16: OR
A17: ='Population Definitions'!$B$17 -> lros_0-14_F | C17: N.A. | F17: OR
A18: ='Population Definitions'!$B$18 -> lros_15-54_F | C18: N.A. | F18: OR
A19: ='Population Definitions'!$B$19 -> lros_65+_F | C19: N.A. | F19: OR
A20: ='Population Definitions'!$B$20 -> hros_0-14_M | C20: N.A. | F20: OR
A21: ='Population Definitions'!$B$21 -> hros_15-54_M | C21: N.A. | F21: OR
A22: ='Population Definitions'!$B$22 -> hros_65+_M | C22: N.A. | F22: OR
A23: ='Population Definitions'!$B$23 -> hros_0-14_F | C23: N.A. | F23: OR
A24: ='Population Definitions'!$B$24 -> hros_15-54_F | C24: N.A. | F24: OR
A25: ='Population Definitions'!$B$25 -> hros_65+_F | C25: N.A. | F25: OR
A27: Prevalence of hepatitis B among arrivals | B27: Provenance | C27: Units | D27: Uncertainty | E27: Constant | G27: 1980 | H27: 1981 | I27: 1982 | J27: 1983 | K27: 1984 | L27: 1985 | M27: 1986 | N27: 1987 | O27: 1988 | P27: 1989 | Q27: 1990 | R27: 1991 | S27: 1992 | T27: 1993 | U27: 1994 | V27: 1995 | W27: 1996 | X27: 1997 | Y27: 1998 | Z27: 1999 | AA27: 2000 | AB27: 2001 | AC27: 2002 | AD27: 2003 | AE27: 2004 | AF27: 2005 | AG27: 2006 | AH27: 2007 | AI27: 2008 | AJ27: 2009 | AK27: 2010 | AL27: 2011 | AM27: 2012 | AN27: 2013 | AO27: 2014 | AP27: 2015 | AQ27: 2016 | AR27: 2017 | AS27: 2018 | AT27: 2019 | AU27: 2020 | AV27: 2021 | AW27: 2022 | AX27: 2023 | AY27: 2024 | AZ27: 2025 | BA27: 2026 | BB27: 2027 | BC27: 2028 | BD27: 2029 | BE27: 2030 | BF27: 2031 | BG27: 2032 | BH27: 2033 | BI27: 2034 | BJ27: 2035 | BK27: 2036 | BL27: 2037 | BM27: 2038 | BN27: 2039 | BO27: 2040 | BP27: 2041 | BQ27: 2042 | BR27: 2043 | BS27: 2044 | BT27: 2045 | BU27: 2046 | BV27: 2047 | BW27: 2048 | BX27: 2049 | BY27: 2050 | BZ27: 2051 | CA27: 2052 | CB27: 2053 | CC27: 2054 | CD27: 2055 | CE27: 2056 | CF27: 2057 | CG27: 2058 | CH27: 2059 | CI27: 2060 | CJ27: 2061 | CK27: 2062 | CL27: 2063 | CM27: 2064 | CN27: 2065 | CO27: 2066 | CP27: 2067 | CQ27: 2068 | CR27: 2069 | CS27: 2070 | CT27: 2071
A28: ='Population Definitions'!$B$2 -> atsi_0-14_M | C28: N.A. | F28: OR
A29: ='Population Definitions'!$B$3 -> atsi_15-54_M | C29: N.A. | F29: OR
A30: ='Population Definitions'!$B$4 -> atsi_65+_M | C30: N.A. | F30: OR
A31: ='Population Definitions'!$B$5 -> atsi_0-14_F | C31: N.A. | F31: OR
A32: ='Population Definitions'!$B$6 -> atsi_15-54_F | C32: N.A. | F32: OR
A33: ='Population Definitions'!$B$7 -> atsi_65+_F | C33: N.A. | F33: OR
A34: ='Population Definitions'!$B$8 -> ausb_0-14_M | C34: N.A. | F34: OR
A35: ='Population Definitions'!$B$9 -> ausb_15-54_M | C35: N.A. | F35: OR
A36: ='Population Definitions'!$B$10 -> ausb_65+_M | C36: N.A. | F36: OR
A37: ='Population Definitions'!$B$11 -> ausb_0-14_F | C37: N.A. | F37: OR
A38: ='Population Definitions'!$B$12 -> ausb_15-54_F | C38: N.A. | F38: OR
A39: ='Population Definitions'!$B$13 -> ausb_65+_F | C39: N.A. | F39: OR
A40: ='Population Definitions'!$B$14 -> lros_0-14_M | C40: N.A. | F40: OR
A41: ='Population Definitions'!$B$15 -> lros_15-54_M | C41: N.A. | F41: OR
...

Sheet Intervention Effectiveness
A1: Treatment Effectiveness: HBeAg± chronic heaptitis to compensated cirrhosis | B1: Provenance | C1: Units | D1: Uncertainty | E1: Constant | G1: 1980 | H1: 1981 | I1: 1982 | J1: 1983 | K1: 1984 | L1: 1985 | M1: 1986 | N1: 1987 | O1: 1988 | P1: 1989 | Q1: 1990 | R1: 1991 | S1: 1992 | T1: 1993 | U1: 1994 | V1: 1995 | W1: 1996 | X1: 1997 | Y1: 1998 | Z1: 1999 | AA1: 2000 | AB1: 2001 | AC1: 2002 | AD1: 2003 | AE1: 2004 | AF1: 2005 | AG1: 2006 | AH1: 2007 | AI1: 2008 | AJ1: 2009 | AK1: 2010 | AL1: 2011 | AM1: 2012 | AN1: 2013 | AO1: 2014 | AP1: 2015 | AQ1: 2016 | AR1: 2017 | AS1: 2018 | AT1: 2019 | AU1: 2020 | AV1: 2021 | AW1: 2022 | AX1: 2023 | AY1: 2024 | AZ1: 2025 | BA1: 2026 | BB1: 2027 | BC1: 2028 | BD1: 2029 | BE1: 2030 | BF1: 2031 | BG1: 2032 | BH1: 2033 | BI1: 2034 | BJ1: 2035 | BK1: 2036 | BL1: 2037 | BM1: 2038 | BN1: 2039 | BO1: 2040 | BP1: 2041 | BQ1: 2042 | BR1: 2043 | BS1: 2044 | BT1: 2045 | BU1: 2046 | BV1: 2047 | BW1: 2048 | BX1: 2049 | BY1: 2050 | BZ1: 2051 | CA1: 2052 | CB1: 2053 | CC1: 2054 | CD1: 2055 | CE1: 2056 | CF1: 2057 | CG1: 2058 | CH1: 2059 | CI1: 2060 | CJ1: 2061 | CK1: 2062 | CL1: 2063 | CM1: 2064 | CN1: 2065 | CO1: 2066 | CP1: 2067 | CQ1: 2068 | CR1: 2069 | CS1: 2070 | CT1: 2071
A2: ='Population Definitions'!$B$2 -> atsi_0-14_M | C2: N.A. | F2: OR
A3: ='Population Definitions'!$B$3 -> atsi_15-54_M | C3: N.A. | F3: OR
A4: ='Population Definitions'!$B$4 -> atsi_65+_M | C4: N.A. | F4: OR
A5: ='Population Definitions'!$B$5 -> atsi_0-14_F | C5: N.A. | F5: OR
A6: ='Population Definitions'!$B$6 -> atsi_15-54_F | C6: N.A. | F6: OR
A7: ='Population Definitions'!$B$7 -> atsi_65+_F | C7: N.A. | F7: OR
A8: ='Population Definitions'!$B$8 -> ausb_0-14_M | C8: N.A. | F8: OR
A9: ='Population Definitions'!$B$9 -> ausb_15-54_M | C9: N.A. | F9: OR
A10: ='Population Definitions'!$B$10 -> ausb_65+_M | C10: N.A. | F10: OR
A11: ='Population Definitions'!$B$11 -> ausb_0-14_F | C11: N.A. | F11: OR
A12: ='Population Definitions'!$B$12 -> ausb_15-54_F | C12: N.A. | F12: OR
A13: ='Population Definitions'!$B$13 -> ausb_65+_F | C13: N.A. | F13: OR
A14: ='Population Definitions'!$B$14 -> lros_0-14_M | C14: N.A. | F14: OR
A15: ='Population Definitions'!$B$15 -> lros_15-54_M | C15: N.A. | F15: OR
A16: ='Population Definitions'!$B$16 -> lros_65+_M | C16: N.A. | F16: OR
A17: ='Population Definitions'!$B$17 -> lros_0-14_F | C17: N.A. | F17: OR
A18: ='Population Definitions'!$B$18 -> lros_15-54_F | C18: N.A. | F18: OR
A19: ='Population Definitions'!$B$19 -> lros_65+_F | C19: N.A. | F19: OR
A20: ='Population Definitions'!$B$20 -> hros_0-14_M | C20: N.A. | F20: OR
A21: ='Population Definitions'!$B$21 -> hros_15-54_M | C21: N.A. | F21: OR
A22: ='Population Definitions'!$B$22 -> hros_65+_M | C22: N.A. | F22: OR
A23: ='Population Definitions'!$B$23 -> hros_0-14_F | C23: N.A. | F23: OR
A24: ='Population Definitions'!$B$24 -> hros_15-54_F | C24: N.A. | F24: OR
A25: ='Population Definitions'!$B$25 -> hros_65+_F | C25: N.A. | F25: OR
A27: Treatment Effectiveness: Chronic hepatitis B to hepatocellular carcinoma | B27: Provenance | C27: Units | D27: Uncertainty | E27: Constant | G27: 1980 | H27: 1981 | I27: 1982 | J27: 1983 | K27: 1984 | L27: 1985 | M27: 1986 | N27: 1987 | O27: 1988 | P27: 1989 | Q27: 1990 | R27: 1991 | S27: 1992 | T27: 1993 | U27: 1994 | V27: 1995 | W27: 1996 | X27: 1997 | Y27: 1998 | Z27: 1999 | AA27: 2000 | AB27: 2001 | AC27: 2002 | AD27: 2003 | AE27: 2004 | AF27: 2005 | AG27: 2006 | AH27: 2007 | AI27: 2008 | AJ27: 2009 | AK27: 2010 | AL27: 2011 | AM27: 2012 | AN27: 2013 | AO27: 2014 | AP27: 2015 | AQ27: 2016 | AR27: 2017 | AS27: 2018 | AT27: 2019 | AU27: 2020 | AV27: 2021 | AW27: 2022 | AX27: 2023 | AY27: 2024 | AZ27: 2025 | BA27: 2026 | BB27: 2027 | BC27: 2028 | BD27: 2029 | BE27: 2030 | BF27: 2031 | BG27: 2032 | BH27: 2033 | BI27: 2034 | BJ27: 2035 | BK27: 2036 | BL27: 2037 | BM27: 2038 | BN27: 2039 | BO27: 2040 | BP27: 2041 | BQ27: 2042 | BR27: 2043 | BS27: 2044 | BT27: 2045 | BU27: 2046 | BV27: 2047 | BW27: 2048 | BX27: 2049 | BY27: 2050 | BZ27: 2051 | CA27: 2052 | CB27: 2053 | CC27: 2054 | CD27: 2055 | CE27: 2056 | CF27: 2057 | CG27: 2058 | CH27: 2059 | CI27: 2060 | CJ27: 2061 | CK27: 2062 | CL27: 2063 | CM27: 2064 | CN27: 2065 | CO27: 2066 | CP27: 2067 | CQ27: 2068 | CR27: 2069 | CS27: 2070 | CT27: 2071
A28: ='Population Definitions'!$B$2 -> atsi_0-14_M | C28: N.A. | F28: OR
A29: ='Population Definitions'!$B$3 -> atsi_15-54_M | C29: N.A. | F29: OR
A30: ='Population Definitions'!$B$4 -> atsi_65+_M | C30: N.A. | F30: OR
A31: ='Population Definitions'!$B$5 -> atsi_0-14_F | C31: N.A. | F31: OR
A32: ='Population Definitions'!$B$6 -> atsi_15-54_F | C32: N.A. | F32: OR
A33: ='Population Definitions'!$B$7 -> atsi_65+_F | C33: N.A. | F33: OR
A34: ='Population Definitions'!$B$8 -> ausb_0-14_M | C34: N.A. | F34: OR
A35: ='Population Definitions'!$B$9 -> ausb_15-54_M | C35: N.A. | F35: OR
A36: ='Population Definitions'!$B$10 -> ausb_65+_M | C36: N.A. | F36: OR
A37: ='Population Definitions'!$B$11 -> ausb_0-14_F | C37: N.A. | F37: OR
A38: ='Population Definitions'!$B$12 -> ausb_15-54_F | C38: N.A. | F38: OR
A39: ='Population Definitions'!$B$13 -> ausb_65+_F | C39: N.A. | F39: OR
A40: ='Population Definitions'!$B$14 -> lros_0-14_M | C40: N.A. | F40: OR
A41: ='Population Definitions'!$B$15 -> lros_15-54_M | C41: N.A. | F41: OR
...

Sheet Disease Progression
A1: HBeAg seroconversion rate (used to fit HBeAg prevalence) | B1: Provenance | C1: Units | D1: Uncertainty | E1: Constant | G1: 1980 | H1: 1981 | I1: 1982 | J1: 1983 | K1: 1984 | L1: 1985 | M1: 1986 | N1: 1987 | O1: 1988 | P1: 1989 | Q1: 1990 | R1: 1991 | S1: 1992 | T1: 1993 | U1: 1994 | V1: 1995 | W1: 1996 | X1: 1997 | Y1: 1998 | Z1: 1999 | AA1: 2000 | AB1: 2001 | AC1: 2002 | AD1: 2003 | AE1: 2004 | AF1: 2005 | AG1: 2006 | AH1: 2007 | AI1: 2008 | AJ1: 2009 | AK1: 2010 | AL1: 2011 | AM1: 2012 | AN1: 2013 | AO1: 2014 | AP1: 2015 | AQ1: 2016 | AR1: 2017 | AS1: 2018 | AT1: 2019 | AU1: 2020 | AV1: 2021 | AW1: 2022 | AX1: 2023 | AY1: 2024 | AZ1: 2025 | BA1: 2026 | BB1: 2027 | BC1: 2028 | BD1: 2029 | BE1: 2030 | BF1: 2031 | BG1: 2032 | BH1: 2033 | BI1: 2034 | BJ1: 2035 | BK1: 2036 | BL1: 2037 | BM1: 2038 | BN1: 2039 | BO1: 2040 | BP1: 2041 | BQ1: 2042 | BR1: 2043 | BS1: 2044 | BT1: 2045 | BU1: 2046 | BV1: 2047 | BW1: 2048 | BX1: 2049 | BY1: 2050 | BZ1: 2051 | CA1: 2052 | CB1: 2053 | CC1: 2054 | CD1: 2055 | CE1: 2056 | CF1: 2057 | CG1: 2058 | CH1: 2059 | CI1: 2060 | CJ1: 2061 | CK1: 2062 | CL1: 2063 | CM1: 2064 | CN1: 2065 | CO1: 2066 | CP1: 2067 | CQ1: 2068 | CR1: 2069 | CS1: 2070 | CT1: 2071
A2: ='Population Definitions'!$B$2 -> atsi_0-14_M | C2: Probability (per year) | F2: OR
A3: ='Population Definitions'!$B$3 -> atsi_15-54_M | C3: Probability (per year) | F3: OR
A4: ='Population Definitions'!$B$4 -> atsi_65+_M | C4: Probability (per year) | F4: OR
A5: ='Population Definitions'!$B$5 -> atsi_0-14_F | C5: Probability (per year) | F5: OR
A6: ='Population Definitions'!$B$6 -> atsi_15-54_F | C6: Probability (per year) | F6: OR
A7: ='Population Definitions'!$B$7 -> atsi_65+_F | C7: Probability (per year) | F7: OR
A8: ='Population Definitions'!$B$8 -> ausb_0-14_M | C8: Probability (per year) | F8: OR
A9: ='Population Definitions'!$B$9 -> ausb_15-54_M | C9: Probability (per year) | F9: OR
A10: ='Population Definitions'!$B$10 -> ausb_65+_M | C10: Probability (per year) | F10: OR
A11: ='Population Definitions'!$B$11 -> ausb_0-14_F | C11: Probability (per year) | F11: OR
A12: ='Population Definitions'!$B$12 -> ausb_15-54_F | C12: Probability (per year) | F12: OR
A13: ='Population Definitions'!$B$13 -> ausb_65+_F | C13: Probability (per year) | F13: OR
A14: ='Population Definitions'!$B$14 -> lros_0-14_M | C14: Probability (per year) | F14: OR
A15: ='Population Definitions'!$B$15 -> lros_15-54_M | C15: Probability (per year) | F15: OR
A16: ='Population Definitions'!$B$16 -> lros_65+_M | C16: Probability (per year) | F16: OR
A17: ='Population Definitions'!$B$17 -> lros_0-14_F | C17: Probability (per year) | F17: OR
A18: ='Population Definitions'!$B$18 -> lros_15-54_F | C18: Probability (per year) | F18: OR
A19: ='Population Definitions'!$B$19 -> lros_65+_F | C19: Probability (per year) | F19: OR
A20: ='Population Definitions'!$B$20 -> hros_0-14_M | C20: Probability (per year) | F20: OR
A21: ='Population Definitions'!$B$21 -> hros_15-54_M | C21: Probability (per year) | F21: OR
A22: ='Population Definitions'!$B$22 -> hros_65+_M | C22: Probability (per year) | F22: OR
A23: ='Population Definitions'!$B$23 -> hros_0-14_F | C23: Probability (per year) | F23: OR
A24: ='Population Definitions'!$B$24 -> hros_15-54_F | C24: Probability (per year) | F24: OR
A25: ='Population Definitions'!$B$25 -> hros_65+_F | C25: Probability (per year) | F25: OR
A27: Natural History: HBeAg positive chronic HBV infection from horizontally acquired acute HBV infection | B27: Provenance | C27: Units | D27: Uncertainty | E27: Constant | G27: 1980 | H27: 1981 | I27: 1982 | J27: 1983 | K27: 1984 | L27: 1985 | M27: 1986 | N27: 1987 | O27: 1988 | P27: 1989 | Q27: 1990 | R27: 1991 | S27: 1992 | T27: 1993 | U27: 1994 | V27: 1995 | W27: 1996 | X27: 1997 | Y27: 1998 | Z27: 1999 | AA27: 2000 | AB27: 2001 | AC27: 2002 | AD27: 2003 | AE27: 2004 | AF27: 2005 | AG27: 2006 | AH27: 2007 | AI27: 2008 | AJ27: 2009 | AK27: 2010 | AL27: 2011 | AM27: 2012 | AN27: 2013 | AO27: 2014 | AP27: 2015 | AQ27: 2016 | AR27: 2017 | AS27: 2018 | AT27: 2019 | AU27: 2020 | AV27: 2021 | AW27: 2022 | AX27: 2023 | AY27: 2024 | AZ27: 2025 | BA27: 2026 | BB27: 2027 | BC27: 2028 | BD27: 2029 | BE27: 2030 | BF27: 2031 | BG27: 2032 | BH27: 2033 | BI27: 2034 | BJ27: 2035 | BK27: 2036 | BL27: 2037 | BM27: 2038 | BN27: 2039 | BO27: 2040 | BP27: 2041 | BQ27: 2042 | BR27: 2043 | BS27: 2044 | BT27: 2045 | BU27: 2046 | BV27: 2047 | BW27: 2048 | BX27: 2049 | BY27: 2050 | BZ27: 2051 | CA27: 2052 | CB27: 2053 | CC27: 2054 | CD27: 2055 | CE27: 2056 | CF27: 2057 | CG27: 2058 | CH27: 2059 | CI27: 2060 | CJ27: 2061 | CK27: 2062 | CL27: 2063 | CM27: 2064 | CN27: 2065 | CO27: 2066 | CP27: 2067 | CQ27: 2068 | CR27: 2069 | CS27: 2070 | CT27: 2071
A28: ='Population Definitions'!$B$2 -> atsi_0-14_M | C28: Probability (per 6 months) | F28: OR
A29: ='Population Definitions'!$B$3 -> atsi_15-54_M | C29: Probability (per 6 months) | F29: OR
A30: ='Population Definitions'!$B$4 -> atsi_65+_M | C30: Probability (per 6 months) | F30: OR
A31: ='Population Definitions'!$B$5 -> atsi_0-14_F | C31: Probability (per 6 months) | F31: OR
A32: ='Population Definitions'!$B$6 -> atsi_15-54_F | C32: Probability (per 6 months) | F32: OR
A33: ='Population Definitions'!$B$7 -> atsi_65+_F | C33: Probability (per 6 months) | F33: OR
A34: ='Population Definitions'!$B$8 -> ausb_0-14_M | C34: Probability (per 6 months) | F34: OR
A35: ='Population Definitions'!$B$9 -> ausb_15-54_M | C35: Probability (per 6 months) | F35: OR
A36: ='Population Definitions'!$B$10 -> ausb_65+_M | C36: Probability (per 6 months) | F36: OR
A37: ='Population Definitions'!$B$11 -> ausb_0-14_F | C37: Probability (per 6 months) | F37: OR
A38: ='Population Definitions'!$B$12 -> ausb_15-54_F | C38: Probability (per 6 months) | F38: OR
A39: ='Population Definitions'!$B$13 -> ausb_65+_F | C39: Probability (per 6 months) | F39: OR
A40: ='Population Definitions'!$B$14 -> lros_0-14_M | C40: Probability (per 6 months) | F40: OR
A41: ='Population Definitions'!$B$15 -> lros_15-54_M | C41: Probability (per 6 months) | F41: OR
...

Sheet Calibration Parameters
A1: Scaling Factor: Rate of HCC progression | B1: Provenance | C1: Units | D1: Uncertainty | E1: Constant | G1: 1980 | H1: 1981 | I1: 1982 | J1: 1983 | K1: 1984 | L1: 1985 | M1: 1986 | N1: 1987 | O1: 1988 | P1: 1989 | Q1: 1990 | R1: 1991 | S1: 1992 | T1: 1993 | U1: 1994 | V1: 1995 | W1: 1996 | X1: 1997 | Y1: 1998 | Z1: 1999 | AA1: 2000 | AB1: 2001 | AC1: 2002 | AD1: 2003 | AE1: 2004 | AF1: 2005 | AG1: 2006 | AH1: 2007 | AI1: 2008 | AJ1: 2009 | AK1: 2010 | AL1: 2011 | AM1: 2012 | AN1: 2013 | AO1: 2014 | AP1: 2015 | AQ1: 2016 | AR1: 2017 | AS1: 2018 | AT1: 2019 | AU1: 2020 | AV1: 2021 | AW1: 2022 | AX1: 2023 | AY1: 2024 | AZ1: 2025 | BA1: 2026 | BB1: 2027 | BC1: 2028 | BD1: 2029 | BE1: 2030 | BF1: 2031 | BG1: 2032 | BH1: 2033 | BI1: 2034 | BJ1: 2035 | BK1: 2036 | BL1: 2037 | BM1: 2038 | BN1: 2039 | BO1: 2040 | BP1: 2041 | BQ1: 2042 | BR1: 2043 | BS1: 2044 | BT1: 2045 | BU1: 2046 | BV1: 2047 | BW1: 2048 | BX1: 2049 | BY1: 2050 | BZ1: 2051 | CA1: 2052 | CB1: 2053 | CC1: 2054 | CD1: 2055 | CE1: 2056 | CF1: 2057 | CG1: 2058 | CH1: 2059 | CI1: 2060 | CJ1: 2061 | CK1: 2062 | CL1: 2063 | CM1: 2064 | CN1: 2065 | CO1: 2066 | CP1: 2067 | CQ1: 2068 | CR1: 2069 | CS1: 2070 | CT1: 2071
A2: ='Population Definitions'!$B$2 -> atsi_0-14_M | C2: N.A. | F2: OR
A3: ='Population Definitions'!$B$3 -> atsi_15-54_M | C3: N.A. | F3: OR
A4: ='Population Definitions'!$B$4 -> atsi_65+_M | C4: N.A. | F4: OR
A5: ='Population Definitions'!$B$5 -> atsi_0-14_F | C5: N.A. | F5: OR
A6: ='Population Definitions'!$B$6 -> atsi_15-54_F | C6: N.A. | F6: OR
A7: ='Population Definitions'!$B$7 -> atsi_65+_F | C7: N.A. | F7: OR
A8: ='Population Definitions'!$B$8 -> ausb_0-14_M | C8: N.A. | F8: OR
A9: ='Population Definitions'!$B$9 -> ausb_15-54_M | C9: N.A. | F9: OR
A10: ='Population Definitions'!$B$10 -> ausb_65+_M | C10: N.A. | F10: OR
A11: ='Population Definitions'!$B$11 -> ausb_0-14_F | C11: N.A. | F11: OR
A12: ='Population Definitions'!$B$12 -> ausb_15-54_F | C12: N.A. | F12: OR
A13: ='Population Definitions'!$B$13 -> ausb_65+_F | C13: N.A. | F13: OR
A14: ='Population Definitions'!$B$14 -> lros_0-14_M | C14: N.A. | F14: OR
A15: ='Population Definitions'!$B$15 -> lros_15-54_M | C15: N.A. | F15: OR
A16: ='Population Definitions'!$B$16 -> lros_65+_M | C16: N.A. | F16: OR
A17: ='Population Definitions'!$B$17 -> lros_0-14_F | C17: N.A. | F17: OR
A18: ='Population Definitions'!$B$18 -> lros_15-54_F | C18: N.A. | F18: OR
A19: ='Population Definitions'!$B$19 -> lros_65+_F | C19: N.A. | F19: OR
A20: ='Population Definitions'!$B$20 -> hros_0-14_M | C20: N.A. | F20: OR
A21: ='Population Definitions'!$B$21 -> hros_15-54_M | C21: N.A. | F21: OR
A22: ='Population Definitions'!$B$22 -> hros_65+_M | C22: N.A. | F22: OR
A23: ='Population Definitions'!$B$23 -> hros_0-14_F | C23: N.A. | F23: OR
A24: ='Population Definitions'!$B$24 -> hros_15-54_F | C24: N.A. | F24: OR
A25: ='Population Definitions'!$B$25 -> hros_65+_F | C25: N.A. | F25: OR
A27: Scaling Factor: Rate of compensated cirrhosis progression from active infection | B27: Provenance | C27: Units | D27: Uncertainty | E27: Constant | G27: 1980 | H27: 1981 | I27: 1982 | J27: 1983 | K27: 1984 | L27: 1985 | M27: 1986 | N27: 1987 | O27: 1988 | P27: 1989 | Q27: 1990 | R27: 1991 | S27: 1992 | T27: 1993 | U27: 1994 | V27: 1995 | W27: 1996 | X27: 1997 | Y27: 1998 | Z27: 1999 | AA27: 2000 | AB27: 2001 | AC27: 2002 | AD27: 2003 | AE27: 2004 | AF27: 2005 | AG27: 2006 | AH27: 2007 | AI27: 2008 | AJ27: 2009 | AK27: 2010 | AL27: 2011 | AM27: 2012 | AN27: 2013 | AO27: 2014 | AP27: 2015 | AQ27: 2016 | AR27: 2017 | AS27: 2018 | AT27: 2019 | AU27: 2020 | AV27: 2021 | AW27: 2022 | AX27: 2023 | AY27: 2024 | AZ27: 2025 | BA27: 2026 | BB27: 2027 | BC27: 2028 | BD27: 2029 | BE27: 2030 | BF27: 2031 | BG27: 2032 | BH27: 2033 | BI27: 2034 | BJ27: 2035 | BK27: 2036 | BL27: 2037 | BM27: 2038 | BN27: 2039 | BO27: 2040 | BP27: 2041 | BQ27: 2042 | BR27: 2043 | BS27: 2044 | BT27: 2045 | BU27: 2046 | BV27: 2047 | BW27: 2048 | BX27: 2049 | BY27: 2050 | BZ27: 2051 | CA27: 2052 | CB27: 2053 | CC27: 2054 | CD27: 2055 | CE27: 2056 | CF27: 2057 | CG27: 2058 | CH27: 2059 | CI27: 2060 | CJ27: 2061 | CK27: 2062 | CL27: 2063 | CM27: 2064 | CN27: 2065 | CO27: 2066 | CP27: 2067 | CQ27: 2068 | CR27: 2069 | CS27: 2070 | CT27: 2071
A28: ='Population Definitions'!$B$2 -> atsi_0-14_M | C28: N.A. | F28: OR
A29: ='Population Definitions'!$B$3 -> atsi_15-54_M | C29: N.A. | F29: OR
A30: ='Population Definitions'!$B$4 -> atsi_65+_M | C30: N.A. | F30: OR
A31: ='Population Definitions'!$B$5 -> atsi_0-14_F | C31: N.A. | F31: OR
A32: ='Population Definitions'!$B$6 -> atsi_15-54_F | C32: N.A. | F32: OR
A33: ='Population Definitions'!$B$7 -> atsi_65+_F | C33: N.A. | F33: OR
A34: ='Population Definitions'!$B$8 -> ausb_0-14_M | C34: N.A. | F34: OR
A35: ='Population Definitions'!$B$9 -> ausb_15-54_M | C35: N.A. | F35: OR
A36: ='Population Definitions'!$B$10 -> ausb_65+_M | C36: N.A. | F36: OR
A37: ='Population Definitions'!$B$11 -> ausb_0-14_F | C37: N.A. | F37: OR
A38: ='Population Definitions'!$B$12 -> ausb_15-54_F | C38: N.A. | F38: OR
A39: ='Population Definitions'!$B$13 -> ausb_65+_F | C39: N.A. | F39: OR
A40: ='Population Definitions'!$B$14 -> lros_0-14_M | C40: N.A. | F40: OR
A41: ='Population Definitions'!$B$15 -> lros_15-54_M | C41: N.A. | F41: OR
...

Sheet Mother to Child
A1: Antenatal Care (first trimester) coverage of Australian pregnancies | B1: Provenance | C1: Units | D1: Uncertainty | E1: Constant | G1: 1980 | H1: 1981 | I1: 1982 | J1: 1983 | K1: 1984 | L1: 1985 | M1: 1986 | N1: 1987 | O1: 1988 | P1: 1989 | Q1: 1990 | R1: 1991 | S1: 1992 | T1: 1993 | U1: 1994 | V1: 1995 | W1: 1996 | X1: 1997 | Y1: 1998 | Z1: 1999 | AA1: 2000 | AB1: 2001 | AC1: 2002 | AD1: 2003 | AE1: 2004 | AF1: 2005 | AG1: 2006 | AH1: 2007 | AI1: 2008 | AJ1: 2009 | AK1: 2010 | AL1: 2011 | AM1: 2012 | AN1: 2013 | AO1: 2014 | AP1: 2015 | AQ1: 2016 | AR1: 2017 | AS1: 2018 | AT1: 2019 | AU1: 2020 | AV1: 2021 | AW1: 2022 | AX1: 2023 | AY1: 2024 | AZ1: 2025 | BA1: 2026 | BB1: 2027 | BC1: 2028 | BD1: 2029 | BE1: 2030 | BF1: 2031 | BG1: 2032 | BH1: 2033 | BI1: 2034 | BJ1: 2035 | BK1: 2036 | BL1: 2037 | BM1: 2038 | BN1: 2039 | BO1: 2040 | BP1: 2041 | BQ1: 2042 | BR1: 2043 | BS1: 2044 | BT1: 2045 | BU1: 2046 | BV1: 2047 | BW1: 2048 | BX1: 2049 | BY1: 2050 | BZ1: 2051 | CA1: 2052 | CB1: 2053 | CC1: 2054 | CD1: 2055 | CE1: 2056 | CF1: 2057 | CG1: 2058 | CH1: 2059 | CI1: 2060 | CJ1: 2061 | CK1: 2062 | CL1: 2063 | CM1: 2064 | CN1: 2065 | CO1: 2066 | CP1: 2067 | CQ1: 2068 | CR1: 2069 | CS1: 2070 | CT1: 2071
A2: ='Population Definitions'!$B$2 -> atsi_0-14_M | C2: N.A. | F2: OR
A3: ='Population Definitions'!$B$3 -> atsi_15-54_M | C3: N.A. | F3: OR
A4: ='Population Definitions'!$B$4 -> atsi_65+_M | C4: N.A. | F4: OR
A5: ='Population Definitions'!$B$5 -> atsi_0-14_F | C5: N.A. | F5: OR
A6: ='Population Definitions'!$B$6 -> atsi_15-54_F | C6: N.A. | F6: OR
A7: ='Population Definitions'!$B$7 -> atsi_65+_F | C7: N.A. | F7: OR
A8: ='Population Definitions'!$B$8 -> ausb_0-14_M | C8: N.A. | F8: OR
A9: ='Population Definitions'!$B$9 -> ausb_15-54_M | C9: N.A. | F9: OR
A10: ='Population Definitions'!$B$10 -> ausb_65+_M | C10: N.A. | F10: OR
A11: ='Population Definitions'!$B$11 -> ausb_0-14_F | C11: N.A. | F11: OR
A12: ='Population Definitions'!$B$12 -> ausb_15-54_F | C12: N.A. | F12: OR
A13: ='Population Definitions'!$B$13 -> ausb_65+_F | C13: N.A. | F13: OR
A14: ='Population Definitions'!$B$14 -> lros_0-14_M | C14: N.A. | F14: OR
A15: ='Population Definitions'!$B$15 -> lros_15-54_M | C15: N.A. | F15: OR
A16: ='Population Definitions'!$B$16 -> lros_65+_M | C16: N.A. | F16: OR
A17: ='Population Definitions'!$B$17 -> lros_0-14_F | C17: N.A. | F17: OR
A18: ='Population Definitions'!$B$18 -> lros_15-54_F | C18: N.A. | F18: OR
A19: ='Population Definitions'!$B$19 -> lros_65+_F | C19: N.A. | F19: OR
A20: ='Population Definitions'!$B$20 -> hros_0-14_M | C20: N.A. | F20: OR
A21: ='Population Definitions'!$B$21 -> hros_15-54_M | C21: N.A. | F21: OR
A22: ='Population Definitions'!$B$22 -> hros_65+_M | C22: N.A. | F22: OR
A23: ='Population Definitions'!$B$23 -> hros_0-14_F | C23: N.A. | F23: OR
A24: ='Population Definitions'!$B$24 -> hros_15-54_F | C24: N.A. | F24: OR
A25: ='Population Definitions'!$B$25 -> hros_65+_F | C25: N.A. | F25: OR
A27: Pregnancies among women in Australia (assumed as n births) | B27: Provenance | C27: Units | D27: Uncertainty | E27: Constant | G27: 1980 | H27: 1981 | I27: 1982 | J27: 1983 | K27: 1984 | L27: 1985 | M27: 1986 | N27: 1987 | O27: 1988 | P27: 1989 | Q27: 1990 | R27: 1991 | S27: 1992 | T27: 1993 | U27: 1994 | V27: 1995 | W27: 1996 | X27: 1997 | Y27: 1998 | Z27: 1999 | AA27: 2000 | AB27: 2001 | AC27: 2002 | AD27: 2003 | AE27: 2004 | AF27: 2005 | AG27: 2006 | AH27: 2007 | AI27: 2008 | AJ27: 2009 | AK27: 2010 | AL27: 2011 | AM27: 2012 | AN27: 2013 | AO27: 2014 | AP27: 2015 | AQ27: 2016 | AR27: 2017 | AS27: 2018 | AT27: 2019 | AU27: 2020 | AV27: 2021 | AW27: 2022 | AX27: 2023 | AY27: 2024 | AZ27: 2025 | BA27: 2026 | BB27: 2027 | BC27: 2028 | BD27: 2029 | BE27: 2030 | BF27: 2031 | BG27: 2032 | BH27: 2033 | BI27: 2034 | BJ27: 2035 | BK27: 2036 | BL27: 2037 | BM27: 2038 | BN27: 2039 | BO27: 2040 | BP27: 2041 | BQ27: 2042 | BR27: 2043 | BS27: 2044 | BT27: 2045 | BU27: 2046 | BV27: 2047 | BW27: 2048 | BX27: 2049 | BY27: 2050 | BZ27: 2051 | CA27: 2052 | CB27: 2053 | CC27: 2054 | CD27: 2055 | CE27: 2056 | CF27: 2057 | CG27: 2058 | CH27: 2059 | CI27: 2060 | CJ27: 2061 | CK27: 2062 | CL27: 2063 | CM27: 2064 | CN27: 2065 | CO27: 2066 | CP27: 2067 | CQ27: 2068 | CR27: 2069 | CS27: 2070 | CT27: 2071
A28: ='Population Definitions'!$B$2 -> atsi_0-14_M | C28: N.A. | F28: OR
A29: ='Population Definitions'!$B$3 -> atsi_15-54_M | C29: N.A. | F29: OR
A30: ='Population Definitions'!$B$4 -> atsi_65+_M | C30: N.A. | F30: OR
A31: ='Population Definitions'!$B$5 -> atsi_0-14_F | C31: N.A. | F31: OR
A32: ='Population Definitions'!$B$6 -> atsi_15-54_F | C32: N.A. | F32: OR
A33: ='Population Definitions'!$B$7 -> atsi_65+_F | C33: N.A. | F33: OR
A34: ='Population Definitions'!$B$8 -> ausb_0-14_M | C34: N.A. | F34: OR
A35: ='Population Definitions'!$B$9 -> ausb_15-54_M | C35: N.A. | F35: OR
A36: ='Population Definitions'!$B$10 -> ausb_65+_M | C36: N.A. | F36: OR
A37: ='Population Definitions'!$B$11 -> ausb_0-14_F | C37: N.A. | F37: OR
A38: ='Population Definitions'!$B$12 -> ausb_15-54_F | C38: N.A. | F38: OR
A39: ='Population Definitions'!$B$13 -> ausb_65+_F | C39: N.A. | F39: OR
A40: ='Population Definitions'!$B$14 -> lros_0-14_M | C40: N.A. | F40: OR
A41: ='Population Definitions'!$B$15 -> lros_15-54_M | C41: N.A. | F41: OR
...

Sheet Care Cascade
A1: Annual rate of treatment cessation (assumed to be lost-to-follow up) | B1: Provenance | C1: Units | D1: Uncertainty | E1: Constant | G1: 1980 | H1: 1981 | I1: 1982 | J1: 1983 | K1: 1984 | L1: 1985 | M1: 1986 | N1: 1987 | O1: 1988 | P1: 1989 | Q1: 1990 | R1: 1991 | S1: 1992 | T1: 1993 | U1: 1994 | V1: 1995 | W1: 1996 | X1: 1997 | Y1: 1998 | Z1: 1999 | AA1: 2000 | AB1: 2001 | AC1: 2002 | AD1: 2003 | AE1: 2004 | AF1: 2005 | AG1: 2006 | AH1: 2007 | AI1: 2008 | AJ1: 2009 | AK1: 2010 | AL1: 2011 | AM1: 2012 | AN1: 2013 | AO1: 2014 | AP1: 2015 | AQ1: 2016 | AR1: 2017 | AS1: 2018 | AT1: 2019 | AU1: 2020 | AV1: 2021 | AW1: 2022 | AX1: 2023 | AY1: 2024 | AZ1: 2025 | BA1: 2026 | BB1: 2027 | BC1: 2028 | BD1: 2029 | BE1: 2030 | BF1: 2031 | BG1: 2032 | BH1: 2033 | BI1: 2034 | BJ1: 2035 | BK1: 2036 | BL1: 2037 | BM1: 2038 | BN1: 2039 | BO1: 2040 | BP1: 2041 | BQ1: 2042 | BR1: 2043 | BS1: 2044 | BT1: 2045 | BU1: 2046 | BV1: 2047 | BW1: 2048 | BX1: 2049 | BY1: 2050 | BZ1: 2051 | CA1: 2052 | CB1: 2053 | CC1: 2054 | CD1: 2055 | CE1: 2056 | CF1: 2057 | CG1: 2058 | CH1: 2059 | CI1: 2060 | CJ1: 2061 | CK1: 2062 | CL1: 2063 | CM1: 2064 | CN1: 2065 | CO1: 2066 | CP1: 2067 | CQ1: 2068 | CR1: 2069 | CS1: 2070 | CT1: 2071
A2: ='Population Definitions'!$B$2 -> atsi_0-14_M | C2: Probability (per year) | F2: OR
A3: ='Population Definitions'!$B$3 -> atsi_15-54_M | C3: Probability (per year) | F3: OR
A4: ='Population Definitions'!$B$4 -> atsi_65+_M | C4: Probability (per year) | F4: OR
A5: ='Population Definitions'!$B$5 -> atsi_0-14_F | C5: Probability (per year) | F5: OR
A6: ='Population Definitions'!$B$6 -> atsi_15-54_F | C6: Probability (per year) | F6: OR
A7: ='Population Definitions'!$B$7 -> atsi_65+_F | C7: Probability (per year) | F7: OR
A8: ='Population Definitions'!$B$8 -> ausb_0-14_M | C8: Probability (per year) | F8: OR
A9: ='Population Definitions'!$B$9 -> ausb_15-54_M | C9: Probability (per year) | F9: OR
A10: ='Population Definitions'!$B$10 -> ausb_65+_M | C10: Probability (per year) | F10: OR
A11: ='Population Definitions'!$B$11 -> ausb_0-14_F | C11: Probability (per year) | F11: OR
A12: ='Population Definitions'!$B$12 -> ausb_15-54_F | C12: Probability (per year) | F12: OR
A13: ='Population Definitions'!$B$13 -> ausb_65+_F | C13: Probability (per year) | F13: OR
A14: ='Population Definitions'!$B$14 -> lros_0-14_M | C14: Probability (per year) | F14: OR
A15: ='Population Definitions'!$B$15 -> lros_15-54_M | C15: Probability (per year) | F15: OR
A16: ='Population Definitions'!$B$16 -> lros_65+_M | C16: Probability (per year) | F16: OR
A17: ='Population Definitions'!$B$17 -> lros_0-14_F | C17: Probability (per year) | F17: OR
A18: ='Population Definitions'!$B$18 -> lros_15-54_F | C18: Probability (per year) | F18: OR
A19: ='Population Definitions'!$B$19 -> lros_65+_F | C19: Probability (per year) | F19: OR
A20: ='Population Definitions'!$B$20 -> hros_0-14_M | C20: Probability (per year) | F20: OR
A21: ='Population Definitions'!$B$21 -> hros_15-54_M | C21: Probability (per year) | F21: OR
A22: ='Population Definitions'!$B$22 -> hros_65+_M | C22: Probability (per year) | F22: OR
A23: ='Population Definitions'!$B$23 -> hros_0-14_F | C23: Probability (per year) | F23: OR
A24: ='Population Definitions'!$B$24 -> hros_15-54_F | C24: Probability (per year) | F24: OR
A25: ='Population Definitions'!$B$25 -> hros_65+_F | C25: Probability (per year) | F25: OR
A27: Annual rate of loss-to-follow up (return to diagnosed only) | B27: Provenance | C27: Units | D27: Uncertainty | E27: Constant | G27: 1980 | H27: 1981 | I27: 1982 | J27: 1983 | K27: 1984 | L27: 1985 | M27: 1986 | N27: 1987 | O27: 1988 | P27: 1989 | Q27: 1990 | R27: 1991 | S27: 1992 | T27: 1993 | U27: 1994 | V27: 1995 | W27: 1996 | X27: 1997 | Y27: 1998 | Z27: 1999 | AA27: 2000 | AB27: 2001 | AC27: 2002 | AD27: 2003 | AE27: 2004 | AF27: 2005 | AG27: 2006 | AH27: 2007 | AI27: 2008 | AJ27: 2009 | AK27: 2010 | AL27: 2011 | AM27: 2012 | AN27: 2013 | AO27: 2014 | AP27: 2015 | AQ27: 2016 | AR27: 2017 | AS27: 2018 | AT27: 2019 | AU27: 2020 | AV27: 2021 | AW27: 2022 | AX27: 2023 | AY27: 2024 | AZ27: 2025 | BA27: 2026 | BB27: 2027 | BC27: 2028 | BD27: 2029 | BE27: 2030 | BF27: 2031 | BG27: 2032 | BH27: 2033 | BI27: 2034 | BJ27: 2035 | BK27: 2036 | BL27: 2037 | BM27: 2038 | BN27: 2039 | BO27: 2040 | BP27: 2041 | BQ27: 2042 | BR27: 2043 | BS27: 2044 | BT27: 2045 | BU27: 2046 | BV27: 2047 | BW27: 2048 | BX27: 2049 | BY27: 2050 | BZ27: 2051 | CA27: 2052 | CB27: 2053 | CC27: 2054 | CD27: 2055 | CE27: 2056 | CF27: 2057 | CG27: 2058 | CH27: 2059 | CI27: 2060 | CJ27: 2061 | CK27: 2062 | CL27: 2063 | CM27: 2064 | CN27: 2065 | CO27: 2066 | CP27: 2067 | CQ27: 2068 | CR27: 2069 | CS27: 2070 | CT27: 2071
A28: ='Population Definitions'!$B$2 -> atsi_0-14_M | C28: Probability (per year) | F28: OR
A29: ='Population Definitions'!$B$3 -> atsi_15-54_M | C29: Probability (per year) | F29: OR
A30: ='Population Definitions'!$B$4 -> atsi_65+_M | C30: Probability (per year) | F30: OR
A31: ='Population Definitions'!$B$5 -> atsi_0-14_F | C31: Probability (per year) | F31: OR
A32: ='Population Definitions'!$B$6 -> atsi_15-54_F | C32: Probability (per year) | F32: OR
A33: ='Population Definitions'!$B$7 -> atsi_65+_F | C33: Probability (per year) | F33: OR
A34: ='Population Definitions'!$B$8 -> ausb_0-14_M | C34: Probability (per year) | F34: OR
A35: ='Population Definitions'!$B$9 -> ausb_15-54_M | C35: Probability (per year) | F35: OR
A36: ='Population Definitions'!$B$10 -> ausb_65+_M | C36: Probability (per year) | F36: OR
A37: ='Population Definitions'!$B$11 -> ausb_0-14_F | C37: Probability (per year) | F37: OR
A38: ='Population Definitions'!$B$12 -> ausb_15-54_F | C38: Probability (per year) | F38: OR
A39: ='Population Definitions'!$B$13 -> ausb_65+_F | C39: Probability (per year) | F39: OR
A40: ='Population Definitions'!$B$14 -> lros_0-14_M | C40: Probability (per year) | F40: OR
A41: ='Population Definitions'!$B$15 -> lros_15-54_M | C41: Probability (per year) | F41: OR
...

Sheet Interactions
A1: Abbreviation | B1: Full Name | C1: From population type | D1: To population type
A2: mx_mtct | B2: Vertical Transmission | C2: default | D2: default
B4: ='Population Definitions'!$B$2 -> atsi_0-14_M | C4: ='Population Definitions'!$B$3 -> atsi_15-54_M | D4: ='Population Definitions'!$B$4 -> atsi_65+_M | E4: ='Population Definitions'!$B$5 -> atsi_0-14_F | F4: ='Population Definitions'!$B$6 -> atsi_15-54_F | G4: ='Population Definitions'!$B$7 -> atsi_65+_F | H4: ='Population Definitions'!$B$8 -> ausb_0-14_M | I4: ='Population Definitions'!$B$9 -> ausb_15-54_M | J4: ='Population Definitions'!$B$10 -> ausb_65+_M | K4: ='Population Definitions'!$B$11 -> ausb_0-14_F | L4: ='Population Definitions'!$B$12 -> ausb_15-54_F | M4: ='Population Definitions'!$B$13 -> ausb_65+_F | N4: ='Population Definitions'!$B$14 -> lros_0-14_M | O4: ='Population Definitions'!$B$15 -> lros_15-54_M | P4: ='Population Definitions'!$B$16 -> lros_65+_M | Q4: ='Population Definitions'!$B$17 -> lros_0-14_F | R4: ='Population Definitions'!$B$18 -> lros_15-54_F | S4: ='Population Definitions'!$B$19 -> lros_65+_F | T4: ='Population Definitions'!$B$20 -> hros_0-14_M | U4: ='Population Definitions'!$B$21 -> hros_15-54_M | V4: ='Population Definitions'!$B$22 -> hros_65+_M | W4: ='Population Definitions'!$B$23 -> hros_0-14_F | X4: ='Population Definitions'!$B$24 -> hros_15-54_F | Y4: ='Population Definitions'!$B$25 -> hros_65+_F
A5: ='Population Definitions'!$B$2 -> atsi_0-14_M | B5: Y | C5: N | D5: N | E5: N | F5: N | G5: N | H5: N | I5: N | J5: N | K5: N | L5: N | M5: N | N5: N | O5: N | P5: N | Q5: N | R5: N | S5: N | T5: N | U5: N | V5: N | W5: N | X5: N | Y5: N
A6: ='Population Definitions'!$B$3 -> atsi_15-54_M | B6: N | C6: N | D6: N | E6: N | F6: N | G6: N | H6: N | I6: N | J6: N | K6: N | L6: N | M6: N | N6: N | O6: N | P6: N | Q6: N | R6: N | S6: N | T6: N | U6: N | V6: N | W6: N | X6: N | Y6: N
A7: ='Population Definitions'!$B$4 -> atsi_65+_M | B7: N | C7: N | D7: N | E7: N | F7: N | G7: N | H7: N | I7: N | J7: N | K7: N | L7: N | M7: N | N7: N | O7: N | P7: N | Q7: N | R7: N | S7: N | T7: N | U7: N | V7: N | W7: N | X7: N | Y7: N
A8: ='Population Definitions'!$B$5 -> atsi_0-14_F | B8: N | C8: N | D8: N | E8: N | F8: N | G8: N | H8: N | I8: N | J8: N | K8: N | L8: N | M8: N | N8: N | O8: N | P8: N | Q8: N | R8: N | S8: N | T8: N | U8: N | V8: N | W8: N | X8: N | Y8: N
A9: ='Population Definitions'!$B$6 -> atsi_15-54_F | B9: N | C9: N | D9: N | E9: N | F9: N | G9: N | H9: N | I9: N | J9: N | K9: N | L9: N | M9: N | N9: N | O9: N | P9: N | Q9: N | R9: N | S9: N | T9: N | U9: N | V9: N | W9: N | X9: N | Y9: N
A10: ='Population Definitions'!$B$7 -> atsi_65+_F | B10: N | C10: N | D10: N | E10: N | F10: N | G10: N | H10: N | I10: N | J10: N | K10: N | L10: N | M10: N | N10: N | O10: N | P10: N | Q10: N | R10: N | S10: N | T10: N | U10: N | V10: N | W10: N | X10: N | Y10: N
A11: ='Population Definitions'!$B$8 -> ausb_0-14_M | B11: N | C11: N | D11: N | E11: N | F11: N | G11: N | H11: N | I11: N | J11: N | K11: N | L11: N | M11: N | N11: N | O11: N | P11: N | Q11: N | R11: N | S11: N | T11: N | U11: N | V11: N | W11: N | X11: N | Y11: N
A12: ='Population Definitions'!$B$9 -> ausb_15-54_M | B12: N | C12: N | D12: N | E12: N | F12: N | G12: N | H12: N | I12: N | J12: N | K12: N | L12: N | M12: N | N12: N | O12: N | P12: N | Q12: N | R12: N | S12: N | T12: N | U12: N | V12: N | W12: N | X12: N | Y12: N
A13: ='Population Definitions'!$B$10 -> ausb_65+_M | B13: N | C13: N | D13: N | E13: N | F13: N | G13: N | H13: N | I13: N | J13: N | K13: N | L13: N | M13: N | N13: N | O13: N | P13: N | Q13: N | R13: N | S13: N | T13: N | U13: N | V13: N | W13: N | X13: N | Y13: N
A14: ='Population Definitions'!$B$11 -> ausb_0-14_F | B14: N | C14: N | D14: N | E14: N | F14: N | G14: N | H14: N | I14: N | J14: N | K14: N | L14: N | M14: N | N14: N | O14: N | P14: N | Q14: N | R14: N | S14: N | T14: N | U14: N | V14: N | W14: N | X14: N | Y14: N
A15: ='Population Definitions'!$B$12 -> ausb_15-54_F | B15: N | C15: N | D15: N | E15: N | F15: N | G15: N | H15: N | I15: N | J15: N | K15: N | L15: N | M15: N | N15: N | O15: N | P15: N | Q15: N | R15: N | S15: N | T15: N | U15: N | V15: N | W15: N | X15: N | Y15: N
A16: ='Population Definitions'!$B$13 -> ausb_65+_F | B16: N | C16: N | D16: N | E16: N | F16: N | G16: N | H16: N | I16: N | J16: N | K16: N | L16: N | M16: N | N16: N | O16: N | P16: N | Q16: N | R16: N | S16: N | T16: N | U16: N | V16: N | W16: N | X16: N | Y16: N
A17: ='Population Definitions'!$B$14 -> lros_0-14_M | B17: N | C17: N | D17: N | E17: N | F17: N | G17: N | H17: N | I17: N | J17: N | K17: N | L17: N | M17: N | N17: N | O17: N | P17: N | Q17: N | R17: N | S17: N | T17: N | U17: N | V17: N | W17: N | X17: N | Y17: N
A18: ='Population Definitions'!$B$15 -> lros_15-54_M | B18: N | C18: N | D18: N | E18: N | F18: N | G18: N | H18: N | I18: N | J18: N | K18: N | L18: N | M18: N | N18: N | O18: N | P18: N | Q18: N | R18: N | S18: N | T18: N | U18: N | V18: N | W18: N | X18: N | Y18: N
A19: ='Population Definitions'!$B$16 -> lros_65+_M | B19: N | C19: N | D19: N | E19: N | F19: N | G19: N | H19: N | I19: N | J19: N | K19: N | L19: N | M19: N | N19: N | O19: N | P19: N | Q19: N | R19: N | S19: N | T19: N | U19: N | V19: N | W19: N | X19: N | Y19: N
A20: ='Population Definitions'!$B$17 -> lros_0-14_F | B20: N | C20: N | D20: N | E20: N | F20: N | G20: N | H20: N | I20: N | J20: N | K20: N | L20: N | M20: N | N20: N | O20: N | P20: N | Q20: N | R20: N | S20: N | T20: N | U20: N | V20: N | W20: N | X20: N | Y20: N
A21: ='Population Definitions'!$B$18 -> lros_15-54_F | B21: N | C21: N | D21: N | E21: N | F21: N | G21: N | H21: N | I21: N | J21: N | K21: N | L21: N | M21: N | N21: N | O21: N | P21: N | Q21: N | R21: N | S21: N | T21: N | U21: N | V21: N | W21: N | X21: N | Y21: N
A22: ='Population Definitions'!$B$19 -> lros_65+_F | B22: N | C22: N | D22: N | E22: N | F22: N | G22: N | H22: N | I22: N | J22: N | K22: N | L22: N | M22: N | N22: N | O22: N | P22: N | Q22: N | R22: N | S22: N | T22: N | U22: N | V22: N | W22: N | X22: N | Y22: N
A23: ='Population Definitions'!$B$20 -> hros_0-14_M | B23: N | C23: N | D23: N | E23: N | F23: N | G23: N | H23: N | I23: N | J23: N | K23: N | L23: N | M23: N | N23: N | O23: N | P23: N | Q23: N | R23: N | S23: N | T23: N | U23: N | V23: N | W23: N | X23: N | Y23: N
A24: ='Population Definitions'!$B$21 -> hros_15-54_M | B24: N | C24: N | D24: N | E24: N | F24: N | G24: N | H24: N | I24: N | J24: N | K24: N | L24: N | M24: N | N24: N | O24: N | P24: N | Q24: N | R24: N | S24: N | T24: N | U24: N | V24: N | W24: N | X24: N | Y24: N
A25: ='Population Definitions'!$B$22 -> hros_65+_M | B25: N | C25: N | D25: N | E25: N | F25: N | G25: N | H25: N | I25: N | J25: N | K25: N | L25: N | M25: N | N25: N | O25: N | P25: N | Q25: N | R25: N | S25: N | T25: N | U25: N | V25: N | W25: N | X25: N | Y25: N
A26: ='Population Definitions'!$B$23 -> hros_0-14_F | B26: N | C26: N | D26: N | E26: N | F26: N | G26: N | H26: N | I26: N | J26: N | K26: N | L26: N | M26: N | N26: N | O26: N | P26: N | Q26: N | R26: N | S26: N | T26: N | U26: N | V26: N | W26: N | X26: N | Y26: N
A27: ='Population Definitions'!$B$24 -> hros_15-54_F | B27: N | C27: N | D27: N | E27: N | F27: N | G27: N | H27: N | I27: N | J27: N | K27: N | L27: N | M27: N | N27: N | O27: N | P27: N | Q27: N | R27: N | S27: N | T27: N | U27: N | V27: N | W27: N | X27: N | Y27: N
A28: ='Population Definitions'!$B$25 -> hros_65+_F | B28: N | C28: N | D28: N | E28: N | F28: N | G28: N | H28: N | I28: N | J28: N | K28: N | L28: N | M28: N | N28: N | O28: N | P28: N | Q28: N | R28: N | S28: N | T28: N | U28: N | V28: N | W28: N | X28: N | Y28: N
A30: From population | C30: To population | D30: Provenance | E30: Units | F30: Uncertainty | G30: Constant | I30: 1980 | J30: 1981 | K30: 1982 | L30: 1983 | M30: 1984 | N30: 1985 | O30: 1986 | P30: 1987 | Q30: 1988 | R30: 1989 | S30: 1990 | T30: 1991 | U30: 1992 | V30: 1993 | W30: 1994 | X30: 1995 | Y30: 1996 | Z30: 1997 | AA30: 1998 | AB30: 1999 | AC30: 2000 | AD30: 2001 | AE30: 2002 | AF30: 2003 | AG30: 2004 | AH30: 2005 | AI30: 2006 | AJ30: 2007 | AK30: 2008 | AL30: 2009 | AM30: 2010 | AN30: 2011 | AO30: 2012 | AP30: 2013 | AQ30: 2014 | AR30: 2015 | AS30: 2016 | AT30: 2017 | AU30: 2018 | AV30: 2019 | AW30: 2020 | AX30: 2021 | AY30: 2022 | AZ30: 2023 | BA30: 2024 | BB30: 2025 | BC30: 2026 | BD30: 2027 | BE30: 2028 | BF30: 2029 | BG30: 2030 | BH30: 2031 | BI30: 2032 | BJ30: 2033 | BK30: 2034 | BL30: 2035 | BM30: 2036 | BN30: 2037 | BO30: 2038 | BP30: 2039 | BQ30: 2040 | BR30: 2041 | BS30: 2042 | BT30: 2043 | BU30: 2044 | BV30: 2045 | BW30: 2046 | BX30: 2047 | BY30: 2048 | BZ30: 2049 | CA30: 2050 | CB30: 2051 | CC30: 2052 | CD30: 2053 | CE30: 2054 | CF30: 2055 | CG30: 2056 | CH30: 2057 | CI30: 2058 | CJ30: 2059 | CK30: 2060 | CL30: 2061 | CM30: 2062 | CN30: 2063 | CO30: 2064 | CP30: 2065 | CQ30: 2066 | CR30: 2067 | CS30: 2068 | CT30: 2069 | CU30: 2070 | CV30: 2071
A31: =IF($B$5="Y",'Population Definitions'!$B$2,"...") -> atsi_0-14_M | B31: =IF($B$5="Y","--->","...") -> ---> | C31: =IF($B$5="Y",'Population Definitions'!$B$2,"...") -> atsi_0-14_M | E31: N.A. | G31: 1 | H31: =IF($B$5="Y","OR","...") -> OR
A32: =IF($C$5="Y",'Population Definitions'!$B$2,"...") -> ... | B32: =IF($C$5="Y","--->","...") -> ... | C32: =IF($C$5="Y",'Population Definitions'!$B$3,"...") -> ... | H32: =IF($C$5="Y","OR","...") -> ...
A33: =IF($D$5="Y",'Population Definitions'!$B$2,"...") -> ... | B33: =IF($D$5="Y","--->","...") -> ... | C33: =IF($D$5="Y",'Population Definitions'!$B$4,"...") -> ... | H33: =IF($D$5="Y","OR","...") -> ...
A34: =IF($E$5="Y",'Population Definitions'!$B$2,"...") -> ... | B34: =IF($E$5="Y","--->","...") -> ... | C34: =IF($E$5="Y",'Population Definitions'!$B$5,"...") -> ... | H34: =IF($E$5="Y","OR","...") -> ...
A35: =IF($F$5="Y",'Population Definitions'!$B$2,"...") -> ... | B35: =IF($F$5="Y","--->","...") -> ... | C35: =IF($F$5="Y",'Population Definitions'!$B$6,"...") -> ... | H35: =IF($F$5="Y","OR","...") -> ...
A36: =IF($G$5="Y",'Population Definitions'!$B$2,"...") -> ... | B36: =IF($G$5="Y","--->","...") -> ... | C36: =IF($G$5="Y",'Population Definitions'!$B$7,"...") -> ... | H36: =IF($G$5="Y","OR","...") -> ...
A37: =IF($H$5="Y",'Population Definitions'!$B$2,"...") -> ... | B37: =IF($H$5="Y","--->","...") -> ... | C37: =IF($H$5="Y",'Population Definitions'!$B$8,"...") -> ... | H37: =IF($H$5="Y","OR","...") -> ...
A38: =IF($I$5="Y",'Population Definitions'!$B$2,"...") -> ... | B38: =IF($I$5="Y","--->","...") -> ... | C38: =IF($I$5="Y",'Population Definitions'!$B$9,"...") -> ... | H38: =IF($I$5="Y","OR","...") -> ...
