Workbook

Sheet Population Definitions
A1: Abbreviation | B1: Full Name | C1: Population type
A2: atsi_0-4_M | B2: atsi_0-4_M | C2: default
A3: atsi_5-14_M | B3: atsi_5-14_M | C3: default
A4: atsi_15-29_M | B4: atsi_15-29_M | C4: default
A5: atsi_30-49_M | B5: atsi_30-49_M | C5: default
A6: atsi_50-64_M | B6: atsi_50-64_M | C6: default
A7: atsi_65+_M | B7: atsi_65+_M | C7: default
A8: atsi_0-4_F | B8: atsi_0-4_F | C8: default
A9: atsi_5-14_F | B9: atsi_5-14_F | C9: default
A10: atsi_15-29_F | B10: atsi_15-29_F | C10: default
A11: atsi_30-49_F | B11: atsi_30-49_F | C11: default
A12: atsi_50-64_F | B12: atsi_50-64_F | C12: default
A13: atsi_65+_F | B13: atsi_65+_F | C13: default

Sheet Population Size
A1: Population living in Australia | B1: Provenance | C1: Units | D1: Uncertainty | E1: 1980 | F1: 1981 | G1: 1982 | H1: 1983 | I1: 1984 | J1: 1985 | K1: 1986 | L1: 1987 | M1: 1988 | N1: 1989 | O1: 1990 | P1: 1991 | Q1: 1992 | R1: 1993 | S1: 1994 | T1: 1995 | U1: 1996 | V1: 1997 | W1: 1998 | X1: 1999 | Y1: 2000 | Z1: 2001 | AA1: 2002 | AB1: 2003 | AC1: 2004 | AD1: 2005 | AE1: 2006 | AF1: 2007 | AG1: 2008 | AH1: 2009 | AI1: 2010 | AJ1: 2011 | AK1: 2012 | AL1: 2013 | AM1: 2014 | AN1: 2015 | AO1: 2016 | AP1: 2017 | AQ1: 2018 | AR1: 2019 | AS1: 2020 | AT1: 2021 | AU1: 2022 | AV1: 2023 | AW1: 2024 | AX1: 2025 | AY1: 2026 | AZ1: 2027 | BA1: 2028 | BB1: 2029 | BC1: 2030 | BD1: 2031 | BE1: 2032 | BF1: 2033 | BG1: 2034 | BH1: 2035 | BI1: 2036 | BJ1: 2037 | BK1: 2038 | BL1: 2039 | BM1: 2040 | BN1: 2041 | BO1: 2042 | BP1: 2043 | BQ1: 2044 | BR1: 2045 | BS1: 2046 | BT1: 2047 | BU1: 2048 | BV1: 2049 | BW1: 2050 | BX1: 2051 | BY1: 2052 | BZ1: 2053 | CA1: 2054 | CB1: 2055 | CC1: 2056 | CD1: 2057 | CE1: 2058 | CF1: 2059 | CG1: 2060 | CH1: 2061 | CI1: 2062 | CJ1: 2063 | CK1: 2064 | CL1: 2065 | CM1: 2066 | CN1: 2067 | CO1: 2068 | CP1: 2069 | CQ1: 2070 | CR1: 2071
A2: ='Population Definitions'!$B$2 -> atsi_0-4_M | C2: Number | E2: 27483.295 | F2: 28134.126 | G2: 28800.37 | H2: 29482.391 | I2: 30180.563 | J2: 30895.268 | K2: 31626.898 | L2: 32375.854 | M2: 33142.546 | N2: 33927.394 | O2: 34730.828 | P2: 35553.288 | Q2: 36395.225 | R2: 37257.099 | S2: 38139.384 | T2: 39042.562 | U2: 39967.128 | V2: 40913.588 | W2: 41882.462 | X2: 42874.28 | Y2: 43889.585 | Z2: 44928.933 | AA2: 45992.894 | AB2: 47082.051 | AC2: 48197 | AD2: 49338.352 | AE2: 50506.733 | AF2: 51702.781 | AG2: 52927.154 | AH2: 54180.521 | AI2: 55463.568 | AJ2: 56777 | AK2: 56794 | AL2: 56670 | AM2: 56576 | AN2: 56399 | AO2: 56462 | AP2: 56209 | AQ2: 55735 | AR2: 55483 | AS2: 55049 | AT2: 54602 | AU2: 55603 | AV2: 56883 | AW2: 58194 | AX2: 60002 | AY2: 62014 | AZ2: 62989 | BA2: 63955 | BB2: 64927 | BC2: 65887 | BD2: 66808 | BE2: 67533.161 | BF2: 68310.795 | BG2: 69195.246 | BH2: 70156.822 | BI2: 71187.072 | BJ2: 72260.788 | BK2: 73361.774 | BL2: 74506.235 | BM2: 75670.625 | BN2: 76853.425 | BO2: 78043.612 | BP2: 79231.406 | BQ2: 80422.534 | BR2: 81620.935 | BS2: 82829.485 | BT2: 84041.091 | BU2: 85263.528 | BV2: 86500.094 | BW2: 87764.268 | BX2: 89064.977 | BY2: 90389.823 | BZ2: 91733.871 | CA2: 93115.095 | CB2: 94536.228 | CC2: 95992.367 | CD2: 97485.986 | CE2: 99013.777 | CF2: 100564.61 | CG2: 102135.23 | CH2: 103732.32 | CI2: 105346.68 | CJ2: 106988.55 | CK2: 108654.48 | CL2: 110342.71 | CM2: 112052.51 | CN2: 113796.03 | CO2: 115553.31 | CP2: 117330.22 | CQ2: 119131.96 | CR2: 120953.07
A3: ='Population Definitions'!$B$3 -> atsi_5-14_M | C3: Number | E3: 45488.757 | F3: 46565.976 | G3: 47668.703 | H3: 48797.545 | I3: 49953.119 | J3: 51136.057 | K3: 52347.009 | L3: 53586.638 | M3: 54855.622 | N3: 56154.656 | O3: 57484.454 | P3: 58845.742 | Q3: 60239.267 | R3: 61665.791 | S3: 63126.098 | T3: 64620.985 | U3: 66151.274 | V3: 67717.8 | W3: 69321.424 | X3: 70963.023 | Y3: 72643.497 | Z3: 74363.766 | AA3: 76124.773 | AB3: 77927.482 | AC3: 79772.881 | AD3: 81661.981 | AE3: 83595.817 | AF3: 85575.447 | AG3: 87601.958 | AH3: 89676.458 | AI3: 91800.084 | AJ3: 93974 | AK3: 96734 | AL3: 99395 | AM3: 101836 | AN3: 104106 | AO3: 105957 | AP3: 107839 | AQ3: 109854 | AR3: 111546 | AS3: 112481 | AT3: 113060 | AU3: 112825 | AV3: 112228 | AW3: 111883 | AX3: 111275 | AY3: 110892 | AZ3: 111640 | BA3: 112447 | BB3: 113506 | BC3: 114881 | BD3: 116445 | BE3: 118416 | BF3: 120341.57 | BG3: 122236.2 | BH3: 124123.55 | BI3: 126019.3 | BJ3: 127935.99 | BK3: 129880.09 | BL3: 131854.29 | BM3: 133864.2 | BN3: 135910.32 | BO3: 137992.79 | BP3: 140109.62 | BQ3: 142257.1 | BR3: 144432.97 | BS3: 146635.97 | BT3: 148865.5 | BU3: 151119.66 | BV3: 153398.2 | BW3: 155701.59 | BX3: 158032.82 | BY3: 160396.36 | BZ3: 162793.86 | CA3: 165225.82 | CB3: 167696.22 | CC3: 170209.17 | CD3: 172767.44 | CE3: 175374.04 | CF3: 178031.04 | CG3: 180738.15 | CH3: 183494.47 | CI3: 186300.49 | CJ3: 189154.88 | CK3: 192058.4 | CL3: 195011.09 | CM3: 198012.62 | CN3: 201062.58 | CO3: 204162.93 | CP3: 207311.59 | CQ3: 210507.8 | CR3: 213751.89
A4: ='Population Definitions'!$B$4 -> atsi_15-29_M | C4: Number | E4: 50294.958 | F4: 51485.991 | G4: 52705.23 | H4: 53953.342 | I4: 55231.01 | J4: 56538.934 | K4: 57877.831 | L4: 59248.435 | M4: 60651.496 | N4: 62087.782 | O4: 63558.082 | P4: 65063.2 | Q4: 66603.96 | R4: 68181.207 | S4: 69795.804 | T4: 71448.637 | U4: 73140.611 | V4: 74872.652 | W4: 76645.71 | X4: 78460.755 | Y4: 80318.783 | Z4: 82220.81 | AA4: 84167.879 | AB4: 86161.057 | AC4: 88201.435 | AD4: 90290.132 | AE4: 92428.29 | AF4: 94617.083 | AG4: 96857.708 | AH4: 99151.393 | AI4: 101499.4 | AJ4: 103903 | AK4: 106816 | AL4: 109773 | AM4: 112680 | AN4: 115772 | AO4: 118837 | AP4: 121883 | AQ4: 124763 | AR4: 127468 | AS4: 130440 | AT4: 133338 | AU4: 136924 | AV4: 140434 | AW4: 143810 | AX4: 146744 | AY4: 149403 | AZ4: 152157 | BA4: 154674 | BB4: 157005 | BC4: 159081 | BD4: 160984 | BE4: 162591 | BF4: 164290.33 | BG4: 166072.32 | BH4: 167929.25 | BI4: 169856.05 | BJ4: 171849.44 | BK4: 173907.54 | BL4: 176029.14 | BM4: 178213.39 | BN4: 180460.01 | BO4: 182768.79 | BP4: 185139.52 | BQ4: 187571.85 | BR4: 190065.07 | BS4: 192618.32 | BT4: 195230.65 | BU4: 197901.14 | BV4: 200628.71 | BW4: 203412.34 | BX4: 206251.11 | BY4: 209144.43 | BZ4: 212092.17 | CA4: 215094.37 | CB4: 218151.1 | CC4: 221262.81 | CD4: 224430.32 | CE4: 227654.65 | CF4: 230937.04 | CG4: 234278.88 | CH4: 237681.42 | CI4: 241145.78 | CJ4: 244673.03 | CK4: 248264.08 | CL4: 251919.85 | CM4: 255641.2 | CN4: 259428.92 | CO4: 263283.72 | CP4: 267206.44 | CQ4: 271197.68 | CR4: 275257.93
A5: ='Population Definitions'!$B$5 -> atsi_30-49_M | C5: Number | E5: 46262.28 | F5: 47357.816 | G5: 48479.296 | H5: 49627.333 | I5: 50802.557 | J5: 52005.611 | K5: 53237.155 | L5: 54497.863 | M5: 55788.425 | N5: 57109.55 | O5: 58461.96 | P5: 59846.396 | Q5: 61263.617 | R5: 62714.4 | S5: 64199.538 | T5: 65719.846 | U5: 67276.156 | V5: 68869.322 | W5: 70500.214 | X5: 72169.729 | Y5: 73878.778 | Z5: 75628.3 | AA5: 77419.252 | AB5: 79252.616 | AC5: 81129.395 | AD5: 83050.619 | AE5: 85017.339 | AF5: 87030.633 | AG5: 89091.603 | AH5: 91201.379 | AI5: 93361.117 | AJ5: 95572 | AK5: 96524 | AL5: 97789 | AM5: 99133 | AN5: 100402 | AO5: 101863 | AP5: 103312 | AQ5: 104810 | AR5: 106662 | AS5: 108455 | AT5: 110255 | AU5: 112094 | AV5: 114493 | AW5: 117182 | AX5: 120399 | AY5: 123582 | AZ5: 126928 | BA5: 130778 | BB5: 134598 | BC5: 138498 | BD5: 142180 | BE5: 145839 | BF5: 149447.52 | BG5: 153012.8 | BH5: 156541.22 | BI5: 160038.49 | BJ5: 163509.81 | BK5: 166959.98 | BL5: 170393.51 | BM5: 173814.68 | BN5: 177227.53 | BO5: 180635.96 | BP5: 184043.66 | BQ5: 187454.21 | BR5: 190871.02 | BS5: 194297.3 | BT5: 197736.11 | BU5: 201190.34 | BV5: 204662.71 | BW5: 208155.77 | BX5: 211671.9 | BY5: 215213.37 | BZ5: 218782.29 | CA5: 222380.71 | CB5: 226010.58 | CC5: 229673.8 | CD5: 233372.19 | CE5: 237107.59 | CF5: 240881.79 | CG5: 244696.6 | CH5: 248553.83 | CI5: 252455.3 | CJ5: 256402.8 | CK5: 260398.15 | CL5: 264443.12 | CM5: 268539.48 | CN5: 272688.97 | CO5: 276893.31 | CP5: 281154.19 | CQ5: 285473.3 | CR5: 289852.28
A6: ='Population Definitions'!$B$6 -> atsi_50-64_M | C6: Number | E6: 19531.209 | F6: 19993.728 | G6: 20467.199 | H6: 20951.882 | I6: 21448.043 | J6: 21955.954 | K6: 22475.892 | L6: 23008.143 | M6: 23552.998 | N6: 24110.757 | O6: 24681.723 | P6: 25266.21 | Q6: 25864.539 | R6: 26477.036 | S6: 27104.038 | T6: 27745.889 | U6: 28402.938 | V6: 29075.548 | W6: 29764.085 | X6: 30468.928 | Y6: 31190.462 | Z6: 31929.083 | AA6: 32685.195 | AB6: 33459.212 | AC6: 34251.559 | AD6: 35062.669 | AE6: 35892.988 | AF6: 36742.969 | AG6: 37613.078 | AH6: 38503.793 | AI6: 39415.6 | AJ6: 40349 | AK6: 42260 | AL6: 44044 | AM6: 45944 | AN6: 47611 | AO6: 49129 | AP6: 50705 | AQ6: 52290 | AR6: 53845 | AS6: 55526 | AT6: 57503 | AU6: 59193 | AV6: 60665 | AW6: 61721 | AX6: 62499 | AY6: 63086 | AZ6: 63495 | BA6: 63752 | BB6: 64072 | BC6: 64418 | BD6: 65134 | BE6: 65828.917 | BF6: 66606.653 | BG6: 67459.951 | BH6: 68382.288 | BI6: 69367.799 | BJ6: 70411.206 | BK6: 71507.766 | BL6: 72653.215 | BM6: 73843.734 | BN6: 75075.905 | BO6: 76346.679 | BP6: 77653.345 | BQ6: 78993.504 | BR6: 80365.038 | BS6: 81766.093 | BT6: 83195.047 | BU6: 84650.496 | BV6: 86131.23 | BW6: 87636.214 | BX6: 89164.572 | BY6: 90715.568 | BZ6: 92288.598 | CA6: 93883.168 | CB6: 95498.893 | CC6: 97135.479 | CD6: 98792.721 | CE6: 100470.49 | CF6: 102168.73 | CG6: 103887.45 | CH6: 105626.72 | CI6: 107386.69 | CJ6: 109167.53 | CK6: 110969.49 | CL6: 112792.86 | CM6: 114637.96 | CN6: 116505.16 | CO6: 118394.87 | CP6: 120307.54 | CQ6: 122243.63 | CR6: 124203.65
A7: ='Population Definitions'!$B$7 -> atsi_65+_M | C7: Number | E7: 5988.7512 | F7: 6130.5707 | G7: 6275.7486 | H7: 6424.3645 | I7: 6576.4997 | J7: 6732.2377 | K7: 6891.6636 | L7: 7054.865 | M7: 7221.9311 | N7: 7392.9535 | O7: 7568.0258 | P7: 7747.2441 | Q7: 7930.7064 | R7: 8118.5133 | S7: 8310.7677 | T7: 8507.5748 | U7: 8709.0425 | V7: 8915.2811 | W7: 9126.4037 | X7: 9342.5259 | Y7: 9563.766 | Z7: 9790.2454 | AA7: 10022.088 | AB7: 10259.421 | AC7: 10502.374 | AD7: 10751.08 | AE7: 11005.677 | AF7: 11266.302 | AG7: 11533.099 | AH7: 11806.214 | AI7: 12085.797 | AJ7: 12372 | AK7: 13381 | AL7: 14470 | AM7: 15454 | AN7: 16596 | AO7: 17808 | AP7: 19048 | AQ7: 20331 | AR7: 21620 | AS7: 23099 | AT7: 24600 | AU7: 26097 | AV7: 27565 | AW7: 29127 | AX7: 30761 | AY7: 32582 | AZ7: 34355 | BA7: 36088 | BB7: 37822 | BC7: 39487 | BD7: 41087 | BE7: 42708.593 | BF7: 44291.721 | BG7: 45842.723 | BH7: 47367.238 | BI7: 48870.287 | BJ7: 50356.333 | BK7: 51829.339 | BL7: 53292.824 | BM7: 54749.907 | BN7: 56203.352 | BO7: 57655.604 | BP7: 59108.83 | BQ7: 60564.945 | BR7: 62025.64 | BS7: 63492.415 | BT7: 64966.596 | BU7: 66449.357 | BV7: 67941.741 | BW7: 69444.677 | BX7: 70958.991 | BY7: 72485.424 | BZ7: 74024.642 | CA7: 75577.245 | CB7: 77143.78 | CC7: 78724.745 | CD7: 80320.601 | CE7: 81931.772 | CF7: 83558.66 | CG7: 85201.641 | CH7: 86861.075 | CI7: 88537.312 | CJ7: 90230.687 | CK7: 91941.535 | CL7: 93670.185 | CM7: 95416.968 | CN7: 97182.216 | CO7: 98966.266 | CP7: 100769.46 | CQ7: 102592.16 | CR7: 104434.71
A8: ='Population Definitions'!$B$8 -> atsi_0-4_F | C8: Number | E8: 26354.959 | F8: 26979.07 | G8: 27617.961 | H8: 28271.981 | I8: 28941.489 | J8: 29626.852 | K8: 30328.445 | L8: 31046.652 | M8: 31781.867 | N8: 32534.493 | O8: 33304.941 | P8: 34093.635 | Q8: 34901.006 | R8: 35727.496 | S8: 36573.558 | T8: 37439.655 | U8: 38326.263 | V8: 39233.866 | W8: 40162.963 | X8: 41114.061 | Y8: 42087.682 | Z8: 43084.36 | AA8: 44104.64 | AB8: 45149.081 | AC8: 46218.255 | AD8: 47312.748 | AE8: 48433.161 | AF8: 49580.105 | AG8: 50754.211 | AH8: 51956.12 | AI8: 53186.492 | AJ8: 54446 | AK8: 54406 | AL8: 54051 | AM8: 53443 | AN8: 52981 | AO8: 52647 | AP8: 52118 | AQ8: 51664 | AR8: 51545 | AS8: 51291 | AT8: 51196 | AU8: 52284 | AV8: 53769 | AW8: 55318 | AX8: 57042 | AY8: 58854 | AZ8: 59777 | BA8: 60692 | BB8: 61612 | BC8: 62520 | BD8: 63392 | BE8: 64127.196 | BF8: 64903.668 | BG8: 65774.865 | BH8: 66713.873 | BI8: 67713.741 | BJ8: 68751.346 | BK8: 69811.977 | BL8: 70911.64 | BM8: 72028.372 | BN8: 73161.099 | BO8: 74299.621 | BP8: 75434.867 | BQ8: 76572.485 | BR8: 77716.383 | BS8: 78869.426 | BT8: 80024.959 | BU8: 81190.471 | BV8: 82369.167 | BW8: 83573.936 | BX8: 84813.323 | BY8: 86075.556 | BZ8: 87355.96 | CA8: 88671.676 | CB8: 90025.326 | CC8: 91412.251 | CD8: 92834.822 | CE8: 94289.897 | CF8: 95766.878 | CG8: 97262.685 | CH8: 98783.675 | CI8: 100321.1 | CJ8: 101884.7 | CK8: 103471.2 | CL8: 105078.94 | CM8: 106707.2 | CN8: 108367.58 | CO8: 110041.04 | CP8: 111733.2 | CQ8: 113449 | CR8: 115183.25
A9: ='Population Definitions'!$B$9 -> atsi_5-14_F | C9: Number | E9: 43249.026 | F9: 44273.206 | G9: 45321.638 | H9: 46394.899 | I9: 47493.576 | J9: 48618.27 | K9: 49769.598 | L9: 50948.191 | M9: 52154.694 | N9: 53389.768 | O9: 54654.09 | P9: 55948.353 | Q9: 57273.264 | R9: 58629.551 | S9: 60017.956 | T9: 61439.24 | U9: 62894.182 | V9: 64383.578 | W9: 65908.244 | X9: 67469.015 | Y9: 69066.748 | Z9: 70702.316 | AA9: 72376.616 | AB9: 74090.565 | AC9: 75845.102 | AD9: 77641.188 | AE9: 79479.808 | AF9: 81361.967 | AG9: 83288.698 | AH9: 85261.056 | AI9: 87280.121 | AJ9: 89347 | AK9: 92004 | AL9: 94604 | AM9: 97062 | AN9: 99409 | AO9: 101247 | AP9: 103303 | AQ9: 104911 | AR9: 106134 | AS9: 106913 | AT9: 106984 | AU9: 106417 | AV9: 105610 | AW9: 104885 | AX9: 104171 | AY9: 103746 | AZ9: 104304 | BA9: 105334 | BB9: 106764 | BC9: 108234 | BD9: 109951 | BE9: 111958 | BF9: 113919.65 | BG9: 115848.23 | BH9: 117765.24 | BI9: 119684.95 | BJ9: 121618.91 | BK9: 123573.14 | BL9: 125550.2 | BM9: 127555.53 | BN9: 129589.81 | BO9: 131653.43 | BP9: 133744.75 | BQ9: 135860.55 | BR9: 137998.99 | BS9: 140159.17 | BT9: 142340.83 | BU9: 144542.43 | BV9: 146764.05 | BW9: 149006.37 | BX9: 151272.51 | BY9: 153566.98 | BZ9: 155891.54 | CA9: 158246.91 | CB9: 160637.06 | CC9: 163066.11 | CD9: 165536.86 | CE9: 168052.34 | CF9: 170614.66 | CG9: 173223.69 | CH9: 175878.71 | CI9: 178580.3 | CJ9: 181327.28 | CK9: 184120.49 | CL9: 186960.03 | CM9: 189845.7 | CN9: 192777.15 | CO9: 195756.33 | CP9: 198781.3 | CQ9: 201851.42 | CR9: 204967.03
A10: ='Population Definitions'!$B$10 -> atsi_15-29_F | C10: Number | E10: 49178.723 | F10: 50343.323 | G10: 51535.502 | H10: 52755.913 | I10: 54005.225 | J10: 55284.121 | K10: 56593.303 | L10: 57933.488 | M10: 59305.41 | N10: 60709.82 | O10: 62147.488 | P10: 63619.201 | Q10: 65125.766 | R10: 66668.008 | S10: 68246.772 | T10: 69862.922 | U10: 71517.345 | V10: 73210.945 | W10: 74944.652 | X10: 76719.415 | Y10: 78536.206 | Z10: 80396.02 | AA10: 82299.876 | AB10: 84248.818 | AC10: 86243.912 | AD10: 88286.253 | AE10: 90376.957 | AF10: 92517.172 | AG10: 94708.069 | AH10: 96950.849 | AI10: 99246.74 | AJ10: 101597 | AK10: 104349 | AL10: 106854 | AM10: 109514 | AN10: 112025 | AO10: 114673 | AP10: 117221 | AQ10: 119817 | AR10: 122257 | AS10: 124939 | AT10: 127779 | AU10: 131085 | AV10: 134285 | AW10: 137428 | AX10: 140375 | AY10: 143108 | AZ10: 145718 | BA10: 147957 | BB10: 149801 | BC10: 151679 | BD10: 153181 | BE10: 154697 | BF10: 156314.05 | BG10: 158022.12 | BH10: 159812.89 | BI10: 161680.53 | BJ10: 163620.89 | BK10: 165631.14 | BL10: 167709.17 | BM10: 169853.23 | BN10: 172062.18 | BO10: 174335.02 | BP10: 176670.83 | BQ10: 179068.6 | BR10: 181527.06 | BS10: 184044.85 | BT10: 186620.62 | BU10: 189253.05 | BV10: 191940.76 | BW10: 194682.46 | BX10: 197476.98 | BY10: 200323.53 | BZ10: 203221.79 | CA10: 206171.6 | CB10: 209172.9 | CC10: 212226 | CD10: 215331.55 | CE10: 218490.47 | CF10: 221703.89 | CG10: 224973.06 | CH10: 228299.17 | CI10: 231683.25 | CJ10: 235126.35 | CK10: 238629.33 | CL10: 242193.1 | CM10: 245818.49 | CN10: 249506.31 | CO10: 253257.26 | CP10: 257072.2 | CQ10: 260951.73 | CR10: 264896.39
A11: ='Population Definitions'!$B$11 -> atsi_30-49_F | C11: Number | E11: 48714.996 | F11: 49868.615 | G11: 51049.553 | H11: 52258.456 | I11: 53495.987 | J11: 54762.825 | K11: 56059.662 | L11: 57387.21 | M11: 58746.195 | N11: 60137.362 | O11: 61561.474 | P11: 63019.31 | Q11: 64511.669 | R11: 66039.368 | S11: 67603.245 | T11: 69204.156 | U11: 70842.978 | V11: 72520.609 | W11: 74237.968 | X11: 75995.996 | Y11: 77795.655 | Z11: 79637.933 | AA11: 81523.837 | AB11: 83454.401 | AC11: 85430.683 | AD11: 87453.765 | AE11: 89524.756 | AF11: 91644.79 | AG11: 93815.028 | AH11: 96036.66 | AI11: 98310.902 | AJ11: 100639 | AK11: 101455 | AL11: 102493 | AM11: 103586 | AN11: 104863 | AO11: 106285 | AP11: 107508 | AQ11: 108582 | AR11: 109806 | AS11: 111373 | AT11: 112917 | AU11: 114624 | AV11: 116697 | AW11: 119061 | AX11: 121813 | AY11: 124612 | AZ11: 127722 | BA11: 130815 | BB11: 133936 | BC11: 137222 | BD11: 140522 | BE11: 143752 | BF11: 146942.47 | BG11: 150100.7 | BH11: 153233.08 | BI11: 156345.32 | BJ11: 159442.57 | BK11: 162529.54 | BL11: 165610.58 | BM11: 168689.78 | BN11: 171770.95 | BO11: 174857.71 | BP11: 177953.45 | BQ11: 181061.4 | BR11: 184184.61 | BS11: 187325.92 | BT11: 190488 | BU11: 193673.33 | BV11: 196884.22 | BW11: 200122.82 | BX11: 203391.1 | BY11: 206690.92 | BZ11: 210024 | CA11: 213391.99 | CB11: 216796.44 | CC11: 220238.87 | CD11: 223720.73 | CE11: 227243.48 | CF11: 230808.55 | CG11: 234417.39 | CH11: 238071.45 | CI11: 241772.22 | CJ11: 245521.17 | CK11: 249319.77 | CL11: 253169.5 | CM11: 257071.8 | CN11: 261028.15 | CO11: 265039.97 | CP11: 269108.7 | CQ11: 273235.75 | CR11: 277422.52
A12: ='Population Definitions'!$B$12 -> atsi_50-64_F | C12: Number | E12: 20457.21 | F12: 20941.657 | G12: 21437.576 | H12: 21945.239 | I12: 22464.923 | J12: 22996.915 | K12: 23541.504 | L12: 24098.99 | M12: 24669.678 | N12: 25253.88 | O12: 25851.916 | P12: 26464.115 | Q12: 27090.811 | R12: 27732.348 | S12: 28389.077 | T12: 29061.358 | U12: 29749.56 | V12: 30454.058 | W12: 31175.24 | X12: 31913.5 | Y12: 32669.243 | Z12: 33442.883 | AA12: 34234.843 | AB12: 35045.558 | AC12: 35875.471 | AD12: 36725.037 | AE12: 37594.722 | AF12: 38485.002 | AG12: 39396.364 | AH12: 40329.309 | AI12: 41284.346 | AJ12: 42262 | AK12: 44506 | AL12: 46895 | AM12: 48996 | AN12: 50953 | AO12: 52801 | AP12: 54677 | AQ12: 56624 | AR12: 58601 | AS12: 60504 | AT12: 62727 | AU12: 64667 | AV12: 66276 | AW12: 67522 | AX12: 68386 | AY12: 68840 | AZ12: 69189 | BA12: 69543 | BB12: 70069 | BC12: 70473 | BD12: 71143 | BE12: 71591.636 | BF12: 72128.484 | BG12: 72746.313 | BH12: 73438.633 | BI12: 74199.611 | BJ12: 75024.007 | BK12: 75907.112 | BL12: 76844.696 | BM12: 77832.968 | BN12: 78868.533 | BO12: 79948.358 | BP12: 81069.74 | BQ12: 82230.28 | BR12: 83427.851 | BS12: 84660.579 | BT12: 85926.813 | BU12: 87225.113 | BV12: 88554.219 | BW12: 89913.04 | BX12: 91300.634 | BY12: 92716.195 | BZ12: 94159.036 | CA12: 95628.576 | CB12: 97124.335 | CC12: 98645.92 | CD12: 100193.02 | CE12: 101765.39 | CF12: 103362.88 | CG12: 104985.36 | CH12: 106632.79 | CI12: 108305.18 | CJ12: 110002.6 | CK12: 111725.16 | CL12: 113473.01 | CM12: 115246.36 | CN12: 117045.45 | CO12: 118870.55 | CP12: 120721.99 | CQ12: 122600.1 | CR12: 124505.26
A13: ='Population Definitions'!$B$13 -> atsi_65+_F | C13: Number | E13: 7189.2122 | F13: 7359.4597 | G13: 7533.739 | H13: 7712.1453 | I13: 7894.7764 | J13: 8081.7324 | K13: 8273.1158 | L13: 8469.0312 | M13: 8669.5862 | N13: 8874.8905 | O13: 9085.0566 | P13: 9300.1996 | Q13: 9520.4374 | R13: 9745.8907 | S13: 9976.6829 | T13: 10212.941 | U13: 10454.793 | V13: 10702.373 | W13: 10955.815 | X13: 11215.26 | Y13: 11480.848 | Z13: 11752.726 | AA13: 12031.042 | AB13: 12315.949 | AC13: 12607.602 | AD13: 12906.163 | AE13: 13211.793 | AF13: 13524.662 | AG13: 13844.939 | AH13: 14172.8 | AI13: 14508.426 | AJ13: 14852 | AK13: 15950 | AL13: 16958 | AM13: 18137 | AN13: 19444 | AO13: 20806 | AP13: 22255 | AQ13: 23826 | AR13: 25447 | AS13: 27053 | AT13: 28748 | AU13: 30369 | AV13: 32051 | AW13: 33828 | AX13: 35718 | AY13: 37917 | AZ13: 40054 | BA13: 42224 | BB13: 44277 | BC13: 46300 | BD13: 48261 | BE13: 50284.706 | BF13: 52249.019 | BG13: 54161.453 | BH13: 56028.794 | BI13: 57857.174 | BJ13: 59652.134 | BK13: 61418.688 | BL13: 63161.368 | BM13: 64884.277 | BN13: 66591.129 | BO13: 68285.291 | BP13: 69969.812 | BQ13: 71647.464 | BR13: 73320.763 | BS13: 74991.999 | BT13: 76663.26 | BU13: 78336.451 | BV13: 80013.317 | BW13: 81695.457 | BX13: 83384.341 | BY13: 85081.322 | BZ13: 86787.654 | CA13: 88504.495 | CB13: 90232.926 | CC13: 91973.951 | CD13: 93728.512 | CE13: 95497.493 | CF13: 97281.727 | CG13: 99082.004 | CH13: 100899.07 | CI13: 102733.65 | CJ13: 104586.42 | CK13: 106458.04 | CL13: 108349.15 | CM13: 110260.38 | CN13: 112192.34 | CO13: 114145.61 | CP13: 116120.78 | CQ13: 118118.43 | CR13: 120139.15

Sheet Population Flows
A1: Annual number of live births in Australia (by age of mother) | B1: Provenance | C1: Units | D1: Uncertainty | E1: Constant | G1: 1980 | H1: 1981 | I1: 1982 | J1: 1983 | K1: 1984 | L1: 1985 | M1: 1986 | N1: 1987 | O1: 1988 | P1: 1989 | Q1: 1990 | R1: 1991 | S1: 1992 | T1: 1993 | U1: 1994 | V1: 1995 | W1: 1996 | X1: 1997 | Y1: 1998 | Z1: 1999 | AA1: 2000 | AB1: 2001 | AC1: 2002 | AD1: 2003 | AE1: 2004 | AF1: 2005 | AG1: 2006 | AH1: 2007 | AI1: 2008 | AJ1: 2009 | AK1: 2010 | AL1: 2011 | AM1: 2012 | AN1: 2013 | AO1: 2014 | AP1: 2015 | AQ1: 2016 | AR1: 2017 | AS1: 2018 | AT1: 2019 | AU1: 2020 | AV1: 2021 | AW1: 2022 | AX1: 2023 | AY1: 2024 | AZ1: 2025 | BA1: 2026 | BB1: 2027 | BC1: 2028 | BD1: 2029 | BE1: 2030 | BF1: 2031 | BG1: 2032 | BH1: 2033 | BI1: 2034 | BJ1: 2035 | BK1: 2036 | BL1: 2037 | BM1: 2038 | BN1: 2039 | BO1: 2040 | BP1: 2041 | BQ1: 2042 | BR1: 2043 | BS1: 2044 | BT1: 2045 | BU1: 2046 | BV1: 2047 | BW1: 2048 | BX1: 2049 | BY1: 2050 | BZ1: 2051 | CA1: 2052 | CB1: 2053 | CC1: 2054 | CD1: 2055 | CE1: 2056 | CF1: 2057 | CG1: 2058 | CH1: 2059 | CI1: 2060 | CJ1: 2061 | CK1: 2062 | CL1: 2063 | CM1: 2064 | CN1: 2065 | CO1: 2066 | CP1: 2067 | CQ1: 2068 | CR1: 2069 | CS1: 2070 | CT1: 2071
A2: ='Population Definitions'!$B$2 -> atsi_0-4_M | C2: Number (per year) | F2: OR | G2: 6835.2126 | H2: 6926.9106 | I2: 7119.9612 | J2: 7131.4365 | K2: 7217.0019 | L2: 7487.0767 | M2: 7533.3927 | N2: 7678.8913 | O2: 7865.6839 | P2: 7993.2615 | Q2: 8097.0758 | R2: 8167.5572 | S2: 8345.0125 | T2: 8444.1218 | U2: 8625.7577 | V2: 8759.5724 | W2: 8965.563 | X2: 9104.8183 | Y2: 9253.8277 | Z2: 9436.6888 | AA2: 9563.9636 | AB2: 9724.9751 | AC2: 9925.7169 | AD2: 10108.233 | AE2: 10280.02 | AF2: 10476.831 | AG2: 10683.684 | AH2: 10922.766 | AI2: 11192.548 | AJ2: 11392.034 | AK2: 11616.582 | AL2: 11844.872 | AM2: 11909.137 | AN2: 11829.876 | AO2: 11679.642 | AP2: 11732.473 | AQ2: 11521.583 | AR2: 11435.092 | AS2: 11525.277 | AT2: 11404.632 | AU2: 11161.652 | AV2: 12402.97 | AW2: 12656.022 | AX2: 12865.098 | AY2: 13075.786 | AZ2: 13288.124 | BA2: 13498.72 | BB2: 13738.708 | BC2: 13960.036 | BD2: 14163.832 | BE2: 14349.527 | BF2: 14366.39 | BG2: 14599.627 | BH2: 14897.026 | BI2: 15184.857 | BJ2: 15478.791 | BK2: 15749.418 | BL2: 16022.114 | BM2: 16324.007 | BN2: 16611.813 | BO2: 16905.253 | BP2: 17193.208 | BQ2: 17475.596 | BR2: 17761.979 | BS2: 18052.499 | BT2: 18341.632 | BU2: 18616.381 | BV2: 18897.572 | BW2: 19178.463 | BX2: 19472.554 | BY2: 19777.999 | BZ2: 20074.761 | CA2: 20369.803 | CB2: 20687.569 | CC2: 21008.973 | CD2: 21324.517 | CE2: 21646.857 | CF2: 21977.791 | CG2: 22301.395 | CH2: 22624.072 | CI2: 22957.624 | CJ2: 23295.543 | CK2: 23651.641 | CL2: 24014.919 | CM2: 24382.006 | CN2: 24746.322 | CO2: 25129.799 | CP2: 25511.577 | CQ2: 25902.752 | CR2: 26302.748 | CS2: 26699.917
A3: ='Population Definitions'!$B$3 -> atsi_5-14_M | C3: Number (per year) | E3: 0 | F3: OR
A4: ='Population Definitions'!$B$4 -> atsi_15-29_M | C4: Number (per year) | E4: 0 | F4: OR
A5: ='Population Definitions'!$B$5 -> atsi_30-49_M | C5: Number (per year) | E5: 0 | F5: OR
A6: ='Population Definitions'!$B$6 -> atsi_50-64_M | C6: Number (per year) | E6: 0 | F6: OR
A7: ='Population Definitions'!$B$7 -> atsi_65+_M | C7: Number (per year) | E7: 0 | F7: OR
A8: ='Population Definitions'!$B$8 -> atsi_0-4_F | C8: Number (per year) | F8: OR | G8: 6173.4697 | H8: 6273.1418 | I8: 6468.9815 | J8: 6542.4244 | K8: 6643.5456 | L8: 6897.6582 | M8: 6956.6833 | N8: 7083.9449 | O8: 7260.6641 | P8: 7423.5842 | Q8: 7514.7268 | R8: 7635.9766 | S8: 7823.7035 | T8: 7932.5963 | U8: 8128.1934 | V8: 8288.7716 | W8: 8472.1557 | X8: 8670.6644 | Y8: 8801.4369 | Z8: 8990.9283 | AA8: 9173.866 | AB8: 9336.5048 | AC8: 9598.5466 | AD8: 9771.671 | AE8: 9957.582 | AF8: 10152.066 | AG8: 10391.23 | AH8: 10654.722 | AI8: 10909.67 | AJ8: 11106.94 | AK8: 11328.263 | AL8: 11574.934 | AM8: 11270.198 | AN8: 11021.957 | AO8: 11249.569 | AP8: 11216.673 | AQ8: 11043.314 | AR8: 10848.216 | AS8: 10892.862 | AT8: 11034.909 | AU8: 10929.802 | AV8: 11971.381 | AW8: 12192.632 | AX8: 12391.874 | AY8: 12597.655 | AZ8: 12809.379 | BA8: 13023.291 | BB8: 13267.818 | BC8: 13496.997 | BD8: 13711.259 | BE8: 13911.737 | BF8: 14001.973 | BG8: 14257.022 | BH8: 14574.959 | BI8: 14884.91 | BJ8: 15203.203 | BK8: 15502.649 | BL8: 15804.303 | BM8: 16137.169 | BN8: 16461.134 | BO8: 16793.032 | BP8: 17122.56 | BQ8: 17444.777 | BR8: 17770.609 | BS8: 18094.466 | BT8: 18418.843 | BU8: 18728.441 | BV8: 19041.944 | BW8: 19352.976 | BX8: 19677.053 | BY8: 20009.273 | BZ8: 20334.076 | CA8: 20656.565 | CB8: 20995.538 | CC8: 21336.941 | CD8: 21673.61 | CE8: 22013.916 | CF8: 22358.735 | CG8: 22697.682 | CH8: 23041.006 | CI8: 23391.573 | CJ8: 23749.066 | CK8: 24126.21 | CL8: 24512.738 | CM8: 24908.064 | CN8: 25304.493 | CO8: 25716.637 | CP8: 26127.094 | CQ8: 26551.632 | CR8: 26982.575 | CS8: 27413.817
A9: ='Population Definitions'!$B$9 -> atsi_5-14_F | C9: Number (per year) | E9: 0 | F9: OR
A10: ='Population Definitions'!$B$10 -> atsi_15-29_F | C10: Number (per year) | E10: 0 | F10: OR
A11: ='Population Definitions'!$B$11 -> atsi_30-49_F | C11: Number (per year) | E11: 0 | F11: OR
A12: ='Population Definitions'!$B$12 -> atsi_50-64_F | C12: Number (per year) | E12: 0 | F12: OR
A13: ='Population Definitions'!$B$13 -> atsi_65+_F | C13: Number (per year) | E13: 0 | F13: OR
A15: Annual rate of all-cause mortality in Australia (by age and sex) | B15: Provenance | C15: Units | D15: Uncertainty | E15: Constant | G15: 1980 | H15: 1981 | I15: 1982 | J15: 1983 | K15: 1984 | L15: 1985 | M15: 1986 | N15: 1987 | O15: 1988 | P15: 1989 | Q15: 1990 | R15: 1991 | S15: 1992 | T15: 1993 | U15: 1994 | V15: 1995 | W15: 1996 | X15: 1997 | Y15: 1998 | Z15: 1999 | AA15: 2000 | AB15: 2001 | AC15: 2002 | AD15: 2003 | AE15: 2004 | AF15: 2005 | AG15: 2006 | AH15: 2007 | AI15: 2008 | AJ15: 2009 | AK15: 2010 | AL15: 2011 | AM15: 2012 | AN15: 2013 | AO15: 2014 | AP15: 2015 | AQ15: 2016 | AR15: 2017 | AS15: 2018 | AT15: 2019 | AU15: 2020 | AV15: 2021 | AW15: 2022 | AX15: 2023 | AY15: 2024 | AZ15: 2025 | BA15: 2026 | BB15: 2027 | BC15: 2028 | BD15: 2029 | BE15: 2030 | BF15: 2031 | BG15: 2032 | BH15: 2033 | BI15: 2034 | BJ15: 2035 | BK15: 2036 | BL15: 2037 | BM15: 2038 | BN15: 2039 | BO15: 2040 | BP15: 2041 | BQ15: 2042 | BR15: 2043 | BS15: 2044 | BT15: 2045 | BU15: 2046 | BV15: 2047 | BW15: 2048 | BX15: 2049 | BY15: 2050 | BZ15: 2051 | CA15: 2052 | CB15: 2053 | CC15: 2054 | CD15: 2055 | CE15: 2056 | CF15: 2057 | CG15: 2058 | CH15: 2059 | CI15: 2060 | CJ15: 2061 | CK15: 2062 | CL15: 2063 | CM15: 2064 | CN15: 2065 | CO15: 2066 | CP15: 2067 | CQ15: 2068 | CR15: 2069 | CS15: 2070 | CT15: 2071
A16: ='Population Definitions'!$B$2 -> atsi_0-4_M | C16: Rate (per year) | F16: OR | G16: 0.0089283596 | H16: 0.0085941792 | I16: 0.008987984 | J16: 0.008096533 | K16: 0.0077292589 | L16: 0.0083503508 | M16: 0.0074693225 | N16: 0.0073049045 | O16: 0.0070786517 | P16: 0.0065424029 | Q16: 0.0070188816 | R16: 0.0058357019 | S16: 0.0060092495 | T16: 0.0053645867 | U16: 0.0049114441 | V16: 0.0046615476 | W16: 0.0048386381 | X16: 0.0043853297 | Y16: 0.0041968884 | Z16: 0.0045487097 | AA16: 0.0041270259 | AB16: 0.0042077442 | AC16: 0.0040592226 | AD16: 0.0038895754 | AE16: 0.0038701953 | AF16: 0.0039786721 | AG16: 0.0038776382 | AH16: 0.0035538309 | AI16: 0.0036103805 | AJ16: 0.0035910537 | AK16: 0.0035506926 | AL16: 0.0030537576 | AM16: 0.0027161109 | AN16: 0.0027713709 | AO16: 0.0014147481 | AP16: 0.0014618124 | AQ16: 0.0015866458 | AR16: 0.0016111049 | AS16: 0.0016094036 | AT16: 0.0016716272 | AU16: 0.0014819693 | AV16: 0.0016444924 | AW16: 0.0015098346 | AX16: 0.0014567962 | AY16: 0.0014463347 | AZ16: 0.001419895 | BA16: 0.0013878366 | BB16: 0.0013719528 | BC16: 0.0013632216 | BD16: 0.0013488029 | BE16: 0.001338399 | BF16: 0.001324079 | BG16: 0.0013175345 | BH16: 0.0013149207 | BI16: 0.0013088569 | BJ16: 0.001303073 | BK16: 0.0012933153 | BL16: 0.0012910806 | BM16: 0.0012844338 | BN16: 0.001281117 | BO16: 0.0012771147 | BP16: 0.0012724321 | BQ16: 0.0012671158 | BR16: 0.0012574044 | BS16: 0.0012513834 | BT16: 0.0012453388 | BU16: 0.0012393678 | BV16: 0.0012336023 | BW16: 0.0012281206 | BX16: 0.0012229545 | BY16: 0.0012181252 | BZ16: 0.0012135717 | CA16: 0.0012054848 | CB16: 0.0012015799 | CC16: 0.0011979191 | CD16: 0.0011943915 | CE16: 0.0011909499 | CF16: 0.0011875411 | CG16: 0.0011841276 | CH16: 0.0011807461 | CI16: 0.0011812902 | CJ16: 0.0011740229 | CK16: 0.0011707433 | CL16: 0.0011674615 | CM16: 0.0011641697 | CN16: 0.001160832 | CO16: 0.0011574776 | CP16: 0.0011579736 | CQ16: 0.0011505848 | CR16: 0.0011430802 | CS16: 0.0011393822
A17: ='Population Definitions'!$B$3 -> atsi_5-14_M | C17: Rate (per year) | F17: OR | G17: 0.00075927465 | H17: 0.0007241134 | I17: 0.00084430892 | J17: 0.00067430388 | K17: 0.00062694917 | L17: 0.00066845684 | M17: 0.00062494127 | N17: 0.000592101 | O17: 0.00060966855 | P17: 0.00055995043 | Q17: 0.0005115846 | R17: 0.00047577764 | S17: 0.00045186327 | T17: 0.00044661497 | U17: 0.00044947731 | V17: 0.00042104148 | W17: 0.00045180949 | X17: 0.00039807587 | Y17: 0.00038911516 | Z17: 0.0003506441 | AA17: 0.0003714758 | AB17: 0.00035397613 | AC17: 0.00035100561 | AD17: 0.00028711352 | AE17: 0.00032149985 | AF17: 0.00027664559 | AG17: 0.00027481742 | AH17: 0.0002514775 | AI17: 0.00025904301 | AJ17: 0.00026584075 | AK17: 0.00027771287 | AL17: 0.00025201089 | AM17: 0.00023452067 | AN17: 0.00024814811 | AO17: 0.00026311598 | AP17: 0.00029703867 | AQ17: 0.00017419351 | AR17: 0.00017511119 | AS17: 0.0001468845 | AT17: 0.00016419778 | AU17: 0.00014448399 | AV17: 0.00017063648 | AW17: 0.00021789548 | AX17: 0.0002180083 | AY17: 0.00021106023 | AZ17: 0.00020028999 | BA17: 0.00020055134 | BB17: 0.00020071399 | BC17: 0.00020066418 | BD17: 0.00019890666 | BE17: 0.00019886071 | BF17: 0.00019672647 | BG17: 0.00019664945 | BH17: 0.00019305233 | BI17: 0.00019299695 | BJ17: 0.00019311557 | BK17: 0.00019135366 | BL17: 0.00019116781 | BM17: 0.00019116694 | BN17: 0.00018932313 | BO17: 0.0001874853 | BP17: 0.00018742087 | BQ17: 0.00018556275 | BR17: 0.00018371125 | BS17: 0.00018364806 | BT17: 0.0001835856 | BU17: 0.00018172902 | BV17: 0.00017987983 | BW17: 0.00017985933 | BX17: 0.00017986363 | BY17: 0.00017989198 | BZ17: 0.00017814879 | CA17: 0.00017821097 | CB17: 0.00017828331 | CC17: 0.00017835964 | CD17: 0.00017843432 | CE17: 0.00017667902 | CF17: 0.00017673408 | CG17: 0.0001767792 | CH17: 0.00017681337 | CI17: 0.00017683615 | CJ17: 0.00017508576 | CK17: 0.00017508792 | CL17: 0.00017325576 | CM17: 0.00017324433 | CN17: 0.00017322854 | CO17: 0.0001732101 | CP17: 0.0001731901 | CQ17: 0.0001713568 | CR17: 0.00017133551 | CS17: 0.0001713136
A18: ='Population Definitions'!$B$4 -> atsi_15-29_M | C18: Rate (per year) | F18: OR | G18: 0.0042931336 | H18: 0.0041479416 | I18: 0.0043235246 | J18: 0.0040397995 | K18: 0.0035979808 | L18: 0.0040938144 | M18: 0.0039419296 | N18: 0.0038562445 | O18: 0.0042278567 | P18: 0.0039286797 | Q18: 0.0037513175 | R18: 0.0034740649 | S18: 0.0033335737 | T18: 0.0032430589 | U18: 0.00324751 | V18: 0.0033267264 | W18: 0.0033573654 | X18: 0.0034916819 | Y18: 0.0035075126 | Z18: 0.0035893074 | AA18: 0.0031571359 | AB18: 0.0028065476 | AC18: 0.0026441226 | AD18: 0.0026001863 | AE18: 0.0023139615 | AF18: 0.0023083293 | AG18: 0.0021444223 | AH18: 0.0021400528 | AI18: 0.0020763161 | AJ18: 0.0019881439 | AK18: 0.0018859124 | AL18: 0.0018304521 | AM18: 0.0018057309 | AN18: 0.0016761764 | AO18: 0.0014939691 | AP18: 0.0015975807 | AQ18: 0.0015429438 | AR18: 0.0015115786 | AS18: 0.0014909917 | AT18: 0.001744297 | AU18: 0.0016420356 | AV18: 0.0015902278 | AW18: 0.0014409477 | AX18: 0.0014193459 | AY18: 0.0014098388 | AZ18: 0.001387326 | BA18: 0.001368357 | BB18: 0.0013611471 | BC18: 0.0013528049 | BD18: 0.0013431322 | BE18: 0.0013387367 | BF18: 0.0013285368 | BG18: 0.0013257317 | BH18: 0.0013257985 | BI18: 0.00132252 | BJ18: 0.0013208414 | BK18: 0.0013144779 | BL18: 0.0013098506 | BM18: 0.0013084713 | BN18: 0.0013049185 | BO18: 0.0013010153 | BP18: 0.0012950422 | BQ18: 0.0012913504 | BR18: 0.0012835668 | BS18: 0.0012813907 | BT18: 0.0012789425 | BU18: 0.0012703713 | BV18: 0.0012642031 | BW18: 0.0012638773 | BX18: 0.001257644 | BY18: 0.0012554959 | BZ18: 0.0012514064 | CA18: 0.001239355 | CB18: 0.001233368 | CC18: 0.0012326833 | CD18: 0.0012262318 | CE18: 0.0012218648 | CF18: 0.0012175368 | CG18: 0.001213478 | CH18: 0.0012079979 | CI18: 0.0012042414 | CJ18: 0.0012005212 | CK18: 0.0011970645 | CL18: 0.0011935996 | CM18: 0.0011904655 | CN18: 0.0011891661 | CO18: 0.0011839685 | CP18: 0.0011774197 | CQ18: 0.0011723898 | CR18: 0.0011690658 | CS18: 0.001167475
A19: ='Population Definitions'!$B$5 -> atsi_30-49_M | C19: Rate (per year) | F19: OR | G19: 0.0084844914 | H19: 0.0079724 | I19: 0.0078114093 | J19: 0.0070218434 | K19: 0.0069852009 | L19: 0.0070356815 | M19: 0.0069476976 | N19: 0.006830125 | O19: 0.0070535492 | P19: 0.0068834089 | Q19: 0.0067765297 | R19: 0.0067255927 | S19: 0.006584661 | T19: 0.0065092194 | U19: 0.0065853603 | V19: 0.006614742 | W19: 0.0065626587 | X19: 0.0063510601 | Y19: 0.0064183583 | Z19: 0.0062034747 | AA19: 0.0061578389 | AB19: 0.005897456 | AC19: 0.005818799 | AD19: 0.0058381054 | AE19: 0.0055904991 | AF19: 0.005626788 | AG19: 0.0054435396 | AH19: 0.0054007075 | AI19: 0.0054664081 | AJ19: 0.005440874 | AK19: 0.005362738 | AL19: 0.0050103552 | AM19: 0.0048241524 | AN19: 0.0048250031 | AO19: 0.0049977818 | AP19: 0.0051251896 | AQ19: 0.0047642595 | AR19: 0.0047757459 | AS19: 0.0045140607 | AT19: 0.0050357633 | AU19: 0.0044703923 | AV19: 0.0043143278 | AW19: 0.0044285419 | AX19: 0.0043766312 | AY19: 0.0043287645 | AZ19: 0.0042872493 | BA19: 0.0042353658 | BB19: 0.0042248545 | BC19: 0.0042209932 | BD19: 0.0042087164 | BE19: 0.0041980413 | BF19: 0.0041853245 | BG19: 0.0041732207 | BH19: 0.0041600194 | BI19: 0.0041475826 | BJ19: 0.0041330354 | BK19: 0.0041134283 | BL19: 0.0040909587 | BM19: 0.0040796521 | BN19: 0.0040585335 | BO19: 0.004037374 | BP19: 0.0040153582 | BQ19: 0.0039961837 | BR19: 0.0039752129 | BS19: 0.0039627458 | BT19: 0.0039413529 | BU19: 0.0039230979 | BV19: 0.003921252 | BW19: 0.0039166401 | BX19: 0.0039107995 | BY19: 0.0039045997 | BZ19: 0.0039039877 | CA19: 0.003900638 | CB19: 0.0039048253 | CC19: 0.0039017874 | CD19: 0.0038932011 | CE19: 0.0038831147 | CF19: 0.0038791896 | CG19: 0.0038629044 | CH19: 0.0038425952 | CI19: 0.0038316428 | CJ19: 0.0038226472 | CK19: 0.0038038404 | CL19: 0.0037854868 | CM19: 0.0037727924 | CN19: 0.0037546869 | CO19: 0.0037367679 | CP19: 0.0037220406 | CQ19: 0.0037043214 | CR19: 0.0036931902 | CS19: 0.0036804515
A20: ='Population Definitions'!$B$6 -> atsi_50-64_M | C20: Rate (per year) | F20: OR | G20: 0.037350094 | H20: 0.036288986 | I20: 0.035991801 | J20: 0.034820076 | K20: 0.033304278 | L20: 0.034085885 | M20: 0.032143499 | N20: 0.031466037 | O20: 0.030590494 | P20: 0.029635274 | Q20: 0.028254399 | R20: 0.026745033 | S20: 0.026095624 | T20: 0.024619746 | U20: 0.023657822 | V20: 0.022387597 | W20: 0.02172237 | X20: 0.020870224 | Y20: 0.01944378 | Z20: 0.01851929 | AA20: 0.017648145 | AB20: 0.017620334 | AC20: 0.017042675 | AD20: 0.01668304 | AE20: 0.016302456 | AF20: 0.015900589 | AG20: 0.015649039 | AH20: 0.015900687 | AI20: 0.01564787 | AJ20: 0.015479539 | AK20: 0.015073552 | AL20: 0.015223454 | AM20: 0.014436993 | AN20: 0.01436647 | AO20: 0.015541718 | AP20: 0.015581067 | AQ20: 0.015145011 | AR20: 0.014644485 | AS20: 0.014763407 | AT20: 0.015748133 | AU20: 0.014457434 | AV20: 0.014610692 | AW20: 0.014753975 | AX20: 0.01463202 | AY20: 0.01451787 | AZ20: 0.014402436 | BA20: 0.014189608 | BB20: 0.014104996 | BC20: 0.014008787 | BD20: 0.013908647 | BE20: 0.013811641 | BF20: 0.01370853 | BG20: 0.013639681 | BH20: 0.013553539 | BI20: 0.013462994 | BJ20: 0.013370388 | BK20: 0.013241525 | BL20: 0.01313558 | BM20: 0.013056178 | BN20: 0.012993864 | BO20: 0.012949862 | BP20: 0.012926879 | BQ20: 0.012919461 | BR20: 0.012924946 | BS20: 0.012935895 | BT20: 0.012937343 | BU20: 0.012930571 | BV20: 0.012922821 | BW20: 0.012906052 | BX20: 0.012883425 | BY20: 0.012846981 | BZ20: 0.01279817 | CA20: 0.012769757 | CB20: 0.012737787 | CC20: 0.012685456 | CD20: 0.012615524 | CE20: 0.012535333 | CF20: 0.012459704 | CG20: 0.012389549 | CH20: 0.012319475 | CI20: 0.012243231 | CJ20: 0.012192098 | CK20: 0.012151951 | CL20: 0.012127668 | CM20: 0.01210704 | CN20: 0.01207292 | CO20: 0.012049922 | CP20: 0.012043725 | CQ20: 0.012047749 | CR20: 0.012043441 | CS20: 0.012030182
A21: ='Population Definitions'!$B$7 -> atsi_65+_M | C21: Rate (per year) | F21: OR | G21: 0.099922152 | H21: 0.098913273 | I21: 0.10155462 | J21: 0.094781554 | K21: 0.093095342 | L21: 0.097557109 | M21: 0.091214435 | N21: 0.091392303 | O21: 0.090991049 | P21: 0.092833188 | Q21: 0.086538471 | R21: 0.084231975 | S21: 0.085991183 | T21: 0.083011907 | U21: 0.085375814 | V21: 0.081707915 | W21: 0.082810176 | X21: 0.0803896 | Y21: 0.078024026 | Z21: 0.076806577 | AA21: 0.075348308 | AB21: 0.073469716 | AC21: 0.075080495 | AD21: 0.072616485 | AE21: 0.071566653 | AF21: 0.06814988 | AG21: 0.068491984 | AH21: 0.068466699 | AI21: 0.069966219 | AJ21: 0.065936565 | AK21: 0.065075727 | AL21: 0.064865505 | AM21: 0.062144609 | AN21: 0.060647526 | AO21: 0.060306221 | AP21: 0.060721891 | AQ21: 0.059569915 | AR21: 0.058718694 | AS21: 0.056432218 | AT21: 0.058286062 | AU21: 0.054289455 | AV21: 0.056423276 | AW21: 0.055502198 | AX21: 0.055167587 | AY21: 0.054895615 | AZ21: 0.054671162 | BA21: 0.054091154 | BB21: 0.054167537 | BC21: 0.054310082 | BD21: 0.054549282 | BE21: 0.054914092 | BF21: 0.055358612 | BG21: 0.056039864 | BH21: 0.056693401 | BI21: 0.057306643 | BJ21: 0.05788126 | BK21: 0.058287938 | BL21: 0.058831813 | BM21: 0.059423966 | BN21: 0.060022671 | BO21: 0.060632565 | BP21: 0.061228171 | BQ21: 0.06181377 | BR21: 0.062358536 | BS21: 0.062811405 | BT21: 0.063191297 | BU21: 0.063431618 | BV21: 0.063575802 | BW21: 0.06362412 | BX21: 0.06365213 | BY21: 0.063641399 | BZ21: 0.06359028 | CA21: 0.063526034 | CB21: 0.063436952 | CC21: 0.06329671 | CD21: 0.063102144 | CE21: 0.062899349 | CF21: 0.062735514 | CG21: 0.062572011 | CH21: 0.062405608 | CI21: 0.062222756 | CJ21: 0.062121456 | CK21: 0.062081465 | CL21: 0.062085159 | CM21: 0.062072914 | CN21: 0.062018852 | CO21: 0.061992522 | CP21: 0.062057494 | CQ21: 0.062132409 | CR21: 0.062185248 | CS21: 0.062219314
A22: ='Population Definitions'!$B$8 -> atsi_0-4_F | C22: Rate (per year) | F22: OR | G22: 0.0057893908 | H22: 0.0055350108 | I22: 0.0058280515 | J22: 0.005528052 | K22: 0.004814524 | L22: 0.0055277314 | M22: 0.0048293283 | N22: 0.0044652565 | O22: 0.0047092776 | P22: 0.0044676328 | Q22: 0.0045484491 | R22: 0.0038643786 | S22: 0.0038796994 | T22: 0.0033948799 | U22: 0.0032694297 | V22: 0.0032160549 | W22: 0.0031066726 | X22: 0.0029247553 | Y22: 0.0028415329 | Z22: 0.0029786073 | AA22: 0.0027930708 | AB22: 0.0027636345 | AC22: 0.0027401415 | AD22: 0.0026571817 | AE22: 0.0025572111 | AF22: 0.0028504126 | AG22: 0.0026002965 | AH22: 0.0024842978 | AI22: 0.0023627573 | AJ22: 0.0023322546 | AK22: 0.0021306504 | AL22: 0.0021466008 | AM22: 0.0019460375 | AN22: 0.0020748313 | AO22: 0.0016423117 | AP22: 0.0015837645 | AQ22: 0.0014566435 | AR22: 0.0015635819 | AS22: 0.0014075107 | AT22: 0.0014785711 | AU22: 0.0014963075 | AV22: 0.0015304828 | AW22: 0.0015374614 | AX22: 0.0014697263 | AY22: 0.0014595708 | AZ22: 0.0014430501 | BA22: 0.0014070869 | BB22: 0.0014030532 | BC22: 0.0013889534 | BD22: 0.0013858887 | BE22: 0.0013785476 | BF22: 0.0013712123 | BG22: 0.0013638529 | BH22: 0.0013608698 | BI22: 0.0013627728 | BJ22: 0.0013517793 | BK22: 0.00134955 | BL22: 0.0013469644 | BM22: 0.0013438479 | BN22: 0.0013445328 | BO22: 0.0013400397 | BP22: 0.0013392496 | BQ22: 0.0013333524 | BR22: 0.0013269281 | BS22: 0.0013202604 | BT22: 0.0013135854 | BU22: 0.0013069884 | BV22: 0.0013006178 | BW22: 0.0012945449 | BX22: 0.0012888197 | BY22: 0.0012834526 | BZ22: 0.0012784298 | CA22: 0.0012692776 | CB22: 0.0012648837 | CC22: 0.0012607744 | CD22: 0.0012524398 | CE22: 0.0012485549 | CF22: 0.0012447142 | CG22: 0.0012408655 | CH22: 0.0012370385 | CI22: 0.0012332726 | CJ22: 0.0012295194 | CK22: 0.0012258037 | CL22: 0.001222086 | CM22: 0.0012227349 | CN22: 0.0012189782 | CO22: 0.0012151837 | CP22: 0.0012113397 | CQ22: 0.0012074042 | CR22: 0.0012033709 | CS22: 0.0011992089
A23: ='Population Definitions'!$B$9 -> atsi_5-14_F | C23: Rate (per year) | F23: OR | G23: 0.00053286813 | H23: 0.00045738434 | I23: 0.00043419559 | J23: 0.00043212134 | K23: 0.00042762036 | L23: 0.00042653371 | M23: 0.00040726453 | N23: 0.00038126226 | O23: 0.00039537202 | P23: 0.00038551312 | Q23: 0.00035934972 | R23: 0.00035123923 | S23: 0.00034698645 | T23: 0.00035693501 | U23: 0.00036243293 | V23: 0.00039318855 | W23: 0.00033844467 | X23: 0.00031396018 | Y23: 0.0002766868 | Z23: 0.00029893655 | AA23: 0.00028033763 | AB23: 0.00024017344 | AC23: 0.0002687048 | AD23: 0.00024279857 | AE23: 0.000213345 | AF23: 0.00021678522 | AG23: 0.00020385829 | AH23: 0.00023451028 | AI23: 0.00020123491 | AJ23: 0.00022182729 | AK23: 0.00019928828 | AL23: 0.00021838342 | AM23: 0.00021409143 | AN23: 0.00019696164 | AO23: 0.00021611595 | AP23: 0.00020757785 | AQ23: 0.00014171139 | AR23: 0.00016256078 | AS23: 0.00015372081 | AT23: 0.00016388038 | AU23: 0.00012789268 | AV23: 0.00016082076 | AW23: 0.00020900612 | AX23: 0.00020910396 | AY23: 0.00020044191 | AZ23: 0.0001917917 | BA23: 0.00018758193 | BB23: 0.00018771911 | BC23: 0.00018767527 | BD23: 0.00018764296 | BE23: 0.00018763203 | BF23: 0.0001873707 | BG23: 0.00018498847 | BH23: 0.0001806417 | BI23: 0.000180679 | BJ23: 0.00018080627 | BK23: 0.00018085147 | BL23: 0.00018069337 | BM23: 0.00018069666 | BN23: 0.00018066864 | BO23: 0.00017841239 | BP23: 0.00017836998 | BQ23: 0.00017614255 | BR23: 0.00017610024 | BS23: 0.00017605422 | BT23: 0.0001760081 | BU23: 0.00017596612 | BV23: 0.00017593394 | BW23: 0.00017591633 | BX23: 0.00017371497 | BY23: 0.0001737266 | BZ23: 0.0001737526 | CA23: 0.00017379103 | CB23: 0.00017383863 | CC23: 0.00017389095 | CD23: 0.00017394381 | CE23: 0.00017399339 | CF23: 0.00017403724 | CG23: 0.00017407405 | CH23: 0.00017410293 | CI23: 0.00017412304 | CJ23: 0.00017413503 | CK23: 0.00017197211 | CL23: 0.0001697628 | CM23: 0.00016975535 | CN23: 0.00016974397 | CO23: 0.0001653532 | CP23: 0.00016533716 | CQ23: 0.00016532043 | CR23: 0.00016530283 | CS23: 0.00016304182
A24: ='Population Definitions'!$B$10 -> atsi_15-29_F | C24: Rate (per year) | F24: OR | G24: 0.001690135 | H24: 0.0017002454 | I24: 0.0016798365 | J24: 0.0016015325 | K24: 0.0016083306 | L24: 0.0017659125 | M24: 0.0017152385 | N24: 0.0016631838 | O24: 0.0016922602 | P24: 0.0015508114 | Q24: 0.0015362892 | R24: 0.0016113547 | S24: 0.0014212317 | T24: 0.0013289533 | U24: 0.0012778795 | V24: 0.0014189161 | W24: 0.0012578385 | X24: 0.001466712 | Y24: 0.0014319687 | Z24: 0.0014284566 | AA24: 0.0014068379 | AB24: 0.001151909 | AC24: 0.0011485539 | AD24: 0.0011556476 | AE24: 0.0011571045 | AF24: 0.00099644163 | AG24: 0.001087807 | AH24: 0.0010338471 | AI24: 0.00097659229 | AJ24: 0.00098865578 | AK24: 0.00094899532 | AL24: 0.00097799772 | AM24: 0.00091330368 | AN24: 0.00086561496 | AO24: 0.00089239883 | AP24: 0.00084126152 | AQ24: 0.00077418094 | AR24: 0.00072988641 | AS24: 0.00068703352 | AT24: 0.00083142877 | AU24: 0.00075608371 | AV24: 0.0007633813 | AW24: 0.00075232697 | AX24: 0.00072515672 | AY24: 0.00071474667 | AZ24: 0.00071280649 | BA24: 0.0006969429 | BB24: 0.00069246266 | BC24: 0.00069083738 | BD24: 0.00068968487 | BE24: 0.00069079005 | BF24: 0.0006877805 | BG24: 0.00068548902 | BH24: 0.00068041224 | BI24: 0.00068175681 | BJ24: 0.0006762712 | BK24: 0.00067217475 | BL24: 0.00066965844 | BM24: 0.00066974782 | BN24: 0.00066967369 | BO24: 0.00066945852 | BP24: 0.00066932836 | BQ24: 0.00066702977 | BR24: 0.00066690818 | BS24: 0.0006667479 | BT24: 0.00066660556 | BU24: 0.00066632544 | BV24: 0.00066611868 | BW24: 0.00066596132 | BX24: 0.00066373919 | BY24: 0.00066356703 | BZ24: 0.00065884023 | CA24: 0.00065616532 | CB24: 0.00065580649 | CC24: 0.00065084638 | CD24: 0.00065046838 | CE24: 0.00064560283 | CF24: 0.00063896745 | CG24: 0.00063878252 | CH24: 0.00063868265 | CI24: 0.00063867512 | CJ24: 0.00063677959 | CK24: 0.00063695296 | CL24: 0.00063719862 | CM24: 0.00063554965 | CN24: 0.00063588355 | CO24: 0.00063622477 | CP24: 0.00063463945 | CQ24: 0.00063494124 | CR24: 0.0006331082 | CS24: 0.00063331267
A25: ='Population Definitions'!$B$11 -> atsi_30-49_F | C25: Rate (per year) | F25: OR | G25: 0.0052633499 | H25: 0.0049809521 | I25: 0.0048347252 | J25: 0.0046480454 | K25: 0.0045523922 | L25: 0.004603677 | M25: 0.0044499538 | N25: 0.0043477446 | O25: 0.0044562057 | P25: 0.0043572968 | Q25: 0.0040622806 | R25: 0.0040635413 | S25: 0.0040662269 | T25: 0.0040408916 | U25: 0.0040298322 | V25: 0.0039482613 | W25: 0.0039247924 | X25: 0.0040562426 | Y25: 0.0039721079 | Z25: 0.0039903807 | AA25: 0.003857516 | AB25: 0.0037268441 | AC25: 0.0036895047 | AD25: 0.0037370728 | AE25: 0.0035585431 | AF25: 0.0034887848 | AG25: 0.0034621688 | AH25: 0.0035332914 | AI25: 0.0034482317 | AJ25: 0.003520281 | AK25: 0.0033807288 | AL25: 0.0034298269 | AM25: 0.0032424884 | AN25: 0.0032646874 | AO25: 0.0032464858 | AP25: 0.003285698 | AQ25: 0.0031138524 | AR25: 0.0029415449 | AS25: 0.0028485146 | AT25: 0.00301077 | AU25: 0.0027857744 | AV25: 0.0028063257 | AW25: 0.0028093309 | AX25: 0.0027690981 | AY25: 0.0027451129 | AZ25: 0.0027264087 | BA25: 0.002696042 | BB25: 0.0027009178 | BC25: 0.0027019205 | BD25: 0.0027089447 | BE25: 0.0027127278 | BF25: 0.0027106266 | BG25: 0.0027134767 | BH25: 0.00271343 | BI25: 0.0027108157 | BJ25: 0.0027011506 | BK25: 0.0026960598 | BL25: 0.0026871398 | BM25: 0.0026779585 | BN25: 0.0026641454 | BO25: 0.0026456489 | BP25: 0.0026332343 | BQ25: 0.0026219583 | BR25: 0.0026129494 | BS25: 0.0026029881 | BT25: 0.0025876369 | BU25: 0.002578816 | BV25: 0.0025724917 | BW25: 0.0025743032 | BX25: 0.0025756074 | BY25: 0.0025742963 | BZ25: 0.0025794753 | CA25: 0.0025848695 | CB25: 0.002588159 | CC25: 0.0025894156 | CD25: 0.0025909976 | CE25: 0.0025920913 | CF25: 0.0025919568 | CG25: 0.0025848661 | CH25: 0.0025833869 | CI25: 0.0025706348 | CJ25: 0.0025701709 | CK25: 0.0025628217 | CL25: 0.00255315 | CM25: 0.0025490823 | CN25: 0.0025452269 | CO25: 0.0025278295 | CP25: 0.0025175442 | CQ25: 0.0025158335 | CR25: 0.0025123454 | CS25: 0.002503732
A26: ='Population Definitions'!$B$12 -> atsi_50-64_F | C26: Rate (per year) | F26: OR | G26: 0.020935188 | H26: 0.020437574 | I26: 0.02150722 | J26: 0.020833975 | K26: 0.019739297 | L26: 0.020394255 | M26: 0.019350539 | N26: 0.018749009 | O26: 0.018696353 | P26: 0.018315979 | Q26: 0.017317873 | R26: 0.016687845 | S26: 0.016535184 | T26: 0.015656664 | U26: 0.015203864 | V26: 0.014652288 | W26: 0.014582577 | X26: 0.014000128 | Y26: 0.013169445 | Z26: 0.012325804 | AA26: 0.012187338 | AB26: 0.011928658 | AC26: 0.0122556 | AD26: 0.011480456 | AE26: 0.011069307 | AF26: 0.010862169 | AG26: 0.010680342 | AH26: 0.011017257 | AI26: 0.010835985 | AJ26: 0.010731245 | AK26: 0.01045641 | AL26: 0.010297764 | AM26: 0.010129617 | AN26: 0.010142036 | AO26: 0.010237542 | AP26: 0.010210896 | AQ26: 0.0096549472 | AR26: 0.0095027669 | AS26: 0.0096674981 | AT26: 0.0098040114 | AU26: 0.0091571276 | AV26: 0.0093234209 | AW26: 0.0093694132 | AX26: 0.0093017926 | AY26: 0.0092369683 | AZ26: 0.0091659725 | BA26: 0.0090505693 | BB26: 0.0090039628 | BC26: 0.008964349 | BD26: 0.0089127182 | BE26: 0.0088705085 | BF26: 0.0088270538 | BG26: 0.0088026274 | BH26: 0.0087689202 | BI26: 0.0087171176 | BJ26: 0.008662659 | BK26: 0.0085883029 | BL26: 0.0085253875 | BM26: 0.0084847897 | BN26: 0.0084485498 | BO26: 0.0084288997 | BP26: 0.00842227 | BQ26: 0.0084255228 | BR26: 0.0084387986 | BS26: 0.0084486519 | BT26: 0.0084698242 | BU26: 0.0084743714 | BV26: 0.0084970701 | BW26: 0.0084976921 | BX26: 0.0085074241 | BY26: 0.0085054855 | BZ26: 0.008498549 | CA26: 0.0084991605 | CB26: 0.0084980974 | CC26: 0.0084761808 | CD26: 0.0084456106 | CE26: 0.0083994899 | CF26: 0.0083579849 | CG26: 0.0083133132 | CH26: 0.0082715664 | CI26: 0.0082304481 | CJ26: 0.0081969869 | CK26: 0.0081698679 | CL26: 0.0081588629 | CM26: 0.0081503987 | CN26: 0.0081434439 | CO26: 0.0081353036 | CP26: 0.0081381058 | CQ26: 0.0081571742 | CR26: 0.0081583776 | CS26: 0.008165512
A27: ='Population Definitions'!$B$13 -> atsi_65+_F | C27: Rate (per year) | F27: OR | G27: 0.08468833 | H27: 0.083013999 | I27: 0.086442485 | J27: 0.080930403 | K27: 0.08047393 | L27: 0.086552752 | M27: 0.080977876 | N27: 0.080803836 | O27: 0.080074391 | P27: 0.082723438 | Q27: 0.078205056 | R27: 0.07593501 | S27: 0.078345896 | T27: 0.075528964 | U27: 0.078444912 | V27: 0.076489036 | W27: 0.07744453 | X27: 0.077398444 | Y27: 0.074294001 | Z27: 0.07427012 | AA27: 0.073893388 | AB27: 0.072961975 | AC27: 0.075625317 | AD27: 0.073521085 | AE27: 0.072826192 | AF27: 0.070690144 | AG27: 0.071663171 | AH27: 0.072120349 | AI27: 0.074440167 | AJ27: 0.069845579 | AK27: 0.069845023 | AL27: 0.069472682 | AM27: 0.067995393 | AN27: 0.065188362 | AO27: 0.069923553 | AP27: 0.070410545 | AQ27: 0.067276459 | AR27: 0.066796325 | AS27: 0.06291403 | AT27: 0.064900731 | AU27: 0.05923981 | AV27: 0.061971784 | AW27: 0.059978212 | AX27: 0.059272916 | AY27: 0.058653502 | AZ27: 0.058124442 | BA27: 0.057369484 | BB27: 0.057285706 | BC27: 0.057309969 | BD27: 0.057505985 | BE27: 0.057906827 | BF27: 0.058425419 | BG27: 0.059177655 | BH27: 0.05994683 | BI27: 0.060684271 | BJ27: 0.061481921 | BK27: 0.062112232 | BL27: 0.062870665 | BM27: 0.063738402 | BN27: 0.06465744 | BO27: 0.065626895 | BP27: 0.066585704 | BQ27: 0.06751279 | BR27: 0.068353685 | BS27: 0.069076341 | BT27: 0.069720246 | BU27: 0.070207541 | BV27: 0.070594288 | BW27: 0.070870425 | BX27: 0.071103133 | BY27: 0.071267008 | BZ27: 0.071393272 | CA27: 0.07147776 | CB27: 0.071503877 | CC27: 0.071483049 | CD27: 0.071379304 | CE27: 0.071243366 | CF27: 0.07111944 | CG27: 0.070985699 | CH27: 0.070870373 | CI27: 0.070753643 | CJ27: 0.07071247 | CK27: 0.070742905 | CL27: 0.07082949 | CM27: 0.070945831 | CN27: 0.071029774 | CO27: 0.071147493 | CP27: 0.071325147 | CQ27: 0.071502965 | CR27: 0.071677507 | CS27: 0.07185354
A29: Annual rate of immigration to Australia from Overseas (by age and sex) | B29: Provenance | C29: Units | D29: Uncertainty | E29: Constant | G29: 1980 | H29: 1981 | I29: 1982 | J29: 1983 | K29: 1984 | L29: 1985 | M29: 1986 | N29: 1987 | O29: 1988 | P29: 1989 | Q29: 1990 | R29: 1991 | S29: 1992 | T29: 1993 | U29: 1994 | V29: 1995 | W29: 1996 | X29: 1997 | Y29: 1998 | Z29: 1999 | AA29: 2000 | AB29: 2001 | AC29: 2002 | AD29: 2003 | AE29: 2004 | AF29: 2005 | AG29: 2006 | AH29: 2007 | AI29: 2008 | AJ29: 2009 | AK29: 2010 | AL29: 2011 | AM29: 2012 | AN29: 2013 | AO29: 2014 | AP29: 2015 | AQ29: 2016 | AR29: 2017 | AS29: 2018 | AT29: 2019 | AU29: 2020 | AV29: 2021 | AW29: 2022 | AX29: 2023 | AY29: 2024 | AZ29: 2025 | BA29: 2026 | BB29: 2027 | BC29: 2028 | BD29: 2029 | BE29: 2030 | BF29: 2031 | BG29: 2032 | BH29: 2033 | BI29: 2034 | BJ29: 2035 | BK29: 2036 | BL29: 2037 | BM29: 2038 | BN29: 2039 | BO29: 2040 | BP29: 2041 | BQ29: 2042 | BR29: 2043 | BS29: 2044 | BT29: 2045 | BU29: 2046 | BV29: 2047 | BW29: 2048 | BX29: 2049 | BY29: 2050 | BZ29: 2051 | CA29: 2052 | CB29: 2053 | CC29: 2054 | CD29: 2055 | CE29: 2056 | CF29: 2057 | CG29: 2058 | CH29: 2059 | CI29: 2060 | CJ29: 2061 | CK29: 2062 | CL29: 2063 | CM29: 2064 | CN29: 2065 | CO29: 2066 | CP29: 2067 | CQ29: 2068 | CR29: 2069 | CS29: 2070 | CT29: 2071
A30: ='Population Definitions'!$B$2 -> atsi_0-4_M | C30: Number (per year) | E30: 0 | F30: OR
A31: ='Population Definitions'!$B$3 -> atsi_5-14_M | C31: Number (per year) | E31: 0 | F31: OR
A32: ='Population Definitions'!$B$4 -> atsi_15-29_M | C32: Number (per year) | E32: 0 | F32: OR
A33: ='Population Definitions'!$B$5 -> atsi_30-49_M | C33: Number (per year) | E33: 0 | F33: OR
A34: ='Population Definitions'!$B$6 -> atsi_50-64_M | C34: Number (per year) | E34: 0 | F34: OR
A35: ='Population Definitions'!$B$7 -> atsi_65+_M | C35: Number (per year) | E35: 0 | F35: OR
A36: ='Population Definitions'!$B$8 -> atsi_0-4_F | C36: Number (per year) | E36: 0 | F36: OR
A37: ='Population Definitions'!$B$9 -> atsi_5-14_F | C37: Number (per year) | E37: 0 | F37: OR
A38: ='Population Definitions'!$B$10 -> atsi_15-29_F | C38: Number (per year) | E38: 0 | F38: OR
A39: ='Population Definitions'!$B$11 -> atsi_30-49_F | C39: Number (per year) | E39: 0 | F39: OR
A40: ='Population Definitions'!$B$12 -> atsi_50-64_F | C40: Number (per year) | E40: 0 | F40: OR
A41: ='Population Definitions'!$B$13 -> atsi_65+_F | C41: Number (per year) | E41: 0 | F41: OR
A43: Annual rate of emigration from Australia to Overseas (by age and sex) | B43: Provenance | C43: Units | D43: Uncertainty | E43: Constant | G43: 1980 | H43: 1981 | I43: 1982 | J43: 1983 | K43: 1984 | L43: 1985 | M43: 1986 | N43: 1987 | O43: 1988 | P43: 1989 | Q43: 1990 | R43: 1991 | S43: 1992 | T43: 1993 | U43: 1994 | V43: 1995 | W43: 1996 | X43: 1997 | Y43: 1998 | Z43: 1999 | AA43: 2000 | AB43: 2001 | AC43: 2002 | AD43: 2003 | AE43: 2004 | AF43: 2005 | AG43: 2006 | AH43: 2007 | AI43: 2008 | AJ43: 2009 | AK43: 2010 | AL43: 2011 | AM43: 2012 | AN43: 2013 | AO43: 2014 | AP43: 2015 | AQ43: 2016 | AR43: 2017 | AS43: 2018 | AT43: 2019 | AU43: 2020 | AV43: 2021 | AW43: 2022 | AX43: 2023 | AY43: 2024 | AZ43: 2025 | BA43: 2026 | BB43: 2027 | BC43: 2028 | BD43: 2029 | BE43: 2030 | BF43: 2031 | BG43: 2032 | BH43: 2033 | BI43: 2034 | BJ43: 2035 | BK43: 2036 | BL43: 2037 | BM43: 2038 | BN43: 2039 | BO43: 2040 | BP43: 2041 | BQ43: 2042 | BR43: 2043 | BS43: 2044 | BT43: 2045 | BU43: 2046 | BV43: 2047 | BW43: 2048 | BX43: 2049 | BY43: 2050 | BZ43: 2051 | CA43: 2052 | CB43: 2053 | CC43: 2054 | CD43: 2055 | CE43: 2056 | CF43: 2057 | CG43: 2058 | CH43: 2059 | CI43: 2060 | CJ43: 2061 | CK43: 2062 | CL43: 2063 | CM43: 2064 | CN43: 2065 | CO43: 2066 | CP43: 2067 | CQ43: 2068 | CR43: 2069 | CS43: 2070 | CT43: 2071
...

Sheet Transfers
A1: Abbreviation | B1: Full Name | C1: From population type | D1: To population type
A2: age | B2: aging | C2: default | D2: default
B4: ='Population Definitions'!$B$2 -> atsi_0-4_M | C4: ='Population Definitions'!$B$3 -> atsi_5-14_M | D4: ='Population Definitions'!$B$4 -> atsi_15-29_M | E4: ='Population Definitions'!$B$5 -> atsi_30-49_M | F4: ='Population Definitions'!$B$6 -> atsi_50-64_M | G4: ='Population Definitions'!$B$7 -> atsi_65+_M | H4: ='Population Definitions'!$B$8 -> atsi_0-4_F | I4: ='Population Definitions'!$B$9 -> atsi_5-14_F | J4: ='Population Definitions'!$B$10 -> atsi_15-29_F | K4: ='Population Definitions'!$B$11 -> atsi_30-49_F | L4: ='Population Definitions'!$B$12 -> atsi_50-64_F | M4: ='Population Definitions'!$B$13 -> atsi_65+_F
A5: ='Population Definitions'!$B$2 -> atsi_0-4_M | B5: N.A. | C5: Y | D5: N | E5: N | F5: N | G5: N | H5: N | I5: N | J5: N | K5: N | L5: N | M5: N
A6: ='Population Definitions'!$B$3 -> atsi_5-14_M | B6: N | C6: N.A. | D6: Y | E6: N | F6: N | G6: N | H6: N | I6: N | J6: N | K6: N | L6: N | M6: N
A7: ='Population Definitions'!$B$4 -> atsi_15-29_M | B7: N | C7: N | D7: N.A. | E7: Y | F7: N | G7: N | H7: N | I7: N | J7: N | K7: N | L7: N | M7: N
A8: ='Population Definitions'!$B$5 -> atsi_30-49_M | B8: N | C8: N | D8: N | E8: N.A. | F8: Y | G8: N | H8: N | I8: N | J8: N | K8: N | L8: N | M8: N
A9: ='Population Definitions'!$B$6 -> atsi_50-64_M | B9: N | C9: N | D9: N | E9: N | F9: N.A. | G9: Y | H9: N | I9: N | J9: N | K9: N | L9: N | M9: N
A10: ='Population Definitions'!$B$7 -> atsi_65+_M | B10: N | C10: N | D10: N | E10: N | F10: N | G10: N.A. | H10: N | I10: N | J10: N | K10: N | L10: N | M10: N
A11: ='Population Definitions'!$B$8 -> atsi_0-4_F | B11: N | C11: N | D11: N | E11: N | F11: N | G11: N | H11: N.A. | I11: Y | J11: N | K11: N | L11: N | M11: N
A12: ='Population Definitions'!$B$9 -> atsi_5-14_F | B12: N | C12: N | D12: N | E12: N | F12: N | G12: N | H12: N | I12: N.A. | J12: Y | K12: N | L12: N | M12: N
A13: ='Population Definitions'!$B$10 -> atsi_15-29_F | B13: N | C13: N | D13: N | E13: N | F13: N | G13: N | H13: N | I13: N | J13: N.A. | K13: Y | L13: N | M13: N
A14: ='Population Definitions'!$B$11 -> atsi_30-49_F | B14: N | C14: N | D14: N | E14: N | F14: N | G14: N | H14: N | I14: N | J14: N | K14: N.A. | L14: Y | M14: N
A15: ='Population Definitions'!$B$12 -> atsi_50-64_F | B15: N | C15: N | D15: N | E15: N | F15: N | G15: N | H15: N | I15: N | J15: N | K15: N | L15: N.A. | M15: Y
A16: ='Population Definitions'!$B$13 -> atsi_65+_F | B16: N | C16: N | D16: N | E16: N | F16: N | G16: N | H16: N | I16: N | J16: N | K16: N | L16: N | M16: N.A.
A18: From population | C18: To population | D18: Provenance | E18: Units | F18: Uncertainty | G18: Constant | I18: 1980 | J18: 1981 | K18: 1982 | L18: 1983 | M18: 1984 | N18: 1985 | O18: 1986 | P18: 1987 | Q18: 1988 | R18: 1989 | S18: 1990 | T18: 1991 | U18: 1992 | V18: 1993 | W18: 1994 | X18: 1995 | Y18: 1996 | Z18: 1997 | AA18: 1998 | AB18: 1999 | AC18: 2000 | AD18: 2001 | AE18: 2002 | AF18: 2003 | AG18: 2004 | AH18: 2005 | AI18: 2006 | AJ18: 2007 | AK18: 2008 | AL18: 2009 | AM18: 2010 | AN18: 2011 | AO18: 2012 | AP18: 2013 | AQ18: 2014 | AR18: 2015 | AS18: 2016 | AT18: 2017 | AU18: 2018 | AV18: 2019 | AW18: 2020 | AX18: 2021 | AY18: 2022 | AZ18: 2023 | BA18: 2024 | BB18: 2025 | BC18: 2026 | BD18: 2027 | BE18: 2028 | BF18: 2029 | BG18: 2030 | BH18: 2031 | BI18: 2032 | BJ18: 2033 | BK18: 2034 | BL18: 2035 | BM18: 2036 | BN18: 2037 | BO18: 2038 | BP18: 2039 | BQ18: 2040 | BR18: 2041 | BS18: 2042 | BT18: 2043 | BU18: 2044 | BV18: 2045 | BW18: 2046 | BX18: 2047 | BY18: 2048 | BZ18: 2049 | CA18: 2050 | CB18: 2051 | CC18: 2052 | CD18: 2053 | CE18: 2054 | CF18: 2055 | CG18: 2056 | CH18: 2057 | CI18: 2058 | CJ18: 2059 | CK18: 2060 | CL18: 2061 | CM18: 2062 | CN18: 2063 | CO18: 2064 | CP18: 2065 | CQ18: 2066 | CR18: 2067 | CS18: 2068 | CT18: 2069 | CU18: 2070 | CV18: 2071
A19: =IF($B$5="Y",'Population Definitions'!$B$2,"...") -> ... | B19: =IF($B$5="Y","--->","...") -> ... | C19: =IF($B$5="Y",'Population Definitions'!$B$2,"...") -> ... | H19: =IF($B$5="Y","OR","...") -> ...
