Workbook

Sheet About
A1: Name | B1: Description
A2: Template | B2: This is a template cascade. For instructions on how to fill it out, please see: cascade.tools/user-guide

Sheet Databook Pages
A1: Datasheet Code Name | B1: Datasheet Title
A2: sh_init | B2: Initialization
A3: sh_pops | B3: Population Demography
A4: sh_data | B4: Calibration Data
A5: sh_calib | B5: Calibration Parameters
A6: sh_prog | B6: Natural History Parameters
A7: sh_cov | B7: Intervention Coverage
A8: sh_eff | B8: Intervention Effectiveness
A9: sh_utils | B9: Health Utilities
A10: sh_costs | B10: Model Costs

Sheet Population types
A1: Code name | B1: Description
A2: default | B2: Default

Sheet Compartments
A1: Code Name | B1: Display Name | C1: Is Source | D1: Is Sink | E1: Is Junction | F1: Setup Weight | G1: Calibrate | H1: Databook Page | I1: Databook Order | J1: Guidance | K1: Population type
A2: j_init | B2: Junction: Model Initialization | E2: y | F2: 1 | H2: sh_init
A3: src_b | B3: Source: Annual Livebirths | C3: y
A4: sus | B4: HBV: Susceptible
A5: vax | B5: HBV: Vaccine Protected
A6: j_acu | B6: HBV: Acute Infection (junction) | E6: y
A7: it | B7: HBV: eAg+ Chronic Infection
A8: it_dx | B8: HBV: eAg+ Chronic Infection (diagnosed)
A9: it_tx | B9: HBV: eAg+ Chronic Infection (treated)
A10: icl | B10: HBV: eAg+ Chronic Hepatitis
A11: icl_dx | B11: HBV: eAg+ Chronic Hepatitis (diagnosed)
A12: icl_tx | B12: HBV: eAg+ Chronic Hepatitis (treated)
A13: ict | B13: HBV: eAg- Chronic Infection
A14: ict_dx | B14: HBV: eAg- Chronic Infection(diagnosed)
A15: ict_tx_i | B15: HBV: eAg- Chronic Infection (treated; initiated at eAg- chronic infection phase)
A16: ict_tx | B16: HBV: eAg- Chronic Infection (treated; initiated at eligible phases)
A17: ie | B17: HBV: eAg- Chronic Hepatitis
A18: ie_dx | B18: HBV: eAg- Chronic Hepatitis (diagnosed)
... A29: rec | B29: HBV: HBsAg seroclearance (recovered)
A30: dd_hbv | B30: HBV: Attributable mortality | D30: y
A31: dd_oth | B31: Non-HBV associated mortality | D31: y
A32: imig | B32: Source: Imigration into the model | C32: y
A33: emig | B33: Sink: Emigration out of the model | D33: y

Sheet Transitions
B1: =IF(Compartments!$A2<>"",Compartments!$A2,"") -> j_init | C1: =IF(Compartments!$A3<>"",Compartments!$A3,"") -> src_b | D1: =IF(Compartments!$A4<>"",Compartments!$A4,"") -> sus | E1: =IF(Compartments!$A5<>"",Compartments!$A5,"") -> vax | F1: =IF(Compartments!$A6<>"",Compartments!$A6,"") -> j_acu | G1: =IF(Compartments!$A7<>"",Compartments!$A7,"") -> it | H1: =IF(Compartments!$A8<>"",Compartments!$A8,"") -> it_dx | I1: =IF(Compartments!$A9<>"",Compartments!$A9,"") -> it_tx | J1: =IF(Compartments!$A10<>"",Compartments!$A10,"") -> icl | K1: =IF(Compartments!$A11<>"",Compartments!$A11,"") -> icl_dx | L1: =IF(Compartments!$A12<>"",Compartments!$A12,"") -> icl_tx | M1: =IF(Compartments!$A13<>"",Compartments!$A13,"") -> ict | N1: =IF(Compartments!$A14<>"",Compartments!$A14,"") -> ict_dx | O1: =IF(Compartments!$A15<>"",Compartments!$A15,"") -> ict_tx_i | P1: =IF(Compartments!$A16<>"",Compartments!$A16,"") -> ict_tx | Q1: =IF(Compartments!$A17<>"",Compartments!$A17,"") -> ie | R1: =IF(Compartments!$A18<>"",Compartments!$A18,"") -> ie_dx | S1: =IF(Compartments!$A19<>"",Compartments!$A19,"") -> ie_tx | T1: =IF(Compartments!$A20<>"",Compartments!$A20,"") -> cc | U1: =IF(Compartments!$A21<>"",Compartments!$A21,"") -> cc_dx | V1: =IF(Compartments!$A22<>"",Compartments!$A22,"") -> cc_tx | W1: =IF(Compartments!$A23<>"",Compartments!$A23,"") -> dc | X1: =IF(Compartments!$A24<>"",Compartments!$A24,"") -> dc_dx | Y1: =IF(Compartments!$A25<>"",Compartments!$A25,"") -> dc_tx | Z1: =IF(Compartments!$A26<>"",Compartments!$A26,"") -> hcc | AA1: =IF(Compartments!$A27<>"",Compartments!$A27,"") -> hcc_dx | AB1: =IF(Compartments!$A28<>"",Compartments!$A28,"") -> hcc_tx | AC1: =IF(Compartments!$A29<>"",Compartments!$A29,"") -> rec | AD1: =IF(Compartments!$A30<>"",Compartments!$A30,"") -> dd_hbv | AE1: =IF(Compartments!$A31<>"",Compartments!$A31,"") -> dd_oth | AF1: =IF(Compartments!$A32<>"",Compartments!$A32,"") -> imig | AG1: =IF(Compartments!$A33<>"",Compartments!$A33,"") -> emig | AH1: =IF(Compartments!$A34<>"",Compartments!$A34,"") | AI1: =IF(Compartments!$A35<>"",Compartments!$A35,"") | AJ1: =IF(Compartments!$A36<>"",Compartments!$A36,"") | AK1: =IF(Compartments!$A37<>"",Compartments!$A37,"") | AL1: =IF(Compartments!$A38<>"",Compartments!$A38,"") | AM1: =IF(Compartments!$A39<>"",Compartments!$A39,"") | AN1: =IF(Compartments!$A40<>"",Compartments!$A40,"") | AO1: =IF(Compartments!$A41<>"",Compartments!$A41,"") | AP1: =IF(Compartments!$A42<>"",Compartments!$A42,"") | AQ1: =IF(Compartments!$A43<>"",Compartments!$A43,"") | AR1: =IF(Compartments!$A44<>"",Compartments!$A44,"") | AS1: =IF(Compartments!$A45<>"",Compartments!$A45,"") | AT1: =IF(Compartments!$A46<>"",Compartments!$A46,"") | AU1: =IF(Compartments!$A47<>"",Compartments!$A47,"") | AV1: =IF(Compartments!$A48<>"",Compartments!$A48,"") | AW1: =IF(Compartments!$A49<>"",Compartments!$A49,"") | AX1: =IF(Compartments!$A50<>"",Compartments!$A50,"") | AY1: =IF(Compartments!$A51<>"",Compartments!$A51,"") | AZ1: =IF(Compartments!$A52<>"",Compartments!$A52,"") | BA1: =IF(Compartments!$A53<>"",Compartments!$A53,"") | BB1: =IF(Compartments!$A54<>"",Compartments!$A54,"") | BC1: =IF(Compartments!$A55<>"",Compartments!$A55,"") | BD1: =IF(Compartments!$A56<>"",Compartments!$A56,"") | BE1: =IF(Compartments!$A57<>"",Compartments!$A57,"") | BF1: =IF(Compartments!$A58<>"",Compartments!$A58,"") | BG1: =IF(Compartments!$A59<>"",Compartments!$A59,"") | BH1: =IF(Compartments!$A60<>"",Compartments!$A60,"") | BI1: =IF(Compartments!$A61<>"",Compartments!$A61,"") | BJ1: =IF(Compartments!$A62<>"",Compartments!$A62,"") | BK1: =IF(Compartments!$A63<>"",Compartments!$A63,"") | BL1: =IF(Compartments!$A64<>"",Compartments!$A64,"") | BM1: =IF(Compartments!$A65<>"",Compartments!$A65,"") | BN1: =IF(Compartments!$A66<>"",Compartments!$A66,"") | BO1: =IF(Compartments!$A67<>"",Compartments!$A67,"") | BP1: =IF(Compartments!$A68<>"",Compartments!$A68,"") | BQ1: =IF(Compartments!$A69<>"",Compartments!$A69,"") | BR1: =IF(Compartments!$A70<>"",Compartments!$A70,"") | BS1: =IF(Compartments!$A71<>"",Compartments!$A71,"") | BT1: =IF(Compartments!$A72<>"",Compartments!$A72,"") | BU1: =IF(Compartments!$A73<>"",Compartments!$A73,"") | BV1: =IF(Compartments!$A74<>"",Compartments!$A74,"") | BW1: =IF(Compartments!$A75<>"",Compartments!$A75,"") | BX1: =IF(Compartments!$A76<>"",Compartments!$A76,"") | BY1: =IF(Compartments!$A77<>"",Compartments!$A77,"") | BZ1: =IF(Compartments!$A78<>"",Compartments!$A78,"") | CA1: =IF(Compartments!$A79<>"",Compartments!$A79,"") | CB1: =IF(Compartments!$A80<>"",Compartments!$A80,"") | CC1: =IF(Compartments!$A81<>"",Compartments!$A81,"") | CD1: =IF(Compartments!$A82<>"",Compartments!$A82,"") | CE1: =IF(Compartments!$A83<>"",Compartments!$A83,"") | CF1: =IF(Compartments!$A84<>"",Compartments!$A84,"") | CG1: =IF(Compartments!$A85<>"",Compartments!$A85,"") | CH1: =IF(Compartments!$A86<>"",Compartments!$A86,"") | CI1: =IF(Compartments!$A87<>"",Compartments!$A87,"") | CJ1: =IF(Compartments!$A88<>"",Compartments!$A88,"") | CK1: =IF(Compartments!$A89<>"",Compartments!$A89,"") | CL1: =IF(Compartments!$A90<>"",Compartments!$A90,"") | CM1: =IF(Compartments!$A91<>"",Compartments!$A91,"") | CN1: =IF(Compartments!$A92<>"",Compartments!$A92,"") | CO1: =IF(Compartments!$A93<>"",Compartments!$A93,"") | CP1: =IF(Compartments!$A94<>"",Compartments!$A94,"") | CQ1: =IF(Compartments!$A95<>"",Compartments!$A95,"") | CR1: =IF(Compartments!$A96<>"",Compartments!$A96,"") | CS1: =IF(Compartments!$A97<>"",Compartments!$A97,"") | CT1: =IF(Compartments!$A98<>"",Compartments!$A98,"") | CU1: =IF(Compartments!$A99<>"",Compartments!$A99,"") | CV1: =IF(Compartments!$A100<>"",Compartments!$A100,"") | CW1: =IF(Compartments!$A101<>"",Compartments!$A101,"") | CX1: =IF(Compartments!$A102<>"",Compartments!$A102,"") | CY1: =IF(Compartments!$A103<>"",Compartments!$A103,"") | CZ1: =IF(Compartments!$A104<>"",Compartments!$A104,"") | DA1: =IF(Compartments!$A105<>"",Compartments!$A105,"") | DB1: =IF(Compartments!$A106<>"",Compartments!$A106,"") | DC1: =IF(Compartments!$A107<>"",Compartments!$A107,"") | DD1: =IF(Compartments!$A108<>"",Compartments!$A108,"") | DE1: =IF(Compartments!$A109<>"",Compartments!$A109,"") | DF1: =IF(Compartments!$A110<>"",Compartments!$A110,"") | DG1: =IF(Compartments!$A111<>"",Compartments!$A111,"") | DH1: =IF(Compartments!$A112<>"",Compartments!$A112,"") | DI1: =IF(Compartments!$A113<>"",Compartments!$A113,"") | DJ1: =IF(Compartments!$A114<>"",Compartments!$A114,"") | DK1: =IF(Compartments!$A115<>"",Compartments!$A115,"") | DL1: =IF(Compartments!$A116<>"",Compartments!$A116,"") | DM1: =IF(Compartments!$A117<>"",Compartments!$A117,"") | DN1: =IF(Compartments!$A118<>"",Compartments!$A118,"") | DO1: =IF(Compartments!$A119<>"",Compartments!$A119,"") | DP1: =IF(Compartments!$A120<>"",Compartments!$A120,"") | DQ1: =IF(Compartments!$A121<>"",Compartments!$A121,"") | DR1: =IF(Compartments!$A122<>"",Compartments!$A122,"") | DS1: =IF(Compartments!$A123<>"",Compartments!$A123,"") | DT1: =IF(Compartments!$A124<>"",Compartments!$A124,"") | DU1: =IF(Compartments!$A125<>"",Compartments!$A125,"") | DV1: =IF(Compartments!$A126<>"",Compartments!$A126,"") | DW1: =IF(Compartments!$A127<>"",Compartments!$A127,"") | DX1: =IF(Compartments!$A128<>"",Compartments!$A128,"") | DY1: =IF(Compartments!$A129<>"",Compartments!$A129,"") | DZ1: =IF(Compartments!$A130<>"",Compartments!$A130,"") | EA1: =IF(Compartments!$A131<>"",Compartments!$A131,"") | EB1: =IF(Compartments!$A132<>"",Compartments!$A132,"") | EC1: =IF(Compartments!$A133<>"",Compartments!$A133,"") | ED1: =IF(Compartments!$A134<>"",Compartments!$A134,"") | EE1: =IF(Compartments!$A135<>"",Compartments!$A135,"") | EF1: =IF(Compartments!$A136<>"",Compartments!$A136,"") | EG1: =IF(Compartments!$A137<>"",Compartments!$A137,"") | EH1: =IF(Compartments!$A138<>"",Compartments!$A138,"") | EI1: =IF(Compartments!$A139<>"",Compartments!$A139,"") | EJ1: =IF(Compartments!$A140<>"",Compartments!$A140,"") | EK1: =IF(Compartments!$A141<>"",Compartments!$A141,"") | EL1: =IF(Compartments!$A142<>"",Compartments!$A142,"") | EM1: =IF(Compartments!$A143<>"",Compartments!$A143,"") | EN1: =IF(Compartments!$A144<>"",Compartments!$A144,"") | EO1: =IF(Compartments!$A145<>"",Compartments!$A145,"") | EP1: =IF(Compartments!$A146<>"",Compartments!$A146,"") | EQ1: =IF(Compartments!$A147<>"",Compartments!$A147,"") | ER1: =IF(Compartments!$A148<>"",Compartments!$A148,"") | ES1: =IF(Compartments!$A149<>"",Compartments!$A149,"") | ET1: =IF(Compartments!$A150<>"",Compartments!$A150,"") | EU1: =IF(Compartments!$A151<>"",Compartments!$A151,"") | EV1: =IF(Compartments!$A152<>"",Compartments!$A152,"") | EW1: =IF(Compartments!$A153<>"",Compartments!$A153,"") | EX1: =IF(Compartments!$A154<>"",Compartments!$A154,"") | EY1: =IF(Compartments!$A155<>"",Compartments!$A155,"") | EZ1: =IF(Compartments!$A156<>"",Compartments!$A156,"") | FA1: =IF(Compartments!$A157<>"",Compartments!$A157,"") | FB1: =IF(Compartments!$A158<>"",Compartments!$A158,"") | FC1: =IF(Compartments!$A159<>"",Compartments!$A159,"") | FD1: =IF(Compartments!$A160<>"",Compartments!$A160,"") | FE1: =IF(Compartments!$A161<>"",Compartments!$A161,"") | FF1: =IF(Compartments!$A162<>"",Compartments!$A162,"") | FG1: =IF(Compartments!$A163<>"",Compartments!$A163,"") | FH1: =IF(Compartments!$A164<>"",Compartments!$A164,"") | FI1: =IF(Compartments!$A165<>"",Compartments!$A165,"") | FJ1: =IF(Compartments!$A166<>"",Compartments!$A166,"") | FK1: =IF(Compartments!$A167<>"",Compartments!$A167,"") | FL1: =IF(Compartments!$A168<>"",Compartments!$A168,"") | FM1: =IF(Compartments!$A169<>"",Compartments!$A169,"") | FN1: =IF(Compartments!$A170<>"",Compartments!$A170,"") | FO1: =IF(Compartments!$A171<>"",Compartments!$A171,"") | FP1: =IF(Compartments!$A172<>"",Compartments!$A172,"") | FQ1: =IF(Compartments!$A173<>"",Compartments!$A173,"") | FR1: =IF(Compartments!$A174<>"",Compartments!$A174,"") | FS1: =IF(Compartments!$A175<>"",Compartments!$A175,"") | FT1: =IF(Compartments!$A176<>"",Compartments!$A176,"") | FU1: =IF(Compartments!$A177<>"",Compartments!$A177,"") | FV1: =IF(Compartments!$A178<>"",Compartments!$A178,"") | FW1: =IF(Compartments!$A179<>"",Compartments!$A179,"") | FX1: =IF(Compartments!$A180<>"",Compartments!$A180,"") | FY1: =IF(Compartments!$A181<>"",Compartments!$A181,"") | FZ1: =IF(Compartments!$A182<>"",Compartments!$A182,"") | GA1: =IF(Compartments!$A183<>"",Compartments!$A183,"") | GB1: =IF(Compartments!$A184<>"",Compartments!$A184,"") | GC1: =IF(Compartments!$A185<>"",Compartments!$A185,"") | GD1: =IF(Compartments!$A186<>"",Compartments!$A186,"") | GE1: =IF(Compartments!$A187<>"",Compartments!$A187,"") | GF1: =IF(Compartments!$A188<>"",Compartments!$A188,"") | GG1: =IF(Compartments!$A189<>"",Compartments!$A189,"") | GH1: =IF(Compartments!$A190<>"",Compartments!$A190,"") | GI1: =IF(Compartments!$A191<>"",Compartments!$A191,"") | GJ1: =IF(Compartments!$A192<>"",Compartments!$A192,"") | GK1: =IF(Compartments!$A193<>"",Compartments!$A193,"") | GL1: =IF(Compartments!$A194<>"",Compartments!$A194,"") | GM1: =IF(Compartments!$A195<>"",Compartments!$A195,"") | GN1: =IF(Compartments!$A196<>"",Compartments!$A196,"") | GO1: =IF(Compartments!$A197<>"",Compartments!$A197,"") | GP1: =IF(Compartments!$A198<>"",Compartments!$A198,"") | GQ1: =IF(Compartments!$A199<>"",Compartments!$A199,"") | GR1: =IF(Compartments!$A200<>"",Compartments!$A200,"") | GS1: =IF(Compartments!$A201<>"",Compartments!$A201,"") | GT1: =IF(Compartments!$A202<>"",Compartments!$A202,"") | GU1: =IF(Compartments!$A203<>"",Compartments!$A203,"") | GV1: =IF(Compartments!$A204<>"",Compartments!$A204,"") | GW1: =IF(Compartments!$A205<>"",Compartments!$A205,"") | GX1: =IF(Compartments!$A206<>"",Compartments!$A206,"") | GY1: =IF(Compartments!$A207<>"",Compartments!$A207,"") | GZ1: =IF(Compartments!$A208<>"",Compartments!$A208,"") | HA1: =IF(Compartments!$A209<>"",Compartments!$A209,"") | HB1: =IF(Compartments!$A210<>"",Compartments!$A210,"") | HC1: =IF(Compartments!$A211<>"",Compartments!$A211,"") | HD1: =IF(Compartments!$A212<>"",Compartments!$A212,"") | HE1: =IF(Compartments!$A213<>"",Compartments!$A213,"") | HF1: =IF(Compartments!$A214<>"",Compartments!$A214,"") | HG1: =IF(Compartments!$A215<>"",Compartments!$A215,"") | HH1: =IF(Compartments!$A216<>"",Compartments!$A216,"") | HI1: =IF(Compartments!$A217<>"",Compartments!$A217,"") | HJ1: =IF(Compartments!$A218<>"",Compartments!$A218,"") | HK1: =IF(Compartments!$A219<>"",Compartments!$A219,"") | HL1: =IF(Compartments!$A220<>"",Compartments!$A220,"") | HM1: =IF(Compartments!$A221<>"",Compartments!$A221,"") | HN1: =IF(Compartments!$A222<>"",Compartments!$A222,"") | HO1: =IF(Compartments!$A223<>"",Compartments!$A223,"") | HP1: =IF(Compartments!$A224<>"",Compartments!$A224,"") | HQ1: =IF(Compartments!$A225<>"",Compartments!$A225,"") | HR1: =IF(Compartments!$A226<>"",Compartments!$A226,"") | HS1: =IF(Compartments!$A227<>"",Compartments!$A227,"") | HT1: =IF(Compartments!$A228<>"",Compartments!$A228,"") | HU1: =IF(Compartments!$A229<>"",Compartments!$A229,"") | HV1: =IF(Compartments!$A230<>"",Compartments!$A230,"") | HW1: =IF(Compartments!$A231<>"",Compartments!$A231,"") | HX1: =IF(Compartments!$A232<>"",Compartments!$A232,"") | HY1: =IF(Compartments!$A233<>"",Compartments!$A233,"") | HZ1: =IF(Compartments!$A234<>"",Compartments!$A234,"") | IA1: =IF(Compartments!$A235<>"",Compartments!$A235,"") | IB1: =IF(Compartments!$A236<>"",Compartments!$A236,"") | IC1: =IF(Compartments!$A237<>"",Compartments!$A237,"") | ID1: =IF(Compartments!$A238<>"",Compartments!$A238,"") | IE1: =IF(Compartments!$A239<>"",Compartments!$A239,"") | IF1: =IF(Compartments!$A240<>"",Compartments!$A240,"") | IG1: =IF(Compartments!$A241<>"",Compartments!$A241,"") | IH1: =IF(Compartments!$A242<>"",Compartments!$A242,"") | II1: =IF(Compartments!$A243<>"",Compartments!$A243,"") | IJ1: =IF(Compartments!$A244<>"",Compartments!$A244,"") | IK1: =IF(Compartments!$A245<>"",Compartments!$A245,"") | IL1: =IF(Compartments!$A246<>"",Compartments!$A246,"") | IM1: =IF(Compartments!$A247<>"",Compartments!$A247,"") | IN1: =IF(Compartments!$A248<>"",Compartments!$A248,"") | IO1: =IF(Compartments!$A249<>"",Compartments!$A249,"") | IP1: =IF(Compartments!$A250<>"",Compartments!$A250,"") | IQ1: =IF(Compartments!$A251<>"",Compartments!$A251,"") | IR1: =IF(Compartments!$A252<>"",Compartments!$A252,"") | IS1: =IF(Compartments!$A253<>"",Compartments!$A253,"") | IT1: =IF(Compartments!$A254<>"",Compartments!$A254,"") | IU1: =IF(Compartments!$A255<>"",Compartments!$A255,"") | IV1: =IF(Compartments!$A256<>"",Compartments!$A256,"") | IW1: =IF(Compartments!$A257<>"",Compartments!$A257,"") | IX1: =IF(Compartments!$A258<>"",Compartments!$A258,"") | IY1: =IF(Compartments!$A259<>"",Compartments!$A259,"") | IZ1: =IF(Compartments!$A260<>"",Compartments!$A260,"") | JA1: =IF(Compartments!$A261<>"",Compartments!$A261,"") | JB1: =IF(Compartments!$A262<>"",Compartments!$A262,"") | JC1: =IF(Compartments!$A263<>"",Compartments!$A263,"") | JD1: =IF(Compartments!$A264<>"",Compartments!$A264,"") | JE1: =IF(Compartments!$A265<>"",Compartments!$A265,"") | JF1: =IF(Compartments!$A266<>"",Compartments!$A266,"") | JG1: =IF(Compartments!$A267<>"",Compartments!$A267,"") | JH1: =IF(Compartments!$A268<>"",Compartments!$A268,"") | JI1: =IF(Compartments!$A269<>"",Compartments!$A269,"") | JJ1: =IF(Compartments!$A270<>"",Compartments!$A270,"") | JK1: =IF(Compartments!$A271<>"",Compartments!$A271,"") | JL1: =IF(Compartments!$A272<>"",Compartments!$A272,"") | JM1: =IF(Compartments!$A273<>"",Compartments!$A273,"") | JN1: =IF(Compartments!$A274<>"",Compartments!$A274,"") | JO1: =IF(Compartments!$A275<>"",Compartments!$A275,"") | JP1: =IF(Compartments!$A276<>"",Compartments!$A276,"") | JQ1: =IF(Compartments!$A277<>"",Compartments!$A277,"") | JR1: =IF(Compartments!$A278<>"",Compartments!$A278,"") | JS1: =IF(Compartments!$A279<>"",Compartments!$A279,"") | JT1: =IF(Compartments!$A280<>"",Compartments!$A280,"") | JU1: =IF(Compartments!$A281<>"",Compartments!$A281,"") | JV1: =IF(Compartments!$A282<>"",Compartments!$A282,"") | JW1: =IF(Compartments!$A283<>"",Compartments!$A283,"") | JX1: =IF(Compartments!$A284<>"",Compartments!$A284,"") | JY1: =IF(Compartments!$A285<>"",Compartments!$A285,"") | JZ1: =IF(Compartments!$A286<>"",Compartments!$A286,"") | KA1: =IF(Compartments!$A287<>"",Compartments!$A287,"") | KB1: =IF(Compartments!$A288<>"",Compartments!$A288,"") | KC1: =IF(Compartments!$A289<>"",Compartments!$A289,"") | KD1: =IF(Compartments!$A290<>"",Compartments!$A290,"") | KE1: =IF(Compartments!$A291<>"",Compartments!$A291,"") | KF1: =IF(Compartments!$A292<>"",Compartments!$A292,"") | KG1: =IF(Compartments!$A293<>"",Compartments!$A293,"") | KH1: =IF(Compartments!$A294<>"",Compartments!$A294,"") | KI1: =IF(Compartments!$A295<>"",Compartments!$A295,"") | KJ1: =IF(Compartments!$A296<>"",Compartments!$A296,"") | KK1: =IF(Compartments!$A297<>"",Compartments!$A297,"") | KL1: =IF(Compartments!$A298<>"",Compartments!$A298,"") | KM1: =IF(Compartments!$A299<>"",Compartments!$A299,"") | KN1: =IF(Compartments!$A300<>"",Compartments!$A300,"") | KO1: =IF(Compartments!$A301<>"",Compartments!$A301,"") | KP1: =IF(Compartments!$A302<>"",Compartments!$A302,"") | KQ1: =IF(Compartments!$A303<>"",Compartments!$A303,"") | KR1: =IF(Compartments!$A304<>"",Compartments!$A304,"") | KS1: =IF(Compartments!$A305<>"",Compartments!$A305,"") | KT1: =IF(Compartments!$A306<>"",Compartments!$A306,"") | KU1: =IF(Compartments!$A307<>"",Compartments!$A307,"") | KV1: =IF(Compartments!$A308<>"",Compartments!$A308,"") | KW1: =IF(Compartments!$A309<>"",Compartments!$A309,"") | KX1: =IF(Compartments!$A310<>"",Compartments!$A310,"") | KY1: =IF(Compartments!$A311<>"",Compartments!$A311,"") | KZ1: =IF(Compartments!$A312<>"",Compartments!$A312,"") | LA1: =IF(Compartments!$A313<>"",Compartments!$A313,"") | LB1: =IF(Compartments!$A314<>"",Compartments!$A314,"") | LC1: =IF(Compartments!$A315<>"",Compartments!$A315,"") | LD1: =IF(Compartments!$A316<>"",Compartments!$A316,"") | LE1: =IF(Compartments!$A317<>"",Compartments!$A317,"") | LF1: =IF(Compartments!$A318<>"",Compartments!$A318,"") | LG1: =IF(Compartments!$A319<>"",Compartments!$A319,"") | LH1: =IF(Compartments!$A320<>"",Compartments!$A320,"") | LI1: =IF(Compartments!$A321<>"",Compartments!$A321,"") | LJ1: =IF(Compartments!$A322<>"",Compartments!$A322,"") | LK1: =IF(Compartments!$A323<>"",Compartments!$A323,"") | LL1: =IF(Compartments!$A324<>"",Compartments!$A324,"") | LM1: =IF(Compartments!$A325<>"",Compartments!$A325,"") | LN1: =IF(Compartments!$A326<>"",Compartments!$A326,"") | LO1: =IF(Compartments!$A327<>"",Compartments!$A327,"") | LP1: =IF(Compartments!$A328<>"",Compartments!$A328,"") | LQ1: =IF(Compartments!$A329<>"",Compartments!$A329,"") | LR1: =IF(Compartments!$A330<>"",Compartments!$A330,"") | LS1: =IF(Compartments!$A331<>"",Compartments!$A331,"") | LT1: =IF(Compartments!$A332<>"",Compartments!$A332,"") | LU1: =IF(Compartments!$A333<>"",Compartments!$A333,"") | LV1: =IF(Compartments!$A334<>"",Compartments!$A334,"") | LW1: =IF(Compartments!$A335<>"",Compartments!$A335,"") | LX1: =IF(Compartments!$A336<>"",Compartments!$A336,"") | LY1: =IF(Compartments!$A337<>"",Compartments!$A337,"") | LZ1: =IF(Compartments!$A338<>"",Compartments!$A338,"") | MA1: =IF(Compartments!$A339<>"",Compartments!$A339,"") | MB1: =IF(Compartments!$A340<>"",Compartments!$A340,"") | MC1: =IF(Compartments!$A341<>"",Compartments!$A341,"") | MD1: =IF(Compartments!$A342<>"",Compartments!$A342,"") | ME1: =IF(Compartments!$A343<>"",Compartments!$A343,"") | MF1: =IF(Compartments!$A344<>"",Compartments!$A344,"") | MG1: =IF(Compartments!$A345<>"",Compartments!$A345,"") | MH1: =IF(Compartments!$A346<>"",Compartments!$A346,"") | MI1: =IF(Compartments!$A347<>"",Compartments!$A347,"") | MJ1: =IF(Compartments!$A348<>"",Compartments!$A348,"") | MK1: =IF(Compartments!$A349<>"",Compartments!$A349,"") | ML1: =IF(Compartments!$A350<>"",Compartments!$A350,"") | MM1: =IF(Compartments!$A351<>"",Compartments!$A351,"") | MN1: =IF(Compartments!$A352<>"",Compartments!$A352,"") | MO1: =IF(Compartments!$A353<>"",Compartments!$A353,"") | MP1: =IF(Compartments!$A354<>"",Compartments!$A354,"") | MQ1: =IF(Compartments!$A355<>"",Compartments!$A355,"") | MR1: =IF(Compartments!$A356<>"",Compartments!$A356,"") | MS1: =IF(Compartments!$A357<>"",Compartments!$A357,"") | MT1: =IF(Compartments!$A358<>"",Compartments!$A358,"") | MU1: =IF(Compartments!$A359<>"",Compartments!$A359,"") | MV1: =IF(Compartments!$A360<>"",Compartments!$A360,"") | MW1: =IF(Compartments!$A361<>"",Compartments!$A361,"") | MX1: =IF(Compartments!$A362<>"",Compartments!$A362,"") | MY1: =IF(Compartments!$A363<>"",Compartments!$A363,"") | MZ1: =IF(Compartments!$A364<>"",Compartments!$A364,"") | NA1: =IF(Compartments!$A365<>"",Compartments!$A365,"") | NB1: =IF(Compartments!$A366<>"",Compartments!$A366,"") | NC1: =IF(Compartments!$A367<>"",Compartments!$A367,"") | ND1: =IF(Compartments!$A368<>"",Compartments!$A368,"") | NE1: =IF(Compartments!$A369<>"",Compartments!$A369,"") | NF1: =IF(Compartments!$A370<>"",Compartments!$A370,"") | NG1: =IF(Compartments!$A371<>"",Compartments!$A371,"") | NH1: =IF(Compartments!$A372<>"",Compartments!$A372,"") | NI1: =IF(Compartments!$A373<>"",Compartments!$A373,"") | NJ1: =IF(Compartments!$A374<>"",Compartments!$A374,"") | NK1: =IF(Compartments!$A375<>"",Compartments!$A375,"") | NL1: =IF(Compartments!$A376<>"",Compartments!$A376,"") | NM1: =IF(Compartments!$A377<>"",Compartments!$A377,"") | NN1: =IF(Compartments!$A378<>"",Compartments!$A378,"") | NO1: =IF(Compartments!$A379<>"",Compartments!$A379,"") | NP1: =IF(Compartments!$A380<>"",Compartments!$A380,"") | NQ1: =IF(Compartments!$A381<>"",Compartments!$A381,"") | NR1: =IF(Compartments!$A382<>"",Compartments!$A382,"") | NS1: =IF(Compartments!$A383<>"",Compartments!$A383,"") | NT1: =IF(Compartments!$A384<>"",Compartments!$A384,"") | NU1: =IF(Compartments!$A385<>"",Compartments!$A385,"") | NV1: =IF(Compartments!$A386<>"",Compartments!$A386,"") | NW1: =IF(Compartments!$A387<>"",Compartments!$A387,"") | NX1: =IF(Compartments!$A388<>"",Compartments!$A388,"") | NY1: =IF(Compartments!$A389<>"",Compartments!$A389,"") | NZ1: =IF(Compartments!$A390<>"",Compartments!$A390,"") | OA1: =IF(Compartments!$A391<>"",Compartments!$A391,"") | OB1: =IF(Compartments!$A392<>"",Compartments!$A392,"") | OC1: =IF(Compartments!$A393<>"",Compartments!$A393,"") | OD1: =IF(Compartments!$A394<>"",Compartments!$A394,"") | OE1: =IF(Compartments!$A395<>"",Compartments!$A395,"") | OF1: =IF(Compartments!$A396<>"",Compartments!$A396,"") | OG1: =IF(Compartments!$A397<>"",Compartments!$A397,"") | OH1: =IF(Compartments!$A398<>"",Compartments!$A398,"") | OI1: =IF(Compartments!$A399<>"",Compartments!$A399,"") | OJ1: =IF(Compartments!$A400<>"",Compartments!$A400,"")
A2: =IF(Compartments!$A2<>"",Compartments!$A2,"") -> j_init | D2: i_sus | E2: i_vax | G2: i_it | H2: i_itd | J2: i_ia | K2: i_iad | L2: i_iat | M2: i_ic | N2: i_icd | P2: i_ict | Q2: i_ie | R2: i_ied | S2: i_iet | T2: i_cc | U2: i_ccd | V2: i_cct | W2: i_dc | X2: i_dcd | Y2: i_dct | Z2: i_hcc | AA2: i_hccd | AB2: i_hcct | AC2: i_rec
A3: =IF(Compartments!$A3<>"",Compartments!$A3,"") -> src_b | D3: b_sus | E3: b_vax | G3: mtct_inf | AC3: mtct_rec
A4: =IF(Compartments!$A4<>"",Compartments!$A4,"") -> sus | E4: hb3_vax | F4: echt, horiz | AE4: acm | AG4: em_rate
A5: =IF(Compartments!$A5<>"",Compartments!$A5,"") -> vax | AE5: acm | AG5: em_rate
A6: =IF(Compartments!$A6<>"",Compartments!$A6,"") -> j_acu | G6: acu_it | J6: acu_icl | AC6: acu_clr | AD6: m_acu
A7: =IF(Compartments!$A7<>"",Compartments!$A7,"") -> it | H7: annual_dx | J7: it_icl | Z7: it_hcc | AE7: acm | AG7: em_rate
A8: =IF(Compartments!$A8<>"",Compartments!$A8,"") -> it_dx | I8: n_it_tx | K8: it_icl | AA8: it_hcc | AE8: acm | AG8: em_rate
A9: =IF(Compartments!$A9<>"",Compartments!$A9,"") -> it_tx | L9: it_icl_t | AB9: it_hcc_t | AE9: acm | AG9: em_rate
A10: =IF(Compartments!$A10<>"",Compartments!$A10,"") -> icl | K10: annual_dx | M10: icl_ict | T10: icl_cc | Z10: icl_hcc | AC10: icl_clr | AE10: acm | AG10: em_rate
A11: =IF(Compartments!$A11<>"",Compartments!$A11,"") -> icl_dx | L11: icl_tx_n | N11: icl_ict | U11: icl_cc | AA11: icl_hcc | AC11: icl_clr | AE11: acm | AG11: em_rate
A12: =IF(Compartments!$A12<>"",Compartments!$A12,"") -> icl_tx | P12: icl_ict_t | V12: icl_cc_t | AB12: icl_hcc_t | AC12: icl_clr_t | AE12: acm | AG12: em_rate
A13: =IF(Compartments!$A13<>"",Compartments!$A13,"") -> ict | J13: ict_icl | N13: annual_dx | Q13: ict_ie | Z13: ict_hcc | AC13: ict_clr | AE13: acm | AG13: em_rate
A14: =IF(Compartments!$A14<>"",Compartments!$A14,"") -> ict_dx | K14: ict_icl | O14: n_ict_tx | R14: ict_ie | AA14: ict_hcc | AC14: ict_clr | AE14: acm | AG14: em_rate
A15: =IF(Compartments!$A15<>"",Compartments!$A15,"") -> ict_tx_i | L15: =L16 -> ict_icl_t | S15: =S16 -> ict_ie_t | AB15: =AB16 -> ict_hcc_t | AC15: =AC16 -> ict_clr_t | AE15: acm | AG15: em_rate
A16: =IF(Compartments!$A16<>"",Compartments!$A16,"") -> ict_tx | L16: ict_icl_t | S16: ict_ie_t | AB16: ict_hcc_t | AC16: ict_clr_t | AE16: acm | AG16: em_rate
A17: =IF(Compartments!$A17<>"",Compartments!$A17,"") -> ie | R17: annual_dx | T17: ie_cc | Z17: ie_hcc | AC17: ie_clr | AE17: acm | AG17: em_rate
A18: =IF(Compartments!$A18<>"",Compartments!$A18,"") -> ie_dx | S18: ie_tx_n | U18: ie_cc | AA18: ie_hcc | AC18: ie_clr | AE18: acm | AG18: em_rate
A19: =IF(Compartments!$A19<>"",Compartments!$A19,"") -> ie_tx | V19: ie_cc_t | AB19: ie_hcc_t | AC19: ie_clr_t | AE19: acm | AG19: em_rate
A20: =IF(Compartments!$A20<>"",Compartments!$A20,"") -> cc | U20: annual_dx | W20: cc_dc | Z20: cc_hcc | AE20: acm | AG20: em_rate
A21: =IF(Compartments!$A21<>"",Compartments!$A21,"") -> cc_dx | V21: cc_tx_n | X21: cc_dc | AA21: cc_hcc | AE21: acm | AG21: em_rate
A22: =IF(Compartments!$A22<>"",Compartments!$A22,"") -> cc_tx | Y22: cc_dc_t | AB22: cc_hcc_t | AE22: acm | AG22: em_rate
A23: =IF(Compartments!$A23<>"",Compartments!$A23,"") -> dc | X23: annual_dx | Z23: dc_hcc | AD23: m_dc | AE23: acm | AG23: em_rate
A24: =IF(Compartments!$A24<>"",Compartments!$A24,"") -> dc_dx | Y24: dc_tx_n | AA24: dc_hcc | AD24: m_dc | AE24: acm | AG24: em_rate
A25: =IF(Compartments!$A25<>"",Compartments!$A25,"") -> dc_tx | V25: te_dc_cc | AB25: dc_hcc_t | AD25: m_dc_t | AE25: acm | AG25: em_rate
A26: =IF(Compartments!$A26<>"",Compartments!$A26,"") -> hcc | AA26: annual_dx | AD26: m_hcc | AE26: acm | AG26: em_rate
A27: =IF(Compartments!$A27<>"",Compartments!$A27,"") -> hcc_dx | AB27: hcc_tx_n | AD27: m_hcc | AE27: acm | AG27: em_rate
A28: =IF(Compartments!$A28<>"",Compartments!$A28,"") -> hcc_tx | AD28: m_hcc_t | AE28: acm | AG28: em_rate
A29: =IF(Compartments!$A29<>"",Compartments!$A29,"") -> rec | AE29: acm | AG29: em_rate
A30: =IF(Compartments!$A30<>"",Compartments!$A30,"") -> dd_hbv
A31: =IF(Compartments!$A31<>"",Compartments!$A31,"") -> dd_oth
A32: =IF(Compartments!$A32<>"",Compartments!$A32,"") -> imig | D32: im_flow
A33: =IF(Compartments!$A33<>"",Compartments!$A33,"") -> emig
A34: =IF(Compartments!$A34<>"",Compartments!$A34,"")
A35: =IF(Compartments!$A35<>"",Compartments!$A35,"")
A36: =IF(Compartments!$A36<>"",Compartments!$A36,"")
A37: =IF(Compartments!$A37<>"",Compartments!$A37,"")
A38: =IF(Compartments!$A38<>"",Compartments!$A38,"")
A39: =IF(Compartments!$A39<>"",Compartments!$A39,"")
A40: =IF(Compartments!$A40<>"",Compartments!$A40,"")
...

Sheet Characteristics
A1: Code Name | B1: Display Name | C1: Components | D1: Denominator | E1: Default Value | F1: Setup Weight | G1: Calibrate | H1: Databook Page | I1: Databook Order | J1: Guidance | K1: Population type
A2: #ignore | B2: Demographics
A3: alive | B3: Total Population | C3: j_init, sus, vax, j_acu, it, it_dx, it_tx, icl, icl_dx, icl_tx, ict, ict_dx, ict_tx_i, ict_tx, ie, ie_dx, ie_tx, cc, cc_dx, cc_tx, dc, dc_dx, dc_tx, hcc, hcc_dx, hcc_tx, rec | F3: 0 | H3: sh_pops
A4: #ignore | B4: Prevalence
A5: chb_pop | B5: People living with chronic hepatitis B | C5: it, it_dx, it_tx, icl, icl_dx, icl_tx, ict, ict_dx, ict_tx_i, ict_tx, ie, ie_dx, ie_tx, cc, cc_dx, cc_tx, dc, dc_dx, dc_tx, hcc, hcc_dx, hcc_tx | F5: 0 | H5: sh_data
A6: prev | B6: Prevalence of chronic hepatitis B | C6: chb_pop | D6: alive | F6: 0 | H6: sh_data
A7: chb_uncomp | B7: People living with uncomplicated chronic hepatitis B | C7: it, it_dx, it_tx, icl, icl_dx, icl_tx, ict, ict_dx, ict_tx_i, ict_tx, ie, ie_dx, ie_tx
A8: comp | B8: People living with compensated cirrhosis attributable to HBV | C8: cc, cc_dx, cc_tx | F8: 0
A9: decomp | B9: People living with decompensated cirrhosis attributable to HBV | C9: dc, dc_dx, dc_tx | F9: 0
A10: hepcc | B10: People living with hepatocellular carcinoma attributable to HBV | C10: hcc, hcc_dx, hcc_tx | F10: 0
A11: eag_ott | B11: Prevalence of HBeAg among people living with chronic hepatitis B | C11: it, it_dx, it_tx, icl, icl_dx, icl_tx | D11: chb_pop | F11: 0 | H11: sh_data
A12: eag_tot | B12: Prevalence of HBeAg in the total living population | C12: it, it_dx, it_tx, icl, icl_dx, icl_tx | D12: alive | F12: 0
A13: sag_tot | B13: Prevalence of non-HBeAg among the total living population | C13: ict, ict_dx, ict_tx_i, ict_tx, ie, ie_dx, ie_tx, cc, cc_dx, cc_tx, dc, dc_dx, dc_tx, hcc, hcc_dx, hcc_tx | D13: alive | F13: 0
A14: #ignore | B14: Care Cascade (total)
A15: undiag | B15: Chronic hepatitis B: Undiagnosed | C15: it, icl, ict, ie, cc, dc, hcc | F15: 0
A16: diag | B16: Chronic hepatitis B: Diagnosed | C16: it_dx, it_tx, icl_dx, icl_tx, ict_dx, ict_tx_i, ict_tx, ie_dx, ie_tx, cc_dx, cc_tx, dc_dx, dc_tx, hcc_dx, hcc_tx | F16: 0
A17: diag_ntx | B17: Chronic hepatitis B: Diagnosed untreated | C17: it_dx, icl_dx, ict_dx, ie_dx, cc_dx, dc_dx, hcc_dx | F17: 0
A18: treat | B18: Chronic hepatitis B: Treated | C18: it_tx, icl_tx, ict_tx_i, ict_tx, ie_tx, cc_tx, dc_tx, hcc_tx | F18: 0
A19: #ignore | B19: Care Cascade (stratified by 2015 WHO treatment eligibility)
A20: elig | B20: Eligible: Total Population | C20: icl, icl_dx, icl_tx, ie, ie_dx, ie_tx, cc, cc_dx, cc_tx, dc, dc_dx, dc_tx, hcc, hcc_dx, hcc_tx | F20: 0
A21: elig_prop | B21: Eligible: Proportion of total CHB cases | C21: elig | D21: chb_pop | F21: 0
A22: elig_undiag | B22: Eligible: Undiagnosed | C22: icl, ie, cc, dc, hcc | F22: 0
A23: elig_diag | B23: Eligible: Diagnosed | C23: icl_dx, icl_tx, ie_dx, ie_tx, cc_dx, cc_tx, dc_dx, dc_tx, hcc_dx, hcc_tx | F23: 0
A24: elig_diag_ntx | B24: Eligible: Diagnosed untreated | C24: icl_dx, ie_dx, cc_dx, dc_dx, hcc_dx | F24: 0
A25: elig_treat | B25: Eligible: Treated | C25: icl_tx, ie_tx, cc_tx, dc_tx, hcc_tx | F25: 0
A26: inelig | B26: Ineligible: Total Population | C26: it, it_dx, it_tx, ict, ict_dx, ict_tx_i | F26: 0
A27: inelig_prop | B27: Ineligible: Proportion of total CHB cases | C27: inelig | D27: chb_pop | F27: 0
A28: inelig_undiag | B28: Ineligible: Undiagnosed | C28: it, ict | F28: 0
A29: inelig_diag | B29: Ineligible: Diagnosed | C29: it_dx, it_tx, ict_dx, ict_tx_i | F29: 0
A30: inelig_diag_ntx | B30: Ineligible: Diagnosed untreated | C30: it_dx, ict_dx | F30: 0
A31: inelig_treat | B31: Ineligible: Treated | C31: it_tx, ict_tx_i | F31: 0
A32: #ignore | B32: Care Coverage Proportions (%)
A33: diag_cov | B33: Coverage: Total Diagnosed/Total CHB population | C33: diag | D33: chb_pop | F33: 0
A34: elig_diag_cov | B34: Coverage: Total eligible diagnosed/Total eligible pop | C34: elig_diag | D34: elig | F34: 0
A35: inelig_diag_cov | B35: Coverage: Total ineligible diagnosed/Total ineligible pop | C35: inelig_diag | D35: inelig | F35: 0
A36: treat_cov | B36: Coverage: Total on treatment/Total CHB population | C36: treat | D36: chb_pop | F36: 0
A37: elig_treat_cov | B37: Coverage: Total eligble on treatment/Total eligible pop | C37: elig_treat | D37: elig | F37: 0
A38: inelig_treat_cov | B38: Coverage: Total ineligble on treatment/Total ineligible pop | C38: inelig_treat | D38: inelig | F38: 0
A39: treat_diag_cov | B39: Coverage: Total Treated/Total Diagnosed | C39: treat | D39: diag | F39: 0
A40: elig_treat_diag_cov | B40: Coverage: Eligible Treated/Eligible Diagnosed | C40: elig_treat | D40: elig_diag | F40: 0
...

Sheet Parameters
A1: Code Name | B1: Display Name | C1: Format | D1: Timescale | E1: Default Value | F1: Minimum Value | G1: Maximum Value | H1: Function | I1: Targetable | J1: Calibrate | K1: Databook Page | L1: Databook Order | M1: Guidance | N1: Population type | O1: Timed | P1: Is derivative
A2: #ignore | B2: Population Demographics
A3: b_rate | B3: Estimated Annual Livebirths | C3: number | K3: sh_pops
A4: acm | B4: Age/sex specific all-cause mortality rate | C4: probability | K4: sh_pops
A5: life_exp | B5: Age/sex specific years life remaining | C5: number | K5: sh_pops
A6: em_rate | B6: Annual emigration rate | C6: probability | K6: sh_pops
A7: im_rate | B7: Annual immigration rate | K7: sh_pops
A8: im_flow | B8: Annual immigrants (source flow) | C8: number | H8: im_rate*alive
A9: #ignore | B9: Discounting
A10: disc | B10: Annual disounting rate | K10: sh_costs
A11: #ignore | B11: Model Initialization
A12: i_vax | B12: Initial vaccination coverage | C12: proportion | H12: 0
A13: i_rec | B13: Initial recovered proportion | C13: proportion | K13: sh_init
A14: i_dx | B14: Initial diagnosis coverage | C14: proportion | K14: sh_init
A15: i_tx | B15: Initial treatment coverage | C15: proportion | K15: sh_init
A16: i_hcp | B16: Initial proportion of CHB with HCC | C16: proportion | K16: sh_init
A17: i_dcp | B17: Initial proportion of CHB with DC | C17: proportion | K17: sh_init
A18: i_ccp | B18: Initial proportion of CHB with CC | C18: proportion | K18: sh_init
A19: i_uchb | B19: Unadjusted initial CHB prevalence | C19: proportion | K19: sh_init
A20: i_epos | B20: Initial proportion HBeAg+ | C20: proportion | K20: sh_init
A21: i_edis | B21: Initial proportion HBeAg+ with chronic infection | C21: proportion | K21: sh_init
A22: i_sdis | B22: Initial proportion HBeAg- with chronic infection | C22: proportion | K22: sh_init
A23: i_chb | B23: Adjusted initial CHB prevalence | C23: proportion | H23: max(i_uchb-(i_uchb*(i_ccp+i_dcp+i_hcp)),0)
A24: i_it | B24: Initial HBeAg+ chronic infection (undiagnosed) | C24: proportion | H24: i_chb*i_epos*i_edis*(1-i_dx)
A25: i_itd | B25: Initial HBeAg+ chronic infection (diagnosed) | C25: proportion | H25: i_chb*i_epos*i_edis*i_dx
A26: i_ia | B26: Initial HBeAg+ chronic hepatitis (undiagnosed) | C26: proportion | H26: i_chb*i_epos*(1-i_edis)*(1-i_dx)
A27: i_iad | B27: Initial HBeAg+ chronic hepatitis (diagnosed) | C27: proportion | H27: i_chb*i_epos*(1-i_edis)*i_dx
A28: i_iat | B28: Initial HBeAg+ chronic hepatitis (treated) | C28: proportion | H28: i_chb*i_epos*(1-i_edis)*i_tx
A29: i_ic | B29: Initial HBeAg- chronic infection (undiagnosed) | C29: proportion | H29: i_chb*(1-i_epos)*i_sdis*(1-i_dx)
A30: i_icd | B30: Initial HBeAg- chronic infection(diagnosed) | C30: proportion | H30: i_chb*(1-i_epos)*i_sdis*i_dx
A31: i_ict | B31: Initial HBeAg- chronic infection (treated) | C31: proportion | H31: i_chb*(1-i_epos)*i_sdis*i_tx
A32: i_ie | B32: Initial HBeAg- chronic hepatitis (undiagnosed) | C32: proportion | H32: i_chb*(1-i_epos)*(1-i_sdis)*(1-i_dx)
A33: i_ied | B33: Initial HBeAg- chronic hepatitis (diagnosed) | C33: proportion | H33: i_chb*(1-i_epos)*(1-i_sdis)*i_dx
A34: i_iet | B34: Initial HBeAg- chronic hepatitis (treated) | C34: proportion | H34: i_chb*(1-i_epos)*(1-i_sdis)*i_tx
... A44: i_sus | B44: Initial: Hepatitis B susceptible population | C44: proportion | H44: 1-(i_uchb+i_rec+i_vax)
A45: #ignore | B45: Vaccine Effectiveness
A46: eag_ve | B46: Vaccine Effectiveness: HepB-BD, eAg+ mother | F46: 0.65 | G46: 0.84 | K46: sh_eff
A47: sag_ve | B47: Vaccine Effectiveness: HepB-BD, eAg- mother | F47: 0.86 | G47: 0.99 | K47: sh_eff
A48: hb3_ve | B48: Vaccine Effectiveness: HepB3 | K48: sh_eff
A49: mav_ve | B49: Vaccine Effectiveness: HepB-BD, eAg+ mother, mAV (sensitivity) | F49: 0.97 | G49: 0.99 | K49: sh_eff
...

Sheet Interactions
A1: Code Name | B1: Display Name | C1: Default Value | D1: From population type | E1: To population type
A2: mx_mtct | B2: Matrix: Mother to Child Transmission | C2: 0 | D2: default | E2: default
A3: mx_echt | B3: Matrix: Early Childhood Horizontal Transmission | C3: 0 | D3: default | E3: default
A4: mx_horiz | B4: Matrix: Population Horizontal Transmission | C4: 0 | D4: default | E4: default

Sheet Cascades
A1: Care Cascade | B1: Constituents
A2: total_chb | B2: undiag,diag,treat
A3: diagnosed | B3: diag, treat
A4: treatment | B4: treat

Sheet Plots
