Workbook

Sheet Population Definitions
A1: Abbreviation | B1: Full Name | C1: Population type
A2: 0-0M | B2: 0-0M | C2: default
A3: 0-0F | B3: 0-0F | C3: default
A4: 1-4M | B4: 1-4M | C4: default
A5: 1-4F | B5: 1-4F | C5: default
A6: 5-9M | B6: 5-9M | C6: default
A7: 5-9F | B7: 5-9F | C7: default
A8: 10-19M | B8: 10-19M | C8: default
A9: 10-19F | B9: 10-19F | C9: default
A10: 20-29M | B10: 20-29M | C10: default
A11: 20-29F | B11: 20-29F | C11: default
A12: 30-39M | B12: 30-39M | C12: default
... A25: 90+F | B25: 90+F | C25: default

Sheet Initialization
A1: Junction: Model Initialization | B1: Provenance | C1: Units | D1: Uncertainty | E1: Constant | G1: 1990 | H1: 1991 | I1: 1992 | J1: 1993 | K1: 1994 | L1: 1995 | M1: 1996 | N1: 1997 | O1: 1998 | P1: 1999 | Q1: 2000 | R1: 2001 | S1: 2002 | T1: 2003 | U1: 2004 | V1: 2005 | W1: 2006 | X1: 2007 | Y1: 2008 | Z1: 2009 | AA1: 2010 | AB1: 2011 | AC1: 2012 | AD1: 2013 | AE1: 2014 | AF1: 2015 | AG1: 2016 | AH1: 2017 | AI1: 2018 | AJ1: 2019 | AK1: 2020 | AL1: 2021 | AM1: 2022 | AN1: 2023 | AO1: 2024 | AP1: 2025 | AQ1: 2026 | AR1: 2027 | AS1: 2028 | AT1: 2029 | AU1: 2030 | AV1: 2031 | AW1: 2032 | AX1: 2033 | AY1: 2034 | AZ1: 2035 | BA1: 2036 | BB1: 2037 | BC1: 2038 | BD1: 2039 | BE1: 2040 | BF1: 2041 | BG1: 2042 | BH1: 2043 | BI1: 2044 | BJ1: 2045 | BK1: 2046 | BL1: 2047 | BM1: 2048 | BN1: 2049 | BO1: 2050 | BP1: 2051 | BQ1: 2052 | BR1: 2053 | BS1: 2054 | BT1: 2055 | BU1: 2056 | BV1: 2057 | BW1: 2058 | BX1: 2059 | BY1: 2060 | BZ1: 2061 | CA1: 2062 | CB1: 2063 | CC1: 2064 | CD1: 2065 | CE1: 2066 | CF1: 2067 | CG1: 2068 | CH1: 2069 | CI1: 2070 | CJ1: 2071 | CK1: 2072 | CL1: 2073 | CM1: 2074 | CN1: 2075 | CO1: 2076 | CP1: 2077 | CQ1: 2078 | CR1: 2079 | CS1: 2080 | CT1: 2081 | CU1: 2082 | CV1: 2083 | CW1: 2084 | CX1: 2085 | CY1: 2086 | CZ1: 2087 | DA1: 2088 | DB1: 2089 | DC1: 2090 | DD1: 2091 | DE1: 2092 | DF1: 2093 | DG1: 2094 | DH1: 2095 | DI1: 2096 | DJ1: 2097 | DK1: 2098 | DL1: 2099 | DM1: 2100
A2: ='Population Definitions'!$B$2 -> 0-0M | C2: Number | E2: 290672 | F2: OR
A3: ='Population Definitions'!$B$3 -> 0-0F | C3: Number | E3: 274920.5 | F3: OR
A4: ='Population Definitions'!$B$4 -> 1-4M | C4: Number | E4: 1142075.5 | F4: OR
A5: ='Population Definitions'!$B$5 -> 1-4F | C5: Number | E5: 1083972 | F5: OR
A6: ='Population Definitions'!$B$6 -> 5-9M | C6: Number | E6: 1539409.5 | F6: OR
A7: ='Population Definitions'!$B$7 -> 5-9F | C7: Number | E7: 1470743 | F7: OR
A8: ='Population Definitions'!$B$8 -> 10-19M | C8: Number | E8: 4048217.5 | F8: OR
A9: ='Population Definitions'!$B$9 -> 10-19F | C9: Number | E9: 3882099.5 | F9: OR
A10: ='Population Definitions'!$B$10 -> 20-29M | C10: Number | E10: 4598554 | F10: OR
A11: ='Population Definitions'!$B$11 -> 20-29F | C11: Number | E11: 4498077.5 | F11: OR
A12: ='Population Definitions'!$B$12 -> 30-39M | C12: Number | E12: 3867540 | F12: OR
A13: ='Population Definitions'!$B$13 -> 30-39F | C13: Number | E13: 3871953.5 | F13: OR
A14: ='Population Definitions'!$B$14 -> 40-49M | C14: Number | E14: 3659283.5 | F14: OR
A15: ='Population Definitions'!$B$15 -> 40-49F | C15: Number | E15: 3722426 | F15: OR
A16: ='Population Definitions'!$B$16 -> 50-59M | C16: Number | E16: 3425374.5 | F16: OR
A17: ='Population Definitions'!$B$17 -> 50-59F | C17: Number | E17: 3626562 | F17: OR
A18: ='Population Definitions'!$B$18 -> 60-69M | C18: Number | E18: 2856853.5 | F18: OR
A19: ='Population Definitions'!$B$19 -> 60-69F | C19: Number | E19: 3383656 | F19: OR
A20: ='Population Definitions'!$B$20 -> 70-79M | C20: Number | E20: 1494732.5 | F20: OR
A21: ='Population Definitions'!$B$21 -> 70-79F | C21: Number | E21: 2143711.5 | F21: OR
A22: ='Population Definitions'!$B$22 -> 80-89M | C22: Number | E22: 564556.5 | F22: OR
A23: ='Population Definitions'!$B$23 -> 80-89F | C23: Number | E23: 1124661.5 | F23: OR
A24: ='Population Definitions'!$B$24 -> 90+M | C24: Number | E24: 46409.5 | F24: OR
A25: ='Population Definitions'!$B$25 -> 90+F | C25: Number | E25: 140099.5 | F25: OR
A27: Initial recovered proportion | B27: Provenance | C27: Units | D27: Uncertainty | E27: Constant | G27: 1990 | H27: 1991 | I27: 1992 | J27: 1993 | K27: 1994 | L27: 1995 | M27: 1996 | N27: 1997 | O27: 1998 | P27: 1999 | Q27: 2000 | R27: 2001 | S27: 2002 | T27: 2003 | U27: 2004 | V27: 2005 | W27: 2006 | X27: 2007 | Y27: 2008 | Z27: 2009 | AA27: 2010 | AB27: 2011 | AC27: 2012 | AD27: 2013 | AE27: 2014 | AF27: 2015 | AG27: 2016 | AH27: 2017 | AI27: 2018 | AJ27: 2019 | AK27: 2020 | AL27: 2021 | AM27: 2022 | AN27: 2023 | AO27: 2024 | AP27: 2025 | AQ27: 2026 | AR27: 2027 | AS27: 2028 | AT27: 2029 | AU27: 2030 | AV27: 2031 | AW27: 2032 | AX27: 2033 | AY27: 2034 | AZ27: 2035 | BA27: 2036 | BB27: 2037 | BC27: 2038 | BD27: 2039 | BE27: 2040 | BF27: 2041 | BG27: 2042 | BH27: 2043 | BI27: 2044 | BJ27: 2045 | BK27: 2046 | BL27: 2047 | BM27: 2048 | BN27: 2049 | BO27: 2050 | BP27: 2051 | BQ27: 2052 | BR27: 2053 | BS27: 2054 | BT27: 2055 | BU27: 2056 | BV27: 2057 | BW27: 2058 | BX27: 2059 | BY27: 2060 | BZ27: 2061 | CA27: 2062 | CB27: 2063 | CC27: 2064 | CD27: 2065 | CE27: 2066 | CF27: 2067 | CG27: 2068 | CH27: 2069 | CI27: 2070 | CJ27: 2071 | CK27: 2072 | CL27: 2073 | CM27: 2074 | CN27: 2075 | CO27: 2076 | CP27: 2077 | CQ27: 2078 | CR27: 2079 | CS27: 2080 | CT27: 2081 | CU27: 2082 | CV27: 2083 | CW27: 2084 | CX27: 2085 | CY27: 2086 | CZ27: 2087 | DA27: 2088 | DB27: 2089 | DC27: 2090 | DD27: 2091 | DE27: 2092 | DF27: 2093 | DG27: 2094 | DH27: 2095 | DI27: 2096 | DJ27: 2097 | DK27: 2098 | DL27: 2099 | DM27: 2100
A28: ='Population Definitions'!$B$2 -> 0-0M | C28: Proportion | D28: 0 | E28: 0.011143138 | F28: OR
A29: ='Population Definitions'!$B$3 -> 0-0F | C29: Proportion | D29: 0 | E29: 0.011143138 | F29: OR
A30: ='Population Definitions'!$B$4 -> 1-4M | C30: Proportion | D30: 0 | E30: 0.011143138 | F30: OR
A31: ='Population Definitions'!$B$5 -> 1-4F | C31: Proportion | D31: 0 | E31: 0.0020413 | F31: OR
A32: ='Population Definitions'!$B$6 -> 5-9M | C32: Proportion | D32: 0 | E32: 0.063120785 | F32: OR
A33: ='Population Definitions'!$B$7 -> 5-9F | C33: Proportion | D33: 0 | E33: 0.035367329 | F33: OR
A34: ='Population Definitions'!$B$8 -> 10-19M | C34: Proportion | D34: 0 | E34: 0.145421 | F34: OR
A35: ='Population Definitions'!$B$9 -> 10-19F | C35: Proportion | D35: 0 | E35: 0.11538355 | F35: OR
A36: ='Population Definitions'!$B$10 -> 20-29M | C36: Proportion | D36: 0 | E36: 0.22772122 | F36: OR
A37: ='Population Definitions'!$B$11 -> 20-29F | C37: Proportion | D37: 0 | E37: 0.19539977 | F37: OR
A38: ='Population Definitions'!$B$12 -> 30-39M | C38: Proportion | D38: 0 | E38: 0.22772122 | F38: OR
A39: ='Population Definitions'!$B$13 -> 30-39F | C39: Proportion | D39: 0 | E39: 0.19539977 | F39: OR
A40: ='Population Definitions'!$B$14 -> 40-49M | C40: Proportion | D40: 0 | E40: 0.22772122 | F40: OR
A41: ='Population Definitions'!$B$15 -> 40-49F | C41: Proportion | D41: 0 | E41: 0.19539977 | F41: OR
...

Sheet Population Demography
A1: Total Population | B1: Provenance | C1: Units | D1: Uncertainty | E1: 1990 | F1: 1991 | G1: 1992 | H1: 1993 | I1: 1994 | J1: 1995 | K1: 1996 | L1: 1997 | M1: 1998 | N1: 1999 | O1: 2000 | P1: 2001 | Q1: 2002 | R1: 2003 | S1: 2004 | T1: 2005 | U1: 2006 | V1: 2007 | W1: 2008 | X1: 2009 | Y1: 2010 | Z1: 2011 | AA1: 2012 | AB1: 2013 | AC1: 2014 | AD1: 2015 | AE1: 2016 | AF1: 2017 | AG1: 2018 | AH1: 2019 | AI1: 2020 | AJ1: 2021 | AK1: 2022 | AL1: 2023 | AM1: 2024 | AN1: 2025 | AO1: 2026 | AP1: 2027 | AQ1: 2028 | AR1: 2029 | AS1: 2030 | AT1: 2031 | AU1: 2032 | AV1: 2033 | AW1: 2034 | AX1: 2035 | AY1: 2036 | AZ1: 2037 | BA1: 2038 | BB1: 2039 | BC1: 2040 | BD1: 2041 | BE1: 2042 | BF1: 2043 | BG1: 2044 | BH1: 2045 | BI1: 2046 | BJ1: 2047 | BK1: 2048 | BL1: 2049 | BM1: 2050 | BN1: 2051 | BO1: 2052 | BP1: 2053 | BQ1: 2054 | BR1: 2055 | BS1: 2056 | BT1: 2057 | BU1: 2058 | BV1: 2059 | BW1: 2060 | BX1: 2061 | BY1: 2062 | BZ1: 2063 | CA1: 2064 | CB1: 2065 | CC1: 2066 | CD1: 2067 | CE1: 2068 | CF1: 2069 | CG1: 2070 | CH1: 2071 | CI1: 2072 | CJ1: 2073 | CK1: 2074 | CL1: 2075 | CM1: 2076 | CN1: 2077 | CO1: 2078 | CP1: 2079 | CQ1: 2080 | CR1: 2081 | CS1: 2082 | CT1: 2083 | CU1: 2084 | CV1: 2085 | CW1: 2086 | CX1: 2087 | CY1: 2088 | CZ1: 2089 | DA1: 2090 | DB1: 2091 | DC1: 2092 | DD1: 2093 | DE1: 2094 | DF1: 2095 | DG1: 2096 | DH1: 2097 | DI1: 2098 | DJ1: 2099 | DK1: 2100
A2: ='Population Definitions'!$B$2 -> 0-0M | C2: Number | E2: 290672 | F2: 277346.5 | G2: 277684 | H2: 287491 | I2: 278024 | J2: 271646 | K2: 271297 | L2: 273439 | M2: 272182.5 | N2: 271876 | O2: 273656 | P2: 271399.5 | Q2: 271653 | R2: 276838 | S2: 282660.5 | T2: 285433.5 | U2: 285486 | V2: 287769.5 | W2: 290919 | X2: 291229.5 | Y2: 287157 | Z2: 280654 | AA2: 275389.5 | AB2: 268749 | AC2: 260063 | AD2: 252754.5 | AE2: 244856.5 | AF2: 237696 | AG2: 227916 | AH2: 217208 | AI2: 211724.5 | AJ2: 210816 | AK2: 210241 | AL2: 209292 | AM2: 208380.5 | AN2: 207469.5 | AO2: 206899.5 | AP2: 206773.5 | AQ2: 206155 | AR2: 205209 | AS2: 205379 | AT2: 205527.5 | AU2: 205821 | AV2: 206175.5 | AW2: 206100 | AX2: 205835.5 | AY2: 205307.5 | AZ2: 205119 | BA2: 205167.5 | BB2: 204501.5 | BC2: 203628.5 | BD2: 202649 | BE2: 201160 | BF2: 199977.5 | BG2: 198067 | BH2: 195697.5 | BI2: 193609.5 | BJ2: 191363.5 | BK2: 188748.5 | BL2: 185787 | BM2: 182550 | BN2: 179580 | BO2: 176997 | BP2: 174535 | BQ2: 172082.5 | BR2: 169945 | BS2: 168131 | BT2: 166313.5 | BU2: 165058 | BV2: 164134 | BW2: 163702.5 | BX2: 163392.5 | BY2: 162728 | BZ2: 162387.5 | CA2: 162231 | CB2: 161859 | CC2: 161630 | CD2: 161322.5 | CE2: 161329.5 | CF2: 161193 | CG2: 160798.5 | CH2: 160687 | CI2: 160291.5 | CJ2: 159604 | CK2: 159134 | CL2: 158879.5 | CM2: 157742.5 | CN2: 156428.5 | CO2: 155363 | CP2: 154418.5 | CQ2: 153568 | CR2: 152044 | CS2: 150524.5 | CT2: 149458 | CU2: 148409 | CV2: 146844 | CW2: 145293 | CX2: 143908.5 | CY2: 142488 | CZ2: 141300.5 | DA2: 140268 | DB2: 139288 | DC2: 138110.5 | DD2: 137293 | DE2: 136719.5 | DF2: 136083.5 | DG2: 135690.5 | DH2: 135431 | DI2: 135254.5 | DJ2: 135201.5 | DK2: 135022.5
A3: ='Population Definitions'!$B$3 -> 0-0F | C3: Number | E3: 274920.5 | F3: 262752.5 | G3: 262958.5 | H3: 272010 | I3: 262669.5 | J3: 256266.5 | K3: 255976.5 | L3: 258386 | M3: 257171 | N3: 257187 | O3: 258881.5 | P3: 256895 | Q3: 257686 | R3: 262159 | S3: 267758 | T3: 269387 | U3: 268527.5 | V3: 271033 | W3: 274836.5 | X3: 275337.5 | Y3: 270624 | Z3: 264639 | AA3: 260318 | AB3: 254354.5 | AC3: 245987.5 | AD3: 238714.5 | AE3: 231620.5 | AF3: 224827 | AG3: 215116.5 | AH3: 205758.5 | AI3: 200614 | AJ3: 199121 | AK3: 198579.5 | AL3: 197688.5 | AM3: 196858.5 | AN3: 196036.5 | AO3: 195511 | AP3: 195416 | AQ3: 194858 | AR3: 193978 | AS3: 194148 | AT3: 194287.5 | AU3: 194547.5 | AV3: 194878 | AW3: 194806.5 | AX3: 194544 | AY3: 194048 | AZ3: 193897 | BA3: 193961 | BB3: 193330 | BC3: 192490 | BD3: 191559 | BE3: 190153 | BF3: 189035.5 | BG3: 187228 | BH3: 184992.5 | BI3: 183025 | BJ3: 180907 | BK3: 178425 | BL3: 175607.5 | BM3: 172564 | BN3: 169754 | BO3: 167303.5 | BP3: 164983.5 | BQ3: 162670.5 | BR3: 160649.5 | BS3: 158923.5 | BT3: 157209 | BU3: 156040 | BV3: 155172.5 | BW3: 154746.5 | BX3: 154445.5 | BY3: 153814.5 | BZ3: 153479.5 | CA3: 153341.5 | CB3: 152995 | CC3: 152767.5 | CD3: 152473 | CE3: 152485 | CF3: 152361.5 | CG3: 151998 | CH3: 151906 | CI3: 151551.5 | CJ3: 150906.5 | CK3: 150445.5 | CL3: 150206 | CM3: 149145 | CN3: 147899 | CO3: 146890.5 | CP3: 145991.5 | CQ3: 145170.5 | CR3: 143722.5 | CS3: 142288 | CT3: 141284.5 | CU3: 140288.5 | CV3: 138807.5 | CW3: 137347 | CX3: 136045.5 | CY3: 134696.5 | CZ3: 133574 | DA3: 132614.5 | DB3: 131695 | DC3: 130578.5 | DD3: 129811 | DE3: 129260 | DF3: 128637 | DG3: 128255.5 | DH3: 128002 | DI3: 127835.5 | DJ3: 127795.5 | DK3: 127634.5
A4: ='Population Definitions'!$B$4 -> 1-4M | C4: Number | E4: 1142075.5 | F4: 1107820.5 | G4: 1080879.5 | H4: 1092417.5 | I4: 1108481.5 | J4: 1114490.5 | K4: 1113316 | L4: 1101077.5 | M4: 1085387.5 | N4: 1077952.5 | O4: 1075329.5 | P4: 1074555 | Q4: 1079530.5 | R4: 1092037.5 | S4: 1105619.5 | T4: 1118911 | U4: 1131137.5 | V4: 1143265.5 | W4: 1154456.5 | X4: 1161364.5 | Y4: 1163902.5 | Z4: 1160095 | AA4: 1151103 | AB4: 1137714.5 | AC4: 1114939 | AD4: 1085079.5 | AE4: 1054300 | AF4: 1022746.5 | AG4: 993539.5 | AH4: 965470.5 | AI4: 932740.5 | AJ4: 899494 | AK4: 872295 | AL4: 853441 | AM4: 844594.5 | AN4: 841570 | AO4: 838346.5 | AP4: 835021 | AQ4: 832516.5 | AR4: 830303.5 | AS4: 828055.5 | AT4: 826547 | AU4: 825311 | AV4: 824986.5 | AW4: 825963 | AX4: 826693.5 | AY4: 827011 | AZ4: 826507 | BA4: 825459 | BB4: 824535 | BC4: 823209.5 | BD4: 821538 | BE4: 819075.5 | BF4: 815076 | BG4: 810560 | BH4: 805007.5 | BI4: 798065.5 | BJ4: 790523.5 | BK4: 781917.5 | BL4: 772608 | BM4: 762707 | BN4: 751655.5 | BO4: 739879.5 | BP4: 728136 | BQ4: 716891.5 | BR4: 706431.5 | BS4: 696803.5 | BT4: 687943.5 | BU4: 679728 | BV4: 672709.5 | BW4: 666904 | BX4: 662480 | BY4: 659563 | BZ4: 657237 | CA4: 655494 | CB4: 654025.5 | CC4: 652496 | CD4: 651401.5 | CE4: 650338.5 | CF4: 649440 | CG4: 648777.5 | CH4: 647949 | CI4: 647316 | CJ4: 646280 | CK4: 644693.5 | CL4: 643032 | CM4: 641226.5 | CN4: 638680 | CO4: 635507.5 | CP4: 631739 | CQ4: 627281.5 | CR4: 623110.5 | CS4: 618729 | CT4: 613893 | CU4: 608935 | CV4: 603778.5 | CW4: 598580.5 | CX4: 593352 | CY4: 587805 | CZ4: 581886 | DA4: 576345 | DB4: 571322.5 | DC4: 566704.5 | DD4: 562329.5 | DE4: 558324.5 | DF4: 554778 | DG4: 551575 | DH4: 549156.5 | DI4: 547296.5 | DJ4: 545832.5 | DK4: 544952.5
A5: ='Population Definitions'!$B$5 -> 1-4F | C5: Number | E5: 1083972 | F5: 1052660.5 | G5: 1027885.5 | H5: 1038155.5 | I5: 1052151.5 | J5: 1056176.5 | K5: 1053806 | L5: 1041445.5 | M5: 1026449 | N5: 1019567.5 | O5: 1017851.5 | P5: 1018144 | Q5: 1023051.5 | R5: 1034812 | S5: 1046884 | T5: 1059007.5 | U5: 1069522.5 | V5: 1078632.5 | W5: 1087532.5 | X5: 1093522 | Y5: 1096765.5 | Z5: 1093928.5 | AA5: 1085996 | AB5: 1073905.5 | AC5: 1052780.5 | AD5: 1025308 | AE5: 996806 | AF5: 967568 | AG5: 939986.5 | AH5: 913214 | AI5: 882858 | AJ5: 851487.5 | AK5: 825372.5 | AL5: 807575.5 | AM5: 798606.5 | AN5: 795156 | AO5: 792187.5 | AP5: 789133 | AQ5: 786873 | AR5: 784884.5 | AS5: 782838 | AT5: 781486.5 | AU5: 780369 | AV5: 780069 | AW5: 780978 | AX5: 781645 | AY5: 781910 | AZ5: 781419 | BA5: 780447 | BB5: 779609.5 | BC5: 778403.5 | BD5: 776853.5 | BE5: 774522.5 | BF5: 770722 | BG5: 766436.5 | BH5: 761183.5 | BI5: 754624.5 | BJ5: 747503.5 | BK5: 739382.5 | BL5: 730587 | BM5: 721209 | BN5: 710756 | BO5: 699611 | BP5: 688497 | BQ5: 677880.5 | BR5: 667993 | BS5: 658893.5 | BT5: 650518.5 | BU5: 642749.5 | BV5: 636123.5 | BW5: 630650 | BX5: 626477.5 | BY5: 623718.5 | BZ5: 621496.5 | CA5: 619807 | CB5: 618405.5 | CC5: 616958.5 | CD5: 615914.5 | CE5: 614909.5 | CF5: 614055.5 | CG5: 613424.5 | CH5: 612656.5 | CI5: 612092.5 | CJ5: 611162.5 | CK5: 609710 | CL5: 608160 | CM5: 606462 | CN5: 604056.5 | CO5: 601051 | CP5: 597499 | CQ5: 593286.5 | CR5: 589314 | CS5: 585140 | CT5: 580539.5 | CU5: 575835 | CV5: 570956 | CW5: 566043.5 | CX5: 561104 | CY5: 555867.5 | CZ5: 550277 | DA5: 545044.5 | DB5: 540314.5 | DC5: 535965 | DD5: 531848 | DE5: 528086.5 | DF5: 524733.5 | DG5: 521677.5 | DH5: 519356.5 | DI5: 517549 | DJ5: 516125 | DK5: 515285
A6: ='Population Definitions'!$B$6 -> 5-9M | C6: Number | E6: 1539409.5 | F6: 1481402 | G6: 1424460.5 | H6: 1399313 | I6: 1384893.5 | J6: 1377204.5 | K6: 1378609 | L6: 1396604.5 | M6: 1413068 | N6: 1412065 | O6: 1400470.5 | P6: 1381496.5 | Q6: 1364319 | R6: 1358017.5 | S6: 1364629.5 | T6: 1379646 | U6: 1394021 | V6: 1408262 | W6: 1424584 | X6: 1438655 | Y6: 1446206 | Z6: 1449907.5 | AA6: 1457128.5 | AB6: 1464043 | AC6: 1464543.5 | AD6: 1459206 | AE6: 1446560.5 | AF6: 1426525 | AG6: 1400197 | AH6: 1368475.5 | AI6: 1333931 | AJ6: 1298439 | AK6: 1263122.5 | AL6: 1227328.5 | AM6: 1188212 | AN6: 1148353 | AO6: 1114959.5 | AP6: 1087604.5 | AQ6: 1067820 | AR6: 1058077.5 | AS6: 1054154.5 | AT6: 1050372.5 | AU6: 1046931.5 | AV6: 1043819.5 | AW6: 1040670.5 | AX6: 1038600.5 | AY6: 1037249 | AZ6: 1036316 | BA6: 1036354.5 | BB6: 1037262 | BC6: 1037735 | BD6: 1037531.5 | BE6: 1036846 | BF6: 1035853 | BG6: 1034270 | BH6: 1032078.5 | BI6: 1029433.5 | BJ6: 1025489 | BK6: 1020314.5 | BL6: 1013895 | BM6: 1005979.5 | BN6: 996956 | BO6: 987176 | BP6: 975963.5 | BQ6: 963698 | BR6: 950566 | BS6: 936552 | BT6: 922201 | BU6: 908002 | BV6: 894311 | BW6: 881719.5 | BX6: 870282.5 | BY6: 859610 | BZ6: 850143.5 | CA6: 842205.5 | CB6: 835972 | CC6: 831242 | CD6: 827664.5 | CE6: 825000.5 | CF6: 823104 | CG6: 821266.5 | CH6: 819509.5 | CI6: 818110 | CJ6: 817058 | CK6: 816026 | CL6: 814971 | CM6: 814033.5 | CN6: 813007.5 | CO6: 811286 | CP6: 809231.5 | CQ6: 807317.5 | CR6: 804378 | CS6: 800520.5 | CT6: 796284.5 | CU6: 791574 | CV6: 786268.5 | CW6: 780576 | CX6: 774677 | CY6: 768776.5 | CZ6: 762772 | DA6: 756053 | DB6: 749306 | DC6: 742694.5 | DD6: 735730 | DE6: 728626 | DF6: 722055 | DG6: 716054.5 | DH6: 710260.5 | DI6: 705070 | DJ6: 700493 | DK6: 696311.5
A7: ='Population Definitions'!$B$7 -> 5-9F | C7: Number | E7: 1470743 | F7: 1415830.5 | G7: 1359545 | H7: 1333664.5 | I7: 1318864 | J7: 1309840.5 | K7: 1309396.5 | L7: 1325577.5 | M7: 1341090.5 | N7: 1339721.5 | O7: 1327595.5 | P7: 1309301.5 | Q7: 1292323 | R7: 1284178 | S7: 1288887 | T7: 1302143.5 | U7: 1315098 | V7: 1328567.5 | W7: 1344046 | X7: 1356927 | Y7: 1362747 | Z7: 1364909 | AA7: 1370960 | AB7: 1377754 | AC7: 1378817.5 | AD7: 1374149 | AE7: 1363572.5 | AF7: 1346323.5 | AG7: 1321683 | AH7: 1291190.5 | AI7: 1259188.5 | AJ7: 1227049 | AK7: 1194381 | AL7: 1160645 | AM7: 1124478 | AN7: 1087448 | AO7: 1055320.5 | AP7: 1029066 | AQ7: 1010393.5 | AR7: 1000607.5 | AS7: 996346.5 | AT7: 992863.5 | AU7: 989724 | AV7: 986916 | AW7: 984057.5 | AX7: 982189 | AY7: 980984.5 | AZ7: 980135 | BA7: 980172 | BB7: 981016.5 | BC7: 981427.5 | BD7: 981203 | BE7: 980568.5 | BF7: 979666.5 | BG7: 978205 | BH7: 976165.5 | BI7: 973689.5 | BJ7: 969960 | BK7: 965050.5 | BL7: 958962.5 | BM7: 951478.5 | BN7: 942958.5 | BO7: 933726 | BP7: 923129.5 | BQ7: 911522.5 | BR7: 899108.5 | BS7: 885852 | BT7: 872261.5 | BU7: 858832.5 | BV7: 845908 | BW7: 834005 | BX7: 823184 | BY7: 813098 | BZ7: 804163 | CA7: 796673.5 | CB7: 790778.5 | CC7: 786307 | CD7: 782919 | CE7: 780365.5 | CF7: 778541.5 | CG7: 776796.5 | CH7: 775123 | CI7: 773785.5 | CJ7: 772795.5 | CK7: 771820.5 | CL7: 770828 | CM7: 769971 | CN7: 769054.5 | CO7: 767481 | CP7: 765569.5 | CQ7: 763781 | CR7: 761024.5 | CS7: 757377 | CT7: 753364.5 | CU7: 748913.5 | CV7: 743882 | CW7: 738464 | CX7: 732857.5 | CY7: 727255.5 | CZ7: 721556.5 | DA7: 715198 | DB7: 708826 | DC7: 702587 | DD7: 696003 | DE7: 689292 | DF7: 683101.5 | DG7: 677452.5 | DH7: 671988 | DI7: 667105 | DJ7: 662795 | DK7: 658820
A8: ='Population Definitions'!$B$8 -> 10-19M | C8: Number | E8: 4048217.5 | F8: 3907932 | G8: 3760119.5 | H8: 3618034.5 | I8: 3474943 | J8: 3339819 | K8: 3225048.5 | L8: 3131266.5 | M8: 3060361.5 | N8: 3011689.5 | O8: 2981566.5 | P8: 2963314.5 | Q8: 2944954.5 | R8: 2926588 | S8: 2914845 | T8: 2910187 | U8: 2912895.5 | V8: 2925112 | W8: 2938450 | X8: 2946838.5 | Y8: 2953778 | Z8: 2955550 | AA8: 2948082 | AB8: 2938825 | AC8: 2936656 | AD8: 2938833.5 | AE8: 2943789.5 | AF8: 2953237.5 | AG8: 2957011 | AH8: 2950364 | AI8: 2935231 | AJ8: 2914446.5 | AK8: 2896041 | AL8: 2872870.5 | AM8: 2840114.5 | AN8: 2801206.5 | AO8: 2755223.5 | AP8: 2702190 | AQ8: 2640941 | AR8: 2570141 | AS8: 2496035 | AT8: 2427549.5 | AU8: 2365123 | AV8: 2309613 | AW8: 2260821.5 | AX8: 2217104.5 | AY8: 2179984.5 | AZ8: 2149240.5 | BA8: 2126388 | BB8: 2113530.5 | BC8: 2107564 | BD8: 2102454 | BE8: 2098103 | BF8: 2095051 | BG8: 2092831.5 | BH8: 2091255 | BI8: 2089720.5 | BJ8: 2088121.5 | BK8: 2087184.5 | BL8: 2086525.5 | BM8: 2084824 | BN8: 2081994 | BO8: 2077381 | BP8: 2071230 | BQ8: 2063245.5 | BR8: 2053156.5 | BS8: 2041505.5 | BT8: 2027797.5 | BU8: 2011427 | BV8: 1992763 | BW8: 1971735.5 | BX8: 1948716.5 | BY8: 1924604 | BZ8: 1899212 | CA8: 1873276 | CB8: 1847570.5 | CC8: 1822138.5 | CD8: 1797133 | CE8: 1773486 | CF8: 1751874.5 | CG8: 1733065 | CH8: 1716913 | CI8: 1702677 | CJ8: 1690560 | CK8: 1680737 | CL8: 1672678.5 | CM8: 1666202 | CN8: 1661234 | CO8: 1657527.5 | CP8: 1654606 | CQ8: 1651722 | CR8: 1649036 | CS8: 1646618.5 | CT8: 1643853.5 | CU8: 1640774 | CV8: 1637811.5 | CW8: 1633941.5 | CX8: 1629065 | CY8: 1623116 | CZ8: 1616360.5 | DA8: 1609149 | DB8: 1600524.5 | DC8: 1590775.5 | DD8: 1580646.5 | DE8: 1569938.5 | DF8: 1557922 | DG8: 1545490 | DH8: 1532986.5 | DI8: 1520128.5 | DJ8: 1507028 | DK8: 1493745
A9: ='Population Definitions'!$B$9 -> 10-19F | C9: Number | E9: 3882099.5 | F9: 3753004.5 | G9: 3615593 | H9: 3476949.5 | I9: 3336347.5 | J9: 3204146.5 | K9: 3090422.5 | L9: 2995426 | M9: 2922449 | N9: 2871580 | O9: 2838946.5 | P9: 2816822 | Q9: 2795536 | R9: 2775937.5 | S9: 2761966 | T9: 2753300 | U9: 2751737 | V9: 2760432.5 | W9: 2769939 | X9: 2773947 | Y9: 2775799.5 | Z9: 2774316.5 | AA9: 2766751.5 | AB9: 2757961.5 | AC9: 2755477.5 | AD9: 2755528.5 | AE9: 2754886 | AF9: 2755404.5 | AG9: 2758536.5 | AH9: 2760535 | AI9: 2754246.5 | AJ9: 2741131.5 | AK9: 2727423 | AL9: 2707729 | AM9: 2677977 | AN9: 2642903.5 | AO9: 2602274.5 | AP9: 2554200 | AQ9: 2496809 | AR9: 2430668.5 | AS9: 2362166 | AT9: 2298286.5 | AU9: 2239589.5 | AV9: 2187226.5 | AW9: 2141314 | AX9: 2100061.5 | AY9: 2064486.5 | AZ9: 2035125 | BA9: 2013672.5 | BB9: 2001048.5 | BC9: 1994937 | BD9: 1990267 | BE9: 1986293.5 | BF9: 1983538 | BG9: 1981538.5 | BH9: 1980096.5 | BI9: 1978681.5 | BJ9: 1977210 | BK9: 1976359 | BL9: 1975753.5 | BM9: 1974137.5 | BN9: 1971451.5 | BO9: 1967099 | BP9: 1961298 | BQ9: 1953760.5 | BR9: 1944249.5 | BS9: 1933266.5 | BT9: 1920316 | BU9: 1904821 | BV9: 1887139.5 | BW9: 1867254 | BX9: 1845489 | BY9: 1822679 | BZ9: 1798666.5 | CA9: 1774147.5 | CB9: 1749840.5 | CC9: 1725773.5 | CD9: 1702110 | CE9: 1679756 | CF9: 1659350 | CG9: 1641561.5 | CH9: 1626279 | CI9: 1612814 | CJ9: 1601333.5 | CK9: 1592026 | CL9: 1584391.5 | CM9: 1578255 | CN9: 1573536.5 | CO9: 1569998.5 | CP9: 1567205 | CQ9: 1564472 | CR9: 1561947 | CS9: 1559699 | CT9: 1557140 | CU9: 1554258 | CV9: 1551482.5 | CW9: 1547872 | CX9: 1543311 | CY9: 1537729.5 | CZ9: 1531372.5 | DA9: 1524559 | DB9: 1516388.5 | DC9: 1507136.5 | DD9: 1497526.5 | DE9: 1487382.5 | DF9: 1475997 | DG9: 1464210.5 | DH9: 1452368 | DI9: 1440185.5 | DJ9: 1427779 | DK9: 1415234
A10: ='Population Definitions'!$B$10 -> 20-29M | C10: Number | E10: 4598554 | F10: 4640979.5 | G10: 4668951 | H10: 4655115 | I10: 4613906 | J10: 4549468 | K10: 4469332.5 | L10: 4376295 | M10: 4275504 | N10: 4159638.5 | O10: 4038310 | P10: 3918373.5 | Q10: 3798404.5 | R10: 3709091.5 | S10: 3632571.5 | T10: 3525360.5 | U10: 3406139 | V10: 3327515 | W10: 3294212.5 | X10: 3268503 | Y10: 3251437.5 | Z10: 3245811 | AA10: 3244687.5 | AB10: 3238288.5 | AC10: 3215624.5 | AD10: 3189332.5 | AE10: 3177929 | AF10: 3181356 | AG10: 3182419.5 | AH10: 3167113.5 | AI10: 3145025.5 | AJ10: 3124129.5 | AK10: 3100079 | AL10: 3081662.5 | AM10: 3072938 | AN10: 3066321.5 | AO10: 3058480.5 | AP10: 3049213.5 | AQ10: 3036916.5 | AR10: 3023116 | AS10: 3007331 | AT10: 2989406.5 | AU10: 2972397.5 | AV10: 2949413.5 | AW10: 2916860.5 | AX10: 2878166.5 | AY10: 2832408 | AZ10: 2779612.5 | BA10: 2718616.5 | BB10: 2648082 | BC10: 2574243.5 | BD10: 2506013 | BE10: 2443827.5 | BF10: 2388538.5 | BG10: 2339946.5 | BH10: 2296415 | BI10: 2259464.5 | BJ10: 2228872.5 | BK10: 2206150.5 | BL10: 2193396 | BM10: 2187514 | BN10: 2182485 | BO10: 2178214.5 | BP10: 2175238.5 | BQ10: 2173091 | BR10: 2171585.5 | BS10: 2170117.5 | BT10: 2168583.5 | BU10: 2167710 | BV10: 2167112.5 | BW10: 2165472 | BX10: 2162704 | BY10: 2158154.5 | BZ10: 2152067.5 | CA10: 2144147.5 | CB10: 2134124.5 | CC10: 2122541.5 | CD10: 2108903 | CE10: 2092605 | CF10: 2074012 | CG10: 2053057.5 | CH10: 2030113.5 | CI10: 2006074 | CJ10: 1980757 | CK10: 1954894 | CL10: 1929260 | CM10: 1903899.5 | CN10: 1878962.5 | CO10: 1855380.5 | CP10: 1833831 | CQ10: 1815079 | CR10: 1798980 | CS10: 1784795.5 | CT10: 1772728 | CU10: 1762950 | CV10: 1754933 | CW10: 1748496.5 | CX10: 1743566 | CY10: 1739894.5 | CZ10: 1737007 | DA10: 1734156.5 | DB10: 1731504 | DC10: 1729118 | DD10: 1726383 | DE10: 1723335.5 | DF10: 1720405 | DG10: 1716565 | DH10: 1711720 | DI10: 1705802 | DJ10: 1699075 | DK10: 1691893
A11: ='Population Definitions'!$B$11 -> 20-29F | C11: Number | E11: 4498077.5 | F11: 4536499.5 | G11: 4558292.5 | H11: 4538268.5 | I11: 4495936.5 | J11: 4433616 | K11: 4356699 | L11: 4269351 | M11: 4176599.5 | N11: 4067906.5 | O11: 3950844.5 | P11: 3833431.5 | Q11: 3718140 | R11: 3625766.5 | S11: 3538114.5 | T11: 3434591 | U11: 3330967.5 | V11: 3263271 | W11: 3233265 | X11: 3207043.5 | Y11: 3188721 | Z11: 3177548 | AA11: 3164569.5 | AB11: 3146656.5 | AC11: 3115185.5 | AD11: 3073746 | AE11: 3036232.5 | AF11: 3006553 | AG11: 2975427 | AH11: 2944072.5 | AI11: 2915260 | AJ11: 2886213 | AK11: 2858975.5 | AL11: 2840741.5 | AM11: 2834707 | AN11: 2833914.5 | AO11: 2834438.5 | AP11: 2836259.5 | AQ11: 2839402.5 | AR11: 2841328 | AS11: 2836914.5 | AT11: 2826815.5 | AU11: 2814527.5 | AV11: 2794910.5 | AW11: 2765243.5 | AX11: 2730259.5 | AY11: 2689721 | AZ11: 2641743 | BA11: 2584454.5 | BB11: 2518421 | BC11: 2450023.5 | BD11: 2386244 | BE11: 2327643 | BF11: 2275368.5 | BG11: 2229537 | BH11: 2188358 | BI11: 2152850 | BJ11: 2123549.5 | BK11: 2102150 | BL11: 2089571 | BM11: 2083498.5 | BN11: 2078864 | BO11: 2074925 | BP11: 2072203.5 | BQ11: 2070236 | BR11: 2068824 | BS11: 2067440.5 | BT11: 2065998 | BU11: 2065174 | BV11: 2064598.5 | BW11: 2063010.5 | BX11: 2060350 | BY11: 2056025 | BZ11: 2050251.5 | CA11: 2042742 | CB11: 2033260 | CC11: 2022306 | CD11: 2009384.5 | CE11: 1993917 | CF11: 1976263 | CG11: 1956406 | CH11: 1934671 | CI11: 1911890 | CJ11: 1887905.5 | CK11: 1863413 | CL11: 1839133.5 | CM11: 1815094.5 | CN11: 1791455 | CO11: 1769126 | CP11: 1748745 | CQ11: 1730976.5 | CR11: 1715713 | CS11: 1702267.5 | CT11: 1690805.5 | CU11: 1681516 | CV11: 1673897.5 | CW11: 1667774 | CX11: 1663069.5 | CY11: 1659545.5 | CZ11: 1656764.5 | DA11: 1654044.5 | DB11: 1651532.5 | DC11: 1649297.5 | DD11: 1646751 | DE11: 1643879 | DF11: 1641114 | DG11: 1637516 | DH11: 1632966.5 | DI11: 1627396.5 | DJ11: 1621050 | DK11: 1614246
A12: ='Population Definitions'!$B$12 -> 30-39M | C12: Number | E12: 3867540 | F12: 3930703 | G12: 4011965 | H12: 4087118.5 | I12: 4176680.5 | J12: 4268086.5 | K12: 4351446 | L12: 4424076 | M12: 4484820.5 | N12: 4536234 | O12: 4571322 | P12: 4592843.5 | Q12: 4616049 | R12: 4655056.5 | S12: 4688993 | T12: 4683888 | U12: 4639508.5 | V12: 4592676.5 | W12: 4546342.5 | X12: 4463389.5 | Y12: 4359489 | Z12: 4249280.5 | AA12: 4144916 | AB12: 4048952 | AC12: 3932827 | AD12: 3810883 | AE12: 3703474 | AF12: 3610571 | AG12: 3539559.5 | AH12: 3481316 | AI12: 3431056.5 | AJ12: 3391904 | AK12: 3358874.5 | AL12: 3329242.5 | AM12: 3300088 | AN12: 3274762 | AO12: 3257875 | AP12: 3247603.5 | AQ12: 3236384.5 | AR12: 3224652 | AS12: 3213024.5 | AT12: 3198218.5 | AU12: 3177430 | AV12: 3159319.5 | AW12: 3150850.5 | AX12: 3144472.5 | AY12: 3136867.5 | AZ12: 3127839.5 | BA12: 3115791.5 | BB12: 3102241 | BC12: 3086703.5 | BD12: 3069023.5 | BE12: 3052244.5 | BF12: 3029498.5 | BG12: 2997205.5 | BH12: 2958784 | BI12: 2913315 | BJ12: 2860823 | BK12: 2800146 | BL12: 2729949.5 | BM12: 2656451 | BN12: 2588539 | BO12: 2526649.5 | BP12: 2471632.5 | BQ12: 2423288.5 | BR12: 2379987 | BS12: 2343242.5 | BT12: 2312837.5 | BU12: 2290278 | BV12: 2277653.5 | BW12: 2271883 | BX12: 2266962 | BY12: 2262794 | BZ12: 2259917.5 | CA12: 2257865.5 | CB12: 2256451 | CC12: 2255075 | CD12: 2253631 | CE12: 2252845 | CF12: 2252331.5 | CG12: 2250775.5 | CH12: 2248093.5 | CI12: 2243633 | CJ12: 2237635 | CK12: 2229803.5 | CL12: 2219872 | CM12: 2208380.5 | CN12: 2194836 | CO12: 2178634 | CP12: 2160137.5 | CQ12: 2139280 | CR12: 2116436 | CS12: 2092497 | CT12: 2067279 | CU12: 2041516.5 | CV12: 2015979.5 | CW12: 1990711.5 | CX12: 1965865 | CY12: 1942369 | CZ12: 1920901.5 | DA12: 1902228.5 | DB12: 1886203 | DC12: 1872085.5 | DD12: 1860082 | DE12: 1850365 | DF12: 1842405 | DG12: 1836023 | DH12: 1831144 | DI12: 1827523 | DJ12: 1824684 | DK12: 1821879
A13: ='Population Definitions'!$B$13 -> 30-39F | C13: Number | E13: 3871953.5 | F13: 3931985 | G13: 4009740 | H13: 4083112 | I13: 4169075 | J13: 4255430 | K13: 4334777 | L13: 4403484 | M13: 4460953 | N13: 4510736 | O13: 4544290.5 | P13: 4563009.5 | Q13: 4583443 | R13: 4618647.5 | S13: 4644593 | T13: 4636303.5 | U13: 4599719.5 | V13: 4566185.5 | W13: 4534166.5 | X13: 4466950.5 | Y13: 4379443 | Z13: 4278470 | AA13: 4170858.5 | AB13: 4062968.5 | AC13: 3937645.5 | AD13: 3807878.5 | AE13: 3689107.5 | AF13: 3584308 | AG13: 3500290 | AH13: 3433591.5 | AI13: 3377281 | AJ13: 3326831 | AK13: 3280629.5 | AL13: 3237795.5 | AM13: 3194598.5 | AN13: 3151709.5 | AO13: 3114963 | AP13: 3084123 | AQ13: 3050766.5 | AR13: 3018194 | AS13: 2991952 | AT13: 2968801 | AU13: 2944638 | AV13: 2926551 | AW13: 2920637 | AX13: 2919950.5 | AY13: 2920574.5 | AZ13: 2922490.5 | BA13: 2925726 | BB13: 2927744 | BC13: 2923429 | BD13: 2913434.5 | BE13: 2901248 | BF13: 2881739 | BG13: 2852191 | BH13: 2817329.5 | BI13: 2776916 | BJ13: 2729070 | BK13: 2671925 | BL13: 2606041 | BM13: 2537792.5 | BN13: 2474154 | BO13: 2415683.5 | BP13: 2363530 | BQ13: 2317810.5 | BR13: 2276736 | BS13: 2241324.5 | BT13: 2212112 | BU13: 2190789.5 | BV13: 2178274.5 | BW13: 2172256 | BX13: 2167673 | BY13: 2163784 | BZ13: 2161112 | CA13: 2159192 | CB13: 2157825 | CC13: 2156485.5 | CD13: 2155088 | CE13: 2154307.5 | CF13: 2153770 | CG13: 2152222.5 | CH13: 2149604.5 | CI13: 2145320 | CJ13: 2139588 | CK13: 2132120.5 | CL13: 2122680.5 | CM13: 2111767 | CN13: 2098886.5 | CO13: 2083462 | CP13: 2065851 | CQ13: 2046036.5 | CR13: 2024342.5 | CS13: 2001602 | CT13: 1977657 | CU13: 1953205 | CV13: 1928964 | CW13: 1904961.5 | CX13: 1881360 | CY13: 1859065.5 | CZ13: 1838716.5 | DA13: 1820979.5 | DB13: 1805746 | DC13: 1792328.5 | DD13: 1780891.5 | DE13: 1771626.5 | DF13: 1764032 | DG13: 1757931 | DH13: 1753248 | DI13: 1749745 | DJ13: 1746983.5 | DK13: 1744282
A14: ='Population Definitions'!$B$14 -> 40-49M | C14: Number | E14: 3659283.5 | F14: 3678718.5 | G14: 3708572 | H14: 3730055 | I14: 3763281.5 | J14: 3812619 | K14: 3827647 | L14: 3805998 | M14: 3787569.5 | N14: 3786941.5 | O14: 3812423 | P14: 3861279.5 | Q14: 3937378.5 | R14: 4038213.5 | S14: 4161712 | T14: 4283833 | U14: 4391895 | V14: 4495391.5 | W14: 4593716.5 | X14: 4676171.5 | Y14: 4735682 | Z14: 4776347 | AA14: 4810689 | AB14: 4832909.5 | AC14: 4822530.5 | AD14: 4786749.5 | AE14: 4735079 | AF14: 4667531.5 | AG14: 4592629 | AH14: 4500207.5 | AI14: 4395041 | AJ14: 4286279.5 | AK14: 4172720 | AL14: 4058756.5 | AM14: 3937868 | AN14: 3818832 | AO14: 3711866 | AP14: 3619315 | AQ14: 3545288.5 | AR14: 3488044.5 | AS14: 3444300 | AT14: 3409466 | AU14: 3379034.5 | AV14: 3350111 | AW14: 3321613.5 | AX14: 3296890 | AY14: 3280516.5 | AZ14: 3270696.5 | BA14: 3259953 | BB14: 3248700.5 | BC14: 3237544.5 | BD14: 3223215.5 | BE14: 3202916.5 | BF14: 3185262.5 | BG14: 3177167.5 | BH14: 3171139 | BI14: 3163892.5 | BJ14: 3155237 | BK14: 3143584.5 | BL14: 3130437.5 | BM14: 3115305 | BN14: 3098016 | BO14: 3081590.5 | BP14: 3059208.5 | BQ14: 3027318.5 | BR14: 2989323 | BS14: 2944300 | BT14: 2892286 | BU14: 2832121.5 | BV14: 2762471 | BW14: 2689529 | BX14: 2622145.5 | BY14: 2560754 | BZ14: 2506198 | CA14: 2458280 | CB14: 2415378 | CC14: 2379002 | CD14: 2348932.5 | CE14: 2326662.5 | CF14: 2314268 | CG14: 2308688 | CH14: 2303954 | CI14: 2299968.5 | CJ14: 2297265 | CK14: 2295379 | CL14: 2294125 | CM14: 2292906.5 | CN14: 2291619 | CO14: 2290983 | CP14: 2290614 | CQ14: 2289204 | CR14: 2286669 | CS14: 2282358 | CT14: 2276512.5 | CU14: 2268838 | CV14: 2259065.5 | CW14: 2247732 | CX14: 2234346.5 | CY14: 2218307 | CZ14: 2199979 | DA14: 2179294.5 | DB14: 2156620.5 | DC14: 2132850 | DD14: 2107803 | DE14: 2082208.5 | DF14: 2056835.5 | DG14: 2031728 | DH14: 2007039 | DI14: 1983697 | DJ14: 1962375 | DK14: 1943836.5
A15: ='Population Definitions'!$B$15 -> 40-49F | C15: Number | E15: 3722426 | F15: 3736818.5 | G15: 3763588.5 | H15: 3782650 | I15: 3816107.5 | J15: 3868175 | K15: 3884513.5 | L15: 3863816 | M15: 3845870 | N15: 3844590 | O15: 3868885 | P15: 3914810.5 | Q15: 3984882.5 | R15: 4088622.5 | S15: 4216822 | T15: 4332832.5 | U15: 4434267 | V15: 4541713 | W15: 4651918.5 | X15: 4745314.5 | Y15: 4818041.5 | Z15: 4870400 | AA15: 4904455.5 | AB15: 4919540 | AC15: 4905240.5 | AD15: 4866158 | AE15: 4809064.5 | AF15: 4733670 | AG15: 4647605 | AH15: 4547027.5 | AI15: 4434962.5 | AJ15: 4316891.5 | AK15: 4196069 | AL15: 4074034.5 | AM15: 3944429 | AN15: 3817878.5 | AO15: 3703220.5 | AP15: 3602302 | AQ15: 3519655 | AR15: 3453336.5 | AS15: 3399561.5 | AT15: 3352739 | AU15: 3308677 | AV15: 3266342 | AW15: 3223613.5 | AX15: 3181174.5 | AY15: 3144834.5 | AZ15: 3114362 | BA15: 3081388.5 | BB15: 3049200 | BC15: 3023317 | BD15: 3000511 | BE15: 2976693 | BF15: 2958922 | BG15: 2953263 | BH15: 2952799 | BI15: 2953634 | BJ15: 2955756.5 | BK15: 2959191.5 | BL15: 2961406 | BM15: 2957303.5 | BN15: 2947532 | BO15: 2935558 | BP15: 2916267 | BQ15: 2886961 | BR15: 2852351 | BS15: 2812199 | BT15: 2764631 | BU15: 2707781.5 | BV15: 2642210 | BW15: 2574274 | BX15: 2510934 | BY15: 2452747.5 | BZ15: 2400857 | CA15: 2355381.5 | CB15: 2314538 | CC15: 2279340 | CD15: 2250322.5 | CE15: 2229168.5 | CF15: 2216793 | CG15: 2210894 | CH15: 2206427.5 | CI15: 2202654 | CJ15: 2200092 | CK15: 2198278 | CL15: 2197013 | CM15: 2195772.5 | CN15: 2194473.5 | CO15: 2193788.5 | CP15: 2193344.5 | CQ15: 2191889 | CR15: 2189361 | CS15: 2185167 | CT15: 2179526 | CU15: 2172150 | CV15: 2162798.5 | CW15: 2151973.5 | CX15: 2139183 | CY15: 2123849 | CZ15: 2106328.5 | DA15: 2086605 | DB15: 2065002 | DC15: 2042351 | DD15: 2018496 | DE15: 1994128.5 | DF15: 1969970 | DG15: 1946048 | DH15: 1922522.5 | DI15: 1900303.5 | DJ15: 1880024.5 | DK15: 1862353.5
A16: ='Population Definitions'!$B$16 -> 50-59M | C16: Number | E16: 3425374.5 | F16: 3439667.5 | G16: 3443868 | H16: 3433849 | I16: 3416551 | J16: 3388276.5 | K16: 3401561.5 | L16: 3455398.5 | M16: 3491982 | N16: 3506435.5 | O16: 3505575.5 | P16: 3512681.5 | Q16: 3538402.5 | R16: 3575730.5 | S16: 3625546.5 | T16: 3691166.5 | U16: 3723684.5 | V16: 3723136.5 | W16: 3727357 | X16: 3747354 | Y16: 3790629.5 | Z16: 3854229 | AA16: 3937842 | AB16: 4031494.5 | AC16: 4136569 | AD16: 4242623.5 | AE16: 4339992.5 | AF16: 4428932.5 | AG16: 4511270 | AH16: 4584644 | AI16: 4638204.5 | AJ16: 4675945.5 | AK16: 4705192.5 | AL16: 4719977 | AM16: 4710763.5 | AN16: 4682100 | AO16: 4637424.5 | AP16: 4577074.5 | AQ16: 4506142.5 | AR16: 4418436.5 | AS16: 4320474.5 | AT16: 4217273.5 | AU16: 4108388 | AV16: 3998053 | AW16: 3880975 | AX16: 3765721 | AY16: 3662170 | AZ16: 3572651.5 | BA16: 3501295 | BB16: 3446341.5 | BC16: 3404543.5 | BD16: 3371429.5 | BE16: 3342597.5 | BF16: 3315183.5 | BG16: 3288079.5 | BH16: 3264643.5 | BI16: 3249381.5 | BJ16: 3240543 | BK16: 3230842.5 | BL16: 3220652 | BM16: 3210539.5 | BN16: 3197268 | BO16: 3178068 | BP16: 3161437.5 | BQ16: 3154178.5 | BR16: 3148940.5 | BS16: 3142497 | BT16: 3134679.5 | BU16: 3123921.5 | BV16: 3111686 | BW16: 3097475.5 | BX16: 3081078.5 | BY16: 3065449.5 | BZ16: 3043880.5 | CA16: 3012893.5 | CB16: 2975858 | CC16: 2931862.5 | CD16: 2880942 | CE16: 2821938.5 | CF16: 2753527 | CG16: 2681847.5 | CH16: 2615671 | CI16: 2555426.5 | CJ16: 2501930.5 | CK16: 2454986 | CL16: 2413002 | CM16: 2377469 | CN16: 2348170.5 | CO16: 2326567 | CP16: 2314704.5 | CQ16: 2309569.5 | CR16: 2305269.5 | CS16: 2301712 | CT16: 2299419 | CU16: 2297934.5 | CV16: 2297072.5 | CW16: 2296230.5 | CX16: 2295311.5 | CY16: 2295035 | CZ16: 2295017.5 | DA16: 2293960.5 | DB16: 2291777 | DC16: 2287823.5 | DD16: 2282343 | DE16: 2275036 | DF16: 2265635 | DG16: 2254674 | DH16: 2241667 | DI16: 2226017.5 | DJ16: 2208081 | DK16: 2187788.5
A17: ='Population Definitions'!$B$17 -> 50-59F | C17: Number | E17: 3626562 | F17: 3631252 | G17: 3626694.5 | H17: 3611768.5 | I17: 3589408 | J17: 3554666 | K17: 3562536 | L17: 3612310.5 | M17: 3645883 | N17: 3657676 | O17: 3653233 | P17: 3657146.5 | Q17: 3678172.5 | R17: 3713885.5 | S17: 3769436.5 | T17: 3839801 | U17: 3872700.5 | V17: 3876080 | W17: 3890205 | X17: 3920824 | Y17: 3977637.5 | Z17: 4054199 | AA17: 4145760 | AB17: 4245411.5 | AC17: 4351334.5 | AD17: 4452496 | AE17: 4543397 | AF17: 4625784.5 | AG17: 4700146.5 | AH17: 4766573 | AI17: 4813803 | AJ17: 4842981.5 | AK17: 4861373 | AL17: 4864450 | AM17: 4845551 | AN17: 4808313 | AO17: 4755354 | AP17: 4684679 | AQ17: 4601783 | AR17: 4503037 | AS17: 4393814 | AT17: 4279579 | AU17: 4161911.5 | AV17: 4042290.5 | AW17: 3915210.5 | AX17: 3791144.5 | AY17: 3678750.5 | AZ17: 3579856 | BA17: 3498992 | BB17: 3434224 | BC17: 3381788.5 | BD17: 3336188.5 | BE17: 3293310.5 | BF17: 3252099 | BG17: 3210425 | BH17: 3168996.5 | BI17: 3133571 | BJ17: 3103944 | BK17: 3071857 | BL17: 3040551.5 | BM17: 3015496.5 | BN17: 2993489.5 | BO17: 2970452 | BP17: 2953383 | BQ17: 2948305 | BR17: 2948356 | BS17: 2949683 | BT17: 2952282.5 | BU17: 2956175 | BV17: 2958848.5 | BW17: 2955240.5 | BX17: 2945977 | BY17: 2934491 | BZ17: 2915716 | CA17: 2886979 | CB17: 2852955 | CC17: 2813405 | CD17: 2766470.5 | CE17: 2710294 | CF17: 2645423.5 | CG17: 2578185 | CH17: 2515512 | CI17: 2457962 | CJ17: 2406668.5 | CK17: 2361741.5 | CL17: 2321410 | CM17: 2286688.5 | CN17: 2258111 | CO17: 2237344.5 | CP17: 2225296 | CQ17: 2219679 | CR17: 2215480.5 | CS17: 2211968 | CT17: 2209658.5 | CU17: 2208091 | CV17: 2207063 | CW17: 2206053.5 | CX17: 2204980.5 | CY17: 2204514.5 | CZ17: 2204284 | DA17: 2203042.5 | DB17: 2200728.5 | DC17: 2196748.5 | DD17: 2191321 | DE17: 2184154.5 | DF17: 2175011.5 | DG17: 2164393.5 | DH17: 2151809.5 | DI17: 2136681 | DJ17: 2119361.5 | DK17: 2099837
A18: ='Population Definitions'!$B$18 -> 60-69M | C18: Number | E18: 2856853.5 | F18: 2896586 | G18: 2921253 | H18: 2931216.5 | I18: 2942449.5 | J18: 2956229.5 | K18: 2965324 | L18: 2972403 | M18: 2994920.5 | N18: 3032987 | O18: 3066053.5 | P18: 3078926.5 | Q18: 3086110.5 | R18: 3094670.5 | S18: 3095818 | T18: 3085508.5 | U18: 3114457.5 | V18: 3182859 | W18: 3236505.5 | X18: 3269889.5 | Y18: 3286949 | Z18: 3308612.5 | AA18: 3337410.5 | AB18: 3367596 | AC18: 3408612 | AD18: 3464401.5 | AE18: 3491446 | AF18: 3488231.5 | AG18: 3489472 | AH18: 3508888.5 | AI18: 3549277 | AJ18: 3605901 | AK18: 3683961.5 | AL18: 3775243.5 | AM18: 3880721 | AN18: 3989605.5 | AO18: 4090115 | AP18: 4181475.5 | AQ18: 4264373 | AR18: 4338332.5 | AS18: 4395125 | AT18: 4437434 | AU18: 4470007 | AV18: 4487240 | AW18: 4482203.5 | AX18: 4458845 | AY18: 4419807 | AZ18: 4365501 | BA18: 4300854 | BB18: 4220090.5 | BC18: 4129342 | BD18: 4033489 | BE18: 3932303.5 | BF18: 3829759 | BG18: 3720865 | BH18: 3613755.5 | BI18: 3517606 | BJ18: 3434668.5 | BK18: 3369100 | BL18: 3319110.5 | BM18: 3281543 | BN18: 3252181.5 | BO18: 3226875.5 | BP18: 3202807.5 | BQ18: 3178797.5 | BR18: 3158221 | BS18: 3145420.5 | BT18: 3138778 | BU18: 3131399.5 | BV18: 3123563.5 | BW18: 3115782 | BX18: 3104879.5 | BY18: 3088122 | BZ18: 3073772 | CA18: 3068409.5 | CB18: 3064981 | CC18: 3060405 | CD18: 3054508 | CE18: 3045777.5 | CF18: 3035610.5 | CG18: 3023470.5 | CH18: 3009096.5 | CI18: 2995311.5 | CJ18: 2975618.5 | CK18: 2946692.5 | CL18: 2911829.5 | CM18: 2870147 | CN18: 2821690 | CO18: 2765287.5 | CP18: 2699628 | CQ18: 2630750 | CR18: 2567251 | CS18: 2509543.5 | CT18: 2458401 | CU18: 2413640.5 | CV18: 2373723 | CW18: 2340066.5 | CX18: 2312472 | CY18: 2292364.5 | CZ18: 2281726 | DA18: 2277632.5 | DB18: 2274339.5 | DC18: 2271769 | DD18: 2270434.5 | DE18: 2269875 | DF18: 2269913 | DG18: 2269956 | DH18: 2269911.5 | DI18: 2270490.5 | DJ18: 2271300 | DK18: 2271070
A19: ='Population Definitions'!$B$19 -> 60-69F | C19: Number | E19: 3383656 | F19: 3401176 | G19: 3404622.5 | H19: 3398463.5 | I19: 3396822.5 | J19: 3399025.5 | K19: 3396339.5 | L19: 3392327.5 | M19: 3404872 | N19: 3433560 | O19: 3455935.5 | P19: 3457080 | Q19: 3451975.5 | R19: 3449043.5 | S19: 3438584.5 | T19: 3414621.5 | U19: 3431932 | V19: 3491415.5 | W19: 3538023.5 | X19: 3565989 | Y19: 3577869 | Z19: 3596676 | AA19: 3626023 | AB19: 3657141 | AC19: 3701540 | AD19: 3765022 | AE19: 3796602 | AF19: 3794707 | AG19: 3796990 | AH19: 3817136.5 | AI19: 3861485.5 | AJ19: 3924297 | AK19: 4005812.5 | AL19: 4098023.5 | AM19: 4200657.5 | AN19: 4302674 | AO19: 4395968 | AP19: 4481187.5 | AQ19: 4557647.5 | AR19: 4623827 | AS19: 4671710.5 | AT19: 4703832.5 | AU19: 4724743.5 | AV19: 4730001 | AW19: 4714173.5 | AX19: 4680583.5 | AY19: 4631473.5 | AZ19: 4564928 | BA19: 4486308 | BB19: 4392146 | BC19: 4287630.5 | BD19: 4178168.5 | BE19: 4065428 | BF19: 3950766 | BG19: 3828828 | BH19: 3709801.5 | BI19: 3601993.5 | BJ19: 3507229.5 | BK19: 3430039 | BL19: 3368465 | BM19: 3318809 | BN19: 3275767.5 | BO19: 3235327.5 | BP19: 3196404 | BQ19: 3156894.5 | BR19: 3117554.5 | BS19: 3084047.5 | BT19: 3056179 | BU19: 3025903.5 | BV19: 2996411 | BW19: 2973056.5 | BX19: 2952670 | BY19: 2931227.5 | BZ19: 2915624.5 | CA19: 2911778 | CB19: 2912929.5 | CC19: 2915299.5 | CD19: 2918910.5 | CE19: 2923778 | CF19: 2927417.5 | CG19: 2924838 | CH19: 2916640 | CI19: 2906201 | CJ19: 2888521.5 | CK19: 2860965 | CL19: 2828148.5 | CM19: 2789836 | CN19: 2744207.5 | CO19: 2689404 | CP19: 2625957 | CQ19: 2560123 | CR19: 2498776 | CS19: 2442480.5 | CT19: 2392353 | CU19: 2348507 | CV19: 2309187 | CW19: 2275401 | CX19: 2247679.5 | CY19: 2227672 | CZ19: 2216279 | DA19: 2211245 | DB19: 2207610 | DC19: 2204646 | DD19: 2202863 | DE19: 2201801 | DF19: 2201264.5 | DG19: 2200734.5 | DH19: 2200131.5 | DI19: 2200122.5 | DJ19: 2200329.5 | DK19: 2199517
A20: ='Population Definitions'!$B$20 -> 70-79M | C20: Number | E20: 1494732.5 | F20: 1538941 | G20: 1578747.5 | H20: 1615150 | I20: 1656844 | J20: 1703300 | K20: 1766226 | L20: 1853011 | M20: 1949670 | N20: 2033375.5 | O20: 2090579.5 | P20: 2127712.5 | Q20: 2159875.5 | R20: 2192757 | S20: 2227460 | T20: 2264306 | U20: 2296778 | V20: 2327471 | W20: 2372277 | X20: 2429841.5 | Y20: 2482379.5 | Z20: 2517425 | AA20: 2538115.5 | AB20: 2551650.5 | AC20: 2558434 | AD20: 2552550.5 | AE20: 2580190.5 | AF20: 2641719.5 | AG20: 2689485.5 | AH20: 2723830 | AI20: 2738444 | AJ20: 2750637 | AK20: 2779640.5 | AL20: 2818990.5 | AM20: 2866940 | AN20: 2926589.5 | AO20: 2964081.5 | AP20: 2977556.5 | AQ20: 2993449.5 | AR20: 3022905.5 | AS20: 3072214.5 | AT20: 3137599 | AU20: 3217155 | AV20: 3304955 | AW20: 3406092.5 | AX20: 3510513 | AY20: 3606900 | AZ20: 3694729.5 | BA20: 3774460.5 | BB20: 3846256 | BC20: 3902839 | BD20: 3946463 | BE20: 3981546 | BF20: 4003089.5 | BG20: 4005862.5 | BH20: 3992715.5 | BI20: 3964776.5 | BJ20: 3922448.5 | BK20: 3870301 | BL20: 3803398 | BM20: 3727098 | BN20: 3645990.5 | BO20: 3560375 | BP20: 3473633.5 | BQ20: 3381308.5 | BR20: 3290695 | BS20: 3209490.5 | BT20: 3139878 | BU20: 3086028 | BV20: 3046087.5 | BW20: 3017148 | BX20: 2995470.5 | BY20: 2977357.5 | BZ20: 2960106.5 | CA20: 2942454 | CB20: 2927812.5 | CC20: 2920209.5 | CD20: 2918151.5 | CE20: 2915592.5 | CF20: 2912684 | CG20: 2909746.5 | CH20: 2903799.5 | CI20: 2892195.5 | CJ20: 2882643 | CK20: 2881260 | CL20: 2881598.5 | CM20: 2880904.5 | CN20: 2879035 | CO20: 2874536 | CP20: 2868657.5 | CQ20: 2860846 | CR20: 2850711.5 | CS20: 2840804 | CT20: 2825071 | CU20: 2800524 | CV20: 2770303.5 | CW20: 2733451 | CX20: 2690077 | CY20: 2639076 | CZ20: 2579156.5 | DA20: 2516096 | DB20: 2458111.5 | DC20: 2405623 | DD20: 2359345.5 | DE20: 2319086.5 | DF20: 2283418 | DG20: 2253671 | DH20: 2229673 | DI20: 2212750.5 | DJ20: 2204729.5 | DK20: 2202874
A21: ='Population Definitions'!$B$21 -> 70-79F | C21: Number | E21: 2143711.5 | F21: 2201304 | G21: 2257429.5 | H21: 2307484.5 | I21: 2356668.5 | J21: 2410069 | K21: 2489365.5 | L21: 2605714 | M21: 2737644.5 | N21: 2849841 | O21: 2912394 | P21: 2936154 | Q21: 2950126 | R21: 2961218 | S21: 2974961.5 | T21: 2992878.5 | U21: 3005151.5 | V21: 3016199.5 | W21: 3042596.5 | X21: 3082896.5 | Y21: 3117136 | Z21: 3132407 | AA21: 3134937.5 | AB21: 3132047.5 | AC21: 3121644.5 | AD21: 3096555.5 | AE21: 3109791 | AF21: 3162189.5 | AG21: 3200429 | AH21: 3224465.5 | AI21: 3232216 | AJ21: 3242714.5 | AK21: 3270104 | AL21: 3306519.5 | AM21: 3356088 | AN21: 3423112 | AO21: 3462427.5 | AP21: 3472476.5 | AQ21: 3485616 | AR21: 3513228 | AS21: 3562881 | AT21: 3630549 | AU21: 3713524.5 | AV21: 3804704 | AW21: 3906158.5 | AX21: 4007322.5 | AY21: 4100012.5 | AZ21: 4184890.5 | BA21: 4261192.5 | BB21: 4327836 | BC21: 4377354 | BD21: 4412125 | BE21: 4436557 | BF21: 4446392 | BG21: 4437007 | BH21: 4411059.5 | BI21: 4369923.5 | BJ21: 4311988.5 | BK21: 4242343 | BL21: 4157729 | BM21: 4062993.5 | BN21: 3963464.5 | BO21: 3860842.5 | BP21: 3756265 | BQ21: 3644865.5 | BR21: 3536238 | BS21: 3437963.5 | BT21: 3351737 | BU21: 3282109.5 | BV21: 3227183.5 | BW21: 3183316 | BX21: 3145552 | BY21: 3110180 | BZ21: 3076076.5 | CA21: 3041136.5 | CB21: 3006186 | CC21: 2976659.5 | CD21: 2952434 | CE21: 2925925 | CF21: 2900173 | CG21: 2880331.5 | CH21: 2863338 | CI21: 2845276.5 | CJ21: 2832801 | CK21: 2831569.5 | CL21: 2835055 | CM21: 2839655.5 | CN21: 2845462 | CO21: 2852454.5 | CP21: 2858199.5 | CQ21: 2857829 | CR21: 2851866 | CS21: 2843577.5 | CT21: 2828124 | CU21: 2802972.5 | CV21: 2772586 | CW21: 2736741.5 | CX21: 2693675 | CY21: 2641551 | CZ21: 2580888 | DA21: 2517816.5 | DB21: 2459101 | DC21: 2405296.5 | DD21: 2357481.5 | DE21: 2315757.5 | DF21: 2278438.5 | DG21: 2246510.5 | DH21: 2220507.5 | DI21: 2202035 | DJ21: 2191949.5 | DK21: 2188071.5
A22: ='Population Definitions'!$B$22 -> 80-89M | C22: Number | E22: 564556.5 | F22: 595698 | G22: 627773.5 | H22: 662519.5 | I22: 692353.5 | J22: 715246 | K22: 720563 | L22: 702057 | M22: 669783.5 | N22: 645490 | O22: 657671.5 | P22: 695120 | Q22: 731456 | R22: 766251.5 | S22: 804663 | T22: 845691 | U22: 890028 | V22: 941399.5 | W22: 993375.5 | X22: 1040419.5 | Y22: 1083906.5 | Z22: 1121515.5 | AA22: 1151173 | AB22: 1181343 | AC22: 1216787 | AD22: 1251866 | AE22: 1283529 | AF22: 1315714 | AG22: 1358745.5 | AH22: 1411727 | AI22: 1453546.5 | AJ22: 1476515 | AK22: 1495216 | AL22: 1514957 | AM22: 1530775 | AN22: 1539650 | AO22: 1574026.5 | AP22: 1634552.5 | AQ22: 1689080 | AR22: 1733965 | AS22: 1769305 | AT22: 1801945 | AU22: 1833275.5 | AV22: 1865000.5 | AW22: 1902044.5 | AX22: 1945432 | AY22: 1978952.5 | AZ22: 2003268.5 | BA22: 2030359.5 | BB22: 2067125.5 | BC22: 2117019 | BD22: 2176814 | BE22: 2244957 | BF22: 2318770.5 | BG22: 2404151.5 | BH22: 2492650.5 | BI22: 2573906 | BJ22: 2647597.5 | BK22: 2713689.5 | BL22: 2773834 | BM22: 2822890.5 | BN22: 2862282 | BO22: 2896064.5 | BP22: 2920537 | BQ22: 2934362.5 | BR22: 2937921.5 | BS22: 2928559 | BT22: 2906948 | BU22: 2876840 | BV22: 2835357 | BW22: 2786252.5 | BX22: 2733514.5 | BY22: 2678698.5 | BZ22: 2623893.5 | CA22: 2566265 | CB22: 2511032 | CC22: 2462122.5 | CD22: 2421055 | CE22: 2392291 | CF22: 2373740 | CG22: 2362703.5 | CH22: 2356847.5 | CI22: 2353678.5 | CJ22: 2350520.5 | CK22: 2345670.5 | CL22: 2342716.5 | CM22: 2344922.5 | CN22: 2351301.5 | CO22: 2358122 | CP22: 2365015 | CQ22: 2371924 | CR22: 2376257 | CS22: 2375513 | CT22: 2375982.5 | CU22: 2382526.5 | CV22: 2390390.5 | CW22: 2397425.5 | CX22: 2403793 | CY22: 2408555.5 | CZ22: 2412462 | DA22: 2414647.5 | DB22: 2414055 | DC22: 2412366.5 | DD22: 2405011 | DE22: 2389988 | DF22: 2370026 | DG22: 2344228.5 | DH22: 2312932 | DI22: 2275115.5 | DJ22: 2229453 | DK22: 2181120.5
A23: ='Population Definitions'!$B$23 -> 80-89F | C23: Number | E23: 1124661.5 | F23: 1178456.5 | G23: 1233093.5 | H23: 1291915 | I23: 1345088.5 | J23: 1388560.5 | K23: 1402774 | L23: 1375006.5 | M23: 1322704.5 | N23: 1282804.5 | O23: 1302841 | P23: 1365602.5 | Q23: 1427448.5 | R23: 1483116.5 | S23: 1539937 | T23: 1600452 | U23: 1669572.5 | V23: 1752296.5 | W23: 1835349.5 | X23: 1904706.5 | Y23: 1954425.5 | Z23: 1986634 | AA23: 2005663 | AB23: 2022990.5 | AC23: 2046083.5 | AD23: 2066752 | AE23: 2081800 | AF23: 2097384 | AG23: 2125766.5 | AH23: 2167611.5 | AI23: 2198030.5 | AJ23: 2209737 | AK23: 2217777.5 | AL23: 2226103.5 | AM23: 2228881.5 | AN23: 2221611.5 | AO23: 2246907 | AP23: 2305367 | AQ23: 2356642.5 | AR23: 2396851 | AS23: 2426145.5 | AT23: 2455850 | AU23: 2488615.5 | AV23: 2523118.5 | AW23: 2566798 | AX23: 2621670 | AY23: 2660233.5 | AZ23: 2683252 | BA23: 2709747.5 | BB23: 2747835 | BC23: 2802429.5 | BD23: 2870146.5 | BE23: 2948679.5 | BF23: 3033479.5 | BG23: 3128312 | BH23: 3223687.5 | BI23: 3310740 | BJ23: 3390616 | BK23: 3462267.5 | BL23: 3525597 | BM23: 3574873 | BN23: 3612215 | BO23: 3641196.5 | BP23: 3658282.5 | BQ23: 3662204.5 | BR23: 3653464.5 | BS23: 3630558 | BT23: 3592363.5 | BU23: 3543296 | BV23: 3481352 | BW23: 3410056.5 | BX23: 3334554.5 | BY23: 3257357.5 | BZ23: 3178997.5 | CA23: 3096107.5 | CB23: 3016290.5 | CC23: 2944301 | CD23: 2881610.5 | CE23: 2833010 | CF23: 2796335.5 | CG23: 2768047 | CH23: 2744534 | CI23: 2723196.5 | CJ23: 2702409.5 | CK23: 2679704.5 | CL23: 2656442.5 | CM23: 2637372.5 | CN23: 2622678 | CO23: 2606462 | CP23: 2591292.5 | CQ23: 2581504.5 | CR23: 2574240 | CS23: 2565978 | CT23: 2562579.5 | CU23: 2568788.5 | CV23: 2578666 | CW23: 2589300.5 | CX23: 2601001.5 | CY23: 2613698.5 | CZ23: 2625241 | DA23: 2631218 | DB23: 2631782.5 | DC23: 2629574 | DD23: 2620322.5 | DE23: 2601929 | DF23: 2578487 | DG23: 2549747.5 | DH23: 2514312.5 | DI23: 2470427 | DJ23: 2418353 | DK23: 2363885
A24: ='Population Definitions'!$B$24 -> 90+M | C24: Number | E24: 46409.5 | F24: 48864 | G24: 51719.5 | H24: 54679 | I24: 57428 | J24: 61147.5 | K24: 65802 | L24: 70439.5 | M24: 75485 | N24: 81766.5 | O24: 89065.5 | P24: 96220.5 | Q24: 103759.5 | R24: 111086 | S24: 117942 | T24: 123632.5 | U24: 124293.5 | V24: 119139 | W24: 111044.5 | X24: 107026 | Y24: 114622 | Z24: 129028.5 | AA24: 141757.5 | AB24: 154024 | AC24: 166521.5 | AD24: 176535.5 | AE24: 185332.5 | AF24: 193744 | AG24: 201763.5 | AH24: 211014 | AI24: 223694.5 | AJ24: 238750 | AK24: 251492 | AL24: 263093 | AM24: 275502.5 | AN24: 288684.5 | AO24: 300556 | AP24: 312794 | AQ24: 329663 | AR24: 349137.5 | AS24: 367975.5 | AT24: 380415 | AU24: 386603.5 | AV24: 392183 | AW24: 397514 | AX24: 401300.5 | AY24: 416821 | AZ24: 444061 | BA24: 469795 | BB24: 491491 | BC24: 507971 | BD24: 520114.5 | BE24: 529026.5 | BF24: 538400.5 | BG24: 550757.5 | BH24: 565883 | BI24: 582304.5 | BJ24: 600207.5 | BK24: 618860.5 | BL24: 640314 | BM24: 665410 | BN24: 692696 | BO24: 721847 | BP24: 753164.5 | BQ24: 790673.5 | BR24: 829521.5 | BS24: 863552.5 | BT24: 893281 | BU24: 918786.5 | BV24: 942607 | BW24: 962962 | BX24: 980363 | BY24: 997209 | BZ24: 1011905.5 | CA24: 1026303.5 | CB24: 1037991 | CC24: 1042299.5 | CD24: 1040028.5 | CE24: 1033773 | CF24: 1023561 | CG24: 1010453 | CH24: 997203 | CI24: 985871.5 | CJ24: 976174.5 | CK24: 967051 | CL24: 959659.5 | CM24: 953120.5 | CN24: 948420 | CO24: 949219.5 | CP24: 953438 | CQ24: 959617 | CR24: 967598 | CS24: 976802 | CT24: 985163 | CU24: 991029.5 | CV24: 997586.5 | CW24: 1006129.5 | CX24: 1016901 | CY24: 1030212.5 | CZ24: 1044480.5 | DA24: 1058733 | DB24: 1071226 | DC24: 1080284.5 | DD24: 1089271 | DE24: 1100387.5 | DF24: 1112559 | DG24: 1125474 | DH24: 1139455.5 | DI24: 1154027.5 | DJ24: 1168460 | DK24: 1181492
A25: ='Population Definitions'!$B$25 -> 90+F | C25: Number | E25: 140099.5 | F25: 148091 | G25: 157749.5 | H25: 168054 | I25: 178844.5 | J25: 191621.5 | K25: 206194 | L25: 220890.5 | M25: 236317 | N25: 253446.5 | O25: 272676 | P25: 292672.5 | Q25: 312899.5 | R25: 331451 | S25: 350256.5 | T25: 366994.5 | U25: 370383.5 | V25: 358659 | W25: 339109.5 | X25: 328701 | Y25: 347102 | Z25: 383369 | AA25: 415559 | AB25: 446279 | AC25: 476947.5 | AD25: 499782.5 | AE25: 519268 | AF25: 537308 | AG25: 551441 | AH25: 566497.5 | AI25: 582716.5 | AJ25: 598618 | AK25: 612101.5 | AL25: 624602 | AM25: 638014 | AN25: 652942 | AO25: 666063.5 | AP25: 679723 | AQ25: 700860 | AR25: 726665 | AS25: 752406.5 | AT25: 768678 | AU25: 774509 | AV25: 779077 | AW25: 782386 | AX25: 782367 | AY25: 801269.5 | AZ25: 839305 | BA25: 876290.5 | BB25: 908302.5 | BC25: 932899 | BD25: 951627 | BE25: 965905 | BF25: 980528.5 | BG25: 999936.5 | BH25: 1023970.5 | BI25: 1049391.5 | BJ25: 1077094 | BK25: 1106306.5 | BL25: 1139307 | BM25: 1177516.5 | BN25: 1219611 | BO25: 1264388.5 | BP25: 1311827 | BQ25: 1367233.5 | BR25: 1423890 | BS25: 1474075.5 | BT25: 1519219 | BU25: 1558599 | BV25: 1594594 | BW25: 1624706.5 | BX25: 1650086 | BY25: 1673271.5 | BZ25: 1692585 | CA25: 1711319.5 | CB25: 1725349.5 | CC25: 1728515 | CD25: 1721857 | CE25: 1708450.5 | CF25: 1688609 | CG25: 1663408 | CH25: 1637548.5 | CI25: 1614625 | CJ25: 1593101 | CK25: 1572096 | CL25: 1553800.5 | CM25: 1536585 | CN25: 1521734 | CO25: 1514183.5 | CP25: 1511527.5 | CQ25: 1510863 | CR25: 1512117 | CS25: 1515573.5 | CT25: 1518368.5 | CU25: 1517799 | CV25: 1516339 | CW25: 1516485.5 | CX25: 1519305 | CY25: 1524359.5 | CZ25: 1532216 | DA25: 1544212.5 | DB25: 1558134.5 | DC25: 1571404 | DD25: 1586529.5 | DE25: 1605157 | DF25: 1624829.5 | DG25: 1645042.5 | DH25: 1667039 | DI25: 1690351 | DJ25: 1713129 | DK25: 1733096.5
A27: Estimated Annual Livebirths | B27: Provenance | C27: Units | D27: Uncertainty | E27: Constant | G27: 1990 | H27: 1991 | I27: 1992 | J27: 1993 | K27: 1994 | L27: 1995 | M27: 1996 | N27: 1997 | O27: 1998 | P27: 1999 | Q27: 2000 | R27: 2001 | S27: 2002 | T27: 2003 | U27: 2004 | V27: 2005 | W27: 2006 | X27: 2007 | Y27: 2008 | Z27: 2009 | AA27: 2010 | AB27: 2011 | AC27: 2012 | AD27: 2013 | AE27: 2014 | AF27: 2015 | AG27: 2016 | AH27: 2017 | AI27: 2018 | AJ27: 2019 | AK27: 2020 | AL27: 2021 | AM27: 2022 | AN27: 2023 | AO27: 2024 | AP27: 2025 | AQ27: 2026 | AR27: 2027 | AS27: 2028 | AT27: 2029 | AU27: 2030 | AV27: 2031 | AW27: 2032 | AX27: 2033 | AY27: 2034 | AZ27: 2035 | BA27: 2036 | BB27: 2037 | BC27: 2038 | BD27: 2039 | BE27: 2040 | BF27: 2041 | BG27: 2042 | BH27: 2043 | BI27: 2044 | BJ27: 2045 | BK27: 2046 | BL27: 2047 | BM27: 2048 | BN27: 2049 | BO27: 2050 | BP27: 2051 | BQ27: 2052 | BR27: 2053 | BS27: 2054 | BT27: 2055 | BU27: 2056 | BV27: 2057 | BW27: 2058 | BX27: 2059 | BY27: 2060 | BZ27: 2061 | CA27: 2062 | CB27: 2063 | CC27: 2064 | CD27: 2065 | CE27: 2066 | CF27: 2067 | CG27: 2068 | CH27: 2069 | CI27: 2070 | CJ27: 2071 | CK27: 2072 | CL27: 2073 | CM27: 2074 | CN27: 2075 | CO27: 2076 | CP27: 2077 | CQ27: 2078 | CR27: 2079 | CS27: 2080 | CT27: 2081 | CU27: 2082 | CV27: 2083 | CW27: 2084 | CX27: 2085 | CY27: 2086 | CZ27: 2087 | DA27: 2088 | DB27: 2089 | DC27: 2090 | DD27: 2091 | DE27: 2092 | DF27: 2093 | DG27: 2094 | DH27: 2095 | DI27: 2096 | DJ27: 2097 | DK27: 2098 | DL27: 2099 | DM27: 2100
A28: ='Population Definitions'!$B$2 -> 0-0M | C28: Number | F28: OR | G28: 292522.8 | H28: 289133.94 | I28: 292343.27 | J28: 283202.04 | K28: 276069.75 | L28: 270843.16 | M28: 271967.75 | N28: 274587.42 | O28: 273954.22 | P28: 276898.93 | Q28: 278724.53 | R28: 274683.64 | S28: 275225.95 | T28: 277370.78 | U28: 286754.33 | V28: 286582.52 | W28: 288482.64 | X28: 289163.94 | Y28: 295223.65 | Z28: 293264.44 | AA28: 289775.7 | AB28: 282101.35 | AC28: 274568.99 | AD28: 262604.12 | AE28: 254621.87 | AF28: 246127.24 | AG28: 239257.45 | AH28: 231877.8 | AI28: 222221.3 | AJ28: 215045.41 | AK28: 210922.04 | AL28: 211125.72 | AM28: 209488.1 | AN28: 208940.85 | AO28: 207667.89 | AP28: 207132.99 | AQ28: 206516.32 | AR28: 206790.16 | AS28: 205191.34 | AT28: 204890.59 | AU28: 205522.41 | AV28: 205170.26 | AW28: 206075.57 | AX28: 205859.14 | AY28: 205906.44 | AZ28: 205302.38 | BA28: 204842.27 | BB28: 204939.95 | BC28: 204945.6 | BD28: 203590.97 | BE28: 203166.85 | BF28: 201612.23 | BG28: 200176.38 | BH28: 199234.05 | BI28: 196341.25 | BJ28: 194485.38 | BK28: 192156.04 | BL28: 189984.52 | BM28: 186903.05 | BN28: 184029.79 | BO28: 180432.7 | BP28: 178075.59 | BQ28: 175246.03 | BR28: 173147.51 | BS28: 170334.92 | BT28: 168861.02 | BU28: 166687.44 | BV28: 165222.28 | BW28: 164186.38 | BX28: 163373.09 | BY28: 163298.03 | BZ28: 162740.24 | CA28: 161961.4 | CB28: 162040.57 | CC28: 161655.51 | CD28: 161297.19 | CE28: 161178.95 | CF28: 160672.57 | CG28: 161196.94 | CH28: 160400.61 | CI28: 160412.95 | CJ28: 160187.78 | CK28: 159636.67 | CL28: 158810.02 | CM28: 158674.81 | CN28: 158302.09 | CO28: 156411.27 | CP28: 155665.32 | CQ28: 154274.7 | CR28: 153764.72 | CS28: 152551.47 | CT28: 150705.88 | CU28: 149509.07 | CV28: 148573.43 | CW28: 147405.41 | CX28: 145438.5 | CY28: 144303.39 | CZ28: 142673.2 | DA28: 141453.26 | DB28: 140294.5 | DC28: 139402.04 | DD28: 138340.95 | DE28: 137041.85 | DF28: 136707.17 | DG28: 135882.06 | DH28: 135409.61 | DI28: 135084.19 | DJ28: 134881.12 | DK28: 134727.92 | DL28: 134781.39 | DM28: 134377.31
A29: ='Population Definitions'!$B$3 -> 0-0F | C29: Number | F29: OR | G29: 275445.2 | H29: 271998.06 | I29: 274500.73 | J29: 265667.96 | K29: 258977.25 | L29: 254551.84 | M29: 255849.25 | N29: 258800.58 | O29: 258203.78 | P29: 261472.07 | Q29: 262452.47 | R29: 259625.36 | S29: 260384.05 | T29: 262413.22 | U29: 271547.67 | V29: 269344.48 | W29: 271385.36 | X29: 272539.06 | Y29: 279303.35 | Z29: 276664.56 | AA29: 273373.3 | AB29: 266384.65 | AC29: 259517.01 | AD29: 248442.88 | AE29: 240436.13 | AF29: 232414.76 | AG29: 226569.55 | AH29: 218959.2 | AI29: 209840.7 | AJ29: 203064.59 | AK29: 199170.96 | AL29: 199363.28 | AM29: 197816.9 | AN29: 197300.15 | AO29: 196098.11 | AP29: 195593.01 | AQ29: 195010.68 | AR29: 195453.84 | AS29: 193942.66 | AT29: 193658.41 | AU29: 194255.59 | AV29: 193922.74 | AW29: 194778.43 | AX29: 194573.86 | AY29: 194618.56 | AZ29: 194047.62 | BA29: 193612.73 | BB29: 193705.05 | BC29: 193710.4 | BD29: 192430.03 | BE29: 192029.15 | BF29: 190559.77 | BG29: 189202.62 | BH29: 188311.95 | BI29: 185577.75 | BJ29: 183823.62 | BK29: 181621.96 | BL29: 179569.48 | BM29: 176656.95 | BN29: 173941.21 | BO29: 170541.3 | BP29: 168313.41 | BQ29: 165638.97 | BR29: 163655.49 | BS29: 160997.08 | BT29: 159603.98 | BU29: 157549.56 | BV29: 156164.72 | BW29: 155185.62 | BX29: 154416.91 | BY29: 154345.97 | BZ29: 153818.76 | CA29: 153082.6 | CB29: 153157.43 | CC29: 152793.49 | CD29: 152454.81 | CE29: 152343.05 | CF29: 151864.43 | CG29: 152360.06 | CH29: 151607.39 | CI29: 151619.05 | CJ29: 151406.22 | CK29: 150885.33 | CL29: 150103.98 | CM29: 149976.19 | CN29: 149623.91 | CO29: 147836.73 | CP29: 147131.68 | CQ29: 145817.3 | CR29: 145335.28 | CS29: 144188.53 | CT29: 142444.12 | CU29: 141312.93 | CV29: 140428.57 | CW29: 139324.59 | CX29: 137465.5 | CY29: 136392.61 | CZ29: 134851.8 | DA29: 133698.74 | DB29: 132603.5 | DC29: 131759.96 | DD29: 130757.05 | DE29: 129529.15 | DF29: 129212.83 | DG29: 128432.94 | DH29: 127986.39 | DI29: 127678.81 | DJ29: 127486.88 | DK29: 127342.08 | DL29: 127392.61 | DM29: 127010.69
A30: ='Population Definitions'!$B$4 -> 1-4M | C30: Number | F30: OR | G30: 0 | H30: 0 | I30: 0 | J30: 0 | K30: 0 | L30: 0 | M30: 0 | N30: 0 | O30: 0 | P30: 0 | Q30: 0 | R30: 0 | S30: 0 | T30: 0 | U30: 0 | V30: 0 | W30: 0 | X30: 0 | Y30: 0 | Z30: 0 | AA30: 0 | AB30: 0 | AC30: 0 | AD30: 0 | AE30: 0 | AF30: 0 | AG30: 0 | AH30: 0 | AI30: 0 | AJ30: 0 | AK30: 0 | AL30: 0 | AM30: 0 | AN30: 0 | AO30: 0 | AP30: 0 | AQ30: 0 | AR30: 0 | AS30: 0 | AT30: 0 | AU30: 0 | AV30: 0 | AW30: 0 | AX30: 0 | AY30: 0 | AZ30: 0 | BA30: 0 | BB30: 0 | BC30: 0 | BD30: 0 | BE30: 0 | BF30: 0 | BG30: 0 | BH30: 0 | BI30: 0 | BJ30: 0 | BK30: 0 | BL30: 0 | BM30: 0 | BN30: 0 | BO30: 0 | BP30: 0 | BQ30: 0 | BR30: 0 | BS30: 0 | BT30: 0 | BU30: 0 | BV30: 0 | BW30: 0 | BX30: 0 | BY30: 0 | BZ30: 0 | CA30: 0 | CB30: 0 | CC30: 0 | CD30: 0 | CE30: 0 | CF30: 0 | CG30: 0 | CH30: 0 | CI30: 0 | CJ30: 0 | CK30: 0 | CL30: 0 | CM30: 0 | CN30: 0 | CO30: 0 | CP30: 0 | CQ30: 0 | CR30: 0 | CS30: 0 | CT30: 0 | CU30: 0 | CV30: 0 | CW30: 0 | CX30: 0 | CY30: 0 | CZ30: 0 | DA30: 0 | DB30: 0 | DC30: 0 | DD30: 0 | DE30: 0 | DF30: 0 | DG30: 0 | DH30: 0 | DI30: 0 | DJ30: 0 | DK30: 0 | DL30: 0 | DM30: 0
