Workbook

Sheet About
A1: Name | B1: Description
A2: Template | B2: This is a template cascade. For instructions on how to fill it out, please see: cascade.tools/user-guide

Sheet Databook Pages
A1: Datasheet Code Name | B1: Datasheet Title
A2: sh_init | B2: Model Initialization
A3: sh_demog | B3: Populations
A4: sh_imig | B4: Immigration Model

Sheet Population types
A1: Code name | B1: Description
A2: default | B2: Default

Sheet Compartments
A1: Code Name | B1: Display Name | C1: Is Source | D1: Is Sink | E1: Is Junction | F1: Setup Weight | G1: Calibrate | H1: Databook Page | I1: Databook Order | J1: Guidance | K1: Population type | L1: Default value | M1: Provenance
A2: j_init | B2: Junction: Model Initialization | E2: y | H2: sh_init
A3: src_births | B3: Population Source: Births | C3: y
A4: src_immig | B4: Population Source: Immigration | C4: y
A5: snk_odth | B5: Population Sink: Non-HBV deaths | D5: y
A6: snk_hdth | B6: Population Sink: HBV attributable deaths | D6: y
A7: snk_emig | B7: Population Sink: Emigration | D7: y
A8: sus | B8: Hepatitis B susceptible
A9: vax | B9: Hepatitis B: Vaccine Protected
A10: imm_acu | B10: Hepatitis B: Cleared Acute Infection
A11: imm_chb | B11: Hepatitis B: Cleared Chronic Infection
A12: acu | B12: Hepatitis B: Acute Infection
A13: ei | B13: Hepatitis B: HBeAg-positive chronic HBV infection (Undiagnosed)
A14: ei_d | B14: Hepatitis B: HBeAg-positive chronic HBV infection (Diagnosed)
A15: ei_l | B15: Hepatitis B: HBeAg-positive chronic HBV infection (Linked to Care)
A16: ei_t | B16: Hepatitis B: HBeAg-positive chronic HBV infection (Treated)
A17: eh | B17: Hepatitis B: HBeAg-positive chronic hepatitis (Undiagnosed)
A18: eh_d | B18: Hepatitis B: HBeAg-positive chronic hepatitis (Diagnosed)
A19: eh_l | B19: Hepatitis B: HBeAg-positive chronic hepatitis (Linked to Care)
... A40: hcc_t | B40: Hepatitis B: Hepatocellular Carcinoma (Treated)

Sheet Transitions
B1: =IF(Compartments!$A2<>"",Compartments!$A2,"") -> j_init | C1: =IF(Compartments!$A3<>"",Compartments!$A3,"") -> src_births | D1: =IF(Compartments!$A4<>"",Compartments!$A4,"") -> src_immig | E1: =IF(Compartments!$A5<>"",Compartments!$A5,"") -> snk_odth | F1: =IF(Compartments!$A6<>"",Compartments!$A6,"") -> snk_hdth | G1: =IF(Compartments!$A7<>"",Compartments!$A7,"") -> snk_emig | H1: =IF(Compartments!$A8<>"",Compartments!$A8,"") -> sus | I1: =IF(Compartments!$A9<>"",Compartments!$A9,"") -> vax | J1: =IF(Compartments!$A10<>"",Compartments!$A10,"") -> imm_acu | K1: =IF(Compartments!$A11<>"",Compartments!$A11,"") -> imm_chb | L1: =IF(Compartments!$A12<>"",Compartments!$A12,"") -> acu | M1: =IF(Compartments!$A13<>"",Compartments!$A13,"") -> ei | N1: =IF(Compartments!$A14<>"",Compartments!$A14,"") -> ei_d | O1: =IF(Compartments!$A15<>"",Compartments!$A15,"") -> ei_l | P1: =IF(Compartments!$A16<>"",Compartments!$A16,"") -> ei_t | Q1: =IF(Compartments!$A17<>"",Compartments!$A17,"") -> eh | R1: =IF(Compartments!$A18<>"",Compartments!$A18,"") -> eh_d | S1: =IF(Compartments!$A19<>"",Compartments!$A19,"") -> eh_l | T1: =IF(Compartments!$A20<>"",Compartments!$A20,"") -> eh_t | U1: =IF(Compartments!$A21<>"",Compartments!$A21,"") -> si | V1: =IF(Compartments!$A22<>"",Compartments!$A22,"") -> si_d | W1: =IF(Compartments!$A23<>"",Compartments!$A23,"") -> si_l | X1: =IF(Compartments!$A24<>"",Compartments!$A24,"") -> si_t | Y1: =IF(Compartments!$A25<>"",Compartments!$A25,"") -> sh | Z1: =IF(Compartments!$A26<>"",Compartments!$A26,"") -> sh_d | AA1: =IF(Compartments!$A27<>"",Compartments!$A27,"") -> sh_l | AB1: =IF(Compartments!$A28<>"",Compartments!$A28,"") -> sh_t | AC1: =IF(Compartments!$A29<>"",Compartments!$A29,"") -> cc | AD1: =IF(Compartments!$A30<>"",Compartments!$A30,"") -> cc_d | AE1: =IF(Compartments!$A31<>"",Compartments!$A31,"") -> cc_l | AF1: =IF(Compartments!$A32<>"",Compartments!$A32,"") -> cc_t | AG1: =IF(Compartments!$A33<>"",Compartments!$A33,"") -> dc | AH1: =IF(Compartments!$A34<>"",Compartments!$A34,"") -> dc_d | AI1: =IF(Compartments!$A35<>"",Compartments!$A35,"") -> dc_l | AJ1: =IF(Compartments!$A36<>"",Compartments!$A36,"") -> dc_t | AK1: =IF(Compartments!$A37<>"",Compartments!$A37,"") -> hcc | AL1: =IF(Compartments!$A38<>"",Compartments!$A38,"") -> hcc_d | AM1: =IF(Compartments!$A39<>"",Compartments!$A39,"") -> hcc_l | AN1: =IF(Compartments!$A40<>"",Compartments!$A40,"") -> hcc_t | AO1: =IF(Compartments!$A41<>"",Compartments!$A41,"") | AP1: =IF(Compartments!$A42<>"",Compartments!$A42,"") | AQ1: =IF(Compartments!$A43<>"",Compartments!$A43,"") | AR1: =IF(Compartments!$A44<>"",Compartments!$A44,"") | AS1: =IF(Compartments!$A45<>"",Compartments!$A45,"") | AT1: =IF(Compartments!$A46<>"",Compartments!$A46,"") | AU1: =IF(Compartments!$A47<>"",Compartments!$A47,"") | AV1: =IF(Compartments!$A48<>"",Compartments!$A48,"") | AW1: =IF(Compartments!$A49<>"",Compartments!$A49,"") | AX1: =IF(Compartments!$A50<>"",Compartments!$A50,"") | AY1: =IF(Compartments!$A51<>"",Compartments!$A51,"") | AZ1: =IF(Compartments!$A52<>"",Compartments!$A52,"") | BA1: =IF(Compartments!$A53<>"",Compartments!$A53,"") | BB1: =IF(Compartments!$A54<>"",Compartments!$A54,"") | BC1: =IF(Compartments!$A55<>"",Compartments!$A55,"") | BD1: =IF(Compartments!$A56<>"",Compartments!$A56,"") | BE1: =IF(Compartments!$A57<>"",Compartments!$A57,"") | BF1: =IF(Compartments!$A58<>"",Compartments!$A58,"") | BG1: =IF(Compartments!$A59<>"",Compartments!$A59,"") | BH1: =IF(Compartments!$A60<>"",Compartments!$A60,"") | BI1: =IF(Compartments!$A61<>"",Compartments!$A61,"") | BJ1: =IF(Compartments!$A62<>"",Compartments!$A62,"") | BK1: =IF(Compartments!$A63<>"",Compartments!$A63,"") | BL1: =IF(Compartments!$A64<>"",Compartments!$A64,"") | BM1: =IF(Compartments!$A65<>"",Compartments!$A65,"") | BN1: =IF(Compartments!$A66<>"",Compartments!$A66,"") | BO1: =IF(Compartments!$A67<>"",Compartments!$A67,"") | BP1: =IF(Compartments!$A68<>"",Compartments!$A68,"") | BQ1: =IF(Compartments!$A69<>"",Compartments!$A69,"") | BR1: =IF(Compartments!$A70<>"",Compartments!$A70,"") | BS1: =IF(Compartments!$A71<>"",Compartments!$A71,"") | BT1: =IF(Compartments!$A72<>"",Compartments!$A72,"") | BU1: =IF(Compartments!$A73<>"",Compartments!$A73,"") | BV1: =IF(Compartments!$A74<>"",Compartments!$A74,"") | BW1: =IF(Compartments!$A75<>"",Compartments!$A75,"") | BX1: =IF(Compartments!$A76<>"",Compartments!$A76,"") | BY1: =IF(Compartments!$A77<>"",Compartments!$A77,"") | BZ1: =IF(Compartments!$A78<>"",Compartments!$A78,"") | CA1: =IF(Compartments!$A79<>"",Compartments!$A79,"") | CB1: =IF(Compartments!$A80<>"",Compartments!$A80,"") | CC1: =IF(Compartments!$A81<>"",Compartments!$A81,"") | CD1: =IF(Compartments!$A82<>"",Compartments!$A82,"") | CE1: =IF(Compartments!$A83<>"",Compartments!$A83,"") | CF1: =IF(Compartments!$A84<>"",Compartments!$A84,"") | CG1: =IF(Compartments!$A85<>"",Compartments!$A85,"") | CH1: =IF(Compartments!$A86<>"",Compartments!$A86,"") | CI1: =IF(Compartments!$A87<>"",Compartments!$A87,"") | CJ1: =IF(Compartments!$A88<>"",Compartments!$A88,"") | CK1: =IF(Compartments!$A89<>"",Compartments!$A89,"") | CL1: =IF(Compartments!$A90<>"",Compartments!$A90,"") | CM1: =IF(Compartments!$A91<>"",Compartments!$A91,"") | CN1: =IF(Compartments!$A92<>"",Compartments!$A92,"") | CO1: =IF(Compartments!$A93<>"",Compartments!$A93,"") | CP1: =IF(Compartments!$A94<>"",Compartments!$A94,"") | CQ1: =IF(Compartments!$A95<>"",Compartments!$A95,"") | CR1: =IF(Compartments!$A96<>"",Compartments!$A96,"") | CS1: =IF(Compartments!$A97<>"",Compartments!$A97,"") | CT1: =IF(Compartments!$A98<>"",Compartments!$A98,"") | CU1: =IF(Compartments!$A99<>"",Compartments!$A99,"") | CV1: =IF(Compartments!$A100<>"",Compartments!$A100,"") | CW1: =IF(Compartments!$A101<>"",Compartments!$A101,"") | CX1: =IF(Compartments!$A102<>"",Compartments!$A102,"") | CY1: =IF(Compartments!$A103<>"",Compartments!$A103,"") | CZ1: =IF(Compartments!$A104<>"",Compartments!$A104,"") | DA1: =IF(Compartments!$A105<>"",Compartments!$A105,"") | DB1: =IF(Compartments!$A106<>"",Compartments!$A106,"") | DC1: =IF(Compartments!$A107<>"",Compartments!$A107,"") | DD1: =IF(Compartments!$A108<>"",Compartments!$A108,"") | DE1: =IF(Compartments!$A109<>"",Compartments!$A109,"") | DF1: =IF(Compartments!$A110<>"",Compartments!$A110,"") | DG1: =IF(Compartments!$A111<>"",Compartments!$A111,"") | DH1: =IF(Compartments!$A112<>"",Compartments!$A112,"") | DI1: =IF(Compartments!$A113<>"",Compartments!$A113,"") | DJ1: =IF(Compartments!$A114<>"",Compartments!$A114,"") | DK1: =IF(Compartments!$A115<>"",Compartments!$A115,"") | DL1: =IF(Compartments!$A116<>"",Compartments!$A116,"") | DM1: =IF(Compartments!$A117<>"",Compartments!$A117,"") | DN1: =IF(Compartments!$A118<>"",Compartments!$A118,"") | DO1: =IF(Compartments!$A119<>"",Compartments!$A119,"") | DP1: =IF(Compartments!$A120<>"",Compartments!$A120,"") | DQ1: =IF(Compartments!$A121<>"",Compartments!$A121,"") | DR1: =IF(Compartments!$A122<>"",Compartments!$A122,"") | DS1: =IF(Compartments!$A123<>"",Compartments!$A123,"") | DT1: =IF(Compartments!$A124<>"",Compartments!$A124,"") | DU1: =IF(Compartments!$A125<>"",Compartments!$A125,"") | DV1: =IF(Compartments!$A126<>"",Compartments!$A126,"") | DW1: =IF(Compartments!$A127<>"",Compartments!$A127,"") | DX1: =IF(Compartments!$A128<>"",Compartments!$A128,"") | DY1: =IF(Compartments!$A129<>"",Compartments!$A129,"") | DZ1: =IF(Compartments!$A130<>"",Compartments!$A130,"") | EA1: =IF(Compartments!$A131<>"",Compartments!$A131,"") | EB1: =IF(Compartments!$A132<>"",Compartments!$A132,"") | EC1: =IF(Compartments!$A133<>"",Compartments!$A133,"") | ED1: =IF(Compartments!$A134<>"",Compartments!$A134,"") | EE1: =IF(Compartments!$A135<>"",Compartments!$A135,"") | EF1: =IF(Compartments!$A136<>"",Compartments!$A136,"") | EG1: =IF(Compartments!$A137<>"",Compartments!$A137,"") | EH1: =IF(Compartments!$A138<>"",Compartments!$A138,"") | EI1: =IF(Compartments!$A139<>"",Compartments!$A139,"") | EJ1: =IF(Compartments!$A140<>"",Compartments!$A140,"") | EK1: =IF(Compartments!$A141<>"",Compartments!$A141,"") | EL1: =IF(Compartments!$A142<>"",Compartments!$A142,"") | EM1: =IF(Compartments!$A143<>"",Compartments!$A143,"") | EN1: =IF(Compartments!$A144<>"",Compartments!$A144,"") | EO1: =IF(Compartments!$A145<>"",Compartments!$A145,"") | EP1: =IF(Compartments!$A146<>"",Compartments!$A146,"") | EQ1: =IF(Compartments!$A147<>"",Compartments!$A147,"") | ER1: =IF(Compartments!$A148<>"",Compartments!$A148,"") | ES1: =IF(Compartments!$A149<>"",Compartments!$A149,"") | ET1: =IF(Compartments!$A150<>"",Compartments!$A150,"") | EU1: =IF(Compartments!$A151<>"",Compartments!$A151,"") | EV1: =IF(Compartments!$A152<>"",Compartments!$A152,"") | EW1: =IF(Compartments!$A153<>"",Compartments!$A153,"") | EX1: =IF(Compartments!$A154<>"",Compartments!$A154,"") | EY1: =IF(Compartments!$A155<>"",Compartments!$A155,"") | EZ1: =IF(Compartments!$A156<>"",Compartments!$A156,"") | FA1: =IF(Compartments!$A157<>"",Compartments!$A157,"") | FB1: =IF(Compartments!$A158<>"",Compartments!$A158,"") | FC1: =IF(Compartments!$A159<>"",Compartments!$A159,"") | FD1: =IF(Compartments!$A160<>"",Compartments!$A160,"") | FE1: =IF(Compartments!$A161<>"",Compartments!$A161,"") | FF1: =IF(Compartments!$A162<>"",Compartments!$A162,"") | FG1: =IF(Compartments!$A163<>"",Compartments!$A163,"") | FH1: =IF(Compartments!$A164<>"",Compartments!$A164,"") | FI1: =IF(Compartments!$A165<>"",Compartments!$A165,"") | FJ1: =IF(Compartments!$A166<>"",Compartments!$A166,"") | FK1: =IF(Compartments!$A167<>"",Compartments!$A167,"") | FL1: =IF(Compartments!$A168<>"",Compartments!$A168,"") | FM1: =IF(Compartments!$A169<>"",Compartments!$A169,"") | FN1: =IF(Compartments!$A170<>"",Compartments!$A170,"") | FO1: =IF(Compartments!$A171<>"",Compartments!$A171,"") | FP1: =IF(Compartments!$A172<>"",Compartments!$A172,"") | FQ1: =IF(Compartments!$A173<>"",Compartments!$A173,"") | FR1: =IF(Compartments!$A174<>"",Compartments!$A174,"") | FS1: =IF(Compartments!$A175<>"",Compartments!$A175,"") | FT1: =IF(Compartments!$A176<>"",Compartments!$A176,"") | FU1: =IF(Compartments!$A177<>"",Compartments!$A177,"") | FV1: =IF(Compartments!$A178<>"",Compartments!$A178,"") | FW1: =IF(Compartments!$A179<>"",Compartments!$A179,"") | FX1: =IF(Compartments!$A180<>"",Compartments!$A180,"") | FY1: =IF(Compartments!$A181<>"",Compartments!$A181,"") | FZ1: =IF(Compartments!$A182<>"",Compartments!$A182,"") | GA1: =IF(Compartments!$A183<>"",Compartments!$A183,"") | GB1: =IF(Compartments!$A184<>"",Compartments!$A184,"") | GC1: =IF(Compartments!$A185<>"",Compartments!$A185,"") | GD1: =IF(Compartments!$A186<>"",Compartments!$A186,"") | GE1: =IF(Compartments!$A187<>"",Compartments!$A187,"") | GF1: =IF(Compartments!$A188<>"",Compartments!$A188,"") | GG1: =IF(Compartments!$A189<>"",Compartments!$A189,"") | GH1: =IF(Compartments!$A190<>"",Compartments!$A190,"") | GI1: =IF(Compartments!$A191<>"",Compartments!$A191,"") | GJ1: =IF(Compartments!$A192<>"",Compartments!$A192,"") | GK1: =IF(Compartments!$A193<>"",Compartments!$A193,"") | GL1: =IF(Compartments!$A194<>"",Compartments!$A194,"") | GM1: =IF(Compartments!$A195<>"",Compartments!$A195,"") | GN1: =IF(Compartments!$A196<>"",Compartments!$A196,"") | GO1: =IF(Compartments!$A197<>"",Compartments!$A197,"") | GP1: =IF(Compartments!$A198<>"",Compartments!$A198,"") | GQ1: =IF(Compartments!$A199<>"",Compartments!$A199,"") | GR1: =IF(Compartments!$A200<>"",Compartments!$A200,"") | GS1: =IF(Compartments!$A201<>"",Compartments!$A201,"") | GT1: =IF(Compartments!$A202<>"",Compartments!$A202,"") | GU1: =IF(Compartments!$A203<>"",Compartments!$A203,"") | GV1: =IF(Compartments!$A204<>"",Compartments!$A204,"") | GW1: =IF(Compartments!$A205<>"",Compartments!$A205,"") | GX1: =IF(Compartments!$A206<>"",Compartments!$A206,"") | GY1: =IF(Compartments!$A207<>"",Compartments!$A207,"") | GZ1: =IF(Compartments!$A208<>"",Compartments!$A208,"") | HA1: =IF(Compartments!$A209<>"",Compartments!$A209,"") | HB1: =IF(Compartments!$A210<>"",Compartments!$A210,"") | HC1: =IF(Compartments!$A211<>"",Compartments!$A211,"") | HD1: =IF(Compartments!$A212<>"",Compartments!$A212,"") | HE1: =IF(Compartments!$A213<>"",Compartments!$A213,"") | HF1: =IF(Compartments!$A214<>"",Compartments!$A214,"") | HG1: =IF(Compartments!$A215<>"",Compartments!$A215,"") | HH1: =IF(Compartments!$A216<>"",Compartments!$A216,"") | HI1: =IF(Compartments!$A217<>"",Compartments!$A217,"") | HJ1: =IF(Compartments!$A218<>"",Compartments!$A218,"") | HK1: =IF(Compartments!$A219<>"",Compartments!$A219,"") | HL1: =IF(Compartments!$A220<>"",Compartments!$A220,"") | HM1: =IF(Compartments!$A221<>"",Compartments!$A221,"") | HN1: =IF(Compartments!$A222<>"",Compartments!$A222,"") | HO1: =IF(Compartments!$A223<>"",Compartments!$A223,"") | HP1: =IF(Compartments!$A224<>"",Compartments!$A224,"") | HQ1: =IF(Compartments!$A225<>"",Compartments!$A225,"") | HR1: =IF(Compartments!$A226<>"",Compartments!$A226,"") | HS1: =IF(Compartments!$A227<>"",Compartments!$A227,"") | HT1: =IF(Compartments!$A228<>"",Compartments!$A228,"") | HU1: =IF(Compartments!$A229<>"",Compartments!$A229,"") | HV1: =IF(Compartments!$A230<>"",Compartments!$A230,"") | HW1: =IF(Compartments!$A231<>"",Compartments!$A231,"") | HX1: =IF(Compartments!$A232<>"",Compartments!$A232,"") | HY1: =IF(Compartments!$A233<>"",Compartments!$A233,"") | HZ1: =IF(Compartments!$A234<>"",Compartments!$A234,"") | IA1: =IF(Compartments!$A235<>"",Compartments!$A235,"") | IB1: =IF(Compartments!$A236<>"",Compartments!$A236,"") | IC1: =IF(Compartments!$A237<>"",Compartments!$A237,"") | ID1: =IF(Compartments!$A238<>"",Compartments!$A238,"") | IE1: =IF(Compartments!$A239<>"",Compartments!$A239,"") | IF1: =IF(Compartments!$A240<>"",Compartments!$A240,"") | IG1: =IF(Compartments!$A241<>"",Compartments!$A241,"") | IH1: =IF(Compartments!$A242<>"",Compartments!$A242,"") | II1: =IF(Compartments!$A243<>"",Compartments!$A243,"") | IJ1: =IF(Compartments!$A244<>"",Compartments!$A244,"") | IK1: =IF(Compartments!$A245<>"",Compartments!$A245,"") | IL1: =IF(Compartments!$A246<>"",Compartments!$A246,"") | IM1: =IF(Compartments!$A247<>"",Compartments!$A247,"") | IN1: =IF(Compartments!$A248<>"",Compartments!$A248,"") | IO1: =IF(Compartments!$A249<>"",Compartments!$A249,"") | IP1: =IF(Compartments!$A250<>"",Compartments!$A250,"") | IQ1: =IF(Compartments!$A251<>"",Compartments!$A251,"") | IR1: =IF(Compartments!$A252<>"",Compartments!$A252,"") | IS1: =IF(Compartments!$A253<>"",Compartments!$A253,"") | IT1: =IF(Compartments!$A254<>"",Compartments!$A254,"") | IU1: =IF(Compartments!$A255<>"",Compartments!$A255,"") | IV1: =IF(Compartments!$A256<>"",Compartments!$A256,"") | IW1: =IF(Compartments!$A257<>"",Compartments!$A257,"") | IX1: =IF(Compartments!$A258<>"",Compartments!$A258,"") | IY1: =IF(Compartments!$A259<>"",Compartments!$A259,"") | IZ1: =IF(Compartments!$A260<>"",Compartments!$A260,"") | JA1: =IF(Compartments!$A261<>"",Compartments!$A261,"") | JB1: =IF(Compartments!$A262<>"",Compartments!$A262,"") | JC1: =IF(Compartments!$A263<>"",Compartments!$A263,"") | JD1: =IF(Compartments!$A264<>"",Compartments!$A264,"") | JE1: =IF(Compartments!$A265<>"",Compartments!$A265,"") | JF1: =IF(Compartments!$A266<>"",Compartments!$A266,"") | JG1: =IF(Compartments!$A267<>"",Compartments!$A267,"") | JH1: =IF(Compartments!$A268<>"",Compartments!$A268,"") | JI1: =IF(Compartments!$A269<>"",Compartments!$A269,"") | JJ1: =IF(Compartments!$A270<>"",Compartments!$A270,"") | JK1: =IF(Compartments!$A271<>"",Compartments!$A271,"") | JL1: =IF(Compartments!$A272<>"",Compartments!$A272,"") | JM1: =IF(Compartments!$A273<>"",Compartments!$A273,"") | JN1: =IF(Compartments!$A274<>"",Compartments!$A274,"") | JO1: =IF(Compartments!$A275<>"",Compartments!$A275,"") | JP1: =IF(Compartments!$A276<>"",Compartments!$A276,"") | JQ1: =IF(Compartments!$A277<>"",Compartments!$A277,"") | JR1: =IF(Compartments!$A278<>"",Compartments!$A278,"") | JS1: =IF(Compartments!$A279<>"",Compartments!$A279,"") | JT1: =IF(Compartments!$A280<>"",Compartments!$A280,"") | JU1: =IF(Compartments!$A281<>"",Compartments!$A281,"") | JV1: =IF(Compartments!$A282<>"",Compartments!$A282,"") | JW1: =IF(Compartments!$A283<>"",Compartments!$A283,"") | JX1: =IF(Compartments!$A284<>"",Compartments!$A284,"") | JY1: =IF(Compartments!$A285<>"",Compartments!$A285,"") | JZ1: =IF(Compartments!$A286<>"",Compartments!$A286,"") | KA1: =IF(Compartments!$A287<>"",Compartments!$A287,"") | KB1: =IF(Compartments!$A288<>"",Compartments!$A288,"") | KC1: =IF(Compartments!$A289<>"",Compartments!$A289,"") | KD1: =IF(Compartments!$A290<>"",Compartments!$A290,"") | KE1: =IF(Compartments!$A291<>"",Compartments!$A291,"") | KF1: =IF(Compartments!$A292<>"",Compartments!$A292,"") | KG1: =IF(Compartments!$A293<>"",Compartments!$A293,"") | KH1: =IF(Compartments!$A294<>"",Compartments!$A294,"") | KI1: =IF(Compartments!$A295<>"",Compartments!$A295,"") | KJ1: =IF(Compartments!$A296<>"",Compartments!$A296,"") | KK1: =IF(Compartments!$A297<>"",Compartments!$A297,"") | KL1: =IF(Compartments!$A298<>"",Compartments!$A298,"") | KM1: =IF(Compartments!$A299<>"",Compartments!$A299,"") | KN1: =IF(Compartments!$A300<>"",Compartments!$A300,"") | KO1: =IF(Compartments!$A301<>"",Compartments!$A301,"") | KP1: =IF(Compartments!$A302<>"",Compartments!$A302,"") | KQ1: =IF(Compartments!$A303<>"",Compartments!$A303,"") | KR1: =IF(Compartments!$A304<>"",Compartments!$A304,"") | KS1: =IF(Compartments!$A305<>"",Compartments!$A305,"") | KT1: =IF(Compartments!$A306<>"",Compartments!$A306,"") | KU1: =IF(Compartments!$A307<>"",Compartments!$A307,"") | KV1: =IF(Compartments!$A308<>"",Compartments!$A308,"") | KW1: =IF(Compartments!$A309<>"",Compartments!$A309,"") | KX1: =IF(Compartments!$A310<>"",Compartments!$A310,"") | KY1: =IF(Compartments!$A311<>"",Compartments!$A311,"") | KZ1: =IF(Compartments!$A312<>"",Compartments!$A312,"") | LA1: =IF(Compartments!$A313<>"",Compartments!$A313,"") | LB1: =IF(Compartments!$A314<>"",Compartments!$A314,"") | LC1: =IF(Compartments!$A315<>"",Compartments!$A315,"") | LD1: =IF(Compartments!$A316<>"",Compartments!$A316,"") | LE1: =IF(Compartments!$A317<>"",Compartments!$A317,"") | LF1: =IF(Compartments!$A318<>"",Compartments!$A318,"") | LG1: =IF(Compartments!$A319<>"",Compartments!$A319,"") | LH1: =IF(Compartments!$A320<>"",Compartments!$A320,"") | LI1: =IF(Compartments!$A321<>"",Compartments!$A321,"") | LJ1: =IF(Compartments!$A322<>"",Compartments!$A322,"") | LK1: =IF(Compartments!$A323<>"",Compartments!$A323,"") | LL1: =IF(Compartments!$A324<>"",Compartments!$A324,"") | LM1: =IF(Compartments!$A325<>"",Compartments!$A325,"") | LN1: =IF(Compartments!$A326<>"",Compartments!$A326,"") | LO1: =IF(Compartments!$A327<>"",Compartments!$A327,"") | LP1: =IF(Compartments!$A328<>"",Compartments!$A328,"") | LQ1: =IF(Compartments!$A329<>"",Compartments!$A329,"") | LR1: =IF(Compartments!$A330<>"",Compartments!$A330,"") | LS1: =IF(Compartments!$A331<>"",Compartments!$A331,"") | LT1: =IF(Compartments!$A332<>"",Compartments!$A332,"") | LU1: =IF(Compartments!$A333<>"",Compartments!$A333,"") | LV1: =IF(Compartments!$A334<>"",Compartments!$A334,"") | LW1: =IF(Compartments!$A335<>"",Compartments!$A335,"") | LX1: =IF(Compartments!$A336<>"",Compartments!$A336,"") | LY1: =IF(Compartments!$A337<>"",Compartments!$A337,"") | LZ1: =IF(Compartments!$A338<>"",Compartments!$A338,"") | MA1: =IF(Compartments!$A339<>"",Compartments!$A339,"") | MB1: =IF(Compartments!$A340<>"",Compartments!$A340,"") | MC1: =IF(Compartments!$A341<>"",Compartments!$A341,"") | MD1: =IF(Compartments!$A342<>"",Compartments!$A342,"") | ME1: =IF(Compartments!$A343<>"",Compartments!$A343,"") | MF1: =IF(Compartments!$A344<>"",Compartments!$A344,"") | MG1: =IF(Compartments!$A345<>"",Compartments!$A345,"") | MH1: =IF(Compartments!$A346<>"",Compartments!$A346,"") | MI1: =IF(Compartments!$A347<>"",Compartments!$A347,"") | MJ1: =IF(Compartments!$A348<>"",Compartments!$A348,"") | MK1: =IF(Compartments!$A349<>"",Compartments!$A349,"") | ML1: =IF(Compartments!$A350<>"",Compartments!$A350,"") | MM1: =IF(Compartments!$A351<>"",Compartments!$A351,"") | MN1: =IF(Compartments!$A352<>"",Compartments!$A352,"") | MO1: =IF(Compartments!$A353<>"",Compartments!$A353,"") | MP1: =IF(Compartments!$A354<>"",Compartments!$A354,"") | MQ1: =IF(Compartments!$A355<>"",Compartments!$A355,"") | MR1: =IF(Compartments!$A356<>"",Compartments!$A356,"") | MS1: =IF(Compartments!$A357<>"",Compartments!$A357,"") | MT1: =IF(Compartments!$A358<>"",Compartments!$A358,"") | MU1: =IF(Compartments!$A359<>"",Compartments!$A359,"") | MV1: =IF(Compartments!$A360<>"",Compartments!$A360,"") | MW1: =IF(Compartments!$A361<>"",Compartments!$A361,"") | MX1: =IF(Compartments!$A362<>"",Compartments!$A362,"") | MY1: =IF(Compartments!$A363<>"",Compartments!$A363,"") | MZ1: =IF(Compartments!$A364<>"",Compartments!$A364,"") | NA1: =IF(Compartments!$A365<>"",Compartments!$A365,"") | NB1: =IF(Compartments!$A366<>"",Compartments!$A366,"") | NC1: =IF(Compartments!$A367<>"",Compartments!$A367,"") | ND1: =IF(Compartments!$A368<>"",Compartments!$A368,"") | NE1: =IF(Compartments!$A369<>"",Compartments!$A369,"") | NF1: =IF(Compartments!$A370<>"",Compartments!$A370,"") | NG1: =IF(Compartments!$A371<>"",Compartments!$A371,"") | NH1: =IF(Compartments!$A372<>"",Compartments!$A372,"") | NI1: =IF(Compartments!$A373<>"",Compartments!$A373,"") | NJ1: =IF(Compartments!$A374<>"",Compartments!$A374,"") | NK1: =IF(Compartments!$A375<>"",Compartments!$A375,"") | NL1: =IF(Compartments!$A376<>"",Compartments!$A376,"") | NM1: =IF(Compartments!$A377<>"",Compartments!$A377,"") | NN1: =IF(Compartments!$A378<>"",Compartments!$A378,"") | NO1: =IF(Compartments!$A379<>"",Compartments!$A379,"") | NP1: =IF(Compartments!$A380<>"",Compartments!$A380,"") | NQ1: =IF(Compartments!$A381<>"",Compartments!$A381,"") | NR1: =IF(Compartments!$A382<>"",Compartments!$A382,"") | NS1: =IF(Compartments!$A383<>"",Compartments!$A383,"") | NT1: =IF(Compartments!$A384<>"",Compartments!$A384,"") | NU1: =IF(Compartments!$A385<>"",Compartments!$A385,"") | NV1: =IF(Compartments!$A386<>"",Compartments!$A386,"") | NW1: =IF(Compartments!$A387<>"",Compartments!$A387,"") | NX1: =IF(Compartments!$A388<>"",Compartments!$A388,"") | NY1: =IF(Compartments!$A389<>"",Compartments!$A389,"") | NZ1: =IF(Compartments!$A390<>"",Compartments!$A390,"") | OA1: =IF(Compartments!$A391<>"",Compartments!$A391,"") | OB1: =IF(Compartments!$A392<>"",Compartments!$A392,"") | OC1: =IF(Compartments!$A393<>"",Compartments!$A393,"") | OD1: =IF(Compartments!$A394<>"",Compartments!$A394,"") | OE1: =IF(Compartments!$A395<>"",Compartments!$A395,"") | OF1: =IF(Compartments!$A396<>"",Compartments!$A396,"") | OG1: =IF(Compartments!$A397<>"",Compartments!$A397,"") | OH1: =IF(Compartments!$A398<>"",Compartments!$A398,"")
A2: =IF(Compartments!$A2<>"",Compartments!$A2,"") -> j_init | H2: init_sus | K2: init_clr | M2: init_ei | Q2: init_eh | U2: init_si | Y2: init_sh | AC2: init_cc | AG2: init_dc | AK2: init_hcc
A3: =IF(Compartments!$A3<>"",Compartments!$A3,"") -> src_births | H3: b_sus | I3: b_vax | K3: b_clr | M3: b_chb
A4: =IF(Compartments!$A4<>"",Compartments!$A4,"") -> src_immig | H4: imig_sus | I4: imig_vax | K4: imig_clr | M4: imig_ei | Q4: imig_eh | U4: imig_si | Y4: imig_sh | AC4: imig_cc
A5: =IF(Compartments!$A5<>"",Compartments!$A5,"") -> snk_odth
A6: =IF(Compartments!$A6<>"",Compartments!$A6,"") -> snk_hdth
A7: =IF(Compartments!$A7<>"",Compartments!$A7,"") -> snk_emig
A8: =IF(Compartments!$A8<>"",Compartments!$A8,"") -> sus | E8: acm | G8: emig_rate | L8: echt, adht
A9: =IF(Compartments!$A9<>"",Compartments!$A9,"") -> vax | E9: acm | G9: emig_rate
A10: =IF(Compartments!$A10<>"",Compartments!$A10,"") -> imm_acu
A11: =IF(Compartments!$A11<>"",Compartments!$A11,"") -> imm_chb | E11: acm | G11: emig_rate
A12: =IF(Compartments!$A12<>"",Compartments!$A12,"") -> acu | E12: acm | F12: acu_dth | G12: emig_rate | K12: acu_clr | M12: acu_chb
A13: =IF(Compartments!$A13<>"",Compartments!$A13,"") -> ei | E13: acm | G13: emig_rate | N13: diag_rate | Q13: ei_eh | AK13: ei_hcc
A14: =IF(Compartments!$A14<>"",Compartments!$A14,"") -> ei_d | E14: acm | G14: emig_rate | O14: ltc_rate | R14: ei_eh | AL14: ei_hcc
A15: =IF(Compartments!$A15<>"",Compartments!$A15,"") -> ei_l | E15: acm | G15: emig_rate | N15: ltf_rate | S15: ei_eh | AM15: ei_hcc
A16: =IF(Compartments!$A16<>"",Compartments!$A16,"") -> ei_t | E16: acm | G16: emig_rate
A17: =IF(Compartments!$A17<>"",Compartments!$A17,"") -> eh | E17: acm | G17: emig_rate | R17: diag_rate | U17: eh_si | AC17: eh_cc | AK17: act_hcc
A18: =IF(Compartments!$A18<>"",Compartments!$A18,"") -> eh_d | E18: acm | G18: emig_rate | S18: ltc_rate | V18: eh_si | AD18: eh_cc | AL18: act_hcc
A19: =IF(Compartments!$A19<>"",Compartments!$A19,"") -> eh_l | E19: acm | G19: emig_rate | R19: ltf_rate | T19: treat_rate | W19: eh_si | AE19: eh_cc | AM19: act_hcc
A20: =IF(Compartments!$A20<>"",Compartments!$A20,"") -> eh_t | E20: acm | G20: emig_rate | R20: ts_rate | X20: eh_si | AF20: eh_cc_t | AN20: act_hcc_t
A21: =IF(Compartments!$A21<>"",Compartments!$A21,"") -> si | E21: acm | G21: emig_rate | V21: diag_rate | Y21: si_sh | AK21: si_hcc
A22: =IF(Compartments!$A22<>"",Compartments!$A22,"") -> si_d | E22: acm | G22: emig_rate | W22: ltc_rate | Z22: si_sh | AL22: si_hcc
A23: =IF(Compartments!$A23<>"",Compartments!$A23,"") -> si_l | E23: acm | G23: emig_rate | V23: ltf_rate | X23: treat_rate | AA23: si_sh | AM23: si_hcc
A24: =IF(Compartments!$A24<>"",Compartments!$A24,"") -> si_t | E24: acm | G24: emig_rate | V24: ts_rate | AN24: si_hcc_t
A25: =IF(Compartments!$A25<>"",Compartments!$A25,"") -> sh | E25: acm | G25: emig_rate | U25: sh_si | Z25: diag_rate | AC25: sh_cc | AK25: act_hcc
A26: =IF(Compartments!$A26<>"",Compartments!$A26,"") -> sh_d | E26: acm | G26: emig_rate | V26: sh_si | AA26: ltc_rate | AD26: sh_cc | AL26: act_hcc
A27: =IF(Compartments!$A27<>"",Compartments!$A27,"") -> sh_l | E27: acm | G27: emig_rate | W27: sh_si | Z27: ltf_rate | AB27: treat_rate | AE27: sh_cc | AM27: act_hcc
A28: =IF(Compartments!$A28<>"",Compartments!$A28,"") -> sh_t | E28: acm | G28: emig_rate | X28: sh_si_t | Z28: ts_rate | AF28: sh_cc_t | AN28: act_hcc_t
A29: =IF(Compartments!$A29<>"",Compartments!$A29,"") -> cc | E29: acm | G29: emig_rate | AD29: diag_rate | AG29: cc_dc | AK29: cir_hcc
A30: =IF(Compartments!$A30<>"",Compartments!$A30,"") -> cc_d | E30: acm | G30: emig_rate | AE30: ltc_rate | AH30: cc_dc | AL30: cir_hcc
A31: =IF(Compartments!$A31<>"",Compartments!$A31,"") -> cc_l | E31: acm | G31: emig_rate | AD31: ltf_rate | AF31: treat_rate | AI31: cc_dc | AM31: cir_hcc
A32: =IF(Compartments!$A32<>"",Compartments!$A32,"") -> cc_t | E32: acm | G32: emig_rate | AD32: ts_rate | AJ32: cc_dc_t | AN32: cir_hcc_t
A33: =IF(Compartments!$A33<>"",Compartments!$A33,"") -> dc | E33: acm | F33: dc_dth | G33: emig_rate | AH33: diag_rate | AK33: cir_hcc
A34: =IF(Compartments!$A34<>"",Compartments!$A34,"") -> dc_d | E34: acm | F34: dc_dth | G34: emig_rate | AI34: ltc_rate | AL34: cir_hcc
A35: =IF(Compartments!$A35<>"",Compartments!$A35,"") -> dc_l | E35: acm | F35: dc_dth | G35: emig_rate | AH35: ltf_rate | AJ35: treat_rate | AM35: cir_hcc
A36: =IF(Compartments!$A36<>"",Compartments!$A36,"") -> dc_t | E36: acm | F36: dc_dth_t | G36: emig_rate | AF36: dc_cc_t | AH36: ts_rate | AN36: cir_hcc_t
A37: =IF(Compartments!$A37<>"",Compartments!$A37,"") -> hcc | E37: acm | F37: hcc_dth | G37: emig_rate | AL37: diag_rate
A38: =IF(Compartments!$A38<>"",Compartments!$A38,"") -> hcc_d | E38: acm | F38: hcc_dth | G38: emig_rate | AM38: ltc_rate
A39: =IF(Compartments!$A39<>"",Compartments!$A39,"") -> hcc_l | E39: acm | F39: hcc_dth | G39: emig_rate | AL39: ltf_rate | AN39: treat_rate
A40: =IF(Compartments!$A40<>"",Compartments!$A40,"") -> hcc_t | E40: acm | F40: hcc_dth | G40: emig_rate | AL40: ts_rate
...

Sheet Parameters
A1: Code Name | B1: Display Name | C1: Format | D1: Timescale | E1: Default Value | F1: Minimum Value | G1: Maximum Value | H1: Function | I1: Targetable | J1: Calibrate | K1: Databook Page | L1: Databook Order | M1: Guidance | N1: Population type | O1: Timed | P1: Is derivative | Q1: Provenance
A2: #ignore | B2: Population Demographics
A3: b_rate | B3: Annual Births (by sex)
A4: acm | B4: Non-HepB (all-cause) mortality rate
A5: imig_rate | B5: Annual Rate of Overseas Arrivals
A6: emig_rate | B6: Annual Rate of Overseas Departures | C6: rate
A7: #ignore | B7: Immigration Model
A8: imig_prev | B8: Prevalence of hepatitis B among arrivals
A9: imig_rem | B9: Non-HepB positive arrivals to Australia | H9: min(imig_rate * (1-imig_prev), imig_rate)
A10: imig_vax_prop | B10: Proportion of non-HepB positive arrivals who are vaccinated
A11: imig_clr_prop | B11: Proportion of non-HepB positive arrivals who are immune
A12: imig_sus_prop | B12: Proportion of non-HepB positive arrivals who are susceptible | H12: 1-(imig_vax_prop+imig_clr_prop)
A13: imig_vax | B13: Arrivals: Vaccinated against hepatitis B | C13: number | H13: imig_rem*imig_vax_prop
A14: imig_clr | B14: Arrivals: Immune to hepatitis B from prior infection | C14: number | H14: imig_rem*imig_clr_prop
A15: imig_sus | B15: Arrivals: Susceptible to hepatitis B infection | C15: number | H15: imig_rem*imig_sus_prop
A16: imig_pos | B16: Hepatitis B positive arrivals to Australia | H16: min(imig_rate*imig_prev, imig_rate)
A17: imig_ei | B17: Arrivals: HBeAg positive chronic HBV infection | C17: number | H17: imig_pos*sdiv(ei, ei+eh+si+sh+cc)
A18: imig_eh | B18: Arrivals: HBeAg positive chronic hepatitis | C18: number | H18: imig_pos*sdiv(eh, ei+eh+si+sh+cc)
A19: imig_sh | B19: Arrivals: HBeAg negative chronic HBV infection | C19: number | H19: imig_pos*sdiv(si, ei+eh+si+sh+cc)
A20: imig_si | B20: Arrivals: HBeAg negative chronic hepatitis | C20: number | H20: imig_pos*sdiv(sh, ei+eh+si+sh+cc)
A21: imig_cc | B21: Arrivals: Compensated cirrhosis | C21: number | H21: imig_pos*sdiv(cc, ei+eh+si+sh+cc)
A22: #ignore | B22: Model Initialization
A23: chb_init | B23: Unadjusted initial prevalence of hepatitis B | K23: sh_init
A24: eag_init | B24: Initial prevalence of HBeAg positive infection among all with hepatitis B | K24: sh_init
A25: cc_prop | B25: Initial prevalence of compensated cirrhosis among all hepatitis B infections | K25: sh_init
A26: dc_prop | B26: Initial prevalence of decompensated cirrhosis among all hepatitis B infections | K26: sh_init
A27: hcc_prop | B27: Initial prevalence of hepatocellular carcinoma among all hepatitis B infections | K27: sh_init
A28: chb_adj | B28: Initial prevalence of hepatitis B adjusted for progression of disease | H28: max(chb_init-chb_init*(cc_prop+dc_prop+hcc_prop), 0)
A29: init_cc | B29: Initial compensated cirrhosis population (undiagnosed) | C29: proportion | H29: max(chb_init*cc_prop, 0)
A30: init_dc | B30: Initial decompensated cirrhosis population (undiagnosed) | C30: proportion | H30: max(chb_init*dc_prop, 0)
A31: init_hcc | B31: Initial hepatocellular carcinoma population (undiagnosed) | C31: proportion | H31: max(chb_init*hcc_prop, 0)
A32: ei_prop | B32: Propoprtion of adjusted CHB positive with HBeAg positive chronic HBV infection (eag_init) | K32: sh_init
A33: si_prop | B33: Propoprtion of CHB positive with HBeAg negative chronic HBV infection (1-eag_init) | K33: sh_init
A34: init_ei | B34: Initial HBeAg positive chronic HBV infection (undiagnosed) | C34: proportion | H34: max(chb_adj*eag_init*ei_prop, 0)
A35: init_eh | B35: Initial HBeAg positive chronic hepatitis (undiagnosed) | C35: proportion | H35: max(chb_adj*eag_init*(1-ei_prop), 0)
A36: init_si | B36: Initial HBeAg negative chronic HBV infection (undiagnosed) | C36: proportion | H36: max(chb_adj*(1-eag_init)*si_prop, 0)
A37: init_sh | B37: Initial HBeAg negative chronic infection (undiagnosed) | C37: proportion | H37: max(chb_adj*(1-eag_init)*(1-si_prop), 0)
A38: init_clr | B38: Initial Recovered (HBsAg serocleared) | C38: proportion | K38: sh_init
A39: init_sus | B39: Initial Susceptible | C39: proportion | H39: max(1-(i_ei+i_eh+i_si+i_sh+i_cc+i_dc+i_hcc+i_rec), 0)
A40: #ignore | B40: Intervention (Vaccine and Treatment) Effectiveness
...

Sheet Characteristics
A1: Code Name | B1: Display Name | C1: Components | D1: Denominator | E1: Default Value | F1: Setup Weight | G1: Calibrate | H1: Databook Page | I1: Databook Order | J1: Guidance | K1: Population type | L1: Provenance
A2: total_pop | B2: Total Population | C2: j_init, sus, vax, imm_chb, acu, ei,ei_d,ei_l,ei_t,eh,eh_d,eh_l,eh_t,si,si_d,si_l,si_t,sh,sh_d,sh_l,sh_t,cc,cc_d,cc_l,cc_t,dc,dc_d,dc_l,dc_t,hcc,hcc_d,hcc_l,hcc_t | F2: 0 | H2: sh_demog
A3: hepb_pop | B3: Population with HBV | C3: ei,ei_d,ei_l,ei_t,eh,eh_d,eh_l,eh_t,si,si_d,si_l,si_t,sh,sh_d,sh_l,sh_t,cc,cc_d,cc_l,cc_t,dc,dc_d,dc_l,dc_t,hcc,hcc_d,hcc_l,hcc_t | F3: 0
A4: hepb_prev | B4: Prevalence of HBV | C4: hepb_pop | D4: total_pop | F4: 0
A5: undiagnosed | B5: Undiagnosed HepB | C5: ei,eh,si,sh,cc,dc,hcc
A6: diagnosed | B6: Diagnosed HepB | C6: ei_d,ei_l,ei_t,eh_d,eh_l,eh_t,si_d,si_l,si_t,sh_d,sh_l,sh_t,cc_d,cc_l,cc_t, dc_d,dc_l,dc_t,hcc_d,hcc_l,hcc_t
A7: linked | B7: Linked-to-care HepB | C7: ei_l,ei_t,eh_l,eh_t,si_l,si_t,sh_l,sh_t,cc_l,cc_t, dc_l,dc_t,hcc_l,hcc_t
A8: treated | B8: Treated HepB | C8: ei_t,eh_t,si_t,sh_t,cc_t,dc_t,hcc_t

Sheet Interactions
A1: Code Name | B1: Display Name | C1: Default Value | D1: From population type | E1: To population type
A2: interaction_1 | B2: Interaction 1 | C2: 1

Sheet Cascades
A1: Cascade name | B1: Constituents
A2: diag | B2: diagnosed,linked,treated
A3: link | B3: linked,treated
A4: treat | B4: treated

Sheet Plots
A1: Code Name | B1: Display Name | C1: Type | D1: Quantities | E1: Aggregate pops | F1: Plot Group
A2: comp1 | B2: Compartment 1 | C2: series | D2: alive
A3: comp2 | B3: Compartment 2 | C3: series | D3: alive
A4: both | D4: {'All':['comp1','comp2']}
